Workbook
Name AnnualFixed: 'Rate Card'!$B$21
Name FabRateIncKg: 'Rate Card'!$B$14
Name FabricAddon: 'Rate Card'!$B$28
Name LiveTotalContri: 'Live Contribution'!$L$281
Name MonthlyFixed: 'Rate Card'!$B$20
Name RM_rate: 'Rate Card'!$B$4
Name Stage1_RM: 'Rate Card'!$B$26
Name Stage2_Yarn: 'Rate Card'!$B$27
Name WCCharge: 'Rate Card'!$B$17

Sheet How to Use
A1: SKU CONTRIBUTION ENGINE v5 — Dual Purchase/Production Model
A3: What's new in v6
A4: Each SKU can now have TWO supply sources in the same year:
A5: • PURCHASED portion — fabric bought from outside and resold
A6: • PRODUCED portion — fabric made in-house (RM → Yarn → Fabric)
A8: The "Produced & Sold" quantity = Sales Kgs − Purchased Kgs:
A9: • POSITIVE → that many Kgs were sold from in-house production
A10: • NEGATIVE → more was purchased than sold; the excess moved to INVENTORY
A12: Contribution for each SKU =
A13: Sales Value − Purchased-portion cost − Produced-portion manufacturing cost
A15: The Purchased-portion cost comes from your actual purchase file (real ₹, not estimates).
A16: The Produced-portion cost is the engine's manufacturing build-up (RM + Yarn + Fabric Rate).
... A36: Change the Rate Card (e.g., new RM rate) and every SKU + the forecast update instantly.

Sheet Apr26
I1: 46113
C2: Sales Monofil From Production | D2: 67411 | E2: 19687267 | F2: 292.04829 | I2: Op Stk | J2: 82860386 | M2: VARIABLE & DIRECT EXPNS | N2: 46113
C3: Sales Monofil from Trading Yarn | D3: 6050 | E3: 1083000 | F3: 179.00826 | I3: Purchase-RM | J3: 226044 | M3: Wages-Fabric | N3: 260305 | O3: =N3/$D$2 -> 3.8614618
C4: Sales Monofil from Trading Fabric | D4: 22533 | E4: 6580724 | F4: 292.04828 | I4: Purchase-Trading | J4: 2224579 | M4: Wages-Inspection & Dispatch | N4: 641461 | O4: =N4/$D$2 -> 9.5156725
C5: Sales RM | D5: 0 | E5: 0 | F5: 0 | I5: Purchase Yarn | J5: 668801 | M5: Fabrication charges | N5: 6451860 | O5: =N5/$D$2 -> 95.709306
C6: Sales Trading Others | D6: 9589 | E6: 2502572 | F6: 260.98363 | I6: Purchase-Fabric+ Cons | J6: 6270684 | M6: Wages-Yarn | N6: 422294 | O6: =N6/$D$2 -> 6.2644672
C7: TOTAL SALES-> | D7: 105583 | E7: 29853563 | F7: 282.74971 | J7: =SUM(J2:J6) -> 92250494 | M7: Yarn Processing charges | N7: 425385 | O7: =N7/$D$2 -> 6.3103203
I8: Cl Stk | J8: 79351875 | M8: Freight Inward | N8: 55683 | O8: =N8/$D$2 -> 0.82602246
C9: Op stock RM | D9: 143489 | E9: 17774647 | F9: 123.87463 | J9: =J7-J8 -> 12898619 | M9: Power Bill | N9: 492773 | O9: =N9/$D$2 -> 7.3099791
C10: Purchase RM | D10: 827 | E10: 226044 | F10: 273.33011 | I10: Sales | J10: 29853563 | M10: R & M-Machinery | N10: 47508 | O10: =N10/$D$2 -> 0.70475145
C11: Cl Stock RM | D11: 78108 | E11: 10892019 | F11: 139.44819 | J11: =J10-J9 -> 16954944 | M11: R & M-Electricals | N11: 9746 | O11: =N11/$D$2 -> 0.14457581
C12: Consumption | D12: 66208 | E12: 7108672 | F12: 107.36878 | M12: Rent | N12: 530150 | O12: =N12/$D$2 -> 7.8644435
C13: RM Consumption Cost | D13: 0 | E13: 0 | F13: 0 | I13: Waste | J13: 21740 | M13: Packing charges | O13: =N13/$D$2 -> 0
C14: Monofil Consumption | D14: 66208 | E14: 7108672 | F14: 107.36878 | I14: GST Refund | M14: Misc | N14: 33730 | O14: =N14/$D$2 -> 0.50036344
C15: Monofil Purchase Yarn | D15: 3668 | E15: 668801 | F15: 182.33397 | I15: Othr Inc | J15: 65 | M15: Manufacturing Direct Expenses | N15: =SUM(N3:N14) -> 9370895 | O15: =N15/$D$2 -> 139.01136
C16: Monofil Purchase Fabric | D16: 22533 | E16: 6270684 | F16: 278.28891 | J16: =SUM(J11:J15) -> 16976749 | M16: Working Capital-Bank Charges | O16: =N16/$D$2 -> 0
C17: Trading Purchase | D17: 9489 | E17: 2224579 | F17: 234.43766 | I17: Direct Expns | J17: 4204754 | M17: Working Capital-LC | N17: 25280 | O17: =N17/$D$2 -> 0.37501298
C18: PFCo Consumption | D18: 101898 | E18: 16272736 | F18: 159.69632 | I18: GST Reversed | M18: Working Capital-OCC | N18: 323410 | O18: =N18/$D$2 -> 4.797585
C19: Stock Difference Monofil | D19: 9093 | E19: -3380536 | I19: In House Fabrn | J19: 616201 | M19: Workig Capital Expns | N19: =SUM(N16:N18) -> 348690 | O19: =N19/$D$2 -> 5.1725979
C20: Stock DifferenceTrading | D20: 100 | E20: 6419 | I20: Fabrication | J20: 6451860 | M20: Total Direct Expenses | N20: =N15+N19 -> 9719585 | O20: =N20/$D$2 -> 144.18396
C21: Total Stock Difference | D21: 9193 | E21: -3374117 | I21: Direct Cost | J21: =SUM(J17:J20) -> 11272815
C22: Total Consumption | D22: 111091 | E22: 12898619 | F22: 116.10859 | I22: Deprecition | J22: 125000 | M22: FIXED EXPNS
I23: Indirect Expns | J23: 961721 | M23: Employees welfare exp | N23: 1005846 | O23: =N23/$D$2 -> 14.921096
C24: Variable-Yarn Cost | E24: 1943381 | F24: 29.352661 | I24: Total Expns | J24: =SUM(J21:J23) -> 12359536 | M24: Salaries Office | N24: 371074 | O24: =N24/$D$2 -> 5.5046506
C25: Variable-Fabric Cost | E25: 7353626 | F25: 111.06854 | M25: Directors Remuneration | N25: 525000 | O25: =N25/$D$2 -> 7.7880465
C26: Variable-Trading | E26: 99168 | F26: 4.4010118 | I26: Profit (A) | J26: =J16-J24 -> 4617213 | M26: Depreciation | N26: 125000 | O26: =N26/$D$2 -> 1.8542968
C27: Variable-Finance | E27: 348690 | F27: 3.4219514 | M27: Admn Expns | N27: 435924 | O27: =N27/$D$2 -> 6.4666597
C28: Total Variable | E28: 9744865 | F28: 95.633526 | M28: Selling Expns | N28: 67213 | O28: =N28/$D$2 -> 0.99706279
C29: Fixed Cost | E29: 2489671 | F29: 24.432972 | M29: Finance Cost-Int On Term Loan | N29: 11281 | O29: =N29/$D$2 -> 0.16734658
C30: Deprn | E30: 125000 | F30: 1.2267169 | M30: Finance Cost-Int On Deposits | N30: 73333 | O30: =N30/$D$2 -> 1.0878492
C31: Total Expenses | E31: 12359536 | N31: =SUM(N23:N30) -> 2614671 | O31: =N31/$D$2 -> 38.787008
C32: Fixed Expns Break up
C33: Salaries | E33: 1901920 | F33: 17.120379
C34: Admn | E34: 435924 | F34: 3.9240262
C35: Selling | E35: 67213 | F35: 0.60502651
C36: Deprn | E36: 125000 | F36: 1.1252037
C37: Interest USL | E37: 433304 | F37: 3.900442
E38: 2963361 | F38: 26.675077
C40: Waste Income | E40: 21740
C41: Other Income | E41: 65
...

Sheet Rate Card
A1: RATE CARD — Change yellow cells to flex the entire model
A3: STAGE 1 — RM Rate
A4: RM rate (HDPE granules) | B4: =IF('Quote Builder'!D4=0,'Apr26'!F14,'Quote Builder'!D4) -> 107.37 | C4: ₹/Kg of RM | D4: FY25-26 actual. Change for forecasts.
A5: Yield (Kg RM input per Kg fabric) | B5: 1.0037 | C5: Kg/Kg | D5: 99.63% historical yield
A6: Wastage allowance | B6: 0.02 | C6: % | D6: On RM cost. Hist=0 (actual consumption). Set 5% for forecasts.
A8: STAGE 2 — Yarn Processing Rate (blended)
A9: In-house yarn cost per Kg | B9: ='Apr26'!F24 -> 29.352661 | C9: ₹/Kg | D9: Wages-Yarn + Power + Freight + Rent + R&M + Misc
A10: Outsourced yarn rate per Kg | B10: =IF('Quote Builder'!D5=0,28,28+'Quote Builder'!D5) -> 30 | C10: ₹/Kg | D10: Paid to external yarn converter
A11: Outsourced % of total yarn | B11: 0.305 | C11: % | D11: FY25-26: 30.5%
A13: STAGE 3 — Fabric Rate Components
A14: Fab Rate increase per Kg | B14: =IF('Quote Builder'!D6=0,0,'Quote Builder'!D6) -> 0 | C14: ₹/Kg | D14: Flat ₹/Kg increase. Hist=0. Set ₹2 for forecasts.
A15: Wages — Fabric | B15: ='Apr26'!O3 -> 3.8614618 | C15: ₹/Kg | D15: Weaving labour
A16: Wages — Inspection & Dispatch | B16: ='Apr26'!O4 -> 9.5156725 | C16: ₹/Kg | D16: QC + shipment labour
A17: Working Capital (Bank+LC+OCC) | B17: ='Apr26'!O19 -> 5.1725979 | C17: ₹/Kg | D17: Financing cost
A19: FIXED COST
A20: Monthly Fixed Expenses | B20: ='Apr26'!E38 -> 2963361 | C20: ₹ | D20: For this month
A21: Annual Fixed Expenses | B21: =B20*12 -> 35560332 | C21: ₹/year
A23: DERIVED RATES (auto-calculated)
A24: RM cost per Kg of fabric | B24: =B4*B5 -> 107.76727
A25: Wastage per Kg of fabric | B25: =B24*B6 -> 2.1553454
A26: STAGE 1 TOTAL — RM Rate per Kg | B26: =B24+B25 -> 109.92261
A27: STAGE 2 TOTAL — Yarn Proc Rate per Kg (blended) | B27: =B9*(1-B11)+B10*B11 -> 29.5501
A28: Fabric Rate add-on (common, ex SKU-specific fab) | B28: =B15+B16+B17 -> 18.549732

Sheet SKU Master
A1: SKU MASTER — Per-SKU data. Empty rows below for new SKUs.
A2: Yellow = your inputs. Blue = semi-static / historical. Grey = derived.
A4: Sl | B4: Code | C4: Product | D4: Colour | E4: Wt/Mt | F4: Rate/Mt (₹/Mtr) | G4: Fab Rate ₹/Kg (derived) | H4: Mfg Cost ₹/Kg (derived) | I4: Hist Sale Kgs | J4: Hist Sale Value | K4: Hist Purchase Kgs | L4: Hist Purchase Value | M4: Hist Purch Rate ₹/Kg | N4: Hist Avg SP ₹/Kg
A5: 1 | B5: 126 | C5: Priya-Gold Max 54" | D5: Blue | E5: =_xlfn.XLOOKUP(B5,'Ratio Master'!$A:$A,'Ratio Master'!$G:$G,"") -> 0.094364576 | F5: =_xlfn.XLOOKUP(B5,'Ratio Master'!$A:$A,'Ratio Master'!$F:$F,"") -> 5.7 | G5: {=IF(AND(E5>0,F5>0),(F5/E5)+FabRateIncKg,0)} -> 60.404023 | H5: =IF(OR(E5="",E5=0),0,Stage1_RM+Stage2_Yarn+G5+FabricAddon) -> 218.42647 | I5: 181.8 | J5: 54000 | M5: =IFERROR(L5/K5,0) -> 0 | N5: =IFERROR(J5/I5,"") -> 297.0297
A6: 2 | B6: 144 | C6: HF 54" | D6: Blue | E6: =_xlfn.XLOOKUP(B6,'Ratio Master'!$A:$A,'Ratio Master'!$G:$G,"") -> 0.039991399 | F6: =_xlfn.XLOOKUP(B6,'Ratio Master'!$A:$A,'Ratio Master'!$F:$F,"") -> 4.7 | G6: {=IF(AND(E6>0,F6>0),(F6/E6)+FabRateIncKg,0)} -> 117.52527 | H6: =IF(OR(E6="",E6=0),0,Stage1_RM+Stage2_Yarn+G6+FabricAddon) -> 275.54772 | I6: 2124.41 | J6: 730296 | M6: =IFERROR(L6/K6,0) -> 0 | N6: =IFERROR(J6/I6,"") -> 343.76415
A7: 3 | B7: 164 | C7: HF 54" | D7: White | E7: =_xlfn.XLOOKUP(B7,'Ratio Master'!$A:$A,'Ratio Master'!$G:$G,"") -> 0.038631111 | F7: =_xlfn.XLOOKUP(B7,'Ratio Master'!$A:$A,'Ratio Master'!$F:$F,"") -> 4.7 | G7: {=IF(AND(E7>0,F7>0),(F7/E7)+FabRateIncKg,0)} -> 121.6636 | H7: =IF(OR(E7="",E7=0),0,Stage1_RM+Stage2_Yarn+G7+FabricAddon) -> 279.68604 | I7: 92.2 | J7: 38400 | M7: =IFERROR(L7/K7,0) -> 0 | N7: =IFERROR(J7/I7,"") -> 416.4859
A8: 4 | B8: 167 | C8: HP 120" | D8: Sea Green | E8: =_xlfn.XLOOKUP(B8,'Ratio Master'!$A:$A,'Ratio Master'!$G:$G,"") -> 0.16016026 | F8: =_xlfn.XLOOKUP(B8,'Ratio Master'!$A:$A,'Ratio Master'!$F:$F,"") -> 12 | G8: {=IF(AND(E8>0,F8>0),(F8/E8)+FabRateIncKg,0)} -> 74.924955 | H8: =IF(OR(E8="",E8=0),0,Stage1_RM+Stage2_Yarn+G8+FabricAddon) -> 232.9474 | I8: 65.44 | J8: 22400 | M8: =IFERROR(L8/K8,0) -> 0 | N8: =IFERROR(J8/I8,"") -> 342.29829
A9: 5 | B9: 177 | C9: Kangaroo 120" | D9: Blue | E9: =_xlfn.XLOOKUP(B9,'Ratio Master'!$A:$A,'Ratio Master'!$G:$G,"") -> 0.17398272 | F9: =_xlfn.XLOOKUP(B9,'Ratio Master'!$A:$A,'Ratio Master'!$F:$F,"") -> 12 | G9: {=IF(AND(E9>0,F9>0),(F9/E9)+FabRateIncKg,0)} -> 68.972368 | H9: =IF(OR(E9="",E9=0),0,Stage1_RM+Stage2_Yarn+G9+FabricAddon) -> 226.99481 | I9: 318.74 | J9: 106200 | M9: =IFERROR(L9/K9,0) -> 0 | N9: =IFERROR(J9/I9,"") -> 333.18692
A10: 6 | B10: 179 | C10: Kangaroo 54" | D10: Blue | E10: =_xlfn.XLOOKUP(B10,'Ratio Master'!$A:$A,'Ratio Master'!$G:$G,"") -> 0.079027579 | F10: =_xlfn.XLOOKUP(B10,'Ratio Master'!$A:$A,'Ratio Master'!$F:$F,"") -> 5.7 | G10: {=IF(AND(E10>0,F10>0),(F10/E10)+FabRateIncKg,0)} -> 72.126719 | H10: =IF(OR(E10="",E10=0),0,Stage1_RM+Stage2_Yarn+G10+FabricAddon) -> 230.14917 | I10: 5943.01 | J10: 1799625 | M10: =IFERROR(L10/K10,0) -> 0 | N10: =IFERROR(J10/I10,"") -> 302.81373
A11: 7 | B11: 188 | C11: Kangaroo 60" | D11: Blue | E11: =_xlfn.XLOOKUP(B11,'Ratio Master'!$A:$A,'Ratio Master'!$G:$G,"") -> 0.088402083 | F11: =_xlfn.XLOOKUP(B11,'Ratio Master'!$A:$A,'Ratio Master'!$F:$F,"") -> 5.7 | G11: {=IF(AND(E11>0,F11>0),(F11/E11)+FabRateIncKg,0)} -> 64.478118 | H11: =IF(OR(E11="",E11=0),0,Stage1_RM+Stage2_Yarn+G11+FabricAddon) -> 222.50056 | I11: 459.72 | J11: 151500 | M11: =IFERROR(L11/K11,0) -> 0 | N11: =IFERROR(J11/I11,"") -> 329.54842
A12: 8 | B12: 193 | C12: Kangaroo 84" | D12: Blue | E12: =_xlfn.XLOOKUP(B12,'Ratio Master'!$A:$A,'Ratio Master'!$G:$G,"") -> 0.12145151 | F12: =_xlfn.XLOOKUP(B12,'Ratio Master'!$A:$A,'Ratio Master'!$F:$F,"") -> 8.5 | G12: {=IF(AND(E12>0,F12>0),(F12/E12)+FabRateIncKg,0)} -> 69.986781 | H12: =IF(OR(E12="",E12=0),0,Stage1_RM+Stage2_Yarn+G12+FabricAddon) -> 228.00923 | I12: 429.36 | J12: 137500 | M12: =IFERROR(L12/K12,0) -> 0 | N12: =IFERROR(J12/I12,"") -> 320.24408
A13: 9 | B13: 199 | C13: Lotus 54" | D13: Badam Pink | E13: =_xlfn.XLOOKUP(B13,'Ratio Master'!$A:$A,'Ratio Master'!$G:$G,"") -> 0.049681788 | F13: =_xlfn.XLOOKUP(B13,'Ratio Master'!$A:$A,'Ratio Master'!$F:$F,"") -> 5 | G13: {=IF(AND(E13>0,F13>0),(F13/E13)+FabRateIncKg,0)} -> 100.6405 | H13: =IF(OR(E13="",E13=0),0,Stage1_RM+Stage2_Yarn+G13+FabricAddon) -> 258.66295 | I13: 135.39 | J13: 43725 | M13: =IFERROR(L13/K13,0) -> 0 | N13: =IFERROR(J13/I13,"") -> 322.95591
A14: 10 | B14: 200 | C14: Lotus 54" | D14: Ivory | E14: =_xlfn.XLOOKUP(B14,'Ratio Master'!$A:$A,'Ratio Master'!$G:$G,"") -> 0.049319799 | F14: =_xlfn.XLOOKUP(B14,'Ratio Master'!$A:$A,'Ratio Master'!$F:$F,"") -> 5 | G14: {=IF(AND(E14>0,F14>0),(F14/E14)+FabRateIncKg,0)} -> 101.37916 | H14: =IF(OR(E14="",E14=0),0,Stage1_RM+Stage2_Yarn+G14+FabricAddon) -> 259.40161 | I14: 100.9 | J14: 33275 | M14: =IFERROR(L14/K14,0) -> 0 | N14: =IFERROR(J14/I14,"") -> 329.78196
A15: 11 | B15: 201 | C15: Lotus 54" | D15: Light Sea Green | E15: =_xlfn.XLOOKUP(B15,'Ratio Master'!$A:$A,'Ratio Master'!$G:$G,"") -> 0.050999278 | F15: =_xlfn.XLOOKUP(B15,'Ratio Master'!$A:$A,'Ratio Master'!$F:$F,"") -> 5 | G15: {=IF(AND(E15>0,F15>0),(F15/E15)+FabRateIncKg,0)} -> 98.040604 | H15: =IF(OR(E15="",E15=0),0,Stage1_RM+Stage2_Yarn+G15+FabricAddon) -> 256.06305 | I15: 225.31 | J15: 68750 | M15: =IFERROR(L15/K15,0) -> 0 | N15: =IFERROR(J15/I15,"") -> 305.13515
A16: 12 | B16: 204 | C16: Lotus 54" | D16: Rose Pink | E16: =_xlfn.XLOOKUP(B16,'Ratio Master'!$A:$A,'Ratio Master'!$G:$G,"") -> 0.049247463 | F16: =_xlfn.XLOOKUP(B16,'Ratio Master'!$A:$A,'Ratio Master'!$F:$F,"") -> 5 | G16: {=IF(AND(E16>0,F16>0),(F16/E16)+FabRateIncKg,0)} -> 101.52807 | H16: =IF(OR(E16="",E16=0),0,Stage1_RM+Stage2_Yarn+G16+FabricAddon) -> 259.55052 | I16: 136.12 | J16: 43725 | M16: =IFERROR(L16/K16,0) -> 0 | N16: =IFERROR(J16/I16,"") -> 321.22392
... A40: 36 | B40: 438 | C40: 20 Mesh MQ 120" | D40: SF Blue | E40: =_xlfn.XLOOKUP(B40,'Ratio Master'!$A:$A,'Ratio Master'!$G:$G,"") -> 0.23072149 | F40: =_xlfn.XLOOKUP(B40,'Ratio Master'!$A:$A,'Ratio Master'!$F:$F,"") -> 13 | G40: {=IF(AND(E40>0,F40>0),(F40/E40)+FabRateIncKg,0)} -> 56.344989 | H40: =IF(OR(E40="",E40=0),0,Stage1_RM+Stage2_Yarn+G40+FabricAddon) -> 214.36744 | I40: 275.6 | J40: 73200 | M40: =IFERROR(L40/K40,0) -> 0 | N40: =IFERROR(J40/I40,"") -> 265.60232
A41: 37 | B41: 439 | C41: 20 Mesh MQ 120" | D41: White | E41: =_xlfn.XLOOKUP(B41,'Ratio Master'!$A:$A,'Ratio Master'!$G:$G,"") -> 0.24121369 | F41: =_xlfn.XLOOKUP(B41,'Ratio Master'!$A:$A,'Ratio Master'!$F:$F,"") -> 13 | G41: {=IF(AND(E41>0,F41>0),(F41/E41)+FabRateIncKg,0)} -> 53.894122 | H41: =IF(OR(E41="",E41=0),0,Stage1_RM+Stage2_Yarn+G41+FabricAddon) -> 211.91657 | I41: 702 | J41: 225000 | K41: 2933.5 | L41: 856936 | M41: =IFERROR(L41/K41,0) -> 292.12067 | N41: =IFERROR(J41/I41,"") -> 320.51282
A42: 38 | B42: 445 | C42: 20 Mesh MQ 42" | D42: Black | E42: =_xlfn.XLOOKUP(B42,'Ratio Master'!$A:$A,'Ratio Master'!$G:$G,"") -> 0.082414277 | F42: =_xlfn.XLOOKUP(B42,'Ratio Master'!$A:$A,'Ratio Master'!$F:$F,"") -> 6 | G42: {=IF(AND(E42>0,F42>0),(F42/E42)+FabRateIncKg,0)} -> 72.80292 | H42: =IF(OR(E42="",E42=0),0,Stage1_RM+Stage2_Yarn+G42+FabricAddon) -> 230.82537 | I42: 432.8 | J42: 91800 | M42: =IFERROR(L42/K42,0) -> 0 | N42: =IFERROR(J42/I42,"") -> 212.10721
A43: 39 | B43: 451 | C43: 20 Mesh MQ 42" | D43: RP Blue | E43: =_xlfn.XLOOKUP(B43,'Ratio Master'!$A:$A,'Ratio Master'!$G:$G,"") -> 0.079495301 | F43: =_xlfn.XLOOKUP(B43,'Ratio Master'!$A:$A,'Ratio Master'!$F:$F,"") -> 6 | G43: {=IF(AND(E43>0,F43>0),(F43/E43)+FabRateIncKg,0)} -> 75.476159 | H43: =IF(OR(E43="",E43=0),0,Stage1_RM+Stage2_Yarn+G43+FabricAddon) -> 233.49861 | I43: 1192.1 | J43: 261360 | K43: 590.4 | L43: 127500 | M43: =IFERROR(L43/K43,0) -> 215.95528 | N43: =IFERROR(J43/I43,"") -> 219.24335
A44: 40 | B44: 453 | C44: 20 Mesh MQ 42" | D44: Sea Green | E44: =_xlfn.XLOOKUP(B44,'Ratio Master'!$A:$A,'Ratio Master'!$G:$G,"") -> 0.088133333 | F44: =_xlfn.XLOOKUP(B44,'Ratio Master'!$A:$A,'Ratio Master'!$F:$F,"") -> 6 | G44: {=IF(AND(E44>0,F44>0),(F44/E44)+FabRateIncKg,0)} -> 68.078669 | H44: =IF(OR(E44="",E44=0),0,Stage1_RM+Stage2_Yarn+G44+FabricAddon) -> 226.10111 | I44: 161.6 | J44: 45000 | M44: =IFERROR(L44/K44,0) -> 0 | N44: =IFERROR(J44/I44,"") -> 278.46535
A45: 41 | B45: 454 | C45: 20 Mesh MQ 42" | D45: White | E45: =_xlfn.XLOOKUP(B45,'Ratio Master'!$A:$A,'Ratio Master'!$G:$G,"") -> 0.088795751 | F45: =_xlfn.XLOOKUP(B45,'Ratio Master'!$A:$A,'Ratio Master'!$F:$F,"") -> 6 | G45: {=IF(AND(E45>0,F45>0),(F45/E45)+FabRateIncKg,0)} -> 67.570801 | H45: =IF(OR(E45="",E45=0),0,Stage1_RM+Stage2_Yarn+G45+FabricAddon) -> 225.59325 | I45: 427.7 | J45: 124200 | K45: 1352 | L45: 380496 | M45: =IFERROR(L45/K45,0) -> 281.43195 | N45: =IFERROR(J45/I45,"") -> 290.39046
A46: 42 | B46: 456 | C46: 20 Mesh MQ 48" | D46: Black | E46: =_xlfn.XLOOKUP(B46,'Ratio Master'!$A:$A,'Ratio Master'!$G:$G,"") -> 0.10266234 | F46: =_xlfn.XLOOKUP(B46,'Ratio Master'!$A:$A,'Ratio Master'!$F:$F,"") -> 5.75 | G46: {=IF(AND(E46>0,F46>0),(F46/E46)+FabRateIncKg,0)} -> 56.008855 | H46: =IF(OR(E46="",E46=0),0,Stage1_RM+Stage2_Yarn+G46+FabricAddon) -> 214.0313 | I46: 734.3 | J46: 187200 | M46: =IFERROR(L46/K46,0) -> 0 | N46: =IFERROR(J46/I46,"") -> 254.93667
A47: 43 | B47: 457 | C47: 20 Mesh MQ 48" | D47: Blue | E47: =_xlfn.XLOOKUP(B47,'Ratio Master'!$A:$A,'Ratio Master'!$G:$G,"") -> 0.1003029 | F47: =_xlfn.XLOOKUP(B47,'Ratio Master'!$A:$A,'Ratio Master'!$F:$F,"") -> 5.75 | G47: {=IF(AND(E47>0,F47>0),(F47/E47)+FabRateIncKg,0)} -> 57.326356 | H47: =IF(OR(E47="",E47=0),0,Stage1_RM+Stage2_Yarn+G47+FabricAddon) -> 215.3488 | I47: 2095.1 | J47: 546000 | K47: 113.5 | L47: 24420 | M47: =IFERROR(L47/K47,0) -> 215.15419 | N47: =IFERROR(J47/I47,"") -> 260.60809
A48: 44 | B48: 458 | C48: 20 Mesh MQ 48" | D48: Grey | E48: =_xlfn.XLOOKUP(B48,'Ratio Master'!$A:$A,'Ratio Master'!$G:$G,"") -> 0.098459218 | F48: =_xlfn.XLOOKUP(B48,'Ratio Master'!$A:$A,'Ratio Master'!$F:$F,"") -> 5.75 | G48: {=IF(AND(E48>0,F48>0),(F48/E48)+FabRateIncKg,0)} -> 58.399814 | H48: =IF(OR(E48="",E48=0),0,Stage1_RM+Stage2_Yarn+G48+FabricAddon) -> 216.42226 | I48: 1807.2 | J48: 468990 | M48: =IFERROR(L48/K48,0) -> 0 | N48: =IFERROR(J48/I48,"") -> 259.51195
A49: 45 | B49: 459 | C49: 20 Mesh MQ 48" | D49: Green | E49: =_xlfn.XLOOKUP(B49,'Ratio Master'!$A:$A,'Ratio Master'!$G:$G,"") -> 0.099565341 | F49: =_xlfn.XLOOKUP(B49,'Ratio Master'!$A:$A,'Ratio Master'!$F:$F,"") -> 5.75 | G49: {=IF(AND(E49>0,F49>0),(F49/E49)+FabRateIncKg,0)} -> 57.75102 | H49: =IF(OR(E49="",E49=0),0,Stage1_RM+Stage2_Yarn+G49+FabricAddon) -> 215.77347 | I49: 1501.8 | J49: 390000 | K49: 455.5 | L49: 103840 | M49: =IFERROR(L49/K49,0) -> 227.96926 | N49: =IFERROR(J49/I49,"") -> 259.68837
A50: 46 | B50: 460 | C50: 20 Mesh MQ 48" | D50: Ivory | E50: =_xlfn.XLOOKUP(B50,'Ratio Master'!$A:$A,'Ratio Master'!$G:$G,"") -> 0.10174279 | F50: =_xlfn.XLOOKUP(B50,'Ratio Master'!$A:$A,'Ratio Master'!$F:$F,"") -> 5.75 | G50: {=IF(AND(E50>0,F50>0),(F50/E50)+FabRateIncKg,0)} -> 56.515064 | H50: =IF(OR(E50="",E50=0),0,Stage1_RM+Stage2_Yarn+G50+FabricAddon) -> 214.53751 | I50: 205.1 | J50: 63000 | M50: =IFERROR(L50/K50,0) -> 0 | N50: =IFERROR(J50/I50,"") -> 307.16724
A51: 47 | B51: 468 | C51: 20 Mesh MQ 48" | D51: White | E51: =_xlfn.XLOOKUP(B51,'Ratio Master'!$A:$A,'Ratio Master'!$G:$G,"") -> 0.10056971 | F51: =_xlfn.XLOOKUP(B51,'Ratio Master'!$A:$A,'Ratio Master'!$F:$F,"") -> 5.75 | G51: {=IF(AND(E51>0,F51>0),(F51/E51)+FabRateIncKg,0)} -> 57.174272 | H51: =IF(OR(E51="",E51=0),0,Stage1_RM+Stage2_Yarn+G51+FabricAddon) -> 215.19672 | I51: 299.6 | J51: 90000 | M51: =IFERROR(L51/K51,0) -> 0 | N51: =IFERROR(J51/I51,"") -> 300.40053
A52: 48 | B52: 469 | C52: 20 Mesh MQ 60" | D52: Black | E52: =_xlfn.XLOOKUP(B52,'Ratio Master'!$A:$A,'Ratio Master'!$G:$G,"") -> 0.12273504 | F52: =_xlfn.XLOOKUP(B52,'Ratio Master'!$A:$A,'Ratio Master'!$F:$F,"") -> 6.75 | G52: {=IF(AND(E52>0,F52>0),(F52/E52)+FabRateIncKg,0)} -> 54.996518 | H52: =IF(OR(E52="",E52=0),0,Stage1_RM+Stage2_Yarn+G52+FabricAddon) -> 213.01896 | I52: 850 | J52: 219375 | M52: =IFERROR(L52/K52,0) -> 0 | N52: =IFERROR(J52/I52,"") -> 258.08824
A53: 49 | B53: 470 | C53: 20 Mesh MQ 60" | D53: Blue | E53: =_xlfn.XLOOKUP(B53,'Ratio Master'!$A:$A,'Ratio Master'!$G:$G,"") -> 0.12551057 | F53: =_xlfn.XLOOKUP(B53,'Ratio Master'!$A:$A,'Ratio Master'!$F:$F,"") -> 6.75 | G53: {=IF(AND(E53>0,F53>0),(F53/E53)+FabRateIncKg,0)} -> 53.780331 | H53: =IF(OR(E53="",E53=0),0,Stage1_RM+Stage2_Yarn+G53+FabricAddon) -> 211.80278 | I53: 2851.9 | J53: 731250 | M53: =IFERROR(L53/K53,0) -> 0 | N53: =IFERROR(J53/I53,"") -> 256.40801
A54: 50 | B54: 471 | C54: 20 Mesh MQ 60" | D54: Grey | E54: =_xlfn.XLOOKUP(B54,'Ratio Master'!$A:$A,'Ratio Master'!$G:$G,"") -> 0.12442673 | F54: =_xlfn.XLOOKUP(B54,'Ratio Master'!$A:$A,'Ratio Master'!$F:$F,"") -> 6.75 | G54: {=IF(AND(E54>0,F54>0),(F54/E54)+FabRateIncKg,0)} -> 54.248795 | H54: =IF(OR(E54="",E54=0),0,Stage1_RM+Stage2_Yarn+G54+FabricAddon) -> 212.27124 | I54: 1935.4 | J54: 511875 | M54: =IFERROR(L54/K54,0) -> 0 | N54: =IFERROR(J54/I54,"") -> 264.48021
A55: 51 | B55: 472 | C55: 20 Mesh MQ 60" | D55: Green | E55: =_xlfn.XLOOKUP(B55,'Ratio Master'!$A:$A,'Ratio Master'!$G:$G,"") -> 0.12576347 | F55: =_xlfn.XLOOKUP(B55,'Ratio Master'!$A:$A,'Ratio Master'!$F:$F,"") -> 6.75 | G55: {=IF(AND(E55>0,F55>0),(F55/E55)+FabRateIncKg,0)} -> 53.672183 | H55: =IF(OR(E55="",E55=0),0,Stage1_RM+Stage2_Yarn+G55+FabricAddon) -> 211.69463 | I55: 1898.7 | J55: 511875 | M55: =IFERROR(L55/K55,0) -> 0 | N55: =IFERROR(J55/I55,"") -> 269.59235
A56: 52 | B56: 478 | C56: 20 Mesh MQ 84" | D56: Black | E56: =_xlfn.XLOOKUP(B56,'Ratio Master'!$A:$A,'Ratio Master'!$G:$G,"") -> 0.16849673 | F56: =_xlfn.XLOOKUP(B56,'Ratio Master'!$A:$A,'Ratio Master'!$F:$F,"") -> 9.5 | G56: {=IF(AND(E56>0,F56>0),(F56/E56)+FabRateIncKg,0)} -> 56.380915 | H56: =IF(OR(E56="",E56=0),0,Stage1_RM+Stage2_Yarn+G56+FabricAddon) -> 214.40336 | I56: 298.8 | J56: 59400 | M56: =IFERROR(L56/K56,0) -> 0 | N56: =IFERROR(J56/I56,"") -> 198.79518
A57: 53 | B57: 484 | C57: 20 Mesh MQ 84" | D57: Green | E57: =_xlfn.XLOOKUP(B57,'Ratio Master'!$A:$A,'Ratio Master'!$G:$G,"") -> 0.17190909 | F57: =_xlfn.XLOOKUP(B57,'Ratio Master'!$A:$A,'Ratio Master'!$F:$F,"") -> 9.5 | G57: {=IF(AND(E57>0,F57>0),(F57/E57)+FabRateIncKg,0)} -> 55.261766 | H57: =IF(OR(E57="",E57=0),0,Stage1_RM+Stage2_Yarn+G57+FabricAddon) -> 213.28421 | I57: 101.5 | J57: 30000 | M57: =IFERROR(L57/K57,0) -> 0 | N57: =IFERROR(J57/I57,"") -> 295.5665
A58: 54 | B58: 487 | C58: 20 Mesh MQ 84" | D58: Military Green | E58: =_xlfn.XLOOKUP(B58,'Ratio Master'!$A:$A,'Ratio Master'!$G:$G,"") -> 0.15777778 | F58: =_xlfn.XLOOKUP(B58,'Ratio Master'!$A:$A,'Ratio Master'!$F:$F,"") -> 9.5 | G58: {=IF(AND(E58>0,F58>0),(F58/E58)+FabRateIncKg,0)} -> 60.211268 | H58: =IF(OR(E58="",E58=0),0,Stage1_RM+Stage2_Yarn+G58+FabricAddon) -> 218.23371 | I58: 782.5 | J58: 156240 | M58: =IFERROR(L58/K58,0) -> 0 | N58: =IFERROR(J58/I58,"") -> 199.66773
A59: 55 | B59: 489 | C59: 20 Mesh MQ 84" | D59: Premium White | E59: =_xlfn.XLOOKUP(B59,'Ratio Master'!$A:$A,'Ratio Master'!$G:$G,"") -> 0.15035317 | F59: =_xlfn.XLOOKUP(B59,'Ratio Master'!$A:$A,'Ratio Master'!$F:$F,"") -> 9.5 | G59: {=IF(AND(E59>0,F59>0),(F59/E59)+FabRateIncKg,0)} -> 63.184565 | H59: =IF(OR(E59="",E59=0),0,Stage1_RM+Stage2_Yarn+G59+FabricAddon) -> 221.20701 | I59: 596.9 | J59: 154440 | M59: =IFERROR(L59/K59,0) -> 0 | N59: =IFERROR(J59/I59,"") -> 258.73681
A60: 56 | B60: 490 | C60: 20 Mesh MQ 84" | D60: PF Blue | E60: =_xlfn.XLOOKUP(B60,'Ratio Master'!$A:$A,'Ratio Master'!$G:$G,"") -> 0.16940639 | F60: =_xlfn.XLOOKUP(B60,'Ratio Master'!$A:$A,'Ratio Master'!$F:$F,"") -> 9.5 | G60: {=IF(AND(E60>0,F60>0),(F60/E60)+FabRateIncKg,0)} -> 56.078167 | H60: =IF(OR(E60="",E60=0),0,Stage1_RM+Stage2_Yarn+G60+FabricAddon) -> 214.10061 | I60: 156.2 | J60: 38700 | M60: =IFERROR(L60/K60,0) -> 0 | N60: =IFERROR(J60/I60,"") -> 247.75928
A61: 57 | B61: 493 | C61: 20 Mesh MQ 84" | D61: Light Blue | E61: =_xlfn.XLOOKUP(B61,'Ratio Master'!$A:$A,'Ratio Master'!$G:$G,"") -> 0.15827533 | F61: =_xlfn.XLOOKUP(B61,'Ratio Master'!$A:$A,'Ratio Master'!$F:$F,"") -> 9.5 | G61: {=IF(AND(E61>0,F61>0),(F61/E61)+FabRateIncKg,0)} -> 60.021989 | H61: =IF(OR(E61="",E61=0),0,Stage1_RM+Stage2_Yarn+G61+FabricAddon) -> 218.04444 | I61: 993.8 | J61: 211680 | M61: =IFERROR(L61/K61,0) -> 0 | N61: =IFERROR(J61/I61,"") -> 213.0006
... A67: 63 | B67: 539 | C67: 24 Mesh LQ 42" | D67: Black | E67: =_xlfn.XLOOKUP(B67,'Ratio Master'!$A:$A,'Ratio Master'!$G:$G,"") -> 0.052351731 | F67: =_xlfn.XLOOKUP(B67,'Ratio Master'!$A:$A,'Ratio Master'!$F:$F,"") -> 4.6 | G67: {=IF(AND(E67>0,F67>0),(F67/E67)+FabRateIncKg,0)} -> 87.8672 | H67: =IF(OR(E67="",E67=0),0,Stage1_RM+Stage2_Yarn+G67+FabricAddon) -> 245.88965 | I67: 969.82 | J67: 338625 | M67: =IFERROR(L67/K67,0) -> 0 | N67: =IFERROR(J67/I67,"") -> 349.16273
A68: 64 | B68: 540 | C68: 24 Mesh LQ 42" | D68: Blue | E68: =_xlfn.XLOOKUP(B68,'Ratio Master'!$A:$A,'Ratio Master'!$G:$G,"") -> 0.050276539 | F68: =_xlfn.XLOOKUP(B68,'Ratio Master'!$A:$A,'Ratio Master'!$F:$F,"") -> 4.6 | G68: {=IF(AND(E68>0,F68>0),(F68/E68)+FabRateIncKg,0)} -> 91.493968 | H68: =IF(OR(E68="",E68=0),0,Stage1_RM+Stage2_Yarn+G68+FabricAddon) -> 249.51641 | I68: 7876.6 | J68: 2302650 | K68: 4336.8 | L68: 1082655 | M68: =IFERROR(L68/K68,0) -> 249.64375 | N68: =IFERROR(J68/I68,"") -> 292.3406
A69: 65 | B69: 551 | C69: 24 Mesh LQ 42" | D69: Rose Pink | E69: =_xlfn.XLOOKUP(B69,'Ratio Master'!$A:$A,'Ratio Master'!$G:$G,"") -> 0.045963719 | F69: =_xlfn.XLOOKUP(B69,'Ratio Master'!$A:$A,'Ratio Master'!$F:$F,"") -> 4.6 | G69: {=IF(AND(E69>0,F69>0),(F69/E69)+FabRateIncKg,0)} -> 100.07893 | H69: =IF(OR(E69="",E69=0),0,Stage1_RM+Stage2_Yarn+G69+FabricAddon) -> 258.10138 | I69: 458.3 | J69: 146160 | M69: =IFERROR(L69/K69,0) -> 0 | N69: =IFERROR(J69/I69,"") -> 318.91774
...

Sheet Live Contribution
A1: LIVE CONTRIBUTION — Purchased + Produced split per SKU
A3: Each SKU: Sales − Purchased-portion cost − Produced-portion mfg cost. Negative Produced Kgs = excess moved to inventory.
A5: Sl | B5: Code | C5: Product | D5: Sale Kgs | E5: Sale Value | F5: Purch Kgs | G5: Purch Cost | H5: Prod Kgs (Sold) | I5: Prod Mfg Cost | J5: Inventory Flag | K5: Total Cost | L5: Contribution | M5: Contri/Kg | N5: Status
A6: 1 | B6: =IF('SKU Master'!B5="","",'SKU Master'!B5) -> 126 | C6: ='SKU Master'!C5 -> Priya-Gold Max 54" | D6: ='SKU Master'!I5 -> 181.8 | E6: ='SKU Master'!J5 -> 54000 | F6: ='SKU Master'!K5 -> 0 | G6: ='SKU Master'!L5 -> 0 | H6: =MAX(D6-F6,0) -> 181.8 | I6: =H6*'SKU Master'!H5 -> 39709.932 | J6: =IF(D6-F6<-0.5,"EXCESS→INV",IF(D6-F6>0.5,"Produced","Matched")) -> Produced | K6: =IF(F6>D6,D6*'SKU Master'!M5,G6)+I6 -> 39709.932 | L6: =IF(E6=0,0,E6-K6) -> 14290.068 | M6: =IFERROR(L6/D6,0) -> 78.603234 | N6: =IF(E6=0,"NO SALES",IF(L6<0,"LOSS",IF(IFERROR(L6/E6,0)<0.1,"THIN","PROFIT"))) -> PROFIT
A7: 2 | B7: =IF('SKU Master'!B6="","",'SKU Master'!B6) -> 144 | C7: ='SKU Master'!C6 -> HF 54" | D7: ='SKU Master'!I6 -> 2124.41 | E7: ='SKU Master'!J6 -> 730296 | F7: ='SKU Master'!K6 -> 0 | G7: ='SKU Master'!L6 -> 0 | H7: =MAX(D7-F7,0) -> 2124.41 | I7: =H7*'SKU Master'!H6 -> 585376.32 | J7: =IF(D7-F7<-0.5,"EXCESS→INV",IF(D7-F7>0.5,"Produced","Matched")) -> Produced | K7: =IF(F7>D7,D7*'SKU Master'!M6,G7)+I7 -> 585376.32 | L7: =IF(E7=0,0,E7-K7) -> 144919.68 | M7: =IFERROR(L7/D7,0) -> 68.216434 | N7: =IF(E7=0,"NO SALES",IF(L7<0,"LOSS",IF(IFERROR(L7/E7,0)<0.1,"THIN","PROFIT"))) -> PROFIT
A8: 3 | B8: =IF('SKU Master'!B7="","",'SKU Master'!B7) -> 164 | C8: ='SKU Master'!C7 -> HF 54" | D8: ='SKU Master'!I7 -> 92.2 | E8: ='SKU Master'!J7 -> 38400 | F8: ='SKU Master'!K7 -> 0 | G8: ='SKU Master'!L7 -> 0 | H8: =MAX(D8-F8,0) -> 92.2 | I8: =H8*'SKU Master'!H7 -> 25787.053 | J8: =IF(D8-F8<-0.5,"EXCESS→INV",IF(D8-F8>0.5,"Produced","Matched")) -> Produced | K8: =IF(F8>D8,D8*'SKU Master'!M7,G8)+I8 -> 25787.053 | L8: =IF(E8=0,0,E8-K8) -> 12612.947 | M8: =IFERROR(L8/D8,0) -> 136.79986 | N8: =IF(E8=0,"NO SALES",IF(L8<0,"LOSS",IF(IFERROR(L8/E8,0)<0.1,"THIN","PROFIT"))) -> PROFIT
A9: 4 | B9: =IF('SKU Master'!B8="","",'SKU Master'!B8) -> 167 | C9: ='SKU Master'!C8 -> HP 120" | D9: ='SKU Master'!I8 -> 65.44 | E9: ='SKU Master'!J8 -> 22400 | F9: ='SKU Master'!K8 -> 0 | G9: ='SKU Master'!L8 -> 0 | H9: =MAX(D9-F9,0) -> 65.44 | I9: =H9*'SKU Master'!H8 -> 15244.078 | J9: =IF(D9-F9<-0.5,"EXCESS→INV",IF(D9-F9>0.5,"Produced","Matched")) -> Produced | K9: =IF(F9>D9,D9*'SKU Master'!M8,G9)+I9 -> 15244.078 | L9: =IF(E9=0,0,E9-K9) -> 7155.9221 | M9: =IFERROR(L9/D9,0) -> 109.35089 | N9: =IF(E9=0,"NO SALES",IF(L9<0,"LOSS",IF(IFERROR(L9/E9,0)<0.1,"THIN","PROFIT"))) -> PROFIT
A10: 5 | B10: =IF('SKU Master'!B9="","",'SKU Master'!B9) -> 177 | C10: ='SKU Master'!C9 -> Kangaroo 120" | D10: ='SKU Master'!I9 -> 318.74 | E10: ='SKU Master'!J9 -> 106200 | F10: ='SKU Master'!K9 -> 0 | G10: ='SKU Master'!L9 -> 0 | H10: =MAX(D10-F10,0) -> 318.74 | I10: =H10*'SKU Master'!H9 -> 72352.327 | J10: =IF(D10-F10<-0.5,"EXCESS→INV",IF(D10-F10>0.5,"Produced","Matched")) -> Produced | K10: =IF(F10>D10,D10*'SKU Master'!M9,G10)+I10 -> 72352.327 | L10: =IF(E10=0,0,E10-K10) -> 33847.673 | M10: =IFERROR(L10/D10,0) -> 106.19211 | N10: =IF(E10=0,"NO SALES",IF(L10<0,"LOSS",IF(IFERROR(L10/E10,0)<0.1,"THIN","PROFIT"))) -> PROFIT
A11: 6 | B11: =IF('SKU Master'!B10="","",'SKU Master'!B10) -> 179 | C11: ='SKU Master'!C10 -> Kangaroo 54" | D11: ='SKU Master'!I10 -> 5943.01 | E11: ='SKU Master'!J10 -> 1799625 | F11: ='SKU Master'!K10 -> 0 | G11: ='SKU Master'!L10 -> 0 | H11: =MAX(D11-F11,0) -> 5943.01 | I11: =H11*'SKU Master'!H10 -> 1367778.8 | J11: =IF(D11-F11<-0.5,"EXCESS→INV",IF(D11-F11>0.5,"Produced","Matched")) -> Produced | K11: =IF(F11>D11,D11*'SKU Master'!M10,G11)+I11 -> 1367778.8 | L11: =IF(E11=0,0,E11-K11) -> 431846.21 | M11: =IFERROR(L11/D11,0) -> 72.664561 | N11: =IF(E11=0,"NO SALES",IF(L11<0,"LOSS",IF(IFERROR(L11/E11,0)<0.1,"THIN","PROFIT"))) -> PROFIT
A12: 7 | B12: =IF('SKU Master'!B11="","",'SKU Master'!B11) -> 188 | C12: ='SKU Master'!C11 -> Kangaroo 60" | D12: ='SKU Master'!I11 -> 459.72 | E12: ='SKU Master'!J11 -> 151500 | F12: ='SKU Master'!K11 -> 0 | G12: ='SKU Master'!L11 -> 0 | H12: =MAX(D12-F12,0) -> 459.72 | I12: =H12*'SKU Master'!H11 -> 102287.96 | J12: =IF(D12-F12<-0.5,"EXCESS→INV",IF(D12-F12>0.5,"Produced","Matched")) -> Produced | K12: =IF(F12>D12,D12*'SKU Master'!M11,G12)+I12 -> 102287.96 | L12: =IF(E12=0,0,E12-K12) -> 49212.04 | M12: =IFERROR(L12/D12,0) -> 107.04786 | N12: =IF(E12=0,"NO SALES",IF(L12<0,"LOSS",IF(IFERROR(L12/E12,0)<0.1,"THIN","PROFIT"))) -> PROFIT
A13: 8 | B13: =IF('SKU Master'!B12="","",'SKU Master'!B12) -> 193 | C13: ='SKU Master'!C12 -> Kangaroo 84" | D13: ='SKU Master'!I12 -> 429.36 | E13: ='SKU Master'!J12 -> 137500 | F13: ='SKU Master'!K12 -> 0 | G13: ='SKU Master'!L12 -> 0 | H13: =MAX(D13-F13,0) -> 429.36 | I13: =H13*'SKU Master'!H12 -> 97898.042 | J13: =IF(D13-F13<-0.5,"EXCESS→INV",IF(D13-F13>0.5,"Produced","Matched")) -> Produced | K13: =IF(F13>D13,D13*'SKU Master'!M12,G13)+I13 -> 97898.042 | L13: =IF(E13=0,0,E13-K13) -> 39601.958 | M13: =IFERROR(L13/D13,0) -> 92.234857 | N13: =IF(E13=0,"NO SALES",IF(L13<0,"LOSS",IF(IFERROR(L13/E13,0)<0.1,"THIN","PROFIT"))) -> PROFIT
A14: 9 | B14: =IF('SKU Master'!B13="","",'SKU Master'!B13) -> 199 | C14: ='SKU Master'!C13 -> Lotus 54" | D14: ='SKU Master'!I13 -> 135.39 | E14: ='SKU Master'!J13 -> 43725 | F14: ='SKU Master'!K13 -> 0 | G14: ='SKU Master'!L13 -> 0 | H14: =MAX(D14-F14,0) -> 135.39 | I14: =H14*'SKU Master'!H13 -> 35020.376 | J14: =IF(D14-F14<-0.5,"EXCESS→INV",IF(D14-F14>0.5,"Produced","Matched")) -> Produced | K14: =IF(F14>D14,D14*'SKU Master'!M13,G14)+I14 -> 35020.376 | L14: =IF(E14=0,0,E14-K14) -> 8704.6237 | M14: =IFERROR(L14/D14,0) -> 64.292959 | N14: =IF(E14=0,"NO SALES",IF(L14<0,"LOSS",IF(IFERROR(L14/E14,0)<0.1,"THIN","PROFIT"))) -> PROFIT
A15: 10 | B15: =IF('SKU Master'!B14="","",'SKU Master'!B14) -> 200 | C15: ='SKU Master'!C14 -> Lotus 54" | D15: ='SKU Master'!I14 -> 100.9 | E15: ='SKU Master'!J14 -> 33275 | F15: ='SKU Master'!K14 -> 0 | G15: ='SKU Master'!L14 -> 0 | H15: =MAX(D15-F15,0) -> 100.9 | I15: =H15*'SKU Master'!H14 -> 26173.622 | J15: =IF(D15-F15<-0.5,"EXCESS→INV",IF(D15-F15>0.5,"Produced","Matched")) -> Produced | K15: =IF(F15>D15,D15*'SKU Master'!M14,G15)+I15 -> 26173.622 | L15: =IF(E15=0,0,E15-K15) -> 7101.3776 | M15: =IFERROR(L15/D15,0) -> 70.380353 | N15: =IF(E15=0,"NO SALES",IF(L15<0,"LOSS",IF(IFERROR(L15/E15,0)<0.1,"THIN","PROFIT"))) -> PROFIT
A16: 11 | B16: =IF('SKU Master'!B15="","",'SKU Master'!B15) -> 201 | C16: ='SKU Master'!C15 -> Lotus 54" | D16: ='SKU Master'!I15 -> 225.31 | E16: ='SKU Master'!J15 -> 68750 | F16: ='SKU Master'!K15 -> 0 | G16: ='SKU Master'!L15 -> 0 | H16: =MAX(D16-F16,0) -> 225.31 | I16: =H16*'SKU Master'!H15 -> 57693.566 | J16: =IF(D16-F16<-0.5,"EXCESS→INV",IF(D16-F16>0.5,"Produced","Matched")) -> Produced | K16: =IF(F16>D16,D16*'SKU Master'!M15,G16)+I16 -> 57693.566 | L16: =IF(E16=0,0,E16-K16) -> 11056.434 | M16: =IFERROR(L16/D16,0) -> 49.072097 | N16: =IF(E16=0,"NO SALES",IF(L16<0,"LOSS",IF(IFERROR(L16/E16,0)<0.1,"THIN","PROFIT"))) -> PROFIT
A17: 12 | B17: =IF('SKU Master'!B16="","",'SKU Master'!B16) -> 204 | C17: ='SKU Master'!C16 -> Lotus 54" | D17: ='SKU Master'!I16 -> 136.12 | E17: ='SKU Master'!J16 -> 43725 | F17: ='SKU Master'!K16 -> 0 | G17: ='SKU Master'!L16 -> 0 | H17: =MAX(D17-F17,0) -> 136.12 | I17: =H17*'SKU Master'!H16 -> 35330.017 | J17: =IF(D17-F17<-0.5,"EXCESS→INV",IF(D17-F17>0.5,"Produced","Matched")) -> Produced | K17: =IF(F17>D17,D17*'SKU Master'!M16,G17)+I17 -> 35330.017 | L17: =IF(E17=0,0,E17-K17) -> 8394.9834 | M17: =IFERROR(L17/D17,0) -> 61.673402 | N17: =IF(E17=0,"NO SALES",IF(L17<0,"LOSS",IF(IFERROR(L17/E17,0)<0.1,"THIN","PROFIT"))) -> PROFIT
... A172: 167 | B172: =IF('SKU Master'!B171="","",'SKU Master'!B171) | C172: ='SKU Master'!C171 -> 0 | D172: ='SKU Master'!I171 -> 0 | E172: ='SKU Master'!J171 -> 0 | F172: ='SKU Master'!K171 -> 0 | G172: ='SKU Master'!L171 -> 0 | H172: =MAX(D172-F172,0) -> 0 | I172: =H172*'SKU Master'!H171 -> 0 | J172: =IF(D172-F172<-0.5,"EXCESS→INV",IF(D172-F172>0.5,"Produced","Matched")) -> Matched | K172: =IF(F172>D172,D172*'SKU Master'!M171,G172)+I172 -> 0 | L172: =IF(E172=0,0,E172-K172) -> 0 | M172: =IFERROR(L172/D172,0) -> 0 | N172: =IF(E172=0,"NO SALES",IF(L172<0,"LOSS",IF(IFERROR(L172/E172,0)<0.1,"THIN","PROFIT"))) -> NO SALES
A173: 168 | B173: =IF('SKU Master'!B172="","",'SKU Master'!B172) | C173: ='SKU Master'!C172 -> 0 | D173: ='SKU Master'!I172 -> 0 | E173: ='SKU Master'!J172 -> 0 | G173: ='SKU Master'!L172 -> 0 | H173: =MAX(D173-F173,0) -> 0 | I173: =H173*'SKU Master'!H172 -> 0 | J173: =IF(D173-F173<-0.5,"EXCESS→INV",IF(D173-F173>0.5,"Produced","Matched")) -> Matched | K173: =IF(F173>D173,D173*'SKU Master'!M172,G173)+I173 -> 0 | L173: =IF(E173=0,0,E173-K173) -> 0 | M173: =IFERROR(L173/D173,0) -> 0 | N173: =IF(E173=0,"NO SALES",IF(L173<0,"LOSS",IF(IFERROR(L173/E173,0)<0.1,"THIN","PROFIT"))) -> NO SALES
A174: 169 | B174: =IF('SKU Master'!B173="","",'SKU Master'!B173) | C174: ='SKU Master'!C173 -> 0 | D174: ='SKU Master'!I173 -> 0 | E174: ='SKU Master'!J173 -> 0 | G174: ='SKU Master'!L173 -> 0 | H174: =MAX(D174-F174,0) -> 0 | I174: =H174*'SKU Master'!H173 -> 0 | J174: =IF(D174-F174<-0.5,"EXCESS→INV",IF(D174-F174>0.5,"Produced","Matched")) -> Matched | K174: =IF(F174>D174,D174*'SKU Master'!M173,G174)+I174 -> 0 | L174: =IF(E174=0,0,E174-K174) -> 0 | M174: =IFERROR(L174/D174,0) -> 0 | N174: =IF(E174=0,"NO SALES",IF(L174<0,"LOSS",IF(IFERROR(L174/E174,0)<0.1,"THIN","PROFIT"))) -> NO SALES
A175: 170 | B175: =IF('SKU Master'!B174="","",'SKU Master'!B174) | C175: ='SKU Master'!C174 -> 0 | D175: ='SKU Master'!I174 -> 0 | E175: ='SKU Master'!J174 -> 0 | G175: ='SKU Master'!L174 -> 0 | H175: =MAX(D175-F175,0) -> 0 | I175: =H175*'SKU Master'!H174 -> 0 | J175: =IF(D175-F175<-0.5,"EXCESS→INV",IF(D175-F175>0.5,"Produced","Matched")) -> Matched | K175: =IF(F175>D175,D175*'SKU Master'!M174,G175)+I175 -> 0 | L175: =IF(E175=0,0,E175-K175) -> 0 | M175: =IFERROR(L175/D175,0) -> 0 | N175: =IF(E175=0,"NO SALES",IF(L175<0,"LOSS",IF(IFERROR(L175/E175,0)<0.1,"THIN","PROFIT"))) -> NO SALES
A176: 171 | B176: =IF('SKU Master'!B175="","",'SKU Master'!B175) | C176: ='SKU Master'!C175 -> 0 | D176: ='SKU Master'!I175 -> 0 | E176: ='SKU Master'!J175 -> 0 | G176: ='SKU Master'!L175 -> 0 | H176: =MAX(D176-F176,0) -> 0 | I176: =H176*'SKU Master'!H175 -> 0 | J176: =IF(D176-F176<-0.5,"EXCESS→INV",IF(D176-F176>0.5,"Produced","Matched")) -> Matched | K176: =IF(F176>D176,D176*'SKU Master'!M175,G176)+I176 -> 0 | L176: =IF(E176=0,0,E176-K176) -> 0 | M176: =IFERROR(L176/D176,0) -> 0 | N176: =IF(E176=0,"NO SALES",IF(L176<0,"LOSS",IF(IFERROR(L176/E176,0)<0.1,"THIN","PROFIT"))) -> NO SALES
A177: 172 | B177: =IF('SKU Master'!B176="","",'SKU Master'!B176) | C177: ='SKU Master'!C176 -> 0 | D177: ='SKU Master'!I176 -> 0 | E177: ='SKU Master'!J176 -> 0 | G177: ='SKU Master'!L176 -> 0 | H177: =MAX(D177-F177,0) -> 0 | I177: =H177*'SKU Master'!H176 -> 0 | J177: =IF(D177-F177<-0.5,"EXCESS→INV",IF(D177-F177>0.5,"Produced","Matched")) -> Matched | K177: =IF(F177>D177,D177*'SKU Master'!M176,G177)+I177 -> 0 | L177: =IF(E177=0,0,E177-K177) -> 0 | M177: =IFERROR(L177/D177,0) -> 0 | N177: =IF(E177=0,"NO SALES",IF(L177<0,"LOSS",IF(IFERROR(L177/E177,0)<0.1,"THIN","PROFIT"))) -> NO SALES
A178: 173 | B178: =IF('SKU Master'!B177="","",'SKU Master'!B177) | C178: ='SKU Master'!C177 -> 0 | D178: ='SKU Master'!I177 -> 0 | E178: ='SKU Master'!J177 -> 0 | G178: ='SKU Master'!L177 -> 0 | H178: =MAX(D178-F178,0) -> 0 | I178: =H178*'SKU Master'!H177 -> 0 | J178: =IF(D178-F178<-0.5,"EXCESS→INV",IF(D178-F178>0.5,"Produced","Matched")) -> Matched | K178: =IF(F178>D178,D178*'SKU Master'!M177,G178)+I178 -> 0 | L178: =IF(E178=0,0,E178-K178) -> 0 | M178: =IFERROR(L178/D178,0) -> 0 | N178: =IF(E178=0,"NO SALES",IF(L178<0,"LOSS",IF(IFERROR(L178/E178,0)<0.1,"THIN","PROFIT"))) -> NO SALES
A179: 174 | B179: =IF('SKU Master'!B178="","",'SKU Master'!B178) | C179: ='SKU Master'!C178 -> 0 | D179: ='SKU Master'!I178 -> 0 | E179: ='SKU Master'!J178 -> 0 | G179: ='SKU Master'!L178 -> 0 | H179: =MAX(D179-F179,0) -> 0 | I179: =H179*'SKU Master'!H178 -> 0 | J179: =IF(D179-F179<-0.5,"EXCESS→INV",IF(D179-F179>0.5,"Produced","Matched")) -> Matched | K179: =IF(F179>D179,D179*'SKU Master'!M178,G179)+I179 -> 0 | L179: =IF(E179=0,0,E179-K179) -> 0 | M179: =IFERROR(L179/D179,0) -> 0 | N179: =IF(E179=0,"NO SALES",IF(L179<0,"LOSS",IF(IFERROR(L179/E179,0)<0.1,"THIN","PROFIT"))) -> NO SALES
A180: 175 | B180: =IF('SKU Master'!B179="","",'SKU Master'!B179) | C180: ='SKU Master'!C179 -> 0 | D180: ='SKU Master'!I179 -> 0 | E180: ='SKU Master'!J179 -> 0 | G180: ='SKU Master'!L179 -> 0 | H180: =MAX(D180-F180,0) -> 0 | I180: =H180*'SKU Master'!H179 -> 0 | J180: =IF(D180-F180<-0.5,"EXCESS→INV",IF(D180-F180>0.5,"Produced","Matched")) -> Matched | K180: =IF(F180>D180,D180*'SKU Master'!M179,G180)+I180 -> 0 | L180: =IF(E180=0,0,E180-K180) -> 0 | M180: =IFERROR(L180/D180,0) -> 0 | N180: =IF(E180=0,"NO SALES",IF(L180<0,"LOSS",IF(IFERROR(L180/E180,0)<0.1,"THIN","PROFIT"))) -> NO SALES
A181: 176 | B181: =IF('SKU Master'!B180="","",'SKU Master'!B180) | C181: ='SKU Master'!C180 -> 0 | D181: ='SKU Master'!I180 -> 0 | E181: ='SKU Master'!J180 -> 0 | G181: ='SKU Master'!L180 -> 0 | H181: =MAX(D181-F181,0) -> 0 | I181: =H181*'SKU Master'!H180 -> 0 | J181: =IF(D181-F181<-0.5,"EXCESS→INV",IF(D181-F181>0.5,"Produced","Matched")) -> Matched | K181: =IF(F181>D181,D181*'SKU Master'!M180,G181)+I181 -> 0 | L181: =IF(E181=0,0,E181-K181) -> 0 | M181: =IFERROR(L181/D181,0) -> 0 | N181: =IF(E181=0,"NO SALES",IF(L181<0,"LOSS",IF(IFERROR(L181/E181,0)<0.1,"THIN","PROFIT"))) -> NO SALES
A182: 177 | B182: =IF('SKU Master'!B181="","",'SKU Master'!B181) | C182: ='SKU Master'!C181 -> 0 | D182: ='SKU Master'!I181 -> 0 | E182: ='SKU Master'!J181 -> 0 | G182: ='SKU Master'!L181 -> 0 | H182: =MAX(D182-F182,0) -> 0 | I182: =H182*'SKU Master'!H181 -> 0 | J182: =IF(D182-F182<-0.5,"EXCESS→INV",IF(D182-F182>0.5,"Produced","Matched")) -> Matched | K182: =IF(F182>D182,D182*'SKU Master'!M181,G182)+I182 -> 0 | L182: =IF(E182=0,0,E182-K182) -> 0 | M182: =IFERROR(L182/D182,0) -> 0 | N182: =IF(E182=0,"NO SALES",IF(L182<0,"LOSS",IF(IFERROR(L182/E182,0)<0.1,"THIN","PROFIT"))) -> NO SALES
A183: 178 | B183: =IF('SKU Master'!B182="","",'SKU Master'!B182) | C183: ='SKU Master'!C182 -> 0 | D183: ='SKU Master'!I182 -> 0 | E183: ='SKU Master'!J182 -> 0 | G183: ='SKU Master'!L182 -> 0 | H183: =MAX(D183-F183,0) -> 0 | I183: =H183*'SKU Master'!H182 -> 0 | J183: =IF(D183-F183<-0.5,"EXCESS→INV",IF(D183-F183>0.5,"Produced","Matched")) -> Matched | K183: =IF(F183>D183,D183*'SKU Master'!M182,G183)+I183 -> 0 | L183: =IF(E183=0,0,E183-K183) -> 0 | M183: =IFERROR(L183/D183,0) -> 0 | N183: =IF(E183=0,"NO SALES",IF(L183<0,"LOSS",IF(IFERROR(L183/E183,0)<0.1,"THIN","PROFIT"))) -> NO SALES
A184: 179 | B184: =IF('SKU Master'!B183="","",'SKU Master'!B183) | C184: ='SKU Master'!C183 -> 0 | D184: ='SKU Master'!I183 -> 0 | E184: ='SKU Master'!J183 -> 0 | G184: ='SKU Master'!L183 -> 0 | H184: =MAX(D184-F184,0) -> 0 | I184: =H184*'SKU Master'!H183 -> 0 | J184: =IF(D184-F184<-0.5,"EXCESS→INV",IF(D184-F184>0.5,"Produced","Matched")) -> Matched | K184: =IF(F184>D184,D184*'SKU Master'!M183,G184)+I184 -> 0 | L184: =IF(E184=0,0,E184-K184) -> 0 | M184: =IFERROR(L184/D184,0) -> 0 | N184: =IF(E184=0,"NO SALES",IF(L184<0,"LOSS",IF(IFERROR(L184/E184,0)<0.1,"THIN","PROFIT"))) -> NO SALES
A185: 180 | B185: =IF('SKU Master'!B184="","",'SKU Master'!B184) | C185: ='SKU Master'!C184 -> 0 | D185: ='SKU Master'!I184 -> 0 | E185: ='SKU Master'!J184 -> 0 | G185: ='SKU Master'!L184 -> 0 | H185: =MAX(D185-F185,0) -> 0 | I185: =H185*'SKU Master'!H184 -> 0 | J185: =IF(D185-F185<-0.5,"EXCESS→INV",IF(D185-F185>0.5,"Produced","Matched")) -> Matched | K185: =IF(F185>D185,D185*'SKU Master'!M184,G185)+I185 -> 0 | L185: =IF(E185=0,0,E185-K185) -> 0 | M185: =IFERROR(L185/D185,0) -> 0 | N185: =IF(E185=0,"NO SALES",IF(L185<0,"LOSS",IF(IFERROR(L185/E185,0)<0.1,"THIN","PROFIT"))) -> NO SALES
A186: 181 | B186: =IF('SKU Master'!B185="","",'SKU Master'!B185) | C186: ='SKU Master'!C185 -> 0 | D186: ='SKU Master'!I185 -> 0 | E186: ='SKU Master'!J185 -> 0 | H186: =MAX(D186-F186,0) -> 0 | I186: =H186*'SKU Master'!H185 -> 0 | J186: =IF(D186-F186<-0.5,"EXCESS→INV",IF(D186-F186>0.5,"Produced","Matched")) -> Matched | K186: =IF(F186>D186,D186*'SKU Master'!M185,G186)+I186 -> 0 | L186: =IF(E186=0,0,E186-K186) -> 0 | M186: =IFERROR(L186/D186,0) -> 0 | N186: =IF(E186=0,"NO SALES",IF(L186<0,"LOSS",IF(IFERROR(L186/E186,0)<0.1,"THIN","PROFIT"))) -> NO SALES
A187: 182 | B187: =IF('SKU Master'!B186="","",'SKU Master'!B186) | C187: ='SKU Master'!C186 -> 0 | D187: ='SKU Master'!I186 -> 0 | E187: ='SKU Master'!J186 -> 0 | H187: =MAX(D187-F187,0) -> 0 | I187: =H187*'SKU Master'!H186 -> 0 | J187: =IF(D187-F187<-0.5,"EXCESS→INV",IF(D187-F187>0.5,"Produced","Matched")) -> Matched | K187: =IF(F187>D187,D187*'SKU Master'!M186,G187)+I187 -> 0 | L187: =IF(E187=0,0,E187-K187) -> 0 | M187: =IFERROR(L187/D187,0) -> 0 | N187: =IF(E187=0,"NO SALES",IF(L187<0,"LOSS",IF(IFERROR(L187/E187,0)<0.1,"THIN","PROFIT"))) -> NO SALES
A188: 183 | B188: =IF('SKU Master'!B187="","",'SKU Master'!B187) | C188: ='SKU Master'!C187 -> 0 | D188: ='SKU Master'!I187 -> 0 | E188: ='SKU Master'!J187 -> 0 | H188: =MAX(D188-F188,0) -> 0 | I188: =H188*'SKU Master'!H187 -> 0 | J188: =IF(D188-F188<-0.5,"EXCESS→INV",IF(D188-F188>0.5,"Produced","Matched")) -> Matched | K188: =IF(F188>D188,D188*'SKU Master'!M187,G188)+I188 -> 0 | L188: =IF(E188=0,0,E188-K188) -> 0 | M188: =IFERROR(L188/D188,0) -> 0 | N188: =IF(E188=0,"NO SALES",IF(L188<0,"LOSS",IF(IFERROR(L188/E188,0)<0.1,"THIN","PROFIT"))) -> NO SALES
A189: 184 | B189: =IF('SKU Master'!B188="","",'SKU Master'!B188) | C189: ='SKU Master'!C188 -> 0 | D189: ='SKU Master'!I188 -> 0 | E189: ='SKU Master'!J188 -> 0 | H189: =MAX(D189-F189,0) -> 0 | I189: =H189*'SKU Master'!H188 -> 0 | J189: =IF(D189-F189<-0.5,"EXCESS→INV",IF(D189-F189>0.5,"Produced","Matched")) -> Matched | K189: =IF(F189>D189,D189*'SKU Master'!M188,G189)+I189 -> 0 | L189: =IF(E189=0,0,E189-K189) -> 0 | M189: =IFERROR(L189/D189,0) -> 0 | N189: =IF(E189=0,"NO SALES",IF(L189<0,"LOSS",IF(IFERROR(L189/E189,0)<0.1,"THIN","PROFIT"))) -> NO SALES
A190: 185 | B190: =IF('SKU Master'!B189="","",'SKU Master'!B189) | C190: ='SKU Master'!C189 -> 0 | D190: ='SKU Master'!I189 -> 0 | E190: ='SKU Master'!J189 -> 0 | H190: =MAX(D190-F190,0) -> 0 | I190: =H190*'SKU Master'!H189 -> 0 | J190: =IF(D190-F190<-0.5,"EXCESS→INV",IF(D190-F190>0.5,"Produced","Matched")) -> Matched | K190: =IF(F190>D190,D190*'SKU Master'!M189,G190)+I190 -> 0 | L190: =IF(E190=0,0,E190-K190) -> 0 | M190: =IFERROR(L190/D190,0) -> 0 | N190: =IF(E190=0,"NO SALES",IF(L190<0,"LOSS",IF(IFERROR(L190/E190,0)<0.1,"THIN","PROFIT"))) -> NO SALES
A191: 186 | B191: =IF('SKU Master'!B190="","",'SKU Master'!B190) | C191: ='SKU Master'!C190 -> 0 | D191: ='SKU Master'!I190 -> 0 | E191: ='SKU Master'!J190 -> 0 | H191: =MAX(D191-F191,0) -> 0 | I191: =H191*'SKU Master'!H190 -> 0 | J191: =IF(D191-F191<-0.5,"EXCESS→INV",IF(D191-F191>0.5,"Produced","Matched")) -> Matched | K191: =IF(F191>D191,D191*'SKU Master'!M190,G191)+I191 -> 0 | L191: =IF(E191=0,0,E191-K191) -> 0 | M191: =IFERROR(L191/D191,0) -> 0 | N191: =IF(E191=0,"NO SALES",IF(L191<0,"LOSS",IF(IFERROR(L191/E191,0)<0.1,"THIN","PROFIT"))) -> NO SALES
A192: 187 | B192: =IF('SKU Master'!B191="","",'SKU Master'!B191) | C192: ='SKU Master'!C191 -> 0 | D192: ='SKU Master'!I191 -> 0 | E192: ='SKU Master'!J191 -> 0 | H192: =MAX(D192-F192,0) -> 0 | I192: =H192*'SKU Master'!H191 -> 0 | J192: =IF(D192-F192<-0.5,"EXCESS→INV",IF(D192-F192>0.5,"Produced","Matched")) -> Matched | K192: =IF(F192>D192,D192*'SKU Master'!M191,G192)+I192 -> 0 | L192: =IF(E192=0,0,E192-K192) -> 0 | M192: =IFERROR(L192/D192,0) -> 0 | N192: =IF(E192=0,"NO SALES",IF(L192<0,"LOSS",IF(IFERROR(L192/E192,0)<0.1,"THIN","PROFIT"))) -> NO SALES
A193: 188 | B193: =IF('SKU Master'!B192="","",'SKU Master'!B192) | C193: ='SKU Master'!C192 -> 0 | D193: ='SKU Master'!I192 -> 0 | E193: ='SKU Master'!J192 -> 0 | H193: =MAX(D193-F193,0) -> 0 | I193: =H193*'SKU Master'!H192 -> 0 | J193: =IF(D193-F193<-0.5,"EXCESS→INV",IF(D193-F193>0.5,"Produced","Matched")) -> Matched | K193: =IF(F193>D193,D193*'SKU Master'!M192,G193)+I193 -> 0 | L193: =IF(E193=0,0,E193-K193) -> 0 | M193: =IFERROR(L193/D193,0) -> 0 | N193: =IF(E193=0,"NO SALES",IF(L193<0,"LOSS",IF(IFERROR(L193/E193,0)<0.1,"THIN","PROFIT"))) -> NO SALES
A194: 189 | B194: =IF('SKU Master'!B193="","",'SKU Master'!B193) | C194: ='SKU Master'!C193 -> 0 | D194: ='SKU Master'!I193 -> 0 | E194: ='SKU Master'!J193 -> 0 | H194: =MAX(D194-F194,0) -> 0 | I194: =H194*'SKU Master'!H193 -> 0 | J194: =IF(D194-F194<-0.5,"EXCESS→INV",IF(D194-F194>0.5,"Produced","Matched")) -> Matched | K194: =IF(F194>D194,D194*'SKU Master'!M193,G194)+I194 -> 0 | L194: =IF(E194=0,0,E194-K194) -> 0 | M194: =IFERROR(L194/D194,0) -> 0 | N194: =IF(E194=0,"NO SALES",IF(L194<0,"LOSS",IF(IFERROR(L194/E194,0)<0.1,"THIN","PROFIT"))) -> NO SALES
A195: 190 | B195: =IF('SKU Master'!B194="","",'SKU Master'!B194) | C195: ='SKU Master'!C194 -> 0 | D195: ='SKU Master'!I194 -> 0 | E195: ='SKU Master'!J194 -> 0 | H195: =MAX(D195-F195,0) -> 0 | I195: =H195*'SKU Master'!H194 -> 0 | J195: =IF(D195-F195<-0.5,"EXCESS→INV",IF(D195-F195>0.5,"Produced","Matched")) -> Matched | K195: =IF(F195>D195,D195*'SKU Master'!M194,G195)+I195 -> 0 | L195: =IF(E195=0,0,E195-K195) -> 0 | M195: =IFERROR(L195/D195,0) -> 0 | N195: =IF(E195=0,"NO SALES",IF(L195<0,"LOSS",IF(IFERROR(L195/E195,0)<0.1,"THIN","PROFIT"))) -> NO SALES
A196: 191 | B196: =IF('SKU Master'!B195="","",'SKU Master'!B195) | C196: ='SKU Master'!C195 -> 0 | D196: ='SKU Master'!I195 -> 0 | E196: ='SKU Master'!J195 -> 0 | H196: =MAX(D196-F196,0) -> 0 | I196: =H196*'SKU Master'!H195 -> 0 | J196: =IF(D196-F196<-0.5,"EXCESS→INV",IF(D196-F196>0.5,"Produced","Matched")) -> Matched | K196: =IF(F196>D196,D196*'SKU Master'!M195,G196)+I196 -> 0 | L196: =IF(E196=0,0,E196-K196) -> 0 | M196: =IFERROR(L196/D196,0) -> 0 | N196: =IF(E196=0,"NO SALES",IF(L196<0,"LOSS",IF(IFERROR(L196/E196,0)<0.1,"THIN","PROFIT"))) -> NO SALES
...

Sheet PAL Reconciliation
A1: PAL RECONCILIATION — Engine contribution vs PAL Net Profit
A3: Step | B3: Item | C3: Amount (₹) | D3: Note
A4: 1 | B4: Total SKU Contribution (Live Contribution sheet) | C4: =LiveTotalContri -> 4461486.6 | D4: Sum of all SKU contributions
A5: 2 | B5: ADD: RM Sale margin | C5: ='Apr26'!E53 -> 0 | D5: RM trading not in SKU list Jan 26 E 53
A6: 3 | B6: ADD: Trading Others margin | C6: ='Apr26'!E54 -> 172406 | D6: Other trading not in SKU list Jan 26 E54
A7: 4 | B7: ADD: Other Income | C7: ='Apr26'!E55 -> 21805 | D7: Jan 26 E55
A8: 5 | B8: ADD: Stock Difference adjustments | C8: ='Apr26'!E21 -> -3374117 | D8: Total Stock Difference (Monofil + Trading), Jan26!E21
A9: 6 | B9: ADJ: Yarn Semi-Finished / residual true-up | C9: 6298993 | D9: Residual true-up — set so engine matches PAL. Hardcode each month.
B10: Target: PAL Profit + Annual Fixed | C10: =SUM(C4:C9) -> 7580573.6
B12: TOTAL ADJUSTED CONTRIBUTION | C12: =SUM(C4:C9) -> 7580573.6
B13: LESS: Annual Fixed Expenses | C13: ='Apr26'!E38 -> 2963361
B14: ENGINE NET PROFIT | C14: =C12-C13 -> 4617212.6
B15: PAL Net Profit (target) | C15: ='Apr26'!E47 -> 4617213
B16: Difference | C16: =C14-C15 -> -0.4037907
A18: Note on Step 6 (balancing item):
A19: Step 6 absorbs: (a) yarn semi-finished margin differences, (b) any sales not tagged at SKU level,
A20: (c) timing/rounding between the SKU data and the PAL. At HISTORICAL Rate Card settings it makes the
A21: engine tie exactly to PAL ₹96 L. As you tag more data at SKU level, this item shrinks toward zero.
A22: When you change the Rate Card for forecasting, the SKU contributions move but Steps 2-6 stay fixed
A23: (they are not rate-sensitive) — so the forecast profit changes only via the SKU contribution.

Sheet Quote Builder
A1: QUOTE BUILDER — Price a single deal
I2: CODE | J2: Item
A3: STEP 1 — SKU code | E3: For | I3: 101 | J3: AIR54"BLUE
A4: SKU Code | B4: 258 | C4: RM Rate | D4: 107.37 | E4: May | I4: 102 | J4: AIR54"R.PINK
C5: Increase in Yarn Processing | D5: 2 | I5: 103 | J5: AIR54"S.BLUE
A6: AUTO-FILLED | C6: Increase in Fabrication rate in Kgs | I6: 104 | J6: AIR54"S.GREEN/Ivory
A7: Product | B7: =IFERROR(VLOOKUP(B4,'SKU Master'!B5:N259,2,FALSE()),IFERROR(VLOOKUP(TEXT(B4,"0"),'SKU Master'!B5:N259,2,FALSE()),"NOT FOUND")) -> SF 54" | I7: 105 | J7: AIR54"SB/IV
A8: Colour | B8: =IFERROR(VLOOKUP(B4,#REF!,3,FALSE()),IFERROR(VLOOKUP(TEXT(B4,"0"),#REF!,3,FALSE()),"")) | I8: 106 | J8: AIR54"V/B.P
A9: Mfg Cost ₹/Kg | B9: =IFERROR(VLOOKUP(B4,'SKU Master'!B5:N259,7,FALSE()),IFERROR(VLOOKUP(TEXT(B4,"0"),'SKU Master'!B5:N259,7,FALSE()),0)) -> 270.2004 | I9: 107 | J9: AIR54"V/White
A10: Hist Purch Rate ₹/Kg | B10: =IFERROR(VLOOKUP(B4,'SKU Master'!B5:N259,12,FALSE()),IFERROR(VLOOKUP(TEXT(B4,"0"),'SKU Master'!B5:N259,12,FALSE()),0)) -> 0 | I10: 108 | J10: AIR54"VIOLET
A11: Hist Avg SP ₹/Kg | B11: =IFERROR(VLOOKUP(B4,'SKU Master'!B5:N259,13,FALSE()),IFERROR(VLOOKUP(TEXT(B4,"0"),'SKU Master'!B5:N259,13,FALSE()),0)) -> 292.43443 | I11: 109 | J11: AIR60"SHINING WHITE
I12: 110 | J12: APSR60" R.Pink
A13: STEP 2 — Deal terms | I13: 111 | J13: APSR60"B.PINK
A14: Sourcing | B14: Produce in-house | C14: Rate Per Mt | D14: Wt/Mt | E14: Wt/Roll | I14: 112 | J14: APSR60"LSG
A15: Proposed Sale Price ₹/Kg | B15: 325 | C15: =_xlfn.CEILING.MATH((B15*D15),0.05) -> 16.55 | D15: =_xlfn.XLOOKUP(B4,'SKU Master'!B5:B259,'SKU Master'!E5:E259,"NA",0) -> 0.050812125 | E15: =IF(B4<300,(D15*50),(D15*30)) -> 2.5406062 | I15: 113 | J15: APSR60"SKY BLUE
A16: Proposed Quantity (Kgs) | B16: 1 | I16: 114 | J16: APSR60"VIOLET
A17: If purchasing — Purchase Rate ₹/Kg | B17: =B10 -> 0 | I17: 115 | J17: CAMEL54"BLUE
I18: 116 | J18: CAMEL54"PF BLUE
A19: RESULTS | I19: 117 | J19: CAPSICUM 72" WHITE
A20: Variable Cost ₹/Kg | B20: =IF(B14="Produce in-house",B9,B17+WCCharge) -> 270.2004 | I20: 118 | J20: CAPSICUM 84" S.GREEN
A21: Contribution ₹/Kg | B21: =B15-B20 -> 54.799604 | I21: 119 | J21: CAPSICUM120"WHITE
A22: P/V Ratio | B22: =IFERROR(B21/B15,0) -> 0.16861417 | I22: 120 | J22: G.JACKPOT54"BLUE
A23: TOTAL CONTRIBUTION (this deal) | B23: =B21*B16 -> 54.799604 | I23: 121 | J23: GIRAFFE54"BLUE
I24: 122 | J24: GIRAFFE54"ZEEBRA
A25: Floor SP (covers VC) | B25: =B20 -> 270.2004 | C25: Do not quote below this | I25: 123 | J25: GOUTAM-GOLD120"BLUE
A26: SP for 15% margin | B26: =B20/0.85 -> 317.88282 | I26: 124 | J26: GOUTAM-GOLD120"WHITE
A27: VERDICT | B27: =IF(B21<0,"REJECT — loss per Kg",IF(B21/B15<0.1,"CAUTION — Thin",IF(B21/B15<0.2,"ACCEPTABLE","STRONG"))) -> ACCEPTABLE | I27: 125 | J27: GOUTAM-GOLD54" White
I28: 126 | J28: GOUTAM-GOLD54"DARK BLUE
I29: 126 | J29: Priya-Gold Super54"BLUE
I30: 126 | J30: Priya-Gold Max54"Blue
I31: 127 | J31: HF84"OLIVE GREEN
I32: 128 | J32: HF104"OLIVE GREEN
I33: 129 | J33: HF104"S.GREEN
I34: 130 | J34: HF37"O.GREEN
I35: 131 | J35: HF42"BLUE
I36: 132 | J36: HF42"GREEN
I37: 133 | J37: HF42"R.PINK
I38: 134 | J38: HF42"S.BLUE
I39: 135 | J39: HF42"S.GREEN
... I538: 726 | J538: 120MESHLQ48"WHITE

Sheet Contribution Forecast
A1: MONTHLY FORECAST — Plan future SKU sales (split purchased vs produced)
A3: For each SKU enter: Planned Monthly Kgs (total), of which Purchased, and Purchase Rate.
A4: Engine splits the volume: Produced Kgs = Planned − Purchased; costs each correctly.
A5: Defaults below = FY25-26 monthly average. Override freely for your plan.
A7: Sl | B7: Code | C7: Product | D7: Colour | E7: Mts | F7: Planned Monthly Kgs | G7: of which Purchased Kgs | H7: Purchase Rate ₹/Kg | I7: Produced Kgs | J7: Sale Price ₹/Kg | K7: Purchased Cost | L7: Produced Cost | M7: Total Cost | N7: Sales Value | O7: Contribution
A8: 1 | B8: 126 | C8: Priya-Gold Super 54" | D8: Blue | E8: 2400 | F8: =E8*(_xlfn.XLOOKUP(B8,'Ratio Master'!A:A,'Ratio Master'!G:G,"")) -> 226.47498 | H8: =IFERROR('SKU Master'!M5+0,0) -> 0 | I8: =MAX(F8-G8,0) -> 226.47498 | J8: =IFERROR('SKU Master'!N5+0,0) -> 297.0297 | K8: =MIN(G8,F8)*H8 -> 0 | L8: =I8*'SKU Master'!H5 -> 49468.131 | M8: =K8+L8 -> 49468.131 | N8: =F8*J8 -> 67269.797 | O8: =N8-M8 -> 17801.666
A9: 2 | B9: 144 | C9: HF 54" | D9: Blue | E9: 48000 | F9: =E9*(_xlfn.XLOOKUP(B9,'Ratio Master'!A:A,'Ratio Master'!G:G,"")) -> 1919.5872 | H9: =IFERROR('SKU Master'!M6+0,0) -> 0 | I9: =MAX(F9-G9,0) -> 1919.5872 | J9: =IFERROR('SKU Master'!N6+0,0) -> 343.76415 | K9: =MIN(G9,F9)*H9 -> 0 | L9: =I9*'SKU Master'!H6 -> 528937.86 | M9: =K9+L9 -> 528937.86 | N9: =F9*J9 -> 659885.25 | O9: =N9-M9 -> 130947.39
A10: 3 | B10: 145 | C10: Star fish 54" | D10: Blue | E10: 0 | F10: =E10*(_xlfn.XLOOKUP(B10,'Ratio Master'!A:A,'Ratio Master'!G:G,"")) -> 0 | H10: =IFERROR('SKU Master'!M7+0,0) -> 0 | I10: =MAX(F10-G10,0) -> 0 | J10: =IFERROR('SKU Master'!N7+0,0) -> 416.4859 | K10: =MIN(G10,F10)*H10 -> 0 | L10: =I10*'SKU Master'!H7 -> 0 | M10: =K10+L10 -> 0 | N10: =F10*J10 -> 0 | O10: =N10-M10 -> 0
A11: 4 | B11: 147 | C11: HF 54" | D11: Badam Pink/Olive Green | E11: 2400 | F11: =E11*(_xlfn.XLOOKUP(B11,'Ratio Master'!A:A,'Ratio Master'!G:G,"")) -> 102.759 | H11: =IFERROR('SKU Master'!M8+0,0) -> 0 | I11: =MAX(F11-G11,0) -> 102.759 | J11: =IFERROR('SKU Master'!N8+0,0) -> 342.29829 | K11: =MIN(G11,F11)*H11 -> 0 | L11: =I11*'SKU Master'!H8 -> 23937.442 | M11: =K11+L11 -> 23937.442 | N11: =F11*J11 -> 35174.23 | O11: =N11-M11 -> 11236.788
A12: 5 | B12: 155 | C12: HF 54" | D12: Olive Green/Ivory | E12: 2400 | F12: =E12*(_xlfn.XLOOKUP(B12,'Ratio Master'!A:A,'Ratio Master'!G:G,"")) -> 98.981695 | H12: =IFERROR('SKU Master'!M9+0,0) -> 0 | I12: =MAX(F12-G12,0) -> 98.981695 | J12: =IFERROR('SKU Master'!N9+0,0) -> 333.18692 | K12: =MIN(G12,F12)*H12 -> 0 | L12: =I12*'SKU Master'!H9 -> 22468.331 | M12: =K12+L12 -> 22468.331 | N12: =F12*J12 -> 32979.406 | O12: =N12-M12 -> 10511.075
A13: 6 | B13: 158 | C13: HF 54" | D13: Sky Blue/Ivory | E13: 2400 | F13: =E13*(_xlfn.XLOOKUP(B13,'Ratio Master'!A:A,'Ratio Master'!G:G,"")) -> 98.086296 | H13: =IFERROR('SKU Master'!M10+0,0) -> 0 | I13: =MAX(F13-G13,0) -> 98.086296 | J13: =IFERROR('SKU Master'!N10+0,0) -> 302.81373 | K13: =MIN(G13,F13)*H13 -> 0 | L13: =I13*'SKU Master'!H10 -> 22574.479 | M13: =K13+L13 -> 22574.479 | N13: =F13*J13 -> 29701.877 | O13: =N13-M13 -> 7127.3976
A14: 7 | B14: 159 | C14: HF 54" | D14: Sea Green | E14: 0 | F14: =E14*(_xlfn.XLOOKUP(B14,'Ratio Master'!A:A,'Ratio Master'!G:G,"")) -> 0 | H14: =IFERROR('SKU Master'!M11+0,0) -> 0 | I14: =MAX(F14-G14,0) -> 0 | J14: =IFERROR('SKU Master'!N11+0,0) -> 329.54842 | K14: =MIN(G14,F14)*H14 -> 0 | L14: =I14*'SKU Master'!H11 -> 0 | M14: =K14+L14 -> 0 | N14: =F14*J14 -> 0 | O14: =N14-M14 -> 0
A15: 8 | B15: 159 | C15: HF 54" | D15: Sea Green/Ivory | E15: 0 | F15: =E15*(_xlfn.XLOOKUP(B15,'Ratio Master'!A:A,'Ratio Master'!G:G,"")) -> 0 | H15: =IFERROR('SKU Master'!M12+0,0) -> 0 | I15: =MAX(F15-G15,0) -> 0 | J15: =IFERROR('SKU Master'!N12+0,0) -> 320.24408 | K15: =MIN(G15,F15)*H15 -> 0 | L15: =I15*'SKU Master'!H12 -> 0 | M15: =K15+L15 -> 0 | N15: =F15*J15 -> 0 | O15: =N15-M15 -> 0
A16: 9 | B16: 164 | C16: HF 54" | D16: White | E16: 2400 | F16: =E16*(_xlfn.XLOOKUP(B16,'Ratio Master'!A:A,'Ratio Master'!G:G,"")) -> 92.714667 | H16: =IFERROR('SKU Master'!M13+0,0) -> 0 | I16: =MAX(F16-G16,0) -> 92.714667 | J16: =IFERROR('SKU Master'!N13+0,0) -> 322.95591 | K16: =MIN(G16,F16)*H16 -> 0 | L16: =I16*'SKU Master'!H13 -> 23981.849 | M16: =K16+L16 -> 23981.849 | N16: =F16*J16 -> 29942.749 | O16: =N16-M16 -> 5960.9002
A17: 10 | B17: 167 | C17: HP 120" | D17: Sea Green | E17: 2000 | F17: =E17*(_xlfn.XLOOKUP(B17,'Ratio Master'!A:A,'Ratio Master'!G:G,"")) -> 320.32051 | H17: =IFERROR('SKU Master'!M14+0,0) -> 0 | I17: =MAX(F17-G17,0) -> 320.32051 | J17: =IFERROR('SKU Master'!N14+0,0) -> 329.78196 | K17: =MIN(G17,F17)*H17 -> 0 | L17: =I17*'SKU Master'!H14 -> 83091.657 | M17: =K17+L17 -> 83091.657 | N17: =F17*J17 -> 105635.93 | O17: =N17-M17 -> 22544.271
A18: 11 | B18: 170 | C18: HP 54" | D18: Sky Blue | E18: 60000 | F18: =E18*(_xlfn.XLOOKUP(B18,'Ratio Master'!A:A,'Ratio Master'!G:G,"")) -> 3435.0913 | H18: =IFERROR('SKU Master'!M15+0,0) -> 0 | I18: =MAX(F18-G18,0) -> 3435.0913 | J18: =IFERROR('SKU Master'!N15+0,0) -> 305.13515 | K18: =MIN(G18,F18)*H18 -> 0 | L18: =I18*'SKU Master'!H15 -> 879599.97 | M18: =K18+L18 -> 879599.97 | N18: =F18*J18 -> 1048167.1 | O18: =N18-M18 -> 168567.14
A19: 12 | B19: 174 | C19: Jasmin 57" | D19: White | E19: 14175 | F19: =E19*(_xlfn.XLOOKUP(B19,'Ratio Master'!A:A,'Ratio Master'!G:G,"")) -> 782.65038 | H19: =IFERROR('SKU Master'!M16+0,0) -> 0 | I19: =MAX(F19-G19,0) -> 782.65038 | J19: =IFERROR('SKU Master'!N16+0,0) -> 321.22392 | K19: =MIN(G19,F19)*H19 -> 0 | L19: =I19*'SKU Master'!H16 -> 203137.31 | M19: =K19+L19 -> 203137.31 | N19: =F19*J19 -> 251406.02 | O19: =N19-M19 -> 48268.711
... A132: 125 | B132: 726 | C132: 120 LQ 48" | D132: White | E132: 0 | F132: =E132*(_xlfn.XLOOKUP(B132,'Ratio Master'!A:A,'Ratio Master'!G:G,"")) -> 0 | H132: =IFERROR('SKU Master'!M129+0,0) -> 0 | I132: =MAX(F132-G132,0) -> 0 | J132: =IFERROR('SKU Master'!N129+0,0) -> 0 | K132: =MIN(G132,F132)*H132 -> 0 | L132: =I132*'SKU Master'!H129 -> 0 | M132: =K132+L132 -> 0 | N132: =F132*J132 -> 0 | O132: =N132-M132 -> 0
A133: 126 | F133: =E133*(_xlfn.XLOOKUP(B133,'Ratio Master'!A:A,'Ratio Master'!G:G,"")) -> 0
A134: 127 | F134: =E134*(_xlfn.XLOOKUP(B134,'Ratio Master'!A:A,'Ratio Master'!G:G,"")) -> 0
A135: 128 | F135: =E135*(_xlfn.XLOOKUP(B135,'Ratio Master'!A:A,'Ratio Master'!G:G,"")) -> 0
A136: 129 | C136: ='SKU Master'!C113 -> 0 | F136: =E136*(_xlfn.XLOOKUP(B136,'Ratio Master'!A:A,'Ratio Master'!G:G,"")) -> 0 | H136: =IFERROR('SKU Master'!M113+0,0) -> 0 | I136: =MAX(F136-G136,0) -> 0 | J136: =IFERROR('SKU Master'!N113+0,0) -> 0 | K136: =MIN(G136,F136)*H136 -> 0 | L136: =I136*'SKU Master'!H113 -> 0 | M136: =K136+L136 -> 0 | N136: =F136*J136 -> 0 | O136: =N136-M136 -> 0
