Workbook

Sheet Table of Contents
B2: Table of Contents
Q3: Remarks
Q4: 1 Reconcile sheet is comapring Tally Inventory with Tarka
Q5: 2.Review Purchase sheet is redundnt Started to compare Purchases & reconcile
Q6: 3.Qty Analysis is Made by Accounts dept
Q7: 4. Input -Purchase comes from Tally
Q8: 5.Input-Dirct Expns from Tally
Q9: 6.Input-Indirect Expns from Tally
Q10: 7.Input-Stock Vauation from Tally
Q11: 8.Input-Inventory Sales Recobciles Gross Sales to Net Sales
Q12: 9.Output- Cost OF Good Sold (COGS)
Q13: 10.Output-PAL1 Gross P& L compares with Tally P& L fro data Validation with Quantities
Q14: 11.Output_Trading PL is checking on Trading monthly performance
... Q17: 14,15,16,17 OUTPUT from abve sheets for MIS understanding

Sheet Reconcile(HMT)
B2: Op Stock | E2: Apr | H2: May | K2: Jun | N2: Jul | Q2: Aug | T2: Sep | W2: Oct | Z2: Nov | AC2: Dec | AF2: Jan | AI2: Feb | AL2: Mar
B3: HMT | C3: CRK | D3: Diff | E3: HMT | F3: CRK | G3: Diff | H3: HMT | I3: CRK | J3: Diff | K3: HMT | L3: CRK | M3: Diff | N3: HMT | O3: CRK | P3: Diff | Q3: HMT | R3: CRK | S3: Diff | T3: HMT | U3: CRK | V3: Diff | W3: HMT | X3: CRK | Y3: Diff | Z3: HMT | AA3: CRK | AB3: Diff | AC3: HMT | AD3: CRK | AE3: Diff | AF3: HMT | AG3: CRK | AH3: Diff | AI3: HMT | AJ3: CRK | AK3: Diff | AL3: HMT | AM3: CRK | AN3: Diff
A4: HDPE | B4: 195845 | C4: ='Stock Valuation (FIFO)'!B5 -> 141140 | D4: =B4-C4 -> 54705 | E4: 180315 | F4: ='Stock Valuation (FIFO)'!E5 -> 75695 | G4: =IF(F4=0,0,(E4-F4)) -> 104620 | H4: 147410 | I4: ='Stock Valuation (FIFO)'!H5 -> 90040 | J4: =IF(I4=0,0,(H4-I4)) -> 57370 | K4: 164125 | L4: ='Stock Valuation (FIFO)'!K5 -> 0 | M4: =IF(L4=0,0,(K4-L4)) -> 0 | N4: 146140 | O4: ='Stock Valuation (FIFO)'!N5 -> 0 | P4: =IF(O4=0,0,(N4-O4)) -> 0 | Q4: 187620 | R4: =' Qty Analysis'!N8 -> 0 | S4: =IF(R4=0,0,(Q4-R4)) -> 0 | T4: 114680 | U4: ='Stock Valuation (FIFO)'!T5 -> 0 | V4: =IF(U4=0,0,(T4-U4)) -> 0 | W4: 139725 | X4: ='Stock Valuation (FIFO)'!W5 -> 0 | Y4: =IF(X4=0,0,(W4-X4)) -> 0 | Z4: 164310 | AA4: ='Stock Valuation (FIFO)'!Z5 -> 0 | AB4: =IF(AA4=0,0,(Z4-AA4)) -> 0 | AC4: 135475 | AD4: ='Stock Valuation (FIFO)'!AC5 -> 0 | AE4: =IF(AD4=0,0,(AC4-AD4)) -> 0 | AF4: 174670 | AG4: 174670 | AH4: =IF(AG4=0,0,(AF4-AG4)) -> 0 | AI4: 154290 | AJ4: ='Stock Valuation (FIFO)'!AI5 -> 0 | AK4: =IF(AJ4=0,0,(AI4-AJ4)) -> 0 | AL4: 141140 | AM4: ='Stock Valuation (FIFO)'!AL5 -> 0 | AN4: =IF(AM4=0,0,(AL4-AM4)) -> 0
A5: MB | B5: 1664 | C5: ='Stock Valuation (FIFO)'!B6 -> 2330 | D5: =B5-C5 -> -666 | E5: 2120.4 | F5: ='Stock Valuation (FIFO)'!E6 -> 2392 | G5: =IF(F5=0,0,(E5-F5)) -> -271.6 | H5: 2293.7 | I5: ='Stock Valuation (FIFO)'!H6 -> 2239 | J5: =IF(I5=0,0,(H5-I5)) -> 54.7 | K5: 2613.1 | L5: ='Stock Valuation (FIFO)'!K6 -> 0 | M5: =IF(L5=0,0,(K5-L5)) -> 0 | N5: 2768.7 | O5: ='Stock Valuation (FIFO)'!N6 -> 0 | P5: =IF(O5=0,0,(N5-O5)) -> 0 | Q5: 3082.1 | R5: =' Qty Analysis'!N21 -> 0 | S5: =IF(R5=0,0,(Q5-R5)) -> 0 | T5: 2819.3 | U5: ='Stock Valuation (FIFO)'!T6 -> 0 | V5: =IF(U5=0,0,(T5-U5)) -> 0 | W5: 2895.3 | X5: ='Stock Valuation (FIFO)'!W6 -> 0 | Y5: =IF(X5=0,0,(W5-X5)) -> 0 | Z5: 2396.4 | AA5: ='Stock Valuation (FIFO)'!Z6 -> 0 | AB5: =IF(AA5=0,0,(Z5-AA5)) -> 0 | AC5: 2395.2 | AD5: ='Stock Valuation (FIFO)'!AC6 -> 0 | AE5: =IF(AD5=0,0,(AC5-AD5)) -> 0 | AF5: 2511.2 | AG5: 2511 | AH5: =IF(AG5=0,0,(AF5-AG5)) -> 0.2 | AI5: 3260.1 | AJ5: ='Stock Valuation (FIFO)'!AI6 -> 0 | AK5: =IF(AJ5=0,0,(AI5-AJ5)) -> 0 | AL5: 2329.6 | AM5: ='Stock Valuation (FIFO)'!AL6 -> 0 | AN5: =IF(AM5=0,0,(AL5-AM5)) -> 0
A6: CP | B6: 32 | C6: ='Stock Valuation (FIFO)'!B7 -> 19 | D6: =B6-C6 -> 13 | E6: 28.2 | F6: ='Stock Valuation (FIFO)'!E7 -> 21 | G6: =IF(F6=0,0,(E6-F6)) -> 7.2 | H6: 40.1 | I6: ='Stock Valuation (FIFO)'!H7 -> 20 | J6: =IF(I6=0,0,(H6-I6)) -> 20.1 | K6: 40.1 | L6: ='Stock Valuation (FIFO)'!K7 -> 0 | M6: =IF(L6=0,0,(K6-L6)) -> 0 | N6: 38.4 | O6: ='Stock Valuation (FIFO)'!N7 -> 0 | P6: =IF(O6=0,0,(N6-O6)) -> 0 | Q6: 25.6 | R6: =' Qty Analysis'!N33 -> 0 | S6: =IF(R6=0,0,(Q6-R6)) -> 0 | T6: 16.2 | U6: ='Stock Valuation (FIFO)'!T7 -> 0 | V6: =IF(U6=0,0,(T6-U6)) -> 0 | W6: 40.9 | X6: ='Stock Valuation (FIFO)'!W7 -> 0 | Y6: =IF(X6=0,0,(W6-X6)) -> 0 | Z6: 46 | AA6: ='Stock Valuation (FIFO)'!Z7 -> 0 | AB6: =IF(AA6=0,0,(Z6-AA6)) -> 0 | AC6: 40.3 | AD6: ='Stock Valuation (FIFO)'!AC7 -> 0 | AE6: =IF(AD6=0,0,(AC6-AD6)) -> 0 | AF6: 40.1 | AG6: 40 | AH6: =IF(AG6=0,0,(AF6-AG6)) -> 0.1 | AI6: 38.8 | AJ6: ='Stock Valuation (FIFO)'!AI7 -> 0 | AK6: =IF(AJ6=0,0,(AI6-AJ6)) -> 0 | AL6: 19 | AM6: ='Stock Valuation (FIFO)'!AL7 -> 0 | AN6: =IF(AM6=0,0,(AL6-AM6)) -> 0
A7: RM Total | B7: =SUM(B4:B6) -> 197541 | C7: =SUM(C4:C6) -> 143489 | D7: =B7-C7 -> 54052 | E7: =SUM(E4:E6) -> 182463.6 | F7: =SUM(F4:F6) -> 78108 | G7: =IF(F7=0,0,(E7-F7)) -> 104355.6 | H7: =SUM(H4:H6) -> 149743.8 | I7: =SUM(I4:I6) -> 92299 | J7: =IF(I7=0,0,(H7-I7)) -> 57444.8 | K7: =SUM(K4:K6) -> 166778.2 | L7: =SUM(L4:L6) -> 0 | M7: =IF(L7=0,0,(K7-L7)) -> 0 | N7: =SUM(N4:N6) -> 148947.1 | O7: =SUM(O4:O6) -> 0 | P7: =IF(O7=0,0,(N7-O7)) -> 0 | Q7: =SUM(Q4:Q6) -> 190727.7 | R7: =SUM(R4:R6) -> 0 | S7: =IF(R7=0,0,(Q7-R7)) -> 0 | T7: =SUM(T4:T6) -> 117515.5 | U7: =SUM(U4:U6) -> 0 | V7: =IF(U7=0,0,(T7-U7)) -> 0 | W7: =SUM(W4:W6) -> 142661.2 | X7: =SUM(X4:X6) -> 0 | Y7: =IF(X7=0,0,(W7-X7)) -> 0 | Z7: =SUM(Z4:Z6) -> 166752.4 | AA7: =SUM(AA4:AA6) -> 0 | AB7: =IF(AA7=0,0,(Z7-AA7)) -> 0 | AC7: =SUM(AC4:AC6) -> 137910.5 | AD7: =SUM(AD4:AD6) -> 0 | AE7: =IF(AD7=0,0,(AC7-AD7)) -> 0 | AF7: =SUM(AF4:AF6) -> 177221.3 | AG7: =SUM(AG4:AG6) -> 177221 | AH7: =IF(AG7=0,0,(AF7-AG7)) -> 0.3 | AI7: =SUM(AI4:AI6) -> 157588.9 | AJ7: =SUM(AJ4:AJ6) -> 0 | AK7: =IF(AJ7=0,0,(AI7-AJ7)) -> 0 | AL7: =SUM(AL4:AL6) -> 143488.6 | AM7: =SUM(AM4:AM6) -> 0 | AN7: =IF(AM7=0,0,(AL7-AM7)) -> 0
A8: Yarn Factory | B8: 49725 | C8: ='Stock Valuation (FIFO)'!B10 -> 37996 | D8: =B8-C8 -> 11729 | E8: 56270 | F8: ='Stock Valuation (FIFO)'!E10 -> 26660 | G8: =IF(F8=0,0,(E8-F8)) -> 29610 | H8: 46564 | I8: ='Stock Valuation (FIFO)'!H10 -> 17001 | J8: =IF(I8=0,0,(H8-I8)) -> 29563 | K8: 52761.2 | L8: ='Stock Valuation (FIFO)'!K10 -> 0 | M8: =IF(L8=0,0,(K8-L8)) -> 0 | N8: 48737.1 | O8: ='Stock Valuation (FIFO)'!N10 -> 0 | P8: =IF(O8=0,0,(N8-O8)) -> 0 | Q8: 49389.9 | R8: =' Qty Analysis'!N61 -> 77470.8 | S8: =IF(R8=0,0,(Q8-R8)) -> -28080.9 | T8: 56273.8 | U8: ='Stock Valuation (FIFO)'!T10 -> 0 | V8: =IF(U8=0,0,(T8-U8)) -> 0 | W8: 60795.6 | X8: ='Stock Valuation (FIFO)'!W10 -> 0 | Y8: =IF(X8=0,0,(W8-X8)) -> 0 | Z8: 57317.4 | AA8: ='Stock Valuation (FIFO)'!Z10 -> 0 | AB8: =IF(AA8=0,0,(Z8-AA8)) -> 0 | AC8: 54865.8 | AD8: ='Stock Valuation (FIFO)'!AC10 -> 0 | AE8: =IF(AD8=0,0,(AC8-AD8)) -> 0 | AF8: 47773.2 | AG8: 47774 | AH8: =IF(AG8=0,0,(AF8-AG8)) -> -0.8 | AI8: 51821.9 | AJ8: ='Stock Valuation (FIFO)'!AI10 -> 0 | AK8: =IF(AJ8=0,0,(AI8-AJ8)) -> 0 | AL8: 37996 | AM8: 37996 | AN8: =IF(AM8=0,0,(AL8-AM8)) -> -2.910383e-11
A9: Yarn Fabrctr | B9: 76468 | C9: ='Stock Valuation (FIFO)'!B11 -> 64171 | D9: =B9-C9 -> 12297 | E9: 63905.6 | F9: ='Stock Valuation (FIFO)'!E11 -> 50337 | G9: =IF(F9=0,0,(E9-F9)) -> 13568.6 | H9: 61851.2 | I9: ='Stock Valuation (FIFO)'!H11 -> 56663 | J9: =IF(I9=0,0,(H9-I9)) -> 5188.2 | K9: 66528 | L9: ='Stock Valuation (FIFO)'!K11 -> 0 | M9: =IF(L9=0,0,(K9-L9)) -> 0 | N9: 73740.4 | O9: ='Stock Valuation (FIFO)'!N11 -> 0 | P9: =IF(O9=0,0,(N9-O9)) -> 0 | Q9: 77586 | R9: =' Qty Analysis'!N71 -> 77584.9 | S9: =IF(R9=0,0,(Q9-R9)) -> 1.1 | T9: =79105.0999999999-25 -> 79080.1 | U9: ='Stock Valuation (FIFO)'!T11 -> 0 | V9: =IF(U9=0,0,(T9-U9)) -> 0 | W9: 80193.4 | X9: ='Stock Valuation (FIFO)'!W11 -> 0 | Y9: =IF(X9=0,0,(W9-X9)) -> 0 | Z9: 85004.2 | AA9: ='Stock Valuation (FIFO)'!Z11 -> 0 | AB9: =IF(AA9=0,0,(Z9-AA9)) -> 0 | AC9: 91727.2 | AD9: ='Stock Valuation (FIFO)'!AC11 -> 0 | AE9: =IF(AD9=0,0,(AC9-AD9)) -> 0 | AF9: 91742.2 | AG9: 91742 | AH9: =IF(AG9=0,0,(AF9-AG9)) -> 0.2 | AI9: 86543.9 | AJ9: ='Stock Valuation (FIFO)'!AI11 -> 0 | AK9: =IF(AJ9=0,0,(AI9-AJ9)) -> 0 | AL9: 84657.29 | AM9: 64171 | AN9: =IF(AM9=0,0,(AL9-AM9)) -> 20486.29
A10: Yarn Total | B10: =SUM(B8:B9) -> 126193 | C10: =SUM(C8:C9) -> 102167 | D10: =B10-C10 -> 24026 | E10: =SUM(E8:E9) -> 120175.6 | F10: =SUM(F8:F9) -> 76997 | G10: =IF(F10=0,0,(E10-F10)) -> 43178.6 | H10: =SUM(H8:H9) -> 108415.2 | I10: =SUM(I8:I9) -> 73664 | J10: =IF(I10=0,0,(H10-I10)) -> 34751.2 | K10: =SUM(K8:K9) -> 119289.2 | L10: =SUM(L8:L9) -> 0 | M10: =IF(L10=0,0,(K10-L10)) -> 0 | N10: =SUM(N8:N9) -> 122477.5 | O10: =SUM(O8:O9) -> 0 | P10: =IF(O10=0,0,(N10-O10)) -> 0 | Q10: =SUM(Q8:Q9) -> 126975.9 | R10: =SUM(R8:R9) -> 155055.7 | S10: =IF(R10=0,0,(Q10-R10)) -> -28079.8 | T10: =SUM(T8:T9) -> 135353.9 | U10: =SUM(U8:U9) -> 0 | V10: =IF(U10=0,0,(T10-U10)) -> 0 | W10: =SUM(W8:W9) -> 140989 | X10: =SUM(X8:X9) -> 0 | Y10: =IF(X10=0,0,(W10-X10)) -> 0 | Z10: =SUM(Z8:Z9) -> 142321.6 | AA10: =SUM(AA8:AA9) -> 0 | AB10: =IF(AA10=0,0,(Z10-AA10)) -> 0 | AC10: =SUM(AC8:AC9) -> 146593 | AD10: =SUM(AD8:AD9) -> 0 | AE10: =IF(AD10=0,0,(AC10-AD10)) -> 0 | AF10: =SUM(AF8:AF9) -> 139515.4 | AG10: =SUM(AG8:AG9) -> 139516 | AH10: =IF(AG10=0,0,(AF10-AG10)) -> -0.6 | AI10: =SUM(AI8:AI9) -> 138365.8 | AJ10: =SUM(AJ8:AJ9) -> 0 | AK10: =IF(AJ10=0,0,(AI10-AJ10)) -> 0 | AL10: =SUM(AL8:AL9) -> 122653.29 | AM10: =SUM(AM8:AM9) -> 102167 | AN10: =IF(AM10=0,0,(AL10-AM10)) -> 20486.29 | AO10: Water Content Fabricator
A11: Fabric | B11: 206027 | C11: ='Stock Valuation (FIFO)'!B14 -> 200810 | D11: =B11-C11 -> 5217 | E11: 224044.9 | F11: ='Stock Valuation (FIFO)'!E14 -> 216887 | G11: =IF(F11=0,0,(E11-F11)) -> 7157.9 | H11: 201846.3 | I11: ='Stock Valuation (FIFO)'!H14 -> 179666 | J11: =IF(I11=0,0,(H11-I11)) -> 22180.3 | K11: 191275.2 | L11: ='Stock Valuation (FIFO)'!K14 -> 0 | M11: =IF(L11=0,0,(K11-L11)) -> 0 | N11: 197795.1 | O11: ='Stock Valuation (FIFO)'!N14 -> 0 | P11: =IF(O11=0,0,(N11-O11)) -> 0 | Q11: 202309.3 | R11: ='Stock Valuation (FIFO)'!Q14 -> 0 | S11: =IF(R11=0,0,(Q11-R11)) -> 0 | T11: 228721.4 | U11: ='Stock Valuation (FIFO)'!T14 -> 0 | V11: =IF(U11=0,0,(T11-U11)) -> 0 | W11: 237947.3 | X11: ='Stock Valuation (FIFO)'!W14 -> 0 | Y11: =IF(X11=0,0,(W11-X11)) -> 0 | Z11: 218950.4 | AA11: ='Stock Valuation (FIFO)'!Z14 -> 0 | AB11: =IF(AA11=0,0,(Z11-AA11)) -> 0 | AC11: 255945.6 | AD11: ='Stock Valuation (FIFO)'!AC14 -> 0 | AE11: =IF(AD11=0,0,(AC11-AD11)) -> 0 | AF11: 261815 | AG11: 261816 | AH11: =IF(AG11=0,0,(AF11-AG11)) -> -1 | AI11: 239651.2 | AJ11: ='Stock Valuation (FIFO)'!AI14 -> 0 | AK11: =IF(AJ11=0,0,(AI11-AJ11)) -> 0 | AL11: 200810.4 | AM11: ='Stock Valuation (FIFO)'!AL14 -> 0 | AN11: =IF(AM11=0,0,(AL11-AM11)) -> 0
A12: TSN | B12: 244 | C12: ='Trading PL'!B42 -> 172 | D12: =B12-C12 -> 72 | E12: 256.6 | F12: ='Trading PL'!B35 -> 172 | G12: =IF(F12=0,0,(E12-F12)) -> 84.6 | H12: 257 | I12: ='Trading PL'!E35 -> 340 | J12: =IF(I12=0,0,(H12-I12)) -> -83 | K12: 197.1 | L12: ='Trading PL'!H35 -> 0 | M12: =IF(L12=0,0,(K12-L12)) -> 0 | N12: 197.1 | O12: ='Trading PL'!K35 -> 0 | P12: =IF(O12=0,0,(N12-O12)) -> 0 | Q12: 197.1 | R12: ='Trading PL'!N35 -> 0 | S12: =IF(R12=0,0,(Q12-R12)) -> 0 | T12: 183.1 | U12: ='Stock Valuation (FIFO)'!T16 -> 0 | V12: =IF(U12=0,0,(T12-U12)) -> 0 | W12: 183.1 | X12: ='Stock Valuation (FIFO)'!W16 -> 0 | Y12: =IF(X12=0,0,(W12-X12)) -> 0 | Z12: =423.5-36.5 -> 387 | AA12: ='Stock Valuation (FIFO)'!Z15 -> 0 | AB12: =IF(AA12=0,0,(Z12-AA12)) -> 0 | AC12: =423.5-AC16 -> 387 | AD12: ='Stock Valuation (FIFO)'!AC15 -> 0 | AE12: =IF(AD12=0,0,(AC12-AD12)) -> 0 | AF12: =423.5-37 -> 386.5 | AG12: 387 | AH12: =IF(AG12=0,0,(AF12-AG12)) -> -0.5 | AI12: =423.5-AI16 -> 386.5 | AJ12: ='Stock Valuation (FIFO)'!AI15 -> 0 | AK12: =IF(AJ12=0,0,(AI12-AJ12)) -> 0 | AL12: =423.5-AL16 -> 386.5 | AM12: ='Stock Valuation (FIFO)'!AL15 -> 0 | AN12: =IF(AM12=0,0,(AL12-AM12)) -> 0
A13: MSN | B13: 387 | C13: ='Trading PL'!B41 -> 387 | D13: =B13-C13 -> 0 | E13: 387 | F13: ='Trading PL'!B34 -> 387 | G13: =IF(F13=0,0,(E13-F13)) -> 0 | H13: 387 | I13: ='Trading PL'!E34 -> 387 | J13: =IF(I13=0,0,(H13-I13)) -> 0 | K13: 387 | L13: ='Trading PL'!H34 -> 0 | M13: =IF(L13=0,0,(K13-L13)) -> 0 | N13: 387 | O13: ='Trading PL'!K34 -> 0 | P13: =IF(O13=0,0,(N13-O13)) -> 0 | Q13: 404 | R13: ='Trading PL'!N34 -> 0 | S13: =IF(R13=0,0,(Q13-R13)) -> 0 | T13: 410 | U13: ='Stock Valuation (FIFO)'!T15 -> 0 | V13: =IF(U13=0,0,(T13-U13)) -> 0 | W13: 410 | X13: ='Stock Valuation (FIFO)'!W15 -> 0 | Y13: =IF(X13=0,0,(W13-X13)) -> 0 | Z13: 183.1 | AA13: ='Stock Valuation (FIFO)'!Z16 -> 0 | AB13: =IF(AA13=0,0,(Z13-AA13)) -> 0 | AC13: 179.1 | AD13: ='Stock Valuation (FIFO)'!AC16 -> 0 | AE13: =IF(AD13=0,0,(AC13-AD13)) -> 0 | AF13: 179.1 | AG13: 179 | AH13: =IF(AG13=0,0,(AF13-AG13)) -> 0.1 | AI13: 177.9 | AJ13: ='Stock Valuation (FIFO)'!AI16 -> 0 | AK13: =IF(AJ13=0,0,(AI13-AJ13)) -> 0 | AL13: 171.9 | AM13: ='Stock Valuation (FIFO)'!AL16 -> 0 | AN13: =IF(AM13=0,0,(AL13-AM13)) -> 0
A14: PP Sacks | C14: ='Trading PL'!B44 -> 0 | D14: =B14-C14 -> 0 | E14: 0 | F14: ='Trading PL'!B38 -> 36 | G14: =IF(F14=0,0,(E14-F14)) -> -36 | H14: 0 | I14: ='Trading PL'!E38 -> 36 | J14: =IF(I14=0,0,(H14-I14)) -> -36 | K14: 0 | L14: ='Trading PL'!H38 -> 0 | M14: =IF(L14=0,0,(K14-L14)) -> 0 | N14: 0 | O14: ='Trading PL'!K38 -> 0 | P14: =IF(O14=0,0,(N14-O14)) -> 0 | S14: =IF(R14=0,0,(Q14-R14)) -> 0 | T14: 0 | V14: =IF(U14=0,0,(T14-U14)) -> 0 | W14: 0 | Y14: =IF(X14=0,0,(W14-X14)) -> 0 | Z14: 804.1 | AA14: ='Stock Valuation (FIFO)'!Z17 -> 0 | AB14: =IF(AA14=0,0,(Z14-AA14)) -> 0 | AC14: 391.2 | AD14: ='Stock Valuation (FIFO)'!AC17 -> 0 | AE14: =IF(AD14=0,0,(AC14-AD14)) -> 0 | AF14: 196.2 | AG14: 196 | AH14: =IF(AG14=0,0,(AF14-AG14)) -> 0.2 | AK14: =IF(AJ14=0,0,(AI14-AJ14)) -> 0 | AL14: 0 | AN14: =IF(AM14=0,0,(AL14-AM14)) -> 0
A15: Weed Mat | B15: 75 | C15: ='Trading PL'!B43 -> 446 | D15: =B15-C15 -> -371 | E15: 46.8 | F15: ='Trading PL'!B37 -> 0 | G15: =IF(F15=0,0,(E15-F15)) -> 0 | H15: 36.1 | I15: ='Trading PL'!E37 -> 0 | J15: =IF(I15=0,0,(H15-I15)) -> 0 | K15: 26.1 | L15: ='Trading PL'!H37 -> 0 | M15: =IF(L15=0,0,(K15-L15)) -> 0 | N15: 129.1 | O15: ='Trading PL'!K37 -> 0 | P15: =IF(O15=0,0,(N15-O15)) -> 0 | Q15: 153.1 | R15: ='Trading PL'!N36 -> 0 | S15: =IF(R15=0,0,(R15-Q15)) -> 0 | T15: 450.1 | U15: ='Stock Valuation (FIFO)'!T17 -> 0 | V15: =IF(U15=0,0,(T15-U15)) -> 0 | W15: 172.1 | X15: ='Stock Valuation (FIFO)'!W17 -> 0 | Y15: =IF(X15=0,0,(W15-X15)) -> 0 | AB15: =IF(AA15=0,0,(Z15-AA15)) -> 0 | AD15: ='Stock Valuation (FIFO)'!AC18 -> 0 | AE15: =IF(AD15=0,0,(AC15-AD15)) -> 0 | AH15: =IF(AG15=0,0,(AF15-AG15)) -> 0 | AI15: 446.2 | AJ15: ='Stock Valuation (FIFO)'!AI17 -> 0 | AK15: =IF(AJ15=0,0,(AI15-AJ15)) -> 0 | AL15: 446.2 | AM15: ='Stock Valuation (FIFO)'!AL17 -> 0 | AN15: =IF(AM15=0,0,(AL15-AM15)) -> 0
A16: PP Fabric | D16: =B16-C16 -> 0 | G16: =IF(F16=0,0,(E16-F16)) -> 0 | J16: =IF(I16=0,0,(H16-I16)) -> 0 | M16: =IF(L16=0,0,(K16-L16)) -> 0 | P16: =IF(O16=0,0,(N16-O16)) -> 0 | R16: ='Trading PL'!N38 -> 0 | S16: =IF(R16=0,0,(R16-Q16)) -> 0 | U16: ='Stock Valuation (FIFO)'!T19 -> 0 | X16: ='Stock Valuation (FIFO)'!W19 -> 0 | Y16: =IF(X16=0,0,(W16-X16)) -> 0 | Z16: 36.5 | AA16: ='Stock Valuation (FIFO)'!Z19 -> 0 | AB16: =IF(AA16=0,0,(Z16-AA16)) -> 0 | AC16: 36.5 | AD16: ='Stock Valuation (FIFO)'!AC19 -> 0 | AE16: =IF(AD16=0,0,(AC16-AD16)) -> 0 | AF16: 37 | AG16: 37 | AH16: =IF(AG16=0,0,(AF16-AG16)) -> 0 | AI16: 37 | AJ16: ='Stock Valuation (FIFO)'!AI19 -> 0 | AK16: =IF(AJ16=0,0,(AI16-AJ16)) -> 0 | AL16: 37 | AM16: ='Stock Valuation (FIFO)'!AL19 -> 0 | AN16: =IF(AM16=0,0,(AL16-AM16)) -> 0
A17: Fabric Total | B17: =SUM(B11:B16) -> 206733 | C17: =SUM(C11:C16) -> 201815 | D17: =B17-C17 -> 4918 | E17: =SUM(E11:E16) -> 224735.3 | F17: =SUM(F11:F16) -> 217482 | G17: =IF(F17=0,0,(E17-F17)) -> 7253.3 | H17: =SUM(H11:H16) -> 202526.4 | I17: =SUM(I11:I16) -> 180429 | J17: =IF(I17=0,0,(H17-I17)) -> 22097.4 | K17: =SUM(K11:K16) -> 191885.4 | L17: =SUM(L11:L16) -> 0 | M17: =IF(L17=0,0,(K17-L17)) -> 0 | N17: =SUM(N11:N16) -> 198508.3 | O17: =SUM(O11:O16) -> 0 | P17: =IF(O17=0,0,(N17-O17)) -> 0 | Q17: =SUM(Q11:Q16) -> 203063.5 | R17: =SUM(R11:R15) -> 0 | S17: =IF(R17=0,0,(Q17-R17)) -> 0 | T17: =SUM(T11:T16) -> 229764.6 | U17: =SUM(U11:U16) -> 0 | V17: =IF(U17=0,0,(T17-U17)) -> 0 | W17: =SUM(W11:W16) -> 238712.5 | X17: =SUM(X11:X16) -> 0 | Y17: =IF(X17=0,0,(W17-X17)) -> 0 | Z17: =SUM(Z11:Z16) -> 220361.1 | AA17: =SUM(AA11:AA16) -> 0 | AB17: =IF(AA17=0,0,(Z17-AA17)) -> 0 | AC17: =SUM(AC11:AC16) -> 256939.4 | AD17: =SUM(AD11:AD16) -> 0 | AE17: =IF(AD17=0,0,(AC17-AD17)) -> 0 | AF17: =SUM(AF11:AF16) -> 262613.8 | AG17: =SUM(AG11:AG16) -> 262615 | AH17: =IF(AG17=0,0,(AF17-AG17)) -> -1.2 | AI17: =SUM(AI11:AI16) -> 240698.8 | AJ17: =SUM(AJ11:AJ16) -> 0 | AK17: =IF(AJ17=0,0,(AI17-AJ17)) -> 0 | AL17: =SUM(AL11:AL16) -> 201852 | AM17: =SUM(AM11:AM16) -> 0 | AN17: =IF(AM17=0,0,(AL17-AM17)) -> 0
A18: TOTAL | B18: =B7+B10+B17 -> 530467 | C18: =C7+C10+C17 -> 447471 | D18: =B18-C18 -> 82996 | E18: =E7+E10+E17 -> 527374.5 | F18: =F7+F10+F17 -> 372587 | G18: =IF(F18=0,0,(E18-F18)) -> 154787.5 | H18: =H7+H10+H17 -> 460685.4 | I18: =I7+I10+I17 -> 346392 | J18: =IF(I18=0,0,(H18-I18)) -> 114293.4 | K18: =K7+K10+K17 -> 477952.8 | L18: =L7+L10+L17 -> 0 | M18: =IF(L18=0,0,(K18-L18)) -> 0 | N18: =N7+N10+N17 -> 469932.9 | O18: =O7+O10+O17 -> 0 | P18: =IF(O18=0,0,(N18-O18)) -> 0 | Q18: =Q7+Q10+Q17 -> 520767.1 | R18: =R7+R10+R17 -> 155055.7 | S18: =IF(R18=0,0,(Q18-R18)) -> 365711.4 | T18: =T7+T10+T17 -> 482634 | U18: =U7+U10+U17 -> 0 | V18: =IF(U18=0,0,(T18-U18)) -> 0 | W18: =W7+W10+W17 -> 522362.7 | X18: =X7+X10+X17 -> 0 | Y18: =IF(X18=0,0,(W18-X18)) -> 0 | Z18: =Z7+Z10+Z17 -> 529435.1 | AA18: =AA7+AA10+AA17 -> 0 | AB18: =IF(AA18=0,0,(Z18-AA18)) -> 0 | AC18: =AC7+AC10+AC17 -> 541442.9 | AD18: =AD7+AD10+AD17 -> 0 | AE18: =IF(AD18=0,0,(AC18-AD18)) -> 0 | AF18: =AF7+AF10+AF17 -> 579350.5 | AG18: =AG7+AG10+AG17 -> 579352 | AH18: =IF(AG18=0,0,(AF18-AG18)) -> -1.5 | AI18: =AI7+AI10+AI17 -> 536653.5 | AJ18: =AJ7+AJ10+AJ17 -> 0 | AK18: =IF(AJ18=0,0,(AI18-AJ18)) -> 0 | AL18: =AL7+AL10+AL17 -> 467993.89 | AM18: =AM7+AM10+AM17 -> 102167 | AN18: =IF(AM18=0,0,(AL18-AM18)) -> 365826.89
A20: SFG/FG | B20: =B18-B7 -> 332926 | C20: =C18-C7 -> 303982 | D20: =B20-C20 -> 28944 | E20: =E18-E7 -> 344910.9 | F20: =F18-F7 -> 294479 | G20: =IF(F20=0,0,(E20-F20)) -> 50431.9 | H20: =H18-H7 -> 310941.6 | I20: =I18-I7 -> 254093 | J20: =IF(I20=0,0,(H20-I20)) -> 56848.6 | K20: =K18-K7 -> 311174.6 | L20: =L18-L7 -> 0 | M20: =IF(L20=0,0,(K20-L20)) -> 0 | N20: =N18-N7 -> 320985.8 | O20: =O18-O7 -> 0 | P20: =IF(O20=0,0,(N20-O20)) -> 0 | Q20: =Q18-Q7 -> 330039.4 | R20: =R18-R7 -> 155055.7 | S20: =IF(R20=0,0,(Q20-R20)) -> 174983.7 | T20: =T18-T7 -> 365118.5 | U20: =U18-U7 -> 0 | V20: =IF(U20=0,0,(T20-U20)) -> 0 | W20: =W18-W7 -> 379701.5 | X20: =X18-X7 -> 0 | Y20: =IF(X20=0,0,(W20-X20)) -> 0 | Z20: =Z18-Z7 -> 362682.7 | AA20: =AA18-AA7 -> 0 | AB20: =IF(AA20=0,0,(Z20-AA20)) -> 0 | AC20: =AC18-AC7 -> 403532.4 | AD20: =AD18-AD7 -> 0 | AE20: =IF(AD20=0,0,(AC20-AD20)) -> 0 | AF20: =AF18-AF7 -> 402129.2 | AG20: =AG18-AG7 -> 402131 | AH20: =IF(AG20=0,0,(AF20-AG20)) -> -1.8 | AI20: =AI18-AI7 -> 379064.6 | AJ20: =AJ18-AJ7 -> 0 | AK20: =IF(AJ20=0,0,(AI20-AJ20)) -> 0 | AL20: =AL18-AL7 -> 324505.29 | AM20: =AM18-AM7 -> 102167 | AN20: =IF(AM20=0,0,(AL20-AM20)) -> 222338.29
E21: =E20-B20 -> 11984.9 | H21: =H20-E20 -> -33969.3 | K21: =K20-H20 -> 233 | N21: =N20-K20 -> 9811.2 | Q21: =Q20-N20 -> 9053.6 | T21: =T20-Q20 -> 35079.1 | W21: =W20-T20 -> 14583
E22: =E20-$B$20 -> 11984.9 | H22: =H20-$B$20 -> -21984.4 | K22: =K20-$B$20 -> -21751.4 | N22: =N20-$B$20 -> -11940.2 | Q22: =Q20-$B$20 -> -2886.6 | T22: =T20-$B$20 -> 32192.5 | W22: =W20-$B$20 -> 46775.5
A23: Tarka->
A24: HDPE | H24: =63410+93000 -> 156410 | I24: =H4-H24 -> -9000
A25: MB | H25: 2240 | I25: =H5-H25 -> 53.7
A26: CP | H26: 80 | I26: =H6-H26 -> -39.9
A27: RM Total | H27: =SUM(H24:H26) -> 158730 | I27: =SUM(I24:I26) -> -8986.2
A28: Yarn Factory | H28: 30450 | I28: =H8-H28 -> 16114
A29: Yarn Fabrctr | H29: 64627 | I29: =H9-H29 -> -2775.8
A30: Yarn Total | H30: =SUM(H28:H29) -> 95077 | I30: =SUM(I28:I29) -> 13338.2
A31: Fabric | H31: 332260 | I31: =H11-H31 -> -130413.7
A32: TSN | H32: 108 | I32: =H12-H32 -> 149
A33: MSN | H33: 1015 | I33: =H13-H33 -> -628
A34: Weed Mat
A35: PP Fab
A36: PP Sacks | Q36: 942.6
A37: Fabric Total | H37: =SUM(H31:H36) -> 333383 | I37: =SUM(I31:I36) -> -130892.7
A38: TOTAL | H38: =H27+H30+H37 -> 587190 | I38: =I27+I30+I37 -> -126540.7
A40: SFG/FG | H40: =H38-H27 -> 428460 | I40: =I38-I27 -> -117554.5

Sheet Inventory Sales
A2: Particulars | B2: Apr | E2: May | H2: Jun | K2: Jul | N2: Aug | Q2: Sep | T2: Oct | W2: Nov | Z2: Dec | AC2: Jan | AF2: Feb | AI2: Mar | AL2: Total
A3: Finished Goods | B3: Outwards Qty | C3: Rate | D3: Amount | E3: Outwards Qty | F3: Rate | G3: Amount | H3: Outwards Qty | I3: Rate | J3: Amount | K3: Outwards Qty | L3: Rate | M3: Amount | N3: Outwards Qty | O3: Rate | P3: Amount | Q3: Outwards Qty | R3: Rate | S3: Amount | T3: Outwards Qty | U3: Rate | V3: Amount | W3: Outwards Qty | X3: Rate | Y3: Amount | Z3: Outwards Qty | AA3: Rate | AB3: Amount | AC3: Outwards Qty | AD3: Rate | AE3: Amount | AF3: Outwards Qty | AG3: Rate | AH3: Amount | AI3: Outwards Qty | AJ3: Rate | AK3: Amount | AL3: Outwards Qty | AM3: Rate | AN3: Amount
A5: MCF | B5: 29736 | C5: =IF(B5=0,0,D5/B5) -> 306.90207 | D5: 9126040 | E5: 42618.06 | F5: =IF(E5=0,0,G5/E5) -> 307.64997 | G5: 13111445 | I5: =IF(H5=0,0,J5/H5) -> 0 | L5: =IF(K5=0,0,M5/K5) -> 0 | O5: =IF(N5=0,0,P5/N5) -> 0 | R5: =IF(Q5=0,0,S5/Q5) -> 0 | U5: =IF(T5=0,0,V5/T5) -> 0 | X5: =IF(W5=0,0,Y5/W5) -> 0 | AA5: =IF(Z5=0,0,AB5/Z5) -> 0 | AD5: =IF(AC5=0,0,AE5/AC5) -> 0 | AG5: =IF(AF5=0,0,AH5/AF5) -> 0 | AJ5: =IF(AI5=0,0,AK5/AI5) -> 0 | AL5: =SUM(B5,E5,H5,K5,N5,Q5,T5,W5,Z5,AC5,AF5,AI5) -> 72354.06 | AM5: =IF(AL5=0,0,AN5/AL5) -> 307.3426 | AN5: =SUM(D5,G5,J5,M5,P5,S5,V5,Y5,AB5,AE5,AH5,AK5) -> 22237485
A6: WMF | B6: 60203 | C6: =IF(B6=0,0,D6/B6) -> 284.90781 | D6: 17152305 | E6: 65542.47 | F6: =IF(E6=0,0,G6/E6) -> 276.00743 | G6: 18090208 | I6: =IF(H6=0,0,J6/H6) -> 0 | L6: =IF(K6=0,0,M6/K6) -> 0 | O6: =IF(N6=0,0,P6/N6) -> 0 | R6: =IF(Q6=0,0,S6/Q6) -> 0 | U6: =IF(T6=0,0,V6/T6) -> 0 | X6: =IF(W6=0,0,Y6/W6) -> 0 | AA6: =IF(Z6=0,0,AB6/Z6) -> 0 | AD6: =IF(AC6=0,0,AE6/AC6) -> 0 | AG6: =IF(AF6=0,0,AH6/AF6) -> 0 | AJ6: =IF(AI6=0,0,AK6/AI6) -> 0 | AL6: =SUM(B6,E6,H6,K6,N6,Q6,T6,W6,Z6,AC6,AF6,AI6) -> 125745.47 | AM6: =IF(AL6=0,0,AN6/AL6) -> 280.26865 | AN6: =SUM(D6,G6,J6,M6,P6,S6,V6,Y6,AB6,AE6,AH6,AK6) -> 35242513
A7: MONOFILAMENT FABRIC INSECT BAGS | C7: =IF(B7=0,0,D7/B7) -> 0 | I7: =IF(H7=0,0,J7/H7) -> 0 | L7: =IF(K7=0,0,M7/K7) -> 0 | R7: =IF(Q7=0,0,S7/Q7) -> 0 | X7: =IF(W7=0,0,Y7/W7) -> 0 | AA7: =IF(Z7=0,0,AB7/Z7) -> 0 | AD7: =IF(AC7=0,0,AE7/AC7) -> 0 | AG7: =IF(AF7=0,0,AH7/AF7) -> 0 | AJ7: =IF(AI7=0,0,AK7/AI7) -> 0 | AL7: =SUM(B7,E7,H7,K7,N7,Q7,T7,W7,Z7,AC7,AF7,AI7) -> 0 | AM7: =IF(AL7=0,0,AN7/AL7) -> 0 | AN7: =SUM(D7,G7,J7,M7,P7,S7,V7,Y7,AB7,AE7,AH7,AK7) -> 0
A8: MONOFILAMENT FABRIC INSECT NET | C8: =IF(B8=0,0,D8/B8) -> 0 | I8: =IF(H8=0,0,J8/H8) -> 0 | L8: =IF(K8=0,0,M8/K8) -> 0 | R8: =IF(Q8=0,0,S8/Q8) -> 0 | U8: =IF(T8=0,0,V8/T8) -> 0 | X8: =IF(W8=0,0,Y8/W8) -> 0 | AA8: =IF(Z8=0,0,AB8/Z8) -> 0 | AD8: =IF(AC8=0,0,AE8/AC8) -> 0 | AG8: =IF(AF8=0,0,AH8/AF8) -> 0 | AJ8: =IF(AI8=0,0,AK8/AI8) -> 0 | AL8: =SUM(B8,E8,H8,K8,N8,Q8,T8,W8,Z8,AC8,AF8,AI8) -> 0 | AM8: =IF(AL8=0,0,AN8/AL8) -> 0 | AN8: =SUM(D8,G8,J8,M8,P8,S8,V8,Y8,AB8,AE8,AH8,AK8) -> 0
A9: MONOFILAMENT FABRIC HAPPA | B9: 5 | C9: =IF(B9=0,0,D9/B9) -> 900 | D9: 4500 | F9: =IF(E9=0,0,G9/E9) -> 0 | I9: =IF(H9=0,0,J9/H9) -> 0 | L9: =IF(K9=0,0,M9/K9) -> 0 | O9: =IF(N9=0,0,P9/N9) -> 0 | R9: =IF(Q9=0,0,S9/Q9) -> 0 | U9: =IF(T9=0,0,V9/T9) -> 0 | X9: =IF(W9=0,0,Y9/W9) -> 0 | AA9: =IF(Z9=0,0,AB9/Z9) -> 0 | AD9: =IF(AC9=0,0,AE9/AC9) -> 0 | AG9: =IF(AF9=0,0,AH9/AF9) -> 0 | AJ9: =IF(AI9=0,0,AK9/AI9) -> 0 | AL9: =SUM(B9,E9,H9,K9,N9,Q9,T9,W9,Z9,AC9,AF9,AI9) -> 5 | AM9: =IF(AL9=0,0,AN9/AL9) -> 900 | AN9: =SUM(D9,G9,J9,M9,P9,S9,V9,Y9,AB9,AE9,AH9,AK9) -> 4500
A10: NWF/Yarn / Twisted Yarn | B10: 6050 | C10: =IF(B10=0,0,D10/B10) -> 179.00826 | D10: 1083000 | E10: 4500 | F10: =IF(E10=0,0,G10/E10) -> 176.11111 | G10: 792500 | I10: =IF(H10=0,0,J10/H10) -> 0 | L10: =IF(K10=0,0,M10/K10) -> 0 | O10: =IF(N10=0,0,P10/N10) -> 0 | R10: =IF(Q10=0,0,S10/Q10) -> 0 | U10: =IF(T10=0,0,V10/T10) -> 0 | X10: =IF(W10=0,0,Y10/W10) -> 0 | AA10: =IF(Z10=0,0,AB10/Z10) -> 0 | AD10: =IF(AC10=0,0,AE10/AC10) -> 0 | AG10: =IF(AF10=0,0,AH10/AF10) -> 0 | AJ10: =IF(AI10=0,0,AK10/AI10) -> 0 | AL10: =SUM(B10,E10,H10,K10,N10,Q10,T10,W10,Z10,AC10,AF10,AI10) -> 10550 | AM10: =IF(AL10=0,0,AN10/AL10) -> 177.77251 | AN10: =SUM(D10,G10,J10,M10,P10,S10,V10,Y10,AB10,AE10,AH10,AK10) -> 1875500
B11: =SUM(B5:B10) -> 95994 | C11: =IF(B11=0,0,D11/B11) -> 285.0787 | D11: =SUM(D5:D10) -> 27365845 | E11: =SUM(E5:E10) -> 112660.53 | F11: =IF(E11=0,0,G11/E11) -> 283.98724 | G11: =SUM(G5:G10) -> 31994153 | H11: =SUM(H5:H10) -> 0 | I11: =IF(H11=0,0,J11/H11) -> 0 | J11: =SUM(J5:J10) -> 0 | K11: =SUM(K5:K10) -> 0 | L11: =IF(K11=0,0,M11/K11) -> 0 | M11: =SUM(M5:M10) -> 0 | N11: =SUM(N5:N10) -> 0 | O11: =IF(N11=0,0,P11/N11) -> 0 | P11: =SUM(P5:P10) -> 0 | Q11: =SUM(Q5:Q10) -> 0 | R11: =IF(Q11=0,0,S11/Q11) -> 0 | S11: =SUM(S5:S10) -> 0 | T11: =SUM(T5:T10) -> 0 | U11: =IF(T11=0,0,V11/T11) -> 0 | V11: =SUM(V5:V10) -> 0 | W11: =SUM(W5:W10) -> 0 | X11: =IF(W11=0,0,Y11/W11) -> 0 | Y11: =SUM(Y5:Y10) -> 0 | Z11: =SUM(Z5:Z10) -> 0 | AA11: =IF(Z11=0,0,AB11/Z11) -> 0 | AB11: =SUM(AB5:AB10) -> 0 | AC11: =SUM(AC5:AC10) -> 0 | AD11: =IF(AC11=0,0,AE11/AC11) -> 0 | AE11: =SUM(AE5:AE10) -> 0 | AF11: =SUM(AF5:AF10) -> 0 | AG11: =IF(AF11=0,0,AH11/AF11) -> 0 | AH11: =SUM(AH5:AH10) -> 0 | AI11: =SUM(AI5:AI10) -> 0 | AJ11: =IF(AI11=0,0,AK11/AI11) -> 0 | AK11: =SUM(AK5:AK10) -> 0 | AL11: =SUM(AL5:AL10) -> 208654.53 | AM11: =IF(AL11=0,0,AN11/AL11) -> 284.48938 | AN11: =SUM(AN5:AN10) -> 59359998
A12: MSN | B12: 1148 | C12: =IF(B12=0,0,D12/B12) -> 288.7108 | D12: 331440 | E12: 1087 | F12: =IF(E12=0,0,G12/E12) -> 306.53032 | G12: 333198.46 | I12: =IF(H12=0,0,J12/H12) -> 0 | O12: =IF(N12=0,0,P12/N12) -> 0 | R12: =IF(Q12=0,0,S12/Q12) -> 0 | U12: =IF(T12=0,0,V12/T12) -> 0 | X12: =IF(W12=0,0,Y12/W12) -> 0 | AA12: =IF(Z12=0,0,AB12/Z12) -> 0 | AD12: =IF(AC12=0,0,AE12/AC12) -> 0 | AG12: =IF(AF12=0,0,AH12/AF12) -> 0 | AJ12: =IF(AI12=0,0,AK12/AI12) -> 0 | AL12: =SUM(B12,E12,H12,K12,N12,Q12,T12,W12,Z12,AC12,AF12,AI12) -> 2235 | AM12: =IF(AL12=0,0,AN12/AL12) -> 297.37739 | AN12: =SUM(D12,G12,J12,M12,P12,S12,V12,Y12,AB12,AE12,AH12,AK12) -> 664638.46
A13: TSN | B13: 544 | C13: =IF(B13=0,0,D13/B13) -> 322.89154 | D13: 175653 | E13: 24 | F13: =IF(E13=0,0,G13/E13) -> 312.5 | G13: 7500 | I13: =IF(H13=0,0,J13/H13) -> 0 | L13: =IF(K13=0,0,M13/K13) -> 0 | R13: =IF(Q13=0,0,S13/Q13) -> 0 | U13: =IF(T13=0,0,V13/T13) -> 0 | X13: =IF(W13=0,0,Y13/W13) -> 0 | AA13: =IF(Z13=0,0,AB13/Z13) -> 0 | AD13: =IF(AC13=0,0,AE13/AC13) -> 0 | AG13: =IF(AF13=0,0,AH13/AF13) -> 0 | AJ13: =IF(AI13=0,0,AK13/AI13) -> 0 | AL13: =SUM(B13,E13,H13,K13,N13,Q13,T13,W13,Z13,AC13,AF13,AI13) -> 568 | AM13: =IF(AL13=0,0,AN13/AL13) -> 322.45246 | AN13: =SUM(D13,G13,J13,M13,P13,S13,V13,Y13,AB13,AE13,AH13,AK13) -> 183153
A14: PP Woven Sacks | B14: 6124 | C14: =IF(B14=0,0,D14/B14) -> 247.34634 | D14: 1514749 | E14: 3727.5 | F14: =IF(E14=0,0,G14/E14) -> 242.55158 | G14: 904111 | I14: =IF(H14=0,0,J14/H14) -> 0 | L14: =IF(K14=0,0,M14/K14) -> 0 | O14: =IF(N14=0,0,P14/N14) -> 0 | R14: =IF(Q14=0,0,S14/Q14) -> 0 | U14: =IF(T14=0,0,V14/T14) -> 0 | X14: =IF(W14=0,0,Y14/W14) -> 0 | AA14: =IF(Z14=0,0,AB14/Z14) -> 0 | AD14: =IF(AC14=0,0,AE14/AC14) -> 0 | AG14: =IF(AF14=0,0,AH14/AF14) -> 0 | AJ14: =IF(AI14=0,0,AK14/AI14) -> 0 | AL14: =SUM(B14,E14,H14,K14,N14,Q14,T14,W14,Z14,AC14,AF14,AI14) -> 9851.5 | AM14: =IF(AL14=0,0,AN14/AL14) -> 245.53215 | AN14: =SUM(D14,G14,J14,M14,P14,S14,V14,Y14,AB14,AE14,AH14,AK14) -> 2418860
A15: ANTI BIRD NET / Rope/MULCH/FIBC | B15: 455 | C15: =IF(B15=0,0,D15/B15) -> 197.64835 | D15: 89930 | O15: =IF(N15=0,0,P15/N15) -> 0 | R15: =IF(Q15=0,0,S15/Q15) -> 0 | X15: =IF(W15=0,0,Y15/W15) -> 0 | AA15: =IF(Z15=0,0,AB15/Z15) -> 0 | AD15: =IF(AC15=0,0,AE15/AC15) -> 0 | AJ15: =IF(AI15=0,0,AK15/AI15) -> 0 | AL15: =SUM(B15,E15,H15,K15,N15,Q15,T15,W15,Z15,AC15,AF15,AI15) -> 455 | AM15: =IF(AL15=0,0,AN15/AL15) -> 197.64835 | AN15: =SUM(D15,G15,J15,M15,P15,S15,V15,Y15,AB15,AE15,AH15,AK15) -> 89930
A16: Knitted Fabric 8" Red/60" D Green | B16: 168 | C16: =IF(B16=0,0,D16/B16) -> 608.92857 | D16: 102300 | I16: =IF(H16=0,0,J16/H16) -> 0 | O16: =IF(N16=0,0,P16/N16) -> 0 | R16: =IF(Q16=0,0,S16/Q16) -> 0 | U16: =IF(T16=0,0,V16/T16) -> 0 | X16: =IF(W16=0,0,Y16/W16) -> 0 | AA16: =IF(Z16=0,0,AB16/Z16) -> 0 | AD16: =IF(AC16=0,0,AE16/AC16) -> 0 | AG16: =IF(AF16=0,0,AH16/AF16) -> 0 | AJ16: =IF(AI16=0,0,AK16/AI16) -> 0 | AL16: =SUM(B16,E16,H16,K16,N16,Q16,T16,W16,Z16,AC16,AF16,AI16) -> 168 | AM16: =IF(AL16=0,0,AN16/AL16) -> 608.92857 | AN16: =SUM(D16,G16,J16,M16,P16,S16,V16,Y16,AB16,AE16,AH16,AK16) -> 102300
A17: Weed Mat | B17: 1150 | C17: =IF(B17=0,0,D17/B17) -> 250.86957 | D17: 288500 | E17: 1690.1 | F17: =IF(E17=0,0,G17/E17) -> 239.9858 | G17: 405600 | I17: =IF(H17=0,0,J17/H17) -> 0 | L17: =IF(K17=0,0,M17/K17) -> 0 | O17: =IF(N17=0,0,P17/N17) -> 0 | R17: =IF(Q17=0,0,S17/Q17) -> 0 | U17: =IF(T17=0,0,V17/T17) -> 0 | X17: =IF(W17=0,0,Y17/W17) -> 0 | AA17: =IF(Z17=0,0,AB17/Z17) -> 0 | AD17: =IF(AC17=0,0,AE17/AC17) -> 0 | AG17: =IF(AF17=0,0,AH17/AF17) -> 0 | AJ17: =IF(AI17=0,0,AK17/AI17) -> 0 | AL17: =SUM(B17,E17,H17,K17,N17,Q17,T17,W17,Z17,AC17,AF17,AI17) -> 2840.1 | AM17: =IF(AL17=0,0,AN17/AL17) -> 244.3928 | AN17: =SUM(D17,G17,J17,M17,P17,S17,V17,Y17,AB17,AE17,AH17,AK17) -> 694100
B18: =SUM(B12:B17) -> 9589 | C18: =IF(B18=0,0,D18/B18) -> 260.98363 | D18: =SUM(D12:D17) -> 2502572 | E18: =SUM(E12:E17) -> 6528.6 | F18: =IF(E18=0,0,G18/E18) -> 252.79684 | G18: =SUM(G12:G17) -> 1650409.5 | H18: =SUM(H12:H17) -> 0 | I18: =IF(H18=0,0,J18/H18) -> 0 | J18: =SUM(J12:J17) -> 0 | K18: =SUM(K12:K17) -> 0 | L18: =IF(K18=0,0,M18/K18) -> 0 | M18: =SUM(M12:M17) -> 0 | N18: =SUM(N12:N17) -> 0 | O18: =IF(N18=0,0,P18/N18) -> 0 | P18: =SUM(P12:P17) -> 0 | Q18: =SUM(Q12:Q17) -> 0 | R18: =IF(Q18=0,0,S18/Q18) -> 0 | S18: =SUM(S12:S17) -> 0 | T18: =SUM(T12:T17) -> 0 | U18: =IF(T18=0,0,V18/T18) -> 0 | V18: =SUM(V12:V17) -> 0 | W18: =SUM(W12:W17) -> 0 | X18: =IF(W18=0,0,Y18/W18) -> 0 | Y18: =SUM(Y12:Y17) -> 0 | Z18: =SUM(Z12:Z17) -> 0 | AA18: =IF(Z18=0,0,AB18/Z18) -> 0 | AB18: =SUM(AB12:AB17) -> 0 | AC18: =SUM(AC12:AC17) -> 0 | AD18: =IF(AC18=0,0,AE18/AC18) -> 0 | AE18: =SUM(AE12:AE17) -> 0 | AF18: =SUM(AF12:AF17) -> 0 | AG18: =IF(AF18=0,0,AH18/AF18) -> 0 | AH18: =SUM(AH12:AH17) -> 0 | AI18: =SUM(AI12:AI17) -> 0 | AJ18: =IF(AI18=0,0,AK18/AI18) -> 0 | AK18: =SUM(AK12:AK17) -> 0 | AL18: =SUM(AL12:AL17) -> 16117.6 | AM18: =IF(AL18=0,0,AN18/AL18) -> 257.66749 | AN18: =SUM(AN12:AN17) -> 4152981.5 | AO18: =AL11+AL18 -> 224772.13
A19: Flexible Intermediate Bulk Container | F19: =IF(E19=0,0,G19/E19) -> 0 | R19: =IF(Q19=0,0,S19/Q19) -> 0 | X19: =IF(W19=0,0,Y19/W19) -> 0 | AA19: =IF(Z19=0,0,AB19/Z19) -> 0 | AD19: =IF(AC19=0,0,AE19/AC19) -> 0 | AG19: =IF(AF19=0,0,AH19/AF19) -> 0 | AJ19: =IF(AI19=0,0,AK19/AI19) -> 0 | AL19: =SUM(B19,E19,H19,K19,N19,Q19,T19,W19,Z19,AC19,AF19,AI19) -> 0 | AM19: =IF(AL19=0,0,AN19/AL19) -> 0 | AN19: =SUM(D19,G19,J19,M19,P19,S19,V19,Y19,AB19,AE19,AH19,AK19) -> 0
A20: Packing Materials / Old use Batteries | F20: =IF(E20=0,0,G20/E20) -> 0 | R20: =IF(Q20=0,0,S20/Q20) -> 0 | X20: =IF(W20=0,0,Y20/W20) -> 0 | AA20: =IF(Z20=0,0,AB20/Z20) -> 0 | AD20: =IF(AC20=0,0,AE20/AC20) -> 0 | AG20: =IF(AF20=0,0,AH20/AF20) -> 0 | AL20: =SUM(B20,E20,H20,K20,N20,Q20,T20,W20,Z20,AC20,AF20,AI20) -> 0 | AM20: =IF(AL20=0,0,AN20/AL20) -> 0 | AN20: =SUM(D20,G20,J20,M20,P20,S20,V20,Y20,AB20,AE20,AH20,AK20) -> 0
A21: HDPE Monofilament Waste | B21: 2174 | C21: =IF(B21=0,0,D21/B21) -> 10 | D21: 21740 | E21: 7460 | F21: =IF(E21=0,0,G21/E21) -> 10 | G21: 74600 | I21: =IF(H21=0,0,J21/H21) -> 0 | L21: =IF(K21=0,0,M21/K21) -> 0 | O21: =IF(N21=0,0,P21/N21) -> 0 | R21: =IF(Q21=0,0,S21/Q21) -> 0 | U21: =IF(T21=0,0,V21/T21) -> 0 | X21: =IF(W21=0,0,Y21/W21) -> 0 | AA21: =IF(Z21=0,0,AB21/Z21) -> 0 | AD21: =IF(AC21=0,0,AE21/AC21) -> 0 | AG21: =IF(AF21=0,0,AH21/AF21) -> 0 | AJ21: =IF(AI21=0,0,AK21/AI21) -> 0 | AL21: =SUM(B21,E21,H21,K21,N21,Q21,T21,W21,Z21,AC21,AF21,AI21) -> 9634 | AM21: =IF(AL21=0,0,AN21/AL21) -> 10 | AN21: =SUM(D21,G21,J21,M21,P21,S21,V21,Y21,AB21,AE21,AH21,AK21) -> 96340
A22: Sale of Asset Etc | R22: =IF(Q22=0,0,S22/Q22) -> 0 | X22: =IF(W22=0,0,Y22/W22) -> 0 | AA22: =IF(Z22=0,0,AB22/Z22) -> 0 | AD22: =IF(AC22=0,0,AE22/AC22) -> 0 | AG22: =IF(AF22=0,0,AH22/AF22) -> 0 | AJ22: =IF(AI22=0,0,AK22/AI22) -> 0 | AL22: =SUM(B22,E22,H22,K22,N22,Q22,T22,W22,Z22,AC22,AF22,AI22) -> 0 | AM22: =IF(AL22=0,0,AN22/AL22) -> 0 | AN22: =SUM(D22,G22,J22,M22,P22,S22,V22,Y22,AB22,AE22,AH22,AK22) -> 0
A23: Colour Pigment | C23: =IF(B23=0,0,D23/B23) -> 0 | L23: =IF(K23=0,0,M23/K23) -> 0 | O23: =IF(N23=0,0,P23/N23) -> 0 | R23: =IF(Q23=0,0,S23/Q23) -> 0 | X23: =IF(W23=0,0,Y23/W23) -> 0 | AA23: =IF(Z23=0,0,AB23/Z23) -> 0 | AD23: =IF(AC23=0,0,AE23/AC23) -> 0 | AG23: =IF(AF23=0,0,AH23/AF23) -> 0 | AJ23: =IF(AI23=0,0,AK23/AI23) -> 0 | AL23: =SUM(B23,E23,H23,K23,N23,Q23,T23,W23,Z23,AC23,AF23,AI23) -> 0 | AM23: =IF(AL23=0,0,AN23/AL23) -> 0 | AN23: =SUM(D23,G23,J23,M23,P23,S23,V23,Y23,AB23,AE23,AH23,AK23) -> 0
A24: Master Batch | C24: =IF(B24=0,0,D24/B24) -> 0 | E24: 25 | F24: =IF(E24=0,0,G24/E24) -> 380 | G24: 9500 | I24: =IF(H24=0,0,J24/H24) -> 0 | L24: =IF(K24=0,0,M24/K24) -> 0 | O24: =IF(N24=0,0,P24/N24) -> 0 | R24: =IF(Q24=0,0,S24/Q24) -> 0 | U24: =IF(T24=0,0,V24/T24) -> 0 | X24: =IF(W24=0,0,Y24/W24) -> 0 | AA24: =IF(Z24=0,0,AB24/Z24) -> 0 | AD24: =IF(AC24=0,0,AE24/AC24) -> 0 | AG24: =IF(AF24=0,0,AH24/AF24) -> 0 | AJ24: =IF(AI24=0,0,AK24/AI24) -> 0 | AL24: =SUM(B24,E24,H24,K24,N24,Q24,T24,W24,Z24,AC24,AF24,AI24) -> 25 | AM24: =IF(AL24=0,0,AN24/AL24) -> 380 | AN24: =SUM(D24,G24,J24,M24,P24,S24,V24,Y24,AB24,AE24,AH24,AK24) -> 9500
A25: HDPE | C25: =IF(B25=0,0,D25/B25) -> 0 | F25: =IF(E25=0,0,G25/E25) -> 0 | I25: =IF(H25=0,0,J25/H25) -> 0 | L25: =IF(K25=0,0,M25/K25) -> 0 | O25: =IF(N25=0,0,P25/N25) -> 0 | R25: =IF(Q25=0,0,S25/Q25) -> 0 | U25: =IF(T25=0,0,V25/T25) -> 0 | X25: =IF(W25=0,0,Y25/W25) -> 0 | AA25: =IF(Z25=0,0,AB25/Z25) -> 0 | AD25: =IF(AC25=0,0,AE25/AC25) -> 0 | AG25: =IF(AF25=0,0,AH25/AF25) -> 0 | AJ25: =IF(AI25=0,0,AK25/AI25) -> 0 | AL25: =SUM(B25,E25,H25,K25,N25,Q25,T25,W25,Z25,AC25,AF25,AI25) -> 0 | AM25: =IF(AL25=0,0,AN25/AL25) -> 0 | AN25: =SUM(D25,G25,J25,M25,P25,S25,V25,Y25,AB25,AE25,AH25,AK25) -> 0 | AO25: =AO18+AL25 -> 224772.13
B26: =SUM(B19:B25) -> 2174 | C26: =IF(B26=0,0,D26/B26) -> 10 | D26: =SUM(D19:D25) -> 21740 | E26: =SUM(E19:E25) -> 7485 | F26: =IF(E26=0,0,G26/E26) -> 11.235805 | G26: =SUM(G19:G25) -> 84100 | H26: =SUM(H19:H25) -> 0 | I26: =IF(H26=0,0,J26/H26) -> 0 | J26: =SUM(J19:J25) -> 0 | K26: =SUM(K19:K25) -> 0 | L26: =IF(K26=0,0,M26/K26) -> 0 | M26: =SUM(M19:M25) -> 0 | N26: =SUM(N19:N25) -> 0 | O26: =IF(N26=0,0,P26/N26) -> 0 | P26: =SUM(P19:P25) -> 0 | Q26: =SUM(Q19:Q25) -> 0 | R26: =IF(Q26=0,0,S26/Q26) -> 0 | S26: =SUM(S19:S25) -> 0 | T26: =SUM(T19:T25) -> 0 | U26: =IF(T26=0,0,V26/T26) -> 0 | V26: =SUM(V19:V25) -> 0 | W26: =SUM(W19:W25) -> 0 | X26: =IF(W26=0,0,Y26/W26) -> 0 | Y26: =SUM(Y19:Y25) -> 0 | Z26: =SUM(Z19:Z25) -> 0 | AA26: =IF(Z26=0,0,AB26/Z26) -> 0 | AB26: =SUM(AB19:AB25) -> 0 | AC26: =SUM(AC19:AC25) -> 0 | AD26: =IF(AC26=0,0,AE26/AC26) -> 0 | AF26: =SUM(AF19:AF25) -> 0 | AG26: =IF(AF26=0,0,AH26/AF26) -> 0 | AH26: =SUM(AH19:AH25) -> 0 | AI26: =SUM(AI19:AI25) -> 0 | AJ26: =IF(AI26=0,0,AK26/AI26) -> 0 | AK26: =SUM(AK19:AK25) -> 0 | AL26: =SUM(AL19:AL25) -> 9659 | AM26: =IF(AL26=0,0,AN26/AL26) -> 10.957656 | AN26: =SUM(AN19:AN25) -> 105840
A27: Grand total: | B27: =SUM(B11,B18,B26) -> 107757 | C27: =IF(B27=0,0,D27/B27) -> 277.38483 | D27: =SUM(D11,D18,D26) -> 29890157 | E27: =SUM(E11,E18,E26) -> 126674.13 | F27: =IF(E27=0,0,G27/E27) -> 266.26323 | G27: =SUM(G11,G18,G26) -> 33728663 | H27: =SUM(H11,H18,H26) -> 0 | I27: =IF(H27=0,0,J27/H27) -> 0 | J27: =SUM(J11,J18,J26) -> 0 | K27: =SUM(K11,K18,K26) -> 0 | L27: =IF(K27=0,0,M27/K27) -> 0 | M27: =SUM(M11,M18,M26) -> 0 | N27: =SUM(N11,N18,N26) -> 0 | O27: =IF(N27=0,0,P27/N27) -> 0 | P27: =SUM(P11,P18,P26) -> 0 | Q27: =SUM(Q11,Q18,Q26) -> 0 | R27: =IF(Q27=0,0,S27/Q27) -> 0 | S27: =SUM(S11,S18,S26) -> 0 | T27: =SUM(T11,T18,T26) -> 0 | U27: =IF(T27=0,0,V27/T27) -> 0 | V27: =SUM(V11,V18,V26) -> 0 | W27: =SUM(W11,W18,W26) -> 0 | X27: =IF(W27=0,0,Y27/W27) -> 0 | Y27: =SUM(Y11,Y18,Y26) -> 0 | Z27: =SUM(Z11,Z18,Z26) -> 0 | AA27: =IF(Z27=0,0,AB27/Z27) -> 0 | AB27: =SUM(AB11,AB18,AB26) -> 0 | AC27: =SUM(AC11,AC18,AC26) -> 0 | AD27: =IF(AC27=0,0,AE27/AC27) -> 0 | AE27: =SUM(AE11,AE18,AE26) -> 0 | AF27: =SUM(AF11,AF18,AF26) -> 0 | AG27: =IF(AF27=0,0,AH27/AF27) -> 0 | AH27: =SUM(AH11,AH18,AH26) -> 0 | AI27: =SUM(AI11,AI18,AI26) -> 0 | AJ27: =IF(AI27=0,0,AK27/AI27) -> 0 | AK27: =SUM(AK11,AK18,AK26) -> 0 | AL27: =SUM(AL11,AL18,AL26) -> 234431.13 | AM27: =IF(AL27=0,0,AN27/AL27) -> 271.37531 | AN27: =SUM(AN11,AN18,AN26) -> 63618820 | AO27: =AN27-AN21 -> 63522480
A28: Other Income | D28: 65.46 | AN28: =SUM(D28,G28,J28,M28,P28,S28,V28,Y28,AB28,AE28,AH28,AK28) -> 65.46
D29: =ROUND((D27-D21),0) -> 29868417 | G29: =ROUND((G27-G21),0) -> 33654063 | J29: =ROUND((J27-J21),0) -> 0 | M29: =ROUND((M27-M21),0) -> 0 | P29: =ROUND((P27-P21),0) -> 0 | S29: =ROUND((S27-S21),0) -> 0 | V29: =ROUND((V27-V21),0) -> 0 | Y29: =ROUND((Y27-Y21),0) -> 0 | AB29: =ROUND((AB27-AB21),0) -> 0 | AE29: =ROUND((AE27-AE21),0) -> 0 | AH29: =ROUND((AH27-AH21),0) -> 0 | AK29: =ROUND((AK27-AK21),0) -> 0 | AL29: =AL11+AL18 -> 224772.13 | AM29: =AN29/AL29 -> 282.56608 | AN29: =AN11+AN18 -> 63512980 | AP29: Sales extract value | AQ29: Sales extract kgs
A30: Gross sales | D30: 31402963 | G30: 35360571 | AN30: =SUM(D30,G30,J30,M30,P30,S30,V30,Y30,AB30,AE30,AH30,AK30) -> 66763534 | AP30: 29890157 | AQ30: 107758.28
A31: tax | D31: 1527660.3 | G31: 1649708 | AN31: =SUM(D31,G31,J31,M31,P31,S31,V31,Y31,AB31,AE31,AH31,AK31) -> 3177368.3 | AP31: =AN27-AP30 -> 33728663 | AQ31: =AL27-AQ30 -> 126672.85
A32: TCS | D32: 0 | AN32: =SUM(D32,G32,J32,M32,P32,S32,V32,Y32,AB32,AE32,AH32,AK32) -> 0
D33: =D31+D32 -> 1527660.3 | G33: =G31+G32 -> 1649708 | J33: =J31+J32 -> 0 | M33: =M31+M32 -> 0 | P33: =P31+P32 -> 0 | S33: =S31+S32 -> 0 | V33: =V31+V32 -> 0 | Y33: =Y31+Y32 -> 0 | AB33: =AB31+AB32 -> 0 | AE33: =AE31+AE32 -> 0 | AH33: =AH31+AH32 -> 0 | AK33: =AK31+AK32 -> 0 | AN33: =SUM(AN31:AN32) -> 3177368.3 | AQ33: P/L sales
D34: =D30-D33 -> 29875303 | G34: =G30-G33 -> 33710863 | J34: =J30-J33 -> 0 | M34: =M30-M33 -> 0 | P34: =P30-P33 -> 0 | S34: =S30-S33 -> 0 | V34: =V30-V33 -> 0 | Y34: =Y30-Y33 -> 0 | AB34: =AB30-AB33 -> 0 | AE34: =AE30-AE33 -> 0 | AH34: =AH30-AH33 -> 0 | AK34: =AK30-AK33 -> 0 | AN34: =AN30-AN33 -> 63586166 | AQ34: 29875303 | AR34: =AQ34-AN34 -> -33710863
A35: Discount | D35: 14854 | G35: 17800 | AN35: =SUM(D35,G35,J35,M35,P35,S35,V35,Y35,AB35,AE35,AH35,AK35) -> 32654
D36: =D34+D35-D37 -> 29890157 | G36: =G34+G35-G37 -> 33728663 | J36: =J34+J35 -> 0 | M36: =M34+M35-M37 -> 0 | P36: =P34+P35 -> 0 | S36: =S34+S35 -> 0 | V36: =V34+V35 -> 0 | Y36: =Y34+Y35 -> 0 | AB36: =AB34+AB35 -> 0 | AE36: =AE34+AE35 -> 0 | AH36: =AH34+AH35 -> 0 | AK36: =AK34+AK35 -> 0 | AN36: =AN34+AN35 -> 63618820 | AO36: =AN27-AN36 -> 0.079999998
A37: Credit Note | Y37: =Y36-Y27 -> 0 | AB37: =AB36-AB27 -> 0 | AE37: =AE36-AE27 -> 0 | AH37: 42540 | AK37: 51048 | AN37: =SUM(D37,G37,J37,M37,P37,S37,V37,Y37,AB37,AE37,AH37,AK37) -> 93588
D38: =D27-D36 -> 0.080000002 | G38: =G27-G36 -> 0 | J38: =J27-J36 -> 0 | M38: =M27-M36 -> 0 | P38: =P27-P36 -> 0 | S38: =S27-S36 -> 0 | V38: =V27-V36 -> 0 | Y38: =Y27-Y36 -> 0 | AB38: =AB27-AB36 -> 0 | AE38: =AE27-AE36 -> 0 | AH38: =AH27-AH36 -> 0 | AK38: =AK27-AK36 -> 0 | AN38: =AN36-AN27 -> -0.079999998
A39: PAL I- FINAL SALES +Less Waste & Discount | D39: =ROUND((D27-(D21+D22+D35)),0) -> 29853563 | G39: =ROUND((G27-(G21+G35)),0) -> 33636263 | J39: =ROUND((J27-(J21+J22+J35)),0) -> 0 | M39: =ROUND((M27-(M21+M22+M35)),0) -> 0 | P39: =ROUND((P27-(P21+P22+P35)),0) -> 0 | S39: =ROUND((S27-(S21+S22+S35)),0) -> 0 | V39: =ROUND((V27-(V21+V22+V35)),0) -> 0 | Y39: =ROUND((Y27-(Y21+Y22+Y35)),0) -> 0 | AB39: =ROUND((AB27-(AB21+AB22+AB35)),0) -> 0 | AE39: =ROUND((AE27-(AE21+AE22+AE35)),0) -> 0 | AH39: =ROUND((AH27-(AH21+AH22+AH35)),0) -> 0 | AK39: =ROUND((AK27-(AK21+AK22+AK35)),0) -> 0 | AN39: =ROUND((AN27-(AN21+AN22+AN35)),0) -> 63489826
AN40: =ROUND((AN39-(AN5+AN6)),0) -> 6009828 | AR40: =AR38-AR39 -> 0
AN41: =AN36-AN27 -> -0.079999998
A42: RM Purchase for sales | B42: =B25 -> 0 | D42: =ROUND((B25*C42),0) -> 0 | E42: =E24 -> 25 | F42: 375 | G42: =ROUND((E42*F42),0) -> 9375 | H42: =H25 -> 0 | I42: 85.79 | J42: =ROUND((H25*I42),0) -> 0 | K42: =K25 -> 0 | L42: 102.13 | M42: =ROUND((K25*L42),0) -> 0 | N42: =N25 -> 0 | O42: 92.93 | P42: =ROUND((N25*O42),0) -> 0 | Q42: =Q25 -> 0 | R42: 99.79 | S42: =ROUND((Q25*R42),0) -> 0 | T42: =T25 -> 0 | U42: 96.12 | V42: =ROUND((T25*U42),0) -> 0 | W42: =W25 -> 0 | X42: 100.88 | Y42: =ROUND((W25*X42),0) -> 0 | Z42: =Z25 -> 0 | AA42: 97.44 | AB42: =ROUND((Z25*AA42),0) -> 0 | AC42: =AC25 -> 0 | AD42: 96.36 | AE42: =ROUND((AC25*AD42),0) -> 0 | AF42: =AF25 -> 0 | AG42: 98.91 | AH42: =ROUND((AF25*AG42),0) -> 0 | AI42: =AI25 -> 0 | AJ42: 96 | AK42: =ROUND((AI25*AJ42),0) -> 0 | AL42: =SUM(B42,E42,H42,K42,N42,Q42,T42,W42,Z42,AC42,AF42,AI42) -> 25 | AN42: =SUM(D42,G42,J42,M42,P42,S42,V42,Y42,AB42,AE42,AH42,AK42) -> 9375 | AP42: `
...

Sheet Stock Valuation (FIFO)
B2: Opening Stock 01 Apr 26 | E2: 46113 | H2: 45778 | K2: 45809 | N2: 45839 | Q2: 45870 | T2: 45901 | W2: 45931 | Z2: 45962 | AC2: 45992 | AF2: 46023 | AI2: 46054 | AL2: 46082 | AO2: Bank Stock Statement
A3: RAW MATERIALS: | B3: QTY IN KGS. | C3: BASIC RATE | D3: BASIC VALUE | E3: QTY IN KGS. | F3: BASIC RATE | G3: BASIC VALUE | H3: QTY IN KGS. | I3: BASIC RATE | J3: BASIC VALUE | K3: QTY IN KGS. | L3: BASIC RATE | M3: BASIC VALUE | N3: QTY IN KGS. | O3: BASIC RATE | P3: BASIC VALUE | Q3: QTY IN KGS. | R3: BASIC RATE | S3: BASIC VALUE | T3: QTY IN KGS. | U3: BASIC RATE | V3: BASIC VALUE | W3: QTY IN KGS. | X3: BASIC RATE | Y3: BASIC VALUE | Z3: QTY IN KGS. | AA3: BASIC RATE | AB3: BASIC VALUE | AC3: QTY IN KGS. | AD3: BASIC RATE | AE3: BASIC VALUE | AF3: QTY IN KGS. | AG3: BASIC RATE | AH3: BASIC VALUE | AI3: QTY IN KGS. | AJ3: BASIC RATE | AL3: QTY IN KGS. | AM3: BASIC RATE | AN3: BASIC VALUE | AO3: QTY IN KGS. | AP3: BASIC RATE | AQ3: BASIC VALUE | AR3: QTY IN KGS. | AS3: BASIC RATE | AT3: BASIC VALUE | AU3: QTY IN KGS. | AV3: BASIC RATE | AW3: BASIC VALUE
AX4: Incr/(Decr)Stk | BA4: Stk frm Tarka as om 01 Apr(Srp) | BE4: Physical
A5: HDPE Granules | B5: 141140 | C5: =D5/B5+0.02 -> 121.99507 | D5: 17215561 | E5: 75695 | F5: =ROUND(IF(G5=0,0,(G5/E5)),0) -> 136 | G5: 10273379 | H5: 90040 | I5: =IF(J5=0,0,(J5/H5)) -> 152.60895 | J5: 13740910 | L5: =IF(M5=0,0,(M5/K5)) -> 0 | O5: =IF(P5=0,0,(P5/N5)) -> 0 | R5: =IF(S5=0,0,(S5/Q5)) -> 0 | U5: =IF(V5=0,0,(V5/T5)) -> 0 | X5: =IF(Y5=0,0,(Y5/W5)) -> 0 | AA5: =IF(AB5=0,0,(AB5/Z5)) -> 0 | AJ5: =IF(AK5=0,0,(AK5/AI5)) -> 0 | AP5: =IF(AQ5=0,0,(AQ5/AO5)) -> 0 | AR5: ='[1] Qty Analysis'!BE15 -> 0 | AT5: =ROUND((AS5*AR5),0) -> 0 | AU5: ='[1] Qty Analysis'!BH15 -> 0 | AW5: =ROUND((AV5*AU5),0) -> 0 | AX5: =Z5-B5 -> -141140 | AY5: =AX5/B5 -> -1 | BA5: =125000+40000 -> 165000 | BB5: 101 | BC5: =ROUND((BA5*BB5),0) -> 16665000 | BE5: 163575
A6: Master Batches | B6: 2330 | C6: =D6/B6+0.04 -> 226.96532 | D6: 528736 | E6: 2392 | F6: =ROUND(IF(G6=0,0,(G6/E6)),0) -> 245 | G6: 586833 | H6: 2239 | I6: =IF(J6=0,0,(J6/H6)) -> 258.70835 | J6: 579248 | L6: =IF(M6=0,0,(M6/K6)) -> 0 | O6: =IF(P6=0,0,(P6/N6)) -> 0 | R6: =IF(S6=0,0,(S6/Q6)) -> 0 | U6: =IF(V6=0,0,(V6/T6)) -> 0 | X6: =IF(Y6=0,0,(Y6/W6)) -> 0 | AA6: =IF(AB6=0,0,(AB6/Z6)) -> 0 | AJ6: =IF(AK6=0,0,(AK6/AI6)) -> 0 | AP6: =IF(AQ6=0,0,(AQ6/AO6)) -> 0 | AR6: ='[1] Qty Analysis'!BE27 -> 0 | AT6: =ROUND((AS6*AR6),0) -> 0 | AU6: ='[1] Qty Analysis'!BH27 -> 0 | AW6: =ROUND((AV6*AU6),0) -> 0 | AX6: =Z6-B6 -> -2330 | AY6: =AX6/B6 -> -1 | BA6: 2730 | BB6: 215 | BC6: =ROUND((BA6*BB6),0) -> 586950 | BE6: 2645
A7: Colour Pigments | B7: 19 | C7: =D7/B7-0.37 -> 1596.9984 | D7: 30350 | E7: 21 | F7: =ROUND(IF(G7=0,0,(G7/E7)),0) -> 1515 | G7: 31807 | H7: 20 | I7: =IF(J7=0,0,(J7/H7)) -> 1568.5 | J7: 31370 | L7: =IF(M7=0,0,(M7/K7)) -> 0 | O7: =IF(P7=0,0,(P7/N7)) -> 0 | R7: =IF(S7=0,0,(S7/Q7)) -> 0 | U7: =IF(V7=0,0,(V7/T7)) -> 0 | X7: =IF(Y7=0,0,(Y7/W7)) -> 0 | AA7: =IF(AB7=0,0,(AB7/Z7)) -> 0 | AJ7: =IF(AK7=0,0,(AK7/AI7)) -> 0 | AP7: =IF(AQ7=0,0,(AQ7/AO7)) -> 0 | AR7: ='[1] Qty Analysis'!BE39 -> 0 | AT7: =ROUND((AS7*AR7),0) -> 0 | AU7: ='[1] Qty Analysis'!BH39 -> 0 | AW7: =ROUND((AV7*AU7),0) -> 0 | AX7: =Z7-B7 -> -19 | AY7: =AX7/B7 -> -1 | BA7: 30 | BB7: 2280 | BC7: =ROUND((BA7*BB7),0) -> 68400 | BE7: 45.3
A8: Total | B8: =SUM(B5:B7) -> 143489 | C8: =D8/B8 -> 123.87463 | D8: =SUM(D5:D7) -> 17774647 | E8: =SUM(E5:E7) -> 78108 | F8: =IF(G8=0,0,(G8/E8)) -> 139.44819 | G8: =SUM(G5:G7) -> 10892019 | H8: =SUM(H5:H7) -> 92299 | I8: =IF(J8=0,0,(J8/H8)) -> 155.48953 | J8: =SUM(J5:J7) -> 14351528 | K8: =SUM(K5:K7) -> 0 | L8: =IF(M8=0,0,(M8/K8)) -> 0 | M8: =SUM(M5:M7) -> 0 | N8: =SUM(N5:N7) -> 0 | O8: =IF(P8=0,0,(P8/N8)) -> 0 | P8: =SUM(P5:P7) -> 0 | Q8: =SUM(Q5:Q7) -> 0 | R8: =IF(S8=0,0,(S8/Q8)) -> 0 | S8: =ROUND(SUM(S5:S7),0) -> 0 | T8: =SUM(T5:T7) -> 0 | U8: =IF(V8=0,0,(V8/T8)) -> 0 | V8: =SUM(V5:V7) -> 0 | W8: =SUM(W5:W7) -> 0 | X8: =IF(Y8=0,0,(Y8/W8)) -> 0 | Y8: =SUM(Y5:Y7) -> 0 | Z8: =SUM(Z5:Z7) -> 0 | AA8: =IF(AB8=0,0,(AB8/Z8)) -> 0 | AB8: =SUM(AB5:AB7) -> 0 | AC8: =SUM(AC5:AC7) -> 0 | AD8: =IF(AE8=0,0,(AE8/AC8)) -> 0 | AE8: =SUM(AE5:AE7) -> 0 | AF8: =SUM(AF5:AF7) -> 0 | AG8: =IF(AH8=0,0,(AH8/AF8)) -> 0 | AH8: =SUM(AH5:AH7) -> 0 | AI8: =SUM(AI5:AI7) -> 0 | AJ8: =IF(AK8=0,0,(AK8/AI8)) -> 0 | AK8: =SUM(AK5:AK7) -> 0 | AL8: =SUM(AL5:AL7) -> 0 | AM8: =IF(AN8=0,0,(AN8/AL8)) -> 0 | AN8: =SUM(AN5:AN7) -> 0 | AO8: =SUM(AO5:AO7) -> 0 | AP8: =IF(AQ8=0,0,(AQ8/AO8)) -> 0 | AQ8: =SUM(AQ5:AQ7) -> 0 | AR8: =SUM(AR5:AR7) -> 0 | AT8: =SUM(AT5:AT7) -> 0 | AU8: =SUM(AU5:AU7) -> 0 | AW8: =SUM(AW5:AW7) -> 0 | AX8: =Z8-B8 -> -143489 | AY8: =AX8/B8 -> -1 | BA8: =SUM(BA5:BA7) -> 167760 | BB8: =BC8/BA8 -> 103.24481 | BC8: =SUM(BC5:BC7) -> 17320350 | BE8: =SUM(BE5:BE7) -> 166265.3
A9: Work in Progress
A10: HDPE Tape - Factory | B10: 37996 | C10: 167 | D10: =B10*C10 -> 6345332 | E10: =26659.9+0.1 -> 26660 | F10: =66+116 -> 182 | G10: =ROUND(E10*F10,0) -> 4852120 | H10: 17001 | I10: 207 | J10: 3519207 | M10: =ROUND(K10*L10,0) -> 0 | P10: =ROUND(N10*O10,0) -> 0 | AB10: =ROUND((Z10*AA10),0) -> 0 | AE10: =ROUND((AC10*AD10),0) -> 0 | AH10: =ROUND((AF10*AG10),0) -> 0 | AK10: =ROUND((AI10*AJ10),0) -> 0 | AN10: =ROUND((AL10*AM10),0) -> 0 | AP10: =IF(AQ10=0,0,(AQ10/AO10)) -> 0 | AR10: ='[1] Qty Analysis'!BE66 -> 0 | AT10: =ROUND((AS10*AR10),0) -> 0 | AU10: ='[1] Qty Analysis'!BH66 -> 0 | AW10: =ROUND((AV10*AU10),0) -> 0 | AX10: =Z10-B10 -> -37996 | AY10: =AX10/B10 -> -1 | BA10: 24480 | BB10: 163 | BC10: =ROUND((BA10*BB10),0) -> 3990240 | BE10: 24112
A11: HDPE Tape - Job Work | B11: =64171.5-0.5 -> 64171 | C11: =C10 -> 167 | D11: =B11*C11 -> 10716557 | E11: 50337 | F11: =F10 -> 182 | G11: =ROUND(E11*F11,0) -> 9161334 | H11: 56663 | I11: 207 | J11: 11729241 | L11: =L10 -> 0 | M11: =ROUND(K11*L11,0) -> 0 | P11: =ROUND(N11*O11,0) -> 0 | R11: =R10 -> 0 | U11: =U10 -> 0 | AA11: =AA10 -> 0 | AB11: =ROUND((Z11*AA11),0) -> 0 | AE11: =ROUND((AC11*AD11),0) -> 0 | AH11: =ROUND((AF11*AG11),0) -> 0 | AJ11: =AJ10 -> 0 | AK11: =ROUND((AI11*AJ11),0) -> 0 | AM11: =AM10 -> 0 | AN11: =ROUND((AL11*AM11),0) -> 0 | AP11: =IF(AQ11=0,0,(AQ11/AO11)) -> 0 | AR11: ='[1] Qty Analysis'!BE81 -> 0 | AT11: =ROUND((AS11*AR11),0) -> 0 | AU11: ='[1] Qty Analysis'!BH81 -> 0 | AW11: =ROUND((AV11*AU11),0) -> 0 | AX11: =Z11-B11 -> -64171 | AY11: =AX11/B11 -> -1 | BA11: 66292 | BB11: 163 | BC11: =ROUND((BA11*BB11),0) -> 10805596 | BE11: 66292
A12: Total | B12: =SUM(B10:B11) -> 102167 | C12: =D12/B12 -> 167 | D12: =SUM(D10:D11) -> 17061889 | E12: =SUM(E10:E11) -> 76997 | F12: =G12/E12 -> 182 | G12: =SUM(G10:G11) -> 14013454 | H12: =SUM(H10:H11) -> 73664 | J12: =SUM(J10:J11) -> 15248448 | K12: =SUM(K10:K11) -> 0 | M12: =SUM(M10:M11) -> 0 | N12: =SUM(N10:N11) -> 0 | P12: =SUM(P10:P11) -> 0 | Q12: =SUM(Q10:Q11) -> 0 | S12: =SUM(S10:S11) -> 0 | T12: =SUM(T10:T11) -> 0 | V12: =SUM(V10:V11) -> 0 | W12: =SUM(W10:W11) -> 0 | X12: =IF(Y12=0,0,(Y12/W12)) -> 0 | Y12: =SUM(Y10:Y11) -> 0 | Z12: =SUM(Z10:Z11) -> 0 | AB12: =SUM(AB10:AB11) -> 0 | AC12: =SUM(AC10:AC11) -> 0 | AE12: =SUM(AE10:AE11) -> 0 | AF12: =SUM(AF10:AF11) -> 0 | AH12: =SUM(AH10:AH11) -> 0 | AI12: =SUM(AI10:AI11) -> 0 | AK12: =SUM(AK10:AK11) -> 0 | AL12: =SUM(AL10:AL11) -> 0 | AN12: =SUM(AN10:AN11) -> 0 | AO12: =SUM(AO10:AO11) -> 0 | AP12: =IF(AQ12=0,0,(AQ12/AO12)) -> 0 | AQ12: =SUM(AQ10:AQ11) -> 0 | AR12: =SUM(AR10:AR11) -> 0 | AT12: =SUM(AT10:AT11) -> 0 | AU12: =SUM(AU10:AU11) -> 0 | AW12: =SUM(AW10:AW11) -> 0 | AX12: =Z12-B12 -> -102167 | AY12: =AX12/B12 -> -1 | BA12: =SUM(BA10:BA11) -> 90772 | BB12: =BC12/BA12 -> 163 | BC12: =SUM(BC10:BC11) -> 14795836 | BE12: =SUM(BE10:BE11) -> 90404
A13: FINISHED GOODS:
A14: HDPE Fishnet Fabrics | B14: 200810 | C14: 238 | D14: =B14*C14 -> 47792780 | E14: 216887 | F14: =116+66+68 -> 250 | G14: =ROUND(E14*F14,0) -> 54221750 | H14: 179666 | I14: 278 | J14: 49947148 | U14: 221 | X14: =IF(Y14=0,0,(Y14/W14)) -> 0 | AA14: =IF(AB14=0,0,(AB14/Z14)) -> 0 | AD14: =IF(AE14=0,0,(AE14/AC14)) -> 0 | AP14: =IF(AQ14=0,0,(AQ14/AO14)) -> 0 | AR14: ='[1] Qty Analysis'!BE101 -> 0 | AT14: =ROUND((AS14*AR14),0) -> 0 | AU14: ='[1] Qty Analysis'!BH101 -> 0 | AW14: =ROUND((AV14*AU14),0) -> 0 | AX14: =Z14-B14 -> -200810 | AY14: =AX14/B14 -> -1 | BA14: 289350 | BB14: 228 | BC14: =ROUND((BA14*BB14),0) -> 65971800
A15: Monofilament Shade Net -MSN | B15: 387 | C15: =IF(B15=0,0,(D15/B15))+0.35 -> 215.00116 | D15: 83070 | E15: 387 | F15: =IF(E15=0,0,(G15/E15))-0.3 -> 240.00233 | G15: 92997 | H15: 387 | I15: =IF(H15=0,0,(J15/H15)) -> 241.70801 | J15: 93541 | L15: =IF(K15=0,0,(M15/K15)) -> 0 | O15: =IF(N15=0,0,(P15/N15)) -> 0 | U15: =V15/T15 -> #DIV/0! | X15: =IF(Y15=0,0,(Y15/W15)) -> 0 | AA15: =IF(AB15=0,0,(AB15/Z15)) -> 0 | AD15: =IF(AE15=0,0,(AE15/AC15)) -> 0 | AP15: =IF(AQ15=0,0,(AQ15/AO15)) -> 0 | AR15: ='[1] Qty Analysis'!BE122 -> 0 | AU15: ='[1] Qty Analysis'!BH122 -> 0 | AX15: =Z15-B15 -> -387 | AY15: =AX15/B15 -> -1 | BA15: 810 | BB15: =BC15/BA15 -> 214.81481 | BC15: 174000
A16: Tape Shade Net-TSN | B16: 172 | C16: =IF(B16=0,0,(D16/B16))+0.12 -> 240.86419 | D16: 41408 | E16: 172 | F16: =IF(E16=0,0,(G16/E16))+0.41 -> 266.84605 | G16: 45827 | H16: 340 | I16: =IF(H16=0,0,(J16/H16)) -> 258.02647 | J16: 87729 | L16: =IF(K16=0,0,(M16/K16)) -> 0 | O16: =IF(N16=0,0,(P16/N16)) -> 0 | U16: =V16/T16 -> #DIV/0! | X16: =IF(Y16=0,0,(Y16/W16)) -> 0 | AA16: =IF(AB16=0,0,(AB16/Z16)) -> 0 | AX16: =Z16-B16 -> -172 | AY16: =AX16/B16 -> -1
A17: Weed Mat | B17: 446 | C17: =IF(B17=0,0,(D17/B17))+0.5 -> 229.10314 | D17: 101957 | E17: 346 | F17: =IF(E17=0,0,(G17/E17))+0.5 -> 229.13295 | G17: 79107 | H17: 276 | I17: =IF(H17=0,0,(J17/H17)) -> 210.07609 | J17: 57981 | L17: =IF(K17=0,0,(M17/K17)) -> 0 | O17: =IF(N17=0,0,(P17/N17)) -> 0 | U17: =V17/T17 -> #DIV/0! | X17: =IF(Y17=0,0,(Y17/W17)) -> 0 | AA17: =IF(AB17=0,0,(AB17/Z17)) -> 0 | AX17: =Z17-B17 -> -446 | AY17: =AX17/B17 -> -1
A18: PP Fabric & Sacks | F18: =IF(E18=0,0,(G18/E18)) -> 0 | I18: =IF(H18=0,0,(J18/H18)) -> 0 | L18: =IF(K18=0,0,(M18/K18)) -> 0 | O18: =IF(N18=0,0,(P18/N18)) -> 0 | AA18: =IF(AB18=0,0,(AB18/Z18)) -> 0
A19: Miscellaneous | B19: 36 | C19: =IF(B19=0,0,(D19/B19))-0.01 -> 128.76778 | D19: 4636 | E19: 36 | F19: =IF(E19=0,0,(G19/E19))-0.14 -> 186.55444 | G19: 6721 | H19: 36 | I19: =IF(H19=0,0,(J19/H19)) -> 186.69444 | J19: 6721 | L19: =IF(K19=0,0,(M19/K19)) -> 0 | O19: =IF(N19=0,0,(P19/N19)) -> 0 | U19: =IF(V19=0,0,(V19/T19)) -> 0 | X19: =IF(Y19=0,0,(Y19/W19)) -> 0 | AA19: =IF(AB19=0,0,(AB19/Z19)) -> 0 | AP19: =IF(AQ19=0,0,(AQ19/AO19)) -> 0
A20: Total | B20: =SUM(B14:B19) -> 201851 | C20: =D20/B20 -> 237.91733 | D20: =SUM(D14:D19)-1 -> 48023850 | E20: =SUM(E14:E19) -> 217828 | F20: =G20/E20 -> 249.95135 | G20: =SUM(G14:G19) -> 54446402 | H20: =SUM(H14:H19) -> 180705 | J20: =SUM(J14:J19) -> 50193120 | K20: =SUM(K14:K19) -> 0 | M20: =SUM(M14:M19) -> 0 | N20: =SUM(N14:N19) -> 0 | P20: =SUM(P14:P19) -> 0 | Q20: =SUM(Q14:Q19) -> 0 | S20: =SUM(S14:S19) -> 0 | T20: =SUM(T14:T19) -> 0 | V20: =SUM(V14:V19) -> 0 | W20: =SUM(W14:W19) -> 0 | Y20: =SUM(Y14:Y19) -> 0 | Z20: =SUM(Z14:Z19) -> 0 | AB20: =SUM(AB14:AB19) -> 0 | AC20: =SUM(AC14:AC19) -> 0 | AE20: =SUM(AE14:AE19) -> 0 | AF20: =SUM(AF14:AF19) -> 0 | AH20: =SUM(AH14:AH19) -> 0 | AI20: =SUM(AI14:AI19) -> 0 | AK20: =SUM(AK14:AK19) -> 0 | AL20: =SUM(AL14:AL19) -> 0 | AN20: =SUM(AN14:AN19) -> 0 | AO20: =SUM(AO14:AO19) -> 0 | AP20: =AQ20/AO20 -> #DIV/0! | AQ20: =SUM(AQ14:AQ19) -> 0 | AR20: =SUM(AR14:AR19) -> 0 | AT20: =SUM(AT14:AT19) -> 0 | AU20: =SUM(AU14:AU19) -> 0 | AW20: =SUM(AW14:AW19) -> 0 | AX20: =Z20-B20 -> -201851 | AY20: =AX20/B20 -> -1 | BA20: =SUM(BA14:BA15) -> 290160 | BB20: =BC20/BA20 -> 227.96319 | BC20: =SUM(BC14:BC15) -> 66145800
A21: Trading Total | B21: =SUM(B15:B19) -> 1041 | C21: =IF(B21=0,0,(D21/B21)) -> 221.96926 | D21: =SUM(D15:D19)-1 -> 231070 | E21: =SUM(E15:E19) -> 941 | F21: =IF(E21=0,0,(G21/E21)) -> 238.73751 | G21: =SUM(G15:G19) -> 224652 | H21: =SUM(H15:H19) -> 1039 | I21: =IF(H21=0,0,(J21/H21)) -> 236.73917 | J21: =SUM(J15:J19) -> 245972 | K21: =SUM(K15:K19) -> 0 | L21: =IF(K21=0,0,(M21/K21)) -> 0 | M21: =SUM(M15:M19) -> 0 | N21: =SUM(N15:N19) -> 0 | O21: =IF(N21=0,0,(P21/N21)) -> 0 | P21: =SUM(P15:P19) -> 0 | Q21: =SUM(Q15:Q19) -> 0 | R21: =IF(Q21=0,0,(S21/Q21)) -> 0 | S21: =SUM(S15:S19) -> 0 | T21: =SUM(T15:T19) -> 0 | U21: =IF(T21=0,0,(V21/T21)) -> 0 | V21: =SUM(V15:V19) -> 0 | W21: =SUM(W15:W19) -> 0 | X21: =IF(W21=0,0,(Y21/W21)) -> 0 | Y21: =SUM(Y15:Y19) -> 0 | Z21: =SUM(Z15:Z19) -> 0 | AA21: =IF(Z21=0,0,(AB21/Z21)) -> 0 | AB21: =SUM(AB15:AB19) -> 0 | AC21: =SUM(AC15:AC19) -> 0 | AE21: =SUM(AE15:AE19) -> 0 | AF21: =SUM(AF15:AF19) -> 0 | AH21: =SUM(AH15:AH19) -> 0 | AI21: =SUM(AI15:AI19) -> 0 | AL21: =SUM(AL15:AL19) -> 0 | AM21: =IF(AL21=0,0,(AN21/AL21)) -> 0 | AN21: =SUM(AN15:AN19) -> 0 | AP21: S Dr
A22: Packing Materials | AP22: LC & Cr | AR22: ='[1] Qty Analysis'!BE44 -> 0 | AU22: ='[1] Qty Analysis'!BH44 -> 0
A23: Seconds | G23: =ROUND((E23*F23),0) -> 0 | J23: =ROUND((H23*I23),0) -> 0 | M23: =ROUND((K23*L23),0) -> 0 | P23: =ROUND((N23*O23),0) -> 0 | S23: =ROUND((Q23*R23),0) -> 0 | V23: =ROUND((T23*U23),0) -> 0 | Y23: =ROUND((W23*X23),0) -> 0 | AB23: =ROUND((Z23*AA23),0) -> 0 | AE23: =ROUND((AC23*AD23),0) -> 0 | AH23: =ROUND((AF23*AG23),0) -> 0 | AK23: =ROUND((AI23*AJ23),0) -> 0 | AN23: =ROUND((AL23*AM23),0) -> 0 | AR23: ='[1] Qty Analysis'!BE132 -> 0 | AU23: ='[1] Qty Analysis'!BH132 -> 0
A24: Total
A25: Grand Total | B25: =B20+B12+B8 -> 447507 | C25: =D25/B25 -> 185.15998 | D25: =D20+D12+D8 -> 82860386 | E25: =E20+E12+E8 -> 372933 | F25: =IF(E25=0,0,G25/E25) -> 212.77783 | G25: =G20+G12+G8 -> 79351875 | H25: =H20+H12+H8 -> 346668 | I25: =IF(H25=0,0,J25/H25) -> 230.17151 | J25: =J20+J12+J8 -> 79793096 | K25: =K20+K12+K8 -> 0 | L25: =IF(K25=0,0,M25/K25) -> 0 | M25: =M20+M12+M8 -> 0 | N25: =N20+N12+N8 -> 0 | O25: =IF(N25=0,0,P25/N25) -> 0 | P25: =P20+P12+P8 -> 0 | Q25: =Q20+Q12+Q8 -> 0 | R25: =IF(Q25=0,0,S25/Q25) -> 0 | S25: =S20+S12+S8 -> 0 | T25: =T20+T12+T8 -> 0 | U25: =IF(T25=0,0,V25/T25) -> 0 | V25: =V20+V12+V8 -> 0 | W25: =W20+W12+W8 -> 0 | X25: =IF(W25=0,0,Y25/W25) -> 0 | Y25: =Y20+Y12+Y8 -> 0 | Z25: =Z20+Z12+Z8 -> 0 | AA25: =IF(Z25=0,0,AB25/Z25) -> 0 | AB25: =AB20+AB12+AB8 -> 0 | AC25: =AC20+AC12+AC8 -> 0 | AD25: =IF(AC25=0,0,AE25/AC25) -> 0 | AE25: =AE20+AE12+AE8 -> 0 | AF25: =AF20+AF12+AF8 -> 0 | AG25: =IF(AF25=0,0,AH25/AF25) -> 0 | AH25: =AH20+AH12+AH8 -> 0 | AI25: =AI20+AI12+AI8 -> 0 | AJ25: =IF(AI25=0,0,AK25/AI25) -> 0 | AK25: =AK20+AK12+AK8 -> 0 | AL25: =AL20+AL12+AL8 -> 0 | AM25: =IF(AL25=0,0,AN25/AL25) -> 0 | AN25: =AN20+AN12+AN8 -> 0 | AO25: =AO20+AO12+AO8 -> 0 | AP25: =IF(AO25=0,0,AQ25/AO25) -> 0 | AQ25: =AQ8+AQ12+AQ20 -> 0 | AR25: =AR20+AR12+AR8 -> 0 | AT25: =AT20+AT12+AT8 -> 0 | AU25: =AU20+AU12+AU8 -> 0 | AW25: =AW20+AW12+AW8 -> 0 | AX25: =Z25-B25 -> -447507 | AY25: =AX25/B25 -> -1 | BA25: =BA20+BA12+BA8 -> 548692 | BB25: =IF(BA25=0,0,BC25/BA25) -> 179.08405 | BC25: =BC20+BC12+BC8 -> 98261986
A26: SFG/FG | B26: =B25-B8 -> 304018 | C26: =D26/B26 -> 214.08515 | D26: =D25-D8 -> 65085739 | E26: =E25-E8 -> 294825 | F26: =IF(E26=0,0,G26/E26) -> 232.20506 | G26: =G25-G8 -> 68459856 | H26: =H25-H8 -> 254369 | I26: =IF(H26=0,0,J26/H26) -> 257.27022 | J26: =J25-J8 -> 65441568 | K26: =K25-K8 -> 0 | L26: =IF(K26=0,0,M26/K26) -> 0 | M26: =M25-M8 -> 0 | N26: =N25-N8 -> 0 | O26: =IF(N26=0,0,P26/N26) -> 0 | P26: =P25-P8 -> 0 | Q26: =Q25-Q8 -> 0 | R26: =IF(Q26=0,0,S26/Q26) -> 0 | S26: =S25-S8 -> 0 | T26: =T25-T8 -> 0 | U26: =IF(T26=0,0,V26/T26) -> 0 | V26: =V25-V8 -> 0 | W26: =W25-W8 -> 0 | X26: =IF(W26=0,0,Y26/W26) -> 0 | Y26: =Y25-Y8 -> 0 | Z26: =Z25-Z8 -> 0 | AA26: =IF(Z26=0,0,AB26/Z26) -> 0 | AB26: =AB25-AB8 -> 0 | AC26: =AC25-AC8 -> 0 | AD26: =IF(AC26=0,0,AE26/AC26) -> 0 | AE26: =AE25-AE8 -> 0 | AF26: =AF25-AF8 -> 0 | AG26: =IF(AF26=0,0,AH26/AF26) -> 0 | AH26: =AH25-AH8 -> 0 | AI26: =AI25-AI8 -> 0 | AJ26: =IF(AI26=0,0,AK26/AI26) -> 0 | AK26: =AK25-AK8 -> 0 | AL26: =AL25-AL8 -> 0 | AM26: =IF(AL26=0,0,AN26/AL26) -> 0 | AN26: =AN25-AN8 -> 0 | AP26: 0.25 | AQ26: =ROUND(((AQ25+AQ21+AQ22)*25%),0) -> 0 | AR26: =AR25-AR8 -> 0 | AS26: =AT26/AR26 -> #DIV/0! | AT26: =AT25-AT8 -> 0 | AU26: =AU25-AU8 -> 0 | AV26: =AW26/AU26 -> #DIV/0! | AW26: =AW25-AW8 -> 0 | BA26: =BA25-BA8 -> 380932 | BC26: =BC25-BC8 -> 80941636
A27: Diff in SFG/FG | E27: =B26-E26 -> 9193 | G27: =D26-G26 -> -3374117 | H27: =E26-H26 -> 40456 | J27: =G26-J26 -> 3018288 | K27: =H26-K26 -> 254369 | M27: =J26-M26 -> 65441568 | N27: =K26-N26 -> 0 | O27: =P27/N27 -> #DIV/0! | P27: =M26-P26 -> 0 | Q27: =N26-Q26 -> 0 | R27: =S27/Q27 -> #DIV/0! | S27: =P26-S26 -> 0 | T27: =Q26-T26 -> 0 | U27: =V27/T27 -> #DIV/0! | V27: =S26-V26 -> 0 | W27: =T26-W26 -> 0 | X27: =Y27/W27 -> #DIV/0! | Y27: =V26-Y26 -> 0 | Z27: =W26-Z26 -> 0 | AA27: =AB27/Z27 -> #DIV/0! | AB27: =Y26-AB26 -> 0 | AC27: =Z26-AC26 -> 0 | AD27: =AE27/AC27 -> #DIV/0! | AE27: =AB26-AE26 -> 0 | AF27: =AC26-AF26 -> 0 | AG27: =AH27/AF27 -> #DIV/0! | AH27: =AE26-AH26 -> 0 | AI27: =AF26-AI26 -> 0 | AJ27: =AK27/AI27 -> #DIV/0! | AK27: =AH26-AK26 -> 0 | AL27: =AL26-AI26 -> 0 | AM27: =AN27/AL27 -> #DIV/0! | AN27: =AK26-AN26 -> 0 | AQ27: =(AQ25+AQ21+AQ22)-AQ26 -> 0 | AR27: =AO26-AR26 -> 0 | AS27: =AT27/AR27 -> #DIV/0! | AT27: =AQ26-AT26 -> 0 | AU27: =AR26-AU26 -> 0 | AV27: =AW27/AU27 -> #DIV/0! | AW27: =AT26-AW26 -> 0 | BB27: Month | BC27: =AK26-BC26 -> -80941636
A28: Monofil | E28: =E27-E29 -> 9093 | G28: =G27-G29 -> -3380536 | H28: =H27-H29 -> 40554 | J28: =J27-J29 -> 3039608 | K28: =K27-K29 -> 253330 | M28: =M27-M29 -> 65195596 | N28: =N27-N29 -> 0 | P28: =P27-P29 -> 0 | Q28: =Q27-Q29 -> 0 | S28: =S27-S29 -> 0 | T28: =T27-T29 -> 0 | V28: =V27-V29 -> 0 | W28: =W27-W29 -> 0 | Y28: =Y27-Y29 -> 0 | Z28: =Z27-Z29 -> 0 | AB28: =AB27-AB29 -> 0 | AC28: =AC27-AC29 -> 0 | AE28: =AE27-AE29 -> 0 | AH28: =AH27-AH29 -> 0 | AK28: =AK27-AK29 -> 0
