Workbook

Sheet Purchase
B3: HDPE | E3: MB | H3: CP | K3: TOTAL | N3: Discount
A4: MONTH | B4: Kgs | C4: Value | D4: Rate | E4: Kgs | F4: Value | G4: Rate | H4: Kgs | I4: Value | J4: Rate | K4: Kgs | L4: Value | M4: Rate | O4: HD -Discount | P4: RM -Disc
A5: APRIL | D5: =IF(B5=0,0,C5/B5) -> 0 | E5: 823 | F5: 222664 | G5: =IF(E5=0,0,F5/E5) -> 270.55164 | H5: 4 | I5: 3380 | J5: =IF(H5=0,0,I5/H5) -> 845 | K5: =B5+E5+H5 -> 827 | L5: =C5+F5+I5 -> 226044 | M5: =IF(K5=0,0,L5/K5) -> 273.33011 | N5: 236050 | O5: =C5-N5 -> -236050 | P5: =ROUND((O5+F5+I5),0) -> -10006
A6: MAY | D6: =IF(B6=0,0,C6/B6) -> 0 | G6: =IF(E6=0,0,F6/E6) -> 0 | J6: =IF(H6=0,0,I6/H6) -> 0 | K6: =B6+E6+H6 -> 0 | L6: =C6+F6+I6 -> 0 | M6: =IF(K6=0,0,L6/K6) -> 0 | O6: =C6-N6 -> 0 | P6: =ROUND((O6+F6+I6),0) -> 0
A7: JUNE | D7: =IF(B7=0,0,C7/B7) -> 0 | G7: =IF(E7=0,0,F7/E7) -> 0 | J7: =IF(H7=0,0,I7/H7) -> 0 | K7: =B7+E7+H7 -> 0 | L7: =C7+F7+I7 -> 0 | M7: =IF(K7=0,0,L7/K7) -> 0 | O7: =C7-N7 -> 0 | P7: =ROUND((O7+F7+I7),0) -> 0
A8: JULY | D8: =IF(B8=0,0,C8/B8) -> 0 | G8: =IF(E8=0,0,F8/E8) -> 0 | J8: =IF(H8=0,0,I8/H8) -> 0 | K8: =B8+E8+H8 -> 0 | L8: =C8+F8+I8 -> 0 | M8: =IF(K8=0,0,L8/K8) -> 0 | O8: =C8-N8 -> 0 | P8: =ROUND((O8+F8+I8),0) -> 0
A9: AUGUST | D9: =IF(B9=0,0,C9/B9) -> 0 | G9: =IF(E9=0,0,F9/E9) -> 0 | J9: =IF(H9=0,0,I9/H9) -> 0 | K9: =B9+E9+H9 -> 0 | L9: =C9+F9+I9 -> 0 | M9: =IF(K9=0,0,L9/K9) -> 0 | O9: =C9-N9 -> 0 | P9: =ROUND((O9+F9+I9),0) -> 0
A10: SEPT | D10: =IF(B10=0,0,C10/B10) -> 0 | G10: =IF(E10=0,0,F10/E10) -> 0 | J10: =IF(H10=0,0,I10/H10) -> 0 | K10: =B10+E10+H10 -> 0 | L10: =C10+F10+I10 -> 0 | M10: =IF(K10=0,0,L10/K10) -> 0 | O10: =C10-N10 -> 0 | P10: =ROUND((O10+F10+I10),0) -> 0
A11: OCT | D11: =IF(B11=0,0,C11/B11) -> 0 | G11: =IF(E11=0,0,F11/E11) -> 0 | J11: =IF(H11=0,0,I11/H11) -> 0 | K11: =B11+E11+H11 -> 0 | L11: =C11+F11+I11 -> 0 | M11: =IF(K11=0,0,L11/K11) -> 0 | O11: =C11-N11 -> 0 | P11: =ROUND((O11+F11+I11),0) -> 0
A12: NOV | D12: =IF(B12=0,0,C12/B12) -> 0 | G12: =IF(E12=0,0,F12/E12) -> 0 | J12: =IF(H12=0,0,I12/H12) -> 0 | K12: =B12+E12+H12 -> 0 | L12: =C12+F12+I12 -> 0 | M12: =IF(K12=0,0,L12/K12) -> 0 | O12: =C12-N12 -> 0 | P12: =ROUND((O12+F12+I12),0) -> 0
A13: DEC | D13: =IF(B13=0,0,C13/B13) -> 0 | G13: =IF(E13=0,0,F13/E13) -> 0 | J13: =IF(H13=0,0,I13/H13) -> 0 | K13: =B13+E13+H13 -> 0 | L13: =C13+F13+I13 -> 0 | M13: =IF(K13=0,0,L13/K13) -> 0 | O13: =C13-N13 -> 0 | P13: =ROUND((O13+F13+I13),0) -> 0
A14: JAN | D14: =IF(B14=0,0,C14/B14) -> 0 | G14: =IF(E14=0,0,F14/E14) -> 0 | J14: =IF(H14=0,0,I14/H14) -> 0 | K14: =B14+E14+H14 -> 0 | L14: =C14+F14+I14 -> 0 | M14: =IF(K14=0,0,L14/K14) -> 0 | O14: =C14-N14 -> 0 | P14: =ROUND((O14+F14+I14),0) -> 0
A15: FEB | D15: =IF(B15=0,0,C15/B15) -> 0 | G15: =IF(E15=0,0,F15/E15) -> 0 | J15: =IF(H15=0,0,I15/H15) -> 0 | K15: =B15+E15+H15 -> 0 | L15: =C15+F15+I15 -> 0 | M15: =IF(K15=0,0,L15/K15) -> 0 | O15: =C15-N15 -> 0 | P15: =ROUND((O15+F15+I15),0) -> 0
A16: MARCH | D16: =IF(B16=0,0,C16/B16) -> 0 | G16: =IF(E16=0,0,F16/E16) -> 0 | J16: =IF(H16=0,0,I16/H16) -> 0 | K16: =B16+E16+H16 -> 0 | L16: =C16+F16+I16 -> 0 | M16: =IF(K16=0,0,L16/K16) -> 0 | O16: =C16-N16 -> 0 | P16: =ROUND((O16+F16+I16),0) -> 0
A17: TOTAL | B17: =SUM(B5:B16) -> 0 | C17: =SUM(C5:C16) -> 0 | D17: =IF(B17=0,0,(C17/B17)) -> 0 | E17: =SUM(E5:E16) -> 823 | F17: =SUM(F5:F16) -> 222664 | G17: =IF(E17=0,0,(F17/E17)) -> 270.55164 | H17: =SUM(H5:H16) -> 4 | I17: =SUM(I5:I16) -> 3380 | J17: =IF(H17=0,0,(I17/H17)) -> 845 | K17: =SUM(K5:K16) -> 827 | L17: =SUM(L5:L16) -> 226044 | M17: =IF(K17=0,0,(L17/K17)) -> 273.33011 | N17: =SUM(N5:N16) -> 236050 | O17: =C17-N17 -> -236050 | P17: =SUM(P5:P16) -> -10006
L18: =L17-N17 -> -10006 | N18: =N17/B17 -> #DIV/0!
A20: Misc Monofil Purchases
A21: MONTH | B21: Sravya | E21: Other Purchases | H21: Consumables | I21: Monofil Fabric Purchase | L21: Yarn Purchase | O21: Mono Fabric Pur | Q21: PL cons
A22: APRIL | B22: =Srvaya!B29 -> 5222 | C22: =Srvaya!C29 -> 1458702 | D22: =IF(B22=0,0,C22/B22) -> 279.3378 | E22: =22528.36+5-B22-0.4 -> 17310.96 | F22: =5990692+2960-C22 -> 4534950 | G22: =IF(E22=0,0,F22/E22) -> 261.96987 | H22: =172581.25+104451.05-0.3 -> 277032 | I22: =ROUND((B22+E22),0) -> 22533 | J22: =ROUND((C22+F22+H22),0) -> 6270684 | K22: =IF(I22=0,0,J22/I22) -> 278.28891 | L22: =3668 -> 3668 | M22: 668801 | N22: =IF(L22=0,0,M22/L22) -> 182.33397 | O22: =ROUND((I22+L22),0) -> 26201 | P22: =ROUND((J22+M22),0) -> 6939485 | Q22: 6939485.3 | R22: =P22-Q22 -> -0.3
A23: MAY | D23: =IF(B23=0,0,C23/B23) -> 0 | G23: =IF(E23=0,0,F23/E23) -> 0 | I23: =ROUND((B23+E23),0) -> 0 | J23: =ROUND((C23+F23+H23),0) -> 0 | K23: =IF(I23=0,0,J23/I23) -> 0 | N23: =IF(L23=0,0,M23/L23) -> 0 | O23: =ROUND((I23+L23),0) -> 0 | P23: =ROUND((J23+M23),0) -> 0 | R23: =P23-Q23 -> 0
A24: JUNE | D24: =IF(B24=0,0,C24/B24) -> 0 | G24: =IF(E24=0,0,F24/E24) -> 0 | I24: =ROUND((B24+E24),0) -> 0 | J24: =ROUND((C24+F24+H24),0) -> 0 | K24: =IF(I24=0,0,J24/I24) -> 0 | N24: =IF(L24=0,0,M24/L24) -> 0 | O24: =ROUND((I24+L24),0) -> 0 | P24: =ROUND((J24+M24),0) -> 0 | R24: =P24-Q24 -> 0
A25: JULY | D25: =IF(B25=0,0,C25/B25) -> 0 | G25: =IF(E25=0,0,F25/E25) -> 0 | I25: =ROUND((B25+E25),0) -> 0 | J25: =ROUND((C25+F25+H25),0) -> 0 | K25: =IF(I25=0,0,J25/I25) -> 0 | N25: =IF(L25=0,0,M25/L25) -> 0 | O25: =ROUND((I25+L25),0) -> 0 | P25: =ROUND((J25+M25),0) -> 0 | R25: =P25-Q25 -> 0
A26: AUGUST | D26: =IF(B26=0,0,C26/B26) -> 0 | G26: =IF(E26=0,0,F26/E26) -> 0 | I26: =ROUND((B26+E26),0) -> 0 | J26: =ROUND((C26+F26+H26),0) -> 0 | K26: =IF(I26=0,0,J26/I26) -> 0 | N26: =IF(L26=0,0,M26/L26) -> 0 | O26: =ROUND((I26+L26),0) -> 0 | P26: =ROUND((J26+M26),0) -> 0 | R26: =P26-Q26 -> 0
A27: SEPT | D27: =IF(B27=0,0,C27/B27) -> 0 | G27: =IF(E27=0,0,F27/E27) -> 0 | I27: =ROUND((B27+E27),0) -> 0 | J27: =ROUND((C27+F27+H27),0) -> 0 | K27: =IF(I27=0,0,J27/I27) -> 0 | N27: =IF(L27=0,0,M27/L27) -> 0 | O27: =ROUND((I27+L27),0) -> 0 | P27: =ROUND((J27+M27),0) -> 0 | R27: =P27-Q27 -> 0
A28: OCT | D28: =IF(B28=0,0,C28/B28) -> 0 | G28: =IF(E28=0,0,F28/E28) -> 0 | I28: =ROUND((B28+E28),0) -> 0 | J28: =ROUND((C28+F28+H28),0) -> 0 | K28: =IF(I28=0,0,J28/I28) -> 0 | N28: =IF(L28=0,0,M28/L28) -> 0 | O28: =ROUND((I28+L28),0) -> 0 | P28: =ROUND((J28+M28),0) -> 0 | R28: =P28-Q28 -> 0
A29: NOV | D29: =IF(B29=0,0,C29/B29) -> 0 | G29: =IF(E29=0,0,F29/E29) -> 0 | I29: =ROUND((B29+E29),0) -> 0 | J29: =ROUND((C29+F29+H29),0) -> 0 | K29: =IF(I29=0,0,J29/I29) -> 0 | N29: =IF(L29=0,0,M29/L29) -> 0 | O29: =ROUND((I29+L29),0) -> 0 | P29: =ROUND((J29+M29),0) -> 0 | R29: =P29-Q29 -> 0
A30: DEC | D30: =IF(B30=0,0,C30/B30) -> 0 | G30: =IF(E30=0,0,F30/E30) -> 0 | I30: =B30+E30 -> 0 | J30: =ROUND(C30+F30+H30,0) -> 0 | K30: =IF(I30=0,0,J30/I30) -> 0 | N30: =IF(L30=0,0,M30/L30) -> 0 | O30: =ROUND((I30+L30),0) -> 0 | P30: =ROUND((J30+M30),0) -> 0 | R30: =P30-Q30 -> 0
A31: JAN | D31: =IF(B31=0,0,C31/B31) -> 0 | G31: =IF(E31=0,0,F31/E31) -> 0 | I31: =B31+E31 -> 0 | J31: =C31+F31+H31 -> 0 | K31: =IF(I31=0,0,J31/I31) -> 0 | N31: =IF(L31=0,0,M31/L31) -> 0 | O31: =ROUND((I31+L31),0) -> 0 | P31: =ROUND((J31+M31),0) -> 0 | R31: =P31-Q31 -> 0
A32: FEB | D32: =IF(B32=0,0,C32/B32) -> 0 | G32: =IF(E32=0,0,F32/E32) -> 0 | I32: =B32+E32 -> 0 | J32: =C32+F32+H32 -> 0 | K32: =IF(I32=0,0,J32/I32) -> 0 | N32: =IF(L32=0,0,M32/L32) -> 0 | O32: =ROUND((I32+L32),0) -> 0 | P32: =ROUND((J32+M32),0) -> 0 | R32: =P32-Q32 -> 0
A33: MARCH | D33: =IF(B33=0,0,C33/B33) -> 0 | G33: =IF(E33=0,0,F33/E33) -> 0 | I33: =B33+E33 -> 0 | J33: =C33+F33+H33 -> 0 | K33: =IF(I33=0,0,J33/I33) -> 0 | N33: =IF(L33=0,0,M33/L33) -> 0 | O33: =ROUND((I33+L33),0) -> 0 | P33: =ROUND((J33+M33),0) -> 0 | R33: =P33-Q33 -> 0
A34: TOTAL | B34: =SUM(B22:B33) -> 5222 | C34: =SUM(C22:C33) -> 1458702 | D34: =IF(B34=0,0,(C34/B34)) -> 279.3378 | E34: =SUM(E22:E33) -> 17310.96 | F34: =SUM(F22:F33) -> 4534950 | G34: =IF(E34=0,0,(F34/E34)) -> 261.96987 | H34: =SUM(H22:H33) -> 277032 | I34: =B34+E34 -> 22532.96 | J34: =ROUND((C34+F34+H34),0) -> 6270684 | K34: =IF(I34=0,0,J34/I34) -> 278.2894 | L34: =SUM(L22:L33) -> 3668 | M34: =SUM(M22:M33) -> 668801 | N34: =IF(L34=0,0,(M34/L34)) -> 182.33397 | O34: =SUM(O22:O33) -> 26201 | P34: =SUM(P22:P33) -> 6939485 | Q34: =SUM(Q22:Q33) -> 6939485.3 | R34: =SUM(R22:R33) -> -0.3
A36: MONTH | B36: TSN | E36: MSN | H36: PPS | K36: TOTAL
A37: APRIL | B37: 544 | C37: 144459 | D37: =IF(B37=0,0,C37/B37) -> 265.54963 | E37: =1147.7+150+18.3 -> 1316 | F37: =275565+70950+10057 -> 356572 | G37: =IF(E37=0,0,F37/E37) -> 270.95137 | H37: 6124 | I37: 1399839 | J37: =IF(H37=0,0,I37/H37) -> 228.58246 | K37: =SUM(B37,E37,H37) -> 7984 | L37: =SUM(C37,F37,I37) -> 1900870 | M37: =IF(K37=0,0,L37/K37) -> 238.08492
A38: MAY | D38: =IF(B38=0,0,C38/B38) -> 0 | G38: =IF(E38=0,0,F38/E38) -> 0 | J38: =IF(H38=0,0,I38/H38) -> 0 | K38: =SUM(B38,E38,H38) -> 0 | L38: =SUM(C38,F38,I38) -> 0 | M38: =IF(K38=0,0,L38/K38) -> 0
A39: JUNE | D39: =IF(B39=0,0,C39/B39) -> 0 | G39: =IF(E39=0,0,F39/E39) -> 0 | J39: =IF(H39=0,0,I39/H39) -> 0 | K39: =SUM(B39,E39,H39) -> 0 | L39: =SUM(C39,F39,I39) -> 0 | M39: =IF(K39=0,0,L39/K39) -> 0
A40: JULY | D40: =IF(B40=0,0,C40/B40) -> 0 | G40: =IF(E40=0,0,F40/E40) -> 0 | J40: =IF(H40=0,0,I40/H40) -> 0 | K40: =SUM(B40,E40,H40) -> 0 | L40: =SUM(C40,F40,I40) -> 0 | M40: =IF(K40=0,0,L40/K40) -> 0
A41: AUGUST | D41: =IF(B41=0,0,C41/B41) -> 0 | G41: =IF(E41=0,0,F41/E41) -> 0 | J41: =IF(H41=0,0,I41/H41) -> 0 | K41: =SUM(B41,E41,H41) -> 0 | L41: =SUM(C41,F41,I41) -> 0 | M41: =IF(K41=0,0,L41/K41) -> 0
A42: SEPT | D42: =IF(B42=0,0,C42/B42) -> 0 | G42: =IF(E42=0,0,F42/E42) -> 0 | J42: =IF(H42=0,0,I42/H42) -> 0 | K42: =SUM(B42,E42,H42) -> 0 | L42: =SUM(C42,F42,I42) -> 0 | M42: =IF(K42=0,0,L42/K42) -> 0
A43: OCT | D43: =IF(B43=0,0,C43/B43) -> 0 | G43: =IF(E43=0,0,F43/E43) -> 0 | J43: =IF(H43=0,0,I43/H43) -> 0 | K43: =SUM(B43,E43,H43) -> 0 | L43: =SUM(C43,F43,I43) -> 0 | M43: =IF(K43=0,0,L43/K43) -> 0
A44: NOV | D44: =IF(B44=0,0,C44/B44) -> 0 | G44: =IF(E44=0,0,F44/E44) -> 0 | J44: =IF(H44=0,0,I44/H44) -> 0 | K44: =SUM(B44,E44,H44) -> 0 | L44: =SUM(C44,F44,I44) -> 0 | M44: =IF(K44=0,0,L44/K44) -> 0
...

Sheet Direct Expns
A1: Group Summary
A2: Particulars | B2: Apr | C2: May | D2: Jun | E2: Jul | F2: Aug | G2: Sep | H2: Oct | I2: Nov | J2: Dec | K2: Jan | L2: Feb | M2: Mar | N2: Total | O2: Average | S2: ='Inventory Sales'!$B$11 -> 95994 | T2: ='Inventory Sales'!$E$11 -> 0 | U2: ='Inventory Sales'!$H$11 -> 0 | V2: ='Inventory Sales'!$K$11 -> 0 | W2: ='Inventory Sales'!$N$11 -> 0 | X2: ='Inventory Sales'!$Q$11 -> 0 | Y2: ='Inventory Sales'!$T$11 -> 0 | Z2: ='Inventory Sales'!$W$11 -> 0 | AA2: ='Inventory Sales'!$Z$11 -> 0 | AB2: ='Inventory Sales'!$AC$11 -> 0 | AC2: ='Inventory Sales'!$AF$11 -> 0 | AD2: ='Inventory Sales'!$AI$11 -> 0 | AE2: =SUM(S2:AD2) -> 95994
A3: Manufacturing Expenses | O3: 4 | R3: VARIABLE & DIRECT EXPNS | S3: Apr | T3: May | U3: Jun | V3: Jul | W3: Aug | X3: Sep | Y3: Oct | Z3: Nov | AA3: Dec | AB3: Jan | AC3: Feb | AD3: Mar | AE3: Total | AG3: Avg
A4: Employees Remunaration & Benefits | B4: 3225980 | N4: =SUM(B4:M4) -> 3225980 | O4: =ROUND((N4/$O$3),0) -> 806495 | R4: Wages-Fabric | S4: 260305 | AE4: =SUM(S4:AD4) -> 260305 | AF4: =AE4/$AE$2 -> 2.7116799 | AG4: =AE4/12 -> 21692.083
A5: Cooli & Cartage | B5: 2180 | N5: =SUM(B5:M5) -> 2180 | O5: =ROUND((N5/$O$3),0) -> 545 | R5: Wages-Inspection & Dispatch | S5: 641461 | AE5: =SUM(S5:AD5) -> 641461 | AF5: =AE5/$AE$2 -> 6.6823031 | AG5: =AE5/12 -> 53455.083
A6: Depreciation | B6: 125000 | N6: =SUM(B6:M6) -> 125000 | O6: =ROUND((N6/$O$3),0) -> 31250 | R6: Fabrication charges | S6: =B7+B8 -> 6451860 | AE6: =SUM(S6:AD6) -> 6451860 | AF6: =AE6/$AE$2 -> 67.211076 | AG6: =AE6/12 -> 537655
A7: Fabrication Charges - B-Lore. | B7: =1371448+4052920 -> 5424368 | N7: =SUM(B7:M7) -> 5424368 | O7: =ROUND((N7/$O$3),0) -> 1356092 | R7: Wages-Yarn | S7: 422294 | AE7: =SUM(S7:AD7) -> 422294 | AF7: =AE7/$AE$2 -> 4.3991708 | AG7: =AE7/12 -> 35191.167
A8: Fabrication Charges-M/H & TN | B8: 1027492 | N8: =SUM(B8:M8) -> 1027492 | O8: =ROUND((N8/$O$3),0) -> 256873 | R8: Yarn Processing charges | S8: =B20 -> 425385 | AE8: =SUM(S8:AD8) -> 425385 | AF8: =AE8/$AE$2 -> 4.4313707 | AG8: =AE8/12 -> 35448.75
A9: Factory Repairs & Maintanance | B9: 47508 | N9: =SUM(B9:M9) -> 47508 | O9: =ROUND((N9/$O$3),0) -> 11877 | R9: Freight Inward | S9: =B11 -> 55683 | AE9: =SUM(S9:AD9) -> 55683 | AF9: =AE9/$AE$2 -> 0.5800675 | AG9: =AE9/12 -> 4640.25
A10: Forwarding Charges Paid | N10: =SUM(B10:M10) -> 0 | O10: =ROUND((N10/$O$3),0) -> 0 | R10: Power Bill | S10: =B16 -> 492773 | AE10: =SUM(S10:AD10) -> 492773 | AF10: =AE10/$AE$2 -> 5.1333729 | AG10: =AE10/12 -> 41064.417
A11: Freight Inwards | B11: =1357+19397+34929 -> 55683 | N11: =SUM(B11:M11) -> 55683 | O11: =ROUND((N11/$O$3),0) -> 13921 | R11: R & M-Machinery | S11: =B9 -> 47508 | AE11: =SUM(S11:AD11) -> 47508 | AF11: =AE11/$AE$2 -> 0.49490593 | AG11: =AE11/12 -> 3959
A12: Insurance on Assets | B12: 14750 | N12: =SUM(B12:M12) -> 14750 | O12: =ROUND((N12/$O$3),0) -> 3688 | R12: R & M-Electricals | S12: =B19 -> 9746 | AE12: =SUM(S12:AD12) -> 9746 | AF12: =AE12/$AE$2 -> 0.10152718 | AG12: =AE12/12 -> 812.16667
A13: ITC Reversal 2018-19 | N13: =SUM(B13:K13) -> 0 | O13: =ROUND((N13/$O$3),0) -> 0 | R13: Rent | S13: =B18 -> 530150 | AE13: =SUM(S13:AD13) -> 530150 | AF13: =AE13/$AE$2 -> 5.522741 | AG13: =AE13/12 -> 44179.167
A14: Medical Exps | N14: =SUM(B14:L14) -> 0 | O14: =ROUND((N14/$O$3),0) -> 0 | R14: Packing charges | AE14: =SUM(S14:AD14) -> 0 | AF14: =AE14/$AE$2 -> 0 | AG14: =AE14/12 -> 0
A15: Packing Materials (Consumables) | N15: =SUM(B15:M15) -> 0 | O15: =ROUND((N15/$O$3),0) -> 0 | R15: Misc | S15: =B5+B12+B17 -> 33730 | AE15: =SUM(S15:AD15) -> 33730 | AF15: =AE15/$AE$2 -> 0.35137613 | AG15: =AE15/12 -> 2810.8333
A16: Electricity & power | B16: 492773 | N16: =SUM(B16:M16) -> 492773 | O16: =ROUND((N16/$O$3),0) -> 123193 | S16: =SUM(S4:S15) -> 9370895 | T16: =SUM(T4:T15) -> 0 | U16: =SUM(U4:U15) -> 0 | V16: =SUM(V4:V15) -> 0 | W16: =SUM(W4:W15) -> 0 | X16: =SUM(X4:X15) -> 0 | Y16: =SUM(Y4:Y15) -> 0 | Z16: =SUM(Z4:Z15) -> 0 | ... AE16: =SUM(AE4:AE15) -> 9370895 | AF16: =AE16/$AE$2 -> 97.619591 | AG16: =SUM(AG4:AG15) -> 780907.92
A17: Processing Charges | B17: 16800 | N17: =SUM(B17:M17) -> 16800 | O17: =ROUND((N17/$O$3),0) -> 4200 | R17: Working Capital-Bank Charges | AD17: ='Indirect Expns'!M42+'Indirect Expns'!M50 -> 0 | AE17: =SUM(S17:AD17) -> 0 | AF17: =AE17/$AE$2 -> 0 | AG17: =AE17/12 -> 0
A18: Rent | B18: =23000+334450+172700 -> 530150 | N18: =SUM(B18:M18) -> 530150 | O18: =ROUND((N18/$O$3),0) -> 132538 | R18: Working Capital-LC | S18: ='Indirect Expns'!B43 -> 25280 | AD18: ='Indirect Expns'!M43 -> 0 | AE18: =SUM(S18:AD18) -> 25280 | AF18: =AE18/$AE$2 -> 0.26334979 | AG18: =AE18/12 -> 2106.6667
A19: Repair & Maintenance AMC | B19: 9746 | N19: =SUM(B19:M19) -> 9746 | O19: =ROUND((N19/$O$3),0) -> 2437 | R19: Working Capital-OCC | S19: ='Indirect Expns'!B46 -> 348690 | AD19: ='Indirect Expns'!M46 -> 0 | AE19: =SUM(S19:AD19) -> 348690 | AF19: =AE19/$AE$2 -> 3.6324145 | AG19: =AE19/12 -> 29057.5
A20: Yarn Processing Charges | B20: =154835+270550 -> 425385 | N20: =SUM(B20:M20) -> 425385 | O20: =ROUND((N20/$O$3),0) -> 106346 | S20: =SUM(S17:S19) -> 373970 | T20: =SUM(T17:T19) -> 0 | U20: =SUM(U17:U19) -> 0 | V20: =SUM(V17:V19) -> 0 | W20: =SUM(W17:W19) -> 0 | X20: =SUM(X17:X19) -> 0 | Y20: =SUM(Y17:Y19) -> 0 | Z20: =SUM(Z17:Z19) -> 0 | ... AE20: =SUM(AE17:AE19) -> 373970 | AF20: =AE20/$AE$2 -> 3.8957643 | AG20: =SUM(AG17:AG19) -> 31164.167
O21: =+N21/$O$3 -> 0 | S21: =S16+S20 -> 9744865 | T21: =T16+T20 -> 0 | U21: =U16+U20 -> 0 | V21: =V16+V20 -> 0 | W21: =W16+W20 -> 0 | X21: =X16+X20 -> 0 | Y21: =Y16+Y20 -> 0 | Z21: =Z16+Z20 -> 0 | ... AE21: =AE16+AE20 -> 9744865 | AF21: =AE21/$AE$2 -> 101.51536 | AG21: =AG16+AG20 -> 812072.08
A22: Grand Total | B22: =SUM(B4:B21) -> 11397815 | C22: =SUM(C4:C21) -> 0 | D22: =SUM(D4:D21) -> 0 | E22: =SUM(E4:E21) -> 0 | F22: =SUM(F4:F21) -> 0 | G22: =SUM(G4:G21) -> 0 | H22: =SUM(H4:H21) -> 0 | I22: =SUM(I4:I21) -> 0 | ... O22: =SUM(O4:O21) -> 2849455 | P22: 13543324 | AE22: Less Fabrn | AF22: =(AE21-AE6)/AE2 -> 34.304279
R23: FIXED EXPNS | AF23: =AE23/$AE$2 -> 0
A24: Manufacturing | B24: =ROUND((B22-(B25+B26+B27+B29)),0) -> 4204754 | C24: =ROUND((C22-(C25+C26+C27+C29)),0) -> 0 | D24: =ROUND((D22-(D25+D26+D27+D29)),0) -> 0 | E24: =ROUND((E22-(E25+E26+E27+E29)),0) -> 0 | F24: =ROUND((F22-(F25+F26+F27+F29)),0) -> 0 | G24: =ROUND((G22-(G25+G26+G27+G29)),0) -> 0 | H24: =ROUND((H22-(H25+H26+H27+H29)),0) -> 0 | I24: =ROUND((I22-(I25+I26+I27+I29)),0) -> 0 | ... N24: =ROUND((N22-(N25+N26+N27+N29)),0) -> 4820955 | O24: =ROUND((N24/$O$3),0) -> 1205239 | R24: Employees welfare exp | S24: =B4-(S4+S5+S7+S25+S26) -> 1005846 | AE24: =N4-(AE4+AE5+AE7+AE25+AE26) -> 1005846 | AF24: =AE24/$AE$2 -> 10.478217 | AG24: =AE24/12 -> 83820.5
A25: ITC Reversed | B25: =B13 -> 0 | C25: =C13 -> 0 | D25: =D13 -> 0 | E25: =E13 -> 0 | F25: =F13 -> 0 | G25: =G13 -> 0 | H25: =H13 -> 0 | I25: =J13 -> 0 | K25: =K13 -> 0 | L25: =L13 -> 0 | M25: =M13 -> 0 | N25: =N13 -> 0 | O25: =+N25/$O$3 -> 0 | R25: Salaries Office | S25: 371074 | AE25: =SUM(S25:AD25) -> 371074 | AF25: =AE25/$AE$2 -> 3.8655958 | AG25: =AE25/12 -> 30922.833
A26: In House Fabrn | B26: 616201 | O26: =ROUND((N26/$O$3),0) -> 0 | R26: Directors Remuneration | S26: 525000 | AE26: =SUM(S26:AD26) -> 525000 | AF26: =AE26/$AE$2 -> 5.4690918 | AG26: =AE26/12 -> 43750
A27: Fabrn | B27: =ROUND((B7+B8),0) -> 6451860 | C27: =ROUND((C7+C8),0) -> 0 | D27: =ROUND((D7+D8),0) -> 0 | E27: =ROUND((E7+E8),0) -> 0 | F27: =ROUND((F7+F8),0) -> 0 | G27: =ROUND((G7+G8),0) -> 0 | H27: =ROUND((H7+H8),0) -> 0 | I27: =ROUND((I7+I8),0) -> 0 | ... L27: =ROUND((L7+L8),0) -> 0 | M27: =M7+M8 -> 0 | N27: =SUM(B27:M27) -> 6451860 | O27: =ROUND((N27/$O$3),0) -> 1612965 | R27: Depreciation | S27: 125000 | AE27: =SUM(S27:AD27) -> 125000 | AF27: =AE27/$AE$2 -> 1.3021647 | AG27: =AE27/12 -> 10416.667
A28: Direct Expns | B28: =SUM(B24:B27) -> 11272815 | C28: =SUM(C24:C27) -> 0 | D28: =SUM(D24:D27) -> 0 | E28: =SUM(E24:E27) -> 0 | F28: =SUM(F24:F27) -> 0 | G28: =SUM(G24:G27) -> 0 | H28: =SUM(H24:H27) -> 0 | I28: =SUM(I24:I27) -> 0 | ... M28: =SUM(M24:M27) -> 0 | N28: =SUM(B28:M28) -> 11272815 | O28: =ROUND((N28/$O$3),0) -> 2818204 | R28: Admn Expns | S28: ='Indirect Expns'!B3 -> 435924 | AE28: =SUM(S28:AD28) -> 435924 | AF28: =AE28/$AE$2 -> 4.5411588 | AG28: =AE28/12 -> 36327
A29: Deprn | B29: =B6 -> 125000 | C29: =C6 -> 0 | D29: =D6 -> 0 | E29: =E6 -> 0 | F29: =F6 -> 0 | G29: =G6 -> 0 | H29: =H6 -> 0 | I29: =I6 -> 0 | ... N29: =N6 -> 125000 | O29: =ROUND((N29/$O$3),0) -> 31250 | R29: Selling Expns | S29: ='Indirect Expns'!B52 -> 67213 | AE29: =SUM(S29:AD29) -> 67213 | AF29: =AE29/$AE$2 -> 0.70017918 | AG29: =AE29/12 -> 5601.0833
A30: Total | B30: =SUM(B28:B29) -> 11397815 | C30: =SUM(C28:C29) -> 0 | D30: =SUM(D28:D29) -> 0 | E30: =SUM(E28:E29) -> 0 | F30: =SUM(F28:F29) -> 0 | G30: =SUM(G28:G29) -> 0 | H30: =SUM(H28:H29) -> 0 | I30: =SUM(I28:I29) -> 0 | ... N30: =SUM(N28:N29) -> 11397815 | O30: =ROUND((N30/$O$3),0) -> 2849454 | R30: Finance Cost-Int On Term Loan | S30: ='Indirect Expns'!B50 -> 11281 | AE30: =SUM(S30:AD30) -> 11281 | AF30: =AE30/$AE$2 -> 0.11751776 | AG30: =AE30/12 -> 940.08333
A31: Fabrn | B31: =B26+B27 -> 7068061 | C31: =C26+C27 -> 0 | D31: =D26+D27 -> 0 | E31: =E26+E27 -> 0 | F31: =F26+F27 -> 0 | G31: =G26+G27 -> 0 | H31: =H26+H27 -> 0 | I31: =I26+I27 -> 0 | ... N31: =N26+N27 -> 6451860 | O31: =ROUND((N31/$O$3),0) -> 1612965 | R31: Finance Cost-Int On Deposits | S31: ='Indirect Expns'!B44 -> 73333 | AE31: =SUM(S31:AD31) -> 73333 | AF31: =AE31/$AE$2 -> 0.76393316 | AG31: =AE31/12 -> 6111.0833
S32: =SUM(S24:S31) -> 2614671 | T32: =SUM(T24:T31) -> 0 | U32: =SUM(U24:U31) -> 0 | V32: =SUM(V24:V31) -> 0 | W32: =SUM(W24:W31) -> 0 | X32: =SUM(X24:X31) -> 0 | Y32: =SUM(Y24:Y31) -> 0 | Z32: =SUM(Z24:Z31) -> 0 | ... AE32: =SUM(AE24:AE31) -> 2614671 | AF32: =AE32/$AE$2 -> 27.237859 | AG32: =SUM(AG24:AG31) -> 217889.25
A33: In House Qty | B33: 7232.2 | N33: =SUM(B33:M33) -> 7232.2 | R33: Total Expns | S33: =S21+S32 -> 12359536 | T33: =T21+T32 -> 0 | U33: =U21+U32 -> 0 | V33: =V21+V32 -> 0 | W33: =W21+W32 -> 0 | X33: =X21+X32 -> 0 | Y33: =Y21+Y32 -> 0 | Z33: =Z21+Z32 -> 0 | ... AE33: =AE21+AE32 -> 12359536 | AF33: =AE33/$AE$2 -> 128.75321
A34: Fabricators Qty | B34: 76251.7 | N34: =SUM(B34:M34) -> 76251.7 | S34: =B37-S33 -> 0
A35: Yarn Processing Qty (In & Out) | B35: =47678+17129 -> 64807 | N35: =SUM(B35:M35) -> 64807 | R35: Variable-Yarn Cost | S35: =ROUND((S21-(S36+S37+S38)),0) -> 1943381 | T35: =ROUND((T21-(T36+T37+T38)),0) -> 0 | U35: =ROUND((U21-(U36+U37+U38)),0) -> 0 | V35: =ROUND((V21-(V36+V37+V38)),0) -> 0 | W35: =ROUND((W21-(W36+W37+W38)),0) -> 0 | X35: =ROUND((X21-(X36+X37+X38)),0) -> 0 | Y35: =ROUND((Y21-(Y36+Y37+Y38)),0) -> 0 | Z35: =ROUND((Z21-(Z36+Z37+Z38)),0) -> 0 | ... AE35: =ROUND((AE21-(AE36+AE37+AE38)),0) -> 2042549
A36: Indirect | B36: ='Indirect Expns'!B75 -> 961721 | C36: ='Indirect Expns'!C75 -> 0 | D36: ='Indirect Expns'!D75 -> 0 | E36: ='Indirect Expns'!E75 -> 0 | F36: ='Indirect Expns'!F75 -> 0 | G36: ='Indirect Expns'!G75 -> 0 | H36: ='Indirect Expns'!H75 -> 0 | I36: ='Indirect Expns'!I75 -> 0 | ... N36: ='Indirect Expns'!N75 -> 961721 | R36: Variable-Fabric Cost | S36: =SUM(S4:S6) -> 7353626 | T36: =SUM(T4:T6) -> 0 | U36: =SUM(U4:U6) -> 0 | V36: =SUM(V4:V6) -> 0 | W36: =SUM(W4:W6) -> 0 | X36: =SUM(X4:X6) -> 0 | Y36: =SUM(Y4:Y6) -> 0 | Z36: =SUM(Z4:Z6) -> 0 | ... AE36: =SUM(AE4:AE6) -> 7353626
A37: Total Expns | B37: =B30+B36 -> 12359536 | C37: =C30+C36 -> 0 | D37: =D30+D36 -> 0 | E37: =E30+E36 -> 0 | F37: =F30+F36 -> 0 | G37: =G30+G36 -> 0 | H37: =H30+H36 -> 0 | I37: =I30+I36 -> 0 | ... N37: =N30+N36 -> 12359536 | R37: Variable-Trading | S37: =99168 -> 99168 | AE37: =AD37 -> 0
R38: Variable-Finance | S38: =ROUND((S19),0) -> 348690 | AE38: =ROUND((AE19),0) -> 348690
A39: P/L | B39: 11397815 | N39: 11397815 | R39: Fixed Cost | S39: =ROUND((S32-S40),0) -> 2489671 | T39: =ROUND((T32-T40),0) -> 0 | U39: =ROUND((U32-U40),0) -> 0 | V39: =ROUND((V32-V40),0) -> 0 | W39: =ROUND((W32-W40),0) -> 0 | X39: =ROUND((X32-X40),0) -> 0 | Y39: =ROUND((Y32-Y40),0) -> 0 | Z39: =ROUND((Z32-Z40),0) -> 0 | ... AE39: =ROUND((AE32-AE40),0) -> 2489671
B40: =B22-B39 -> 0.35 | C40: =C22-C39 -> 0 | D40: =D22-D39 -> 0 | E40: =E22-E39 -> 0 | F40: =F22-F39 -> 0 | G40: =G22-G39 -> 0 | H40: =H22-H39 -> 0 | I40: =I22-I39 -> 0 | ... L40: =L22-L39 -> 0 | N40: =N39-N22 -> -0.35 | R40: Deprn | S40: =S27 -> 125000 | T40: =T27 -> 0 | U40: =U27 -> 0 | V40: =V27 -> 0 | W40: =W27 -> 0 | X40: =X27 -> 0 | Y40: =Y27 -> 0 | Z40: =Z27 -> 0 | ... AE40: =AE27 -> 125000
...

Sheet Indirect Expns
A1: Indirect Expenses
A2: Particulars | B2: Apr | C2: May | D2: Jun | E2: Jul | F2: Aug | G2: Sep | H2: Oct | I2: Nov | J2: Dec | K2: Jan | L2: Feb | M2: Mar | N2: TOTAL | Q2: Veh Expns | R2: Apr | S2: May | T2: Jun | U2: Jul | V2: Aug | W2: Sep | X2: Oct | Y2: Nov | Z2: Dec | AA2: Jan | AB2: Feb | AC2: Mar | AD2: Total
A3: Administrative Expenses | B3: =SUM(B4:B40) -> 435924 | C3: =SUM(C4:C40) -> 0 | D3: =SUM(D4:D40) -> 0 | E3: =SUM(E4:E40) -> 0 | F3: =SUM(F4:F40) -> 0 | G3: =SUM(G4:G40) -> 0 | H3: =SUM(H4:H40) -> 0 | I3: =SUM(I4:I40) -> 0 | ... M3: =SUM(M4:M40) -> 0 | N3: =SUM(B3:M3) -> 435924 | Q3: Tempo 6749 | R3: 29983 | S3: 33769 | T3: 39757 | U3: 69701 | AD3: =SUM(R3:AC3) -> 173210
A4: Vehicle Four Wheelers Expenses | B4: 52033 | N4: =SUM(B4:M4) -> 52033 | Q4: Leyland 8979 | R4: 3097 | S4: 3094 | T4: 2859 | U4: 3000 | AD4: =SUM(R4:AC4) -> 12050
A5: Installation & Programming Charges | N5: =SUM(B5:M5) -> 0 | Q5: Tata 407 | R5: 18818 | S5: 14494 | T5: 11754 | U5: 16711 | AD5: =SUM(R5:AC5) -> 61777
A6: Arrears of Tax | N6: =SUM(B6:M6) -> 0 | R6: =SUM(R3:R5) -> 51898 | S6: =SUM(S3:S5) -> 51357 | T6: =SUM(T3:T5) -> 54370 | U6: =SUM(U3:U5) -> 89412 | V6: =SUM(V3:V5) -> 0 | W6: =SUM(W3:W5) -> 0 | X6: =SUM(X3:X5) -> 0 | Y6: =SUM(Y3:Y5) -> 0 | ... AD6: =SUM(AD3:AD5) -> 247037
A7: Audit Fees | B7: 30000 | N7: =SUM(B7:M7) -> 30000 | Q7: SantaFe | R7: 8341 | S7: 46772 | T7: 4400 | U7: 5996 | AD7: =SUM(R7:AC7) -> 65509
A8: Books & Periodical | B8: 310 | N8: =SUM(B8:M8) -> 310 | Q8: Hyundai I20 | T8: 2996 | U8: 8710 | AD8: =SUM(R8:AC8) -> 11706
A9: Building Repair & Maintence Exp | N9: =SUM(B9:M9) -> 0 | Q9: Celerio | R9: 2995 | S9: 5016 | AD9: =SUM(R9:AC9) -> 8011
A10: Computer Stores & Maint. | B10: 38983 | N10: =SUM(B10:M10) -> 38983 | Q10: Hyundai I10 | R10: 19530 | S10: 23438 | T10: 19376 | U10: 11020 | AD10: =SUM(R10:AC10) -> 73364
A11: Conveyance Charges | B11: 3168 | N11: =SUM(B11:M11) -> 3168 | Q11: Ertiga | R11: 9608 | S11: 5569 | AD11: =SUM(R11:AC11) -> 15177
A12: Contract/Consultancy Service Chrgs 18% | N12: =SUM(B12:M12) -> 0 | Q12: Brezza | T12: 4473 | U12: 7703 | AD12: =SUM(R12:AC12) -> 12176
A13: Donation | N13: =SUM(B13:M13) -> 0 | R13: =SUM(R7:R12) -> 40474 | S13: =SUM(S7:S12) -> 80795 | T13: =SUM(T7:T12) -> 31245 | U13: =SUM(U7:U12) -> 33429 | V13: =SUM(V7:V12) -> 0 | W13: =SUM(W7:W12) -> 0 | X13: =SUM(X7:X12) -> 0 | Y13: =SUM(Y7:Y12) -> 0 | ... AD13: =SUM(AD7:AD12) -> 185943
A14: General Expenses | B14: 1461 | N14: =SUM(B14:M14) -> 1461 | R14: =R6+R13 -> 92372 | S14: =S6+S13 -> 132152 | T14: =T6+T13 -> 85615 | U14: =U6+U13 -> 122841 | V14: =V6+V13 -> 0 | W14: =W6+W13 -> 0 | X14: =X6+X13 -> 0 | Y14: =Y6+Y13 -> 0 | ... AD14: =AD6+AD13 -> 432980
A15: General Repairs & Maintanance | N15: =SUM(B15:M15) -> 0
A16: Audit Fees GST | N16: =SUM(B16:M16) -> 0
A17: Income Tax Exps | N17: =SUM(B17:M17) -> 0
A18: Medical Expenses | N18: =SUM(B18:M18) -> 0
A19: Mediclaim Exps | N19: =SUM(B19:M19) -> 0
A20: Office Maintenance | B20: 2200 | N20: =SUM(B20:M20) -> 2200
A21: Pooja Expenses | B21: 5190 | N21: =SUM(B21:M21) -> 5190
A22: Postage,Tel, Telex Charges | B22: =1085.87+1357+0.13 -> 2443 | N22: =SUM(B22:M22) -> 2443
A23: Printing & Stationary | B23: 34615 | N23: =SUM(B23:M23) -> 34615
A24: Professional Charges | B24: 5500 | N24: =SUM(B24:M24) -> 5500
A25: Professional Consultation Charges | N25: =SUM(B25:M25) -> 0
A26: Rates & Taxes | N26: =SUM(B26:M26) -> 0
A27: Registration & Renewal | B27: 10000 | N27: =SUM(B27:M27) -> 10000
A28: Repairs & Service Charges | N28: =SUM(B28:M28) -> 0
A29: Freight charges | N29: =SUM(B29:M29) -> 0
A30: Round Off (+-) | B30: =11.7+0.3 -> 12 | N30: =SUM(B30:M30) -> 12
A31: Seminar, Training, Dvpt. Exp. | N31: =SUM(B31:M31) -> 0
A32: Software maintenance | B32: =2715.58+46725+50000+0.42 -> 99441 | N32: =SUM(B32:M32) -> 99441
A33: RCM Freight paid | N33: =SUM(B33:M33) -> 0
A34: Subscription & Membership | B34: 53513 | N34: =SUM(B34:M34) -> 53513
A35: TDS - Interest on TDS | N35: =SUM(B35:M35) -> 0
A36: Telephone Charges-Airtel | B36: =16046.82+0.18 -> 16047 | N36: =SUM(B36:M36) -> 16047
A37: Telephone Charges-BSNL | B37: 4008 | N37: =SUM(B37:M37) -> 4008
A38: Fluctuation In Foreign Currency | N38: =SUM(B38:M38) -> 0
A39: VEHICLE MAINTENANCE | N39: =SUM(B39:M39) -> 0
A40: Watch & Ward | B40: =77000 -> 77000 | N40: =SUM(B40:M40) -> 77000
...

Sheet Inventory Sales
A2: Particulars | B2: Apr | E2: May | H2: Jun | K2: Jul | N2: Aug | Q2: Sep | T2: Oct | W2: Nov | Z2: Dec | AC2: Jan | AF2: Feb | AI2: Mar | AL2: Total
A3: Finished Goods | B3: Outwards Qty | C3: Rate | D3: Amount | E3: Outwards Qty | F3: Rate | G3: Amount | H3: Outwards Qty | I3: Rate | J3: Amount | K3: Outwards Qty | L3: Rate | M3: Amount | N3: Outwards Qty | O3: Rate | P3: Amount | Q3: Outwards Qty | R3: Rate | S3: Amount | T3: Outwards Qty | U3: Rate | V3: Amount | W3: Outwards Qty | X3: Rate | Y3: Amount | Z3: Outwards Qty | AA3: Rate | AB3: Amount | AC3: Outwards Qty | AD3: Rate | AE3: Amount | AF3: Outwards Qty | AG3: Rate | AH3: Amount | AI3: Outwards Qty | AJ3: Rate | AK3: Amount | AL3: Outwards Qty | AM3: Rate | AN3: Amount
A5: MCF | B5: 29736 | C5: =IF(B5=0,0,D5/B5) -> 306.90207 | D5: 9126040 | F5: =IF(E5=0,0,G5/E5) -> 0 | I5: =IF(H5=0,0,J5/H5) -> 0 | L5: =IF(K5=0,0,M5/K5) -> 0 | O5: =IF(N5=0,0,P5/N5) -> 0 | R5: =IF(Q5=0,0,S5/Q5) -> 0 | U5: =IF(T5=0,0,V5/T5) -> 0 | X5: =IF(W5=0,0,Y5/W5) -> 0 | AA5: =IF(Z5=0,0,AB5/Z5) -> 0 | AD5: =IF(AC5=0,0,AE5/AC5) -> 0 | AG5: =IF(AF5=0,0,AH5/AF5) -> 0 | AJ5: =IF(AI5=0,0,AK5/AI5) -> 0 | AL5: =SUM(B5,E5,H5,K5,N5,Q5,T5,W5,Z5,AC5,AF5,AI5) -> 29736 | AM5: =IF(AL5=0,0,AN5/AL5) -> 306.90207 | AN5: =SUM(D5,G5,J5,M5,P5,S5,V5,Y5,AB5,AE5,AH5,AK5) -> 9126040
A6: WMF | B6: 60203 | C6: =IF(B6=0,0,D6/B6) -> 284.90781 | D6: 17152305 | F6: =IF(E6=0,0,G6/E6) -> 0 | I6: =IF(H6=0,0,J6/H6) -> 0 | L6: =IF(K6=0,0,M6/K6) -> 0 | O6: =IF(N6=0,0,P6/N6) -> 0 | R6: =IF(Q6=0,0,S6/Q6) -> 0 | U6: =IF(T6=0,0,V6/T6) -> 0 | X6: =IF(W6=0,0,Y6/W6) -> 0 | AA6: =IF(Z6=0,0,AB6/Z6) -> 0 | AD6: =IF(AC6=0,0,AE6/AC6) -> 0 | AG6: =IF(AF6=0,0,AH6/AF6) -> 0 | AJ6: =IF(AI6=0,0,AK6/AI6) -> 0 | AL6: =SUM(B6,E6,H6,K6,N6,Q6,T6,W6,Z6,AC6,AF6,AI6) -> 60203 | AM6: =IF(AL6=0,0,AN6/AL6) -> 284.90781 | AN6: =SUM(D6,G6,J6,M6,P6,S6,V6,Y6,AB6,AE6,AH6,AK6) -> 17152305
A7: MONOFILAMENT FABRIC INSECT BAGS | C7: =IF(B7=0,0,D7/B7) -> 0 | I7: =IF(H7=0,0,J7/H7) -> 0 | L7: =IF(K7=0,0,M7/K7) -> 0 | R7: =IF(Q7=0,0,S7/Q7) -> 0 | X7: =IF(W7=0,0,Y7/W7) -> 0 | AA7: =IF(Z7=0,0,AB7/Z7) -> 0 | AD7: =IF(AC7=0,0,AE7/AC7) -> 0 | AG7: =IF(AF7=0,0,AH7/AF7) -> 0 | AJ7: =IF(AI7=0,0,AK7/AI7) -> 0 | AL7: =SUM(B7,E7,H7,K7,N7,Q7,T7,W7,Z7,AC7,AF7,AI7) -> 0 | AM7: =IF(AL7=0,0,AN7/AL7) -> 0 | AN7: =SUM(D7,G7,J7,M7,P7,S7,V7,Y7,AB7,AE7,AH7,AK7) -> 0
A8: MONOFILAMENT FABRIC INSECT NET | C8: =IF(B8=0,0,D8/B8) -> 0 | I8: =IF(H8=0,0,J8/H8) -> 0 | L8: =IF(K8=0,0,M8/K8) -> 0 | R8: =IF(Q8=0,0,S8/Q8) -> 0 | U8: =IF(T8=0,0,V8/T8) -> 0 | X8: =IF(W8=0,0,Y8/W8) -> 0 | AA8: =IF(Z8=0,0,AB8/Z8) -> 0 | AD8: =IF(AC8=0,0,AE8/AC8) -> 0 | AG8: =IF(AF8=0,0,AH8/AF8) -> 0 | AJ8: =IF(AI8=0,0,AK8/AI8) -> 0 | AL8: =SUM(B8,E8,H8,K8,N8,Q8,T8,W8,Z8,AC8,AF8,AI8) -> 0 | AM8: =IF(AL8=0,0,AN8/AL8) -> 0 | AN8: =SUM(D8,G8,J8,M8,P8,S8,V8,Y8,AB8,AE8,AH8,AK8) -> 0
A9: MONOFILAMENT FABRIC HAPPA | B9: 5 | C9: =IF(B9=0,0,D9/B9) -> 900 | D9: 4500 | F9: =IF(E9=0,0,G9/E9) -> 0 | I9: =IF(H9=0,0,J9/H9) -> 0 | L9: =IF(K9=0,0,M9/K9) -> 0 | O9: =IF(N9=0,0,P9/N9) -> 0 | R9: =IF(Q9=0,0,S9/Q9) -> 0 | U9: =IF(T9=0,0,V9/T9) -> 0 | X9: =IF(W9=0,0,Y9/W9) -> 0 | AA9: =IF(Z9=0,0,AB9/Z9) -> 0 | AD9: =IF(AC9=0,0,AE9/AC9) -> 0 | AG9: =IF(AF9=0,0,AH9/AF9) -> 0 | AJ9: =IF(AI9=0,0,AK9/AI9) -> 0 | AL9: =SUM(B9,E9,H9,K9,N9,Q9,T9,W9,Z9,AC9,AF9,AI9) -> 5 | AM9: =IF(AL9=0,0,AN9/AL9) -> 900 | AN9: =SUM(D9,G9,J9,M9,P9,S9,V9,Y9,AB9,AE9,AH9,AK9) -> 4500
A10: NWF/Yarn / Twisted Yarn | B10: 6050 | C10: =IF(B10=0,0,D10/B10) -> 179.00826 | D10: 1083000 | F10: =IF(E10=0,0,G10/E10) -> 0 | I10: =IF(H10=0,0,J10/H10) -> 0 | L10: =IF(K10=0,0,M10/K10) -> 0 | O10: =IF(N10=0,0,P10/N10) -> 0 | R10: =IF(Q10=0,0,S10/Q10) -> 0 | U10: =IF(T10=0,0,V10/T10) -> 0 | X10: =IF(W10=0,0,Y10/W10) -> 0 | AA10: =IF(Z10=0,0,AB10/Z10) -> 0 | AD10: =IF(AC10=0,0,AE10/AC10) -> 0 | AG10: =IF(AF10=0,0,AH10/AF10) -> 0 | AJ10: =IF(AI10=0,0,AK10/AI10) -> 0 | AL10: =SUM(B10,E10,H10,K10,N10,Q10,T10,W10,Z10,AC10,AF10,AI10) -> 6050 | AM10: =IF(AL10=0,0,AN10/AL10) -> 179.00826 | AN10: =SUM(D10,G10,J10,M10,P10,S10,V10,Y10,AB10,AE10,AH10,AK10) -> 1083000
B11: =SUM(B5:B10) -> 95994 | C11: =IF(B11=0,0,D11/B11) -> 285.0787 | D11: =SUM(D5:D10) -> 27365845 | E11: =SUM(E5:E10) -> 0 | F11: =IF(E11=0,0,G11/E11) -> 0 | G11: =SUM(G5:G10) -> 0 | H11: =SUM(H5:H10) -> 0 | I11: =IF(H11=0,0,J11/H11) -> 0 | J11: =SUM(J5:J10) -> 0 | K11: =SUM(K5:K10) -> 0 | L11: =IF(K11=0,0,M11/K11) -> 0 | M11: =SUM(M5:M10) -> 0 | N11: =SUM(N5:N10) -> 0 | O11: =IF(N11=0,0,P11/N11) -> 0 | P11: =SUM(P5:P10) -> 0 | Q11: =SUM(Q5:Q10) -> 0 | R11: =IF(Q11=0,0,S11/Q11) -> 0 | S11: =SUM(S5:S10) -> 0 | T11: =SUM(T5:T10) -> 0 | U11: =IF(T11=0,0,V11/T11) -> 0 | V11: =SUM(V5:V10) -> 0 | W11: =SUM(W5:W10) -> 0 | X11: =IF(W11=0,0,Y11/W11) -> 0 | Y11: =SUM(Y5:Y10) -> 0 | Z11: =SUM(Z5:Z10) -> 0 | AA11: =IF(Z11=0,0,AB11/Z11) -> 0 | AB11: =SUM(AB5:AB10) -> 0 | AC11: =SUM(AC5:AC10) -> 0 | AD11: =IF(AC11=0,0,AE11/AC11) -> 0 | AE11: =SUM(AE5:AE10) -> 0 | AF11: =SUM(AF5:AF10) -> 0 | AG11: =IF(AF11=0,0,AH11/AF11) -> 0 | AH11: =SUM(AH5:AH10) -> 0 | AI11: =SUM(AI5:AI10) -> 0 | AJ11: =IF(AI11=0,0,AK11/AI11) -> 0 | AK11: =SUM(AK5:AK10) -> 0 | AL11: =SUM(AL5:AL10) -> 95994 | AM11: =IF(AL11=0,0,AN11/AL11) -> 285.0787 | AN11: =SUM(AN5:AN10) -> 27365845
A12: MSN | B12: 1148 | C12: =IF(B12=0,0,D12/B12) -> 288.7108 | D12: 331440 | F12: =IF(E12=0,0,G12/E12) -> 0 | I12: =IF(H12=0,0,J12/H12) -> 0 | O12: =IF(N12=0,0,P12/N12) -> 0 | R12: =IF(Q12=0,0,S12/Q12) -> 0 | U12: =IF(T12=0,0,V12/T12) -> 0 | X12: =IF(W12=0,0,Y12/W12) -> 0 | AA12: =IF(Z12=0,0,AB12/Z12) -> 0 | AD12: =IF(AC12=0,0,AE12/AC12) -> 0 | AG12: =IF(AF12=0,0,AH12/AF12) -> 0 | AJ12: =IF(AI12=0,0,AK12/AI12) -> 0 | AL12: =SUM(B12,E12,H12,K12,N12,Q12,T12,W12,Z12,AC12,AF12,AI12) -> 1148 | AM12: =IF(AL12=0,0,AN12/AL12) -> 288.7108 | AN12: =SUM(D12,G12,J12,M12,P12,S12,V12,Y12,AB12,AE12,AH12,AK12) -> 331440
A13: TSN | B13: 544 | C13: =IF(B13=0,0,D13/B13) -> 322.89154 | D13: 175653 | F13: =IF(E13=0,0,G13/E13) -> 0 | I13: =IF(H13=0,0,J13/H13) -> 0 | L13: =IF(K13=0,0,M13/K13) -> 0 | R13: =IF(Q13=0,0,S13/Q13) -> 0 | U13: =IF(T13=0,0,V13/T13) -> 0 | X13: =IF(W13=0,0,Y13/W13) -> 0 | AA13: =IF(Z13=0,0,AB13/Z13) -> 0 | AD13: =IF(AC13=0,0,AE13/AC13) -> 0 | AG13: =IF(AF13=0,0,AH13/AF13) -> 0 | AJ13: =IF(AI13=0,0,AK13/AI13) -> 0 | AL13: =SUM(B13,E13,H13,K13,N13,Q13,T13,W13,Z13,AC13,AF13,AI13) -> 544 | AM13: =IF(AL13=0,0,AN13/AL13) -> 322.89154 | AN13: =SUM(D13,G13,J13,M13,P13,S13,V13,Y13,AB13,AE13,AH13,AK13) -> 175653
A14: PP Woven Sacks | B14: 6124 | C14: =IF(B14=0,0,D14/B14) -> 247.34634 | D14: 1514749 | F14: =IF(E14=0,0,G14/E14) -> 0 | I14: =IF(H14=0,0,J14/H14) -> 0 | L14: =IF(K14=0,0,M14/K14) -> 0 | O14: =IF(N14=0,0,P14/N14) -> 0 | R14: =IF(Q14=0,0,S14/Q14) -> 0 | U14: =IF(T14=0,0,V14/T14) -> 0 | X14: =IF(W14=0,0,Y14/W14) -> 0 | AA14: =IF(Z14=0,0,AB14/Z14) -> 0 | AD14: =IF(AC14=0,0,AE14/AC14) -> 0 | AG14: =IF(AF14=0,0,AH14/AF14) -> 0 | AJ14: =IF(AI14=0,0,AK14/AI14) -> 0 | AL14: =SUM(B14,E14,H14,K14,N14,Q14,T14,W14,Z14,AC14,AF14,AI14) -> 6124 | AM14: =IF(AL14=0,0,AN14/AL14) -> 247.34634 | AN14: =SUM(D14,G14,J14,M14,P14,S14,V14,Y14,AB14,AE14,AH14,AK14) -> 1514749
A15: ANTI BIRD NET / Rope/MULCH/FIBC | B15: 455 | C15: =IF(B15=0,0,D15/B15) -> 197.64835 | D15: 89930 | O15: =IF(N15=0,0,P15/N15) -> 0 | R15: =IF(Q15=0,0,S15/Q15) -> 0 | X15: =IF(W15=0,0,Y15/W15) -> 0 | AA15: =IF(Z15=0,0,AB15/Z15) -> 0 | AD15: =IF(AC15=0,0,AE15/AC15) -> 0 | AJ15: =IF(AI15=0,0,AK15/AI15) -> 0 | AL15: =SUM(B15,E15,H15,K15,N15,Q15,T15,W15,Z15,AC15,AF15,AI15) -> 455 | AM15: =IF(AL15=0,0,AN15/AL15) -> 197.64835 | AN15: =SUM(D15,G15,J15,M15,P15,S15,V15,Y15,AB15,AE15,AH15,AK15) -> 89930
A16: Knitted Fabric 8" Red/60" D Green | B16: 168 | C16: =IF(B16=0,0,D16/B16) -> 608.92857 | D16: 102300 | I16: =IF(H16=0,0,J16/H16) -> 0 | O16: =IF(N16=0,0,P16/N16) -> 0 | R16: =IF(Q16=0,0,S16/Q16) -> 0 | U16: =IF(T16=0,0,V16/T16) -> 0 | X16: =IF(W16=0,0,Y16/W16) -> 0 | AA16: =IF(Z16=0,0,AB16/Z16) -> 0 | AD16: =IF(AC16=0,0,AE16/AC16) -> 0 | AG16: =IF(AF16=0,0,AH16/AF16) -> 0 | AJ16: =IF(AI16=0,0,AK16/AI16) -> 0 | AL16: =SUM(B16,E16,H16,K16,N16,Q16,T16,W16,Z16,AC16,AF16,AI16) -> 168 | AM16: =IF(AL16=0,0,AN16/AL16) -> 608.92857 | AN16: =SUM(D16,G16,J16,M16,P16,S16,V16,Y16,AB16,AE16,AH16,AK16) -> 102300
A17: Weed Mat | B17: 1150 | C17: =IF(B17=0,0,D17/B17) -> 250.86957 | D17: 288500 | F17: =IF(E17=0,0,G17/E17) -> 0 | I17: =IF(H17=0,0,J17/H17) -> 0 | L17: =IF(K17=0,0,M17/K17) -> 0 | O17: =IF(N17=0,0,P17/N17) -> 0 | R17: =IF(Q17=0,0,S17/Q17) -> 0 | U17: =IF(T17=0,0,V17/T17) -> 0 | X17: =IF(W17=0,0,Y17/W17) -> 0 | AA17: =IF(Z17=0,0,AB17/Z17) -> 0 | AD17: =IF(AC17=0,0,AE17/AC17) -> 0 | AG17: =IF(AF17=0,0,AH17/AF17) -> 0 | AJ17: =IF(AI17=0,0,AK17/AI17) -> 0 | AL17: =SUM(B17,E17,H17,K17,N17,Q17,T17,W17,Z17,AC17,AF17,AI17) -> 1150 | AM17: =IF(AL17=0,0,AN17/AL17) -> 250.86957 | AN17: =SUM(D17,G17,J17,M17,P17,S17,V17,Y17,AB17,AE17,AH17,AK17) -> 288500
B18: =SUM(B12:B17) -> 9589 | C18: =IF(B18=0,0,D18/B18) -> 260.98363 | D18: =SUM(D12:D17) -> 2502572 | E18: =SUM(E12:E17) -> 0 | F18: =IF(E18=0,0,G18/E18) -> 0 | G18: =SUM(G12:G17) -> 0 | H18: =SUM(H12:H17) -> 0 | I18: =IF(H18=0,0,J18/H18) -> 0 | J18: =SUM(J12:J17) -> 0 | K18: =SUM(K12:K17) -> 0 | L18: =IF(K18=0,0,M18/K18) -> 0 | M18: =SUM(M12:M17) -> 0 | N18: =SUM(N12:N17) -> 0 | O18: =IF(N18=0,0,P18/N18) -> 0 | P18: =SUM(P12:P17) -> 0 | Q18: =SUM(Q12:Q17) -> 0 | R18: =IF(Q18=0,0,S18/Q18) -> 0 | S18: =SUM(S12:S17) -> 0 | T18: =SUM(T12:T17) -> 0 | U18: =IF(T18=0,0,V18/T18) -> 0 | V18: =SUM(V12:V17) -> 0 | W18: =SUM(W12:W17) -> 0 | X18: =IF(W18=0,0,Y18/W18) -> 0 | Y18: =SUM(Y12:Y17) -> 0 | Z18: =SUM(Z12:Z17) -> 0 | AA18: =IF(Z18=0,0,AB18/Z18) -> 0 | AB18: =SUM(AB12:AB17) -> 0 | AC18: =SUM(AC12:AC17) -> 0 | AD18: =IF(AC18=0,0,AE18/AC18) -> 0 | AE18: =SUM(AE12:AE17) -> 0 | AF18: =SUM(AF12:AF17) -> 0 | AG18: =IF(AF18=0,0,AH18/AF18) -> 0 | AH18: =SUM(AH12:AH17) -> 0 | AI18: =SUM(AI12:AI17) -> 0 | AJ18: =IF(AI18=0,0,AK18/AI18) -> 0 | AK18: =SUM(AK12:AK17) -> 0 | AL18: =SUM(AL12:AL17) -> 9589 | AM18: =IF(AL18=0,0,AN18/AL18) -> 260.98363 | AN18: =SUM(AN12:AN17) -> 2502572 | AO18: =AL11+AL18 -> 105583
A19: Flexible Intermediate Bulk Container | F19: =IF(E19=0,0,G19/E19) -> 0 | R19: =IF(Q19=0,0,S19/Q19) -> 0 | X19: =IF(W19=0,0,Y19/W19) -> 0 | AA19: =IF(Z19=0,0,AB19/Z19) -> 0 | AD19: =IF(AC19=0,0,AE19/AC19) -> 0 | AG19: =IF(AF19=0,0,AH19/AF19) -> 0 | AJ19: =IF(AI19=0,0,AK19/AI19) -> 0 | AL19: =SUM(B19,E19,H19,K19,N19,Q19,T19,W19,Z19,AC19,AF19,AI19) -> 0 | AM19: =IF(AL19=0,0,AN19/AL19) -> 0 | AN19: =SUM(D19,G19,J19,M19,P19,S19,V19,Y19,AB19,AE19,AH19,AK19) -> 0
A20: Packing Materials / Old use Batteries | F20: =IF(E20=0,0,G20/E20) -> 0 | R20: =IF(Q20=0,0,S20/Q20) -> 0 | X20: =IF(W20=0,0,Y20/W20) -> 0 | AA20: =IF(Z20=0,0,AB20/Z20) -> 0 | AD20: =IF(AC20=0,0,AE20/AC20) -> 0 | AG20: =IF(AF20=0,0,AH20/AF20) -> 0 | AL20: =SUM(B20,E20,H20,K20,N20,Q20,T20,W20,Z20,AC20,AF20,AI20) -> 0 | AM20: =IF(AL20=0,0,AN20/AL20) -> 0 | AN20: =SUM(D20,G20,J20,M20,P20,S20,V20,Y20,AB20,AE20,AH20,AK20) -> 0
A21: HDPE Monofilament Waste | B21: 2174 | C21: =IF(B21=0,0,D21/B21) -> 10 | D21: 21740 | F21: =IF(E21=0,0,G21/E21) -> 0 | I21: =IF(H21=0,0,J21/H21) -> 0 | L21: =IF(K21=0,0,M21/K21) -> 0 | O21: =IF(N21=0,0,P21/N21) -> 0 | R21: =IF(Q21=0,0,S21/Q21) -> 0 | U21: =IF(T21=0,0,V21/T21) -> 0 | X21: =IF(W21=0,0,Y21/W21) -> 0 | AA21: =IF(Z21=0,0,AB21/Z21) -> 0 | AD21: =IF(AC21=0,0,AE21/AC21) -> 0 | AG21: =IF(AF21=0,0,AH21/AF21) -> 0 | AJ21: =IF(AI21=0,0,AK21/AI21) -> 0 | AL21: =SUM(B21,E21,H21,K21,N21,Q21,T21,W21,Z21,AC21,AF21,AI21) -> 2174 | AM21: =IF(AL21=0,0,AN21/AL21) -> 10 | AN21: =SUM(D21,G21,J21,M21,P21,S21,V21,Y21,AB21,AE21,AH21,AK21) -> 21740
A22: Sale of Asset Etc | R22: =IF(Q22=0,0,S22/Q22) -> 0 | X22: =IF(W22=0,0,Y22/W22) -> 0 | AA22: =IF(Z22=0,0,AB22/Z22) -> 0 | AD22: =IF(AC22=0,0,AE22/AC22) -> 0 | AG22: =IF(AF22=0,0,AH22/AF22) -> 0 | AJ22: =IF(AI22=0,0,AK22/AI22) -> 0 | AL22: =SUM(B22,E22,H22,K22,N22,Q22,T22,W22,Z22,AC22,AF22,AI22) -> 0 | AM22: =IF(AL22=0,0,AN22/AL22) -> 0 | AN22: =SUM(D22,G22,J22,M22,P22,S22,V22,Y22,AB22,AE22,AH22,AK22) -> 0
A23: Colour Pigment | C23: =IF(B23=0,0,D23/B23) -> 0 | L23: =IF(K23=0,0,M23/K23) -> 0 | O23: =IF(N23=0,0,P23/N23) -> 0 | R23: =IF(Q23=0,0,S23/Q23) -> 0 | X23: =IF(W23=0,0,Y23/W23) -> 0 | AA23: =IF(Z23=0,0,AB23/Z23) -> 0 | AD23: =IF(AC23=0,0,AE23/AC23) -> 0 | AG23: =IF(AF23=0,0,AH23/AF23) -> 0 | AJ23: =IF(AI23=0,0,AK23/AI23) -> 0 | AL23: =SUM(B23,E23,H23,K23,N23,Q23,T23,W23,Z23,AC23,AF23,AI23) -> 0 | AM23: =IF(AL23=0,0,AN23/AL23) -> 0 | AN23: =SUM(D23,G23,J23,M23,P23,S23,V23,Y23,AB23,AE23,AH23,AK23) -> 0
A24: Master Batch | C24: =IF(B24=0,0,D24/B24) -> 0 | F24: =IF(E24=0,0,G24/E24) -> 0 | I24: =IF(H24=0,0,J24/H24) -> 0 | L24: =IF(K24=0,0,M24/K24) -> 0 | O24: =IF(N24=0,0,P24/N24) -> 0 | R24: =IF(Q24=0,0,S24/Q24) -> 0 | U24: =IF(T24=0,0,V24/T24) -> 0 | X24: =IF(W24=0,0,Y24/W24) -> 0 | AA24: =IF(Z24=0,0,AB24/Z24) -> 0 | AD24: =IF(AC24=0,0,AE24/AC24) -> 0 | AG24: =IF(AF24=0,0,AH24/AF24) -> 0 | AJ24: =IF(AI24=0,0,AK24/AI24) -> 0 | AL24: =SUM(B24,E24,H24,K24,N24,Q24,T24,W24,Z24,AC24,AF24,AI24) -> 0 | AM24: =IF(AL24=0,0,AN24/AL24) -> 0 | AN24: =SUM(D24,G24,J24,M24,P24,S24,V24,Y24,AB24,AE24,AH24,AK24) -> 0
A25: HDPE | C25: =IF(B25=0,0,D25/B25) -> 0 | F25: =IF(E25=0,0,G25/E25) -> 0 | I25: =IF(H25=0,0,J25/H25) -> 0 | L25: =IF(K25=0,0,M25/K25) -> 0 | O25: =IF(N25=0,0,P25/N25) -> 0 | R25: =IF(Q25=0,0,S25/Q25) -> 0 | U25: =IF(T25=0,0,V25/T25) -> 0 | X25: =IF(W25=0,0,Y25/W25) -> 0 | AA25: =IF(Z25=0,0,AB25/Z25) -> 0 | AD25: =IF(AC25=0,0,AE25/AC25) -> 0 | AG25: =IF(AF25=0,0,AH25/AF25) -> 0 | AJ25: =IF(AI25=0,0,AK25/AI25) -> 0 | AL25: =SUM(B25,E25,H25,K25,N25,Q25,T25,W25,Z25,AC25,AF25,AI25) -> 0 | AM25: =IF(AL25=0,0,AN25/AL25) -> 0 | AN25: =SUM(D25,G25,J25,M25,P25,S25,V25,Y25,AB25,AE25,AH25,AK25) -> 0 | AO25: =AO18+AL25 -> 105583
B26: =SUM(B19:B25) -> 2174 | C26: =IF(B26=0,0,D26/B26) -> 10 | D26: =SUM(D19:D25) -> 21740 | E26: =SUM(E19:E25) -> 0 | F26: =IF(E26=0,0,G26/E26) -> 0 | G26: =SUM(G19:G25) -> 0 | H26: =SUM(H19:H25) -> 0 | I26: =IF(H26=0,0,J26/H26) -> 0 | J26: =SUM(J19:J25) -> 0 | K26: =SUM(K19:K25) -> 0 | L26: =IF(K26=0,0,M26/K26) -> 0 | M26: =SUM(M19:M25) -> 0 | N26: =SUM(N19:N25) -> 0 | O26: =IF(N26=0,0,P26/N26) -> 0 | P26: =SUM(P19:P25) -> 0 | Q26: =SUM(Q19:Q25) -> 0 | R26: =IF(Q26=0,0,S26/Q26) -> 0 | S26: =SUM(S19:S25) -> 0 | T26: =SUM(T19:T25) -> 0 | U26: =IF(T26=0,0,V26/T26) -> 0 | V26: =SUM(V19:V25) -> 0 | W26: =SUM(W19:W25) -> 0 | X26: =IF(W26=0,0,Y26/W26) -> 0 | Y26: =SUM(Y19:Y25) -> 0 | Z26: =SUM(Z19:Z25) -> 0 | AA26: =IF(Z26=0,0,AB26/Z26) -> 0 | AB26: =SUM(AB19:AB25) -> 0 | AC26: =SUM(AC19:AC25) -> 0 | AD26: =IF(AC26=0,0,AE26/AC26) -> 0 | AF26: =SUM(AF19:AF25) -> 0 | AG26: =IF(AF26=0,0,AH26/AF26) -> 0 | AH26: =SUM(AH19:AH25) -> 0 | AI26: =SUM(AI19:AI25) -> 0 | AJ26: =IF(AI26=0,0,AK26/AI26) -> 0 | AK26: =SUM(AK19:AK25) -> 0 | AL26: =SUM(AL19:AL25) -> 2174 | AM26: =IF(AL26=0,0,AN26/AL26) -> 10 | AN26: =SUM(AN19:AN25) -> 21740
A27: Grand total: | B27: =SUM(B11,B18,B26) -> 107757 | C27: =IF(B27=0,0,D27/B27) -> 277.38483 | D27: =SUM(D11,D18,D26) -> 29890157 | E27: =SUM(E11,E18,E26) -> 0 | F27: =IF(E27=0,0,G27/E27) -> 0 | G27: =SUM(G11,G18,G26) -> 0 | H27: =SUM(H11,H18,H26) -> 0 | I27: =IF(H27=0,0,J27/H27) -> 0 | J27: =SUM(J11,J18,J26) -> 0 | K27: =SUM(K11,K18,K26) -> 0 | L27: =IF(K27=0,0,M27/K27) -> 0 | M27: =SUM(M11,M18,M26) -> 0 | N27: =SUM(N11,N18,N26) -> 0 | O27: =IF(N27=0,0,P27/N27) -> 0 | P27: =SUM(P11,P18,P26) -> 0 | Q27: =SUM(Q11,Q18,Q26) -> 0 | R27: =IF(Q27=0,0,S27/Q27) -> 0 | S27: =SUM(S11,S18,S26) -> 0 | T27: =SUM(T11,T18,T26) -> 0 | U27: =IF(T27=0,0,V27/T27) -> 0 | V27: =SUM(V11,V18,V26) -> 0 | W27: =SUM(W11,W18,W26) -> 0 | X27: =IF(W27=0,0,Y27/W27) -> 0 | Y27: =SUM(Y11,Y18,Y26) -> 0 | Z27: =SUM(Z11,Z18,Z26) -> 0 | AA27: =IF(Z27=0,0,AB27/Z27) -> 0 | AB27: =SUM(AB11,AB18,AB26) -> 0 | AC27: =SUM(AC11,AC18,AC26) -> 0 | AD27: =IF(AC27=0,0,AE27/AC27) -> 0 | AE27: =SUM(AE11,AE18,AE26) -> 0 | AF27: =SUM(AF11,AF18,AF26) -> 0 | AG27: =IF(AF27=0,0,AH27/AF27) -> 0 | AH27: =SUM(AH11,AH18,AH26) -> 0 | AI27: =SUM(AI11,AI18,AI26) -> 0 | AJ27: =IF(AI27=0,0,AK27/AI27) -> 0 | AK27: =SUM(AK11,AK18,AK26) -> 0 | AL27: =SUM(AL11,AL18,AL26) -> 107757 | AM27: =IF(AL27=0,0,AN27/AL27) -> 277.38483 | AN27: =SUM(AN11,AN18,AN26) -> 29890157 | AO27: =AN27-AN21 -> 29868417
A28: Other Income | D28: 65.46 | AN28: =SUM(D28,G28,J28,M28,P28,S28,V28,Y28,AB28,AE28,AH28,AK28) -> 65.46
D29: =ROUND((D27-D21),0) -> 29868417 | G29: =ROUND((G27-G21),0) -> 0 | J29: =ROUND((J27-J21),0) -> 0 | M29: =ROUND((M27-M21),0) -> 0 | P29: =ROUND((P27-P21),0) -> 0 | S29: =ROUND((S27-S21),0) -> 0 | V29: =ROUND((V27-V21),0) -> 0 | Y29: =ROUND((Y27-Y21),0) -> 0 | AB29: =ROUND((AB27-AB21),0) -> 0 | AE29: =ROUND((AE27-AE21),0) -> 0 | AH29: =ROUND((AH27-AH21),0) -> 0 | AK29: =ROUND((AK27-AK21),0) -> 0 | AL29: =AL11+AL18 -> 105583 | AM29: =AN29/AL29 -> 282.8904 | AN29: =AN11+AN18 -> 29868417 | AP29: Sales extract value | AQ29: Sales extract kgs
A30: Gross sales | D30: 31402963 | AN30: =SUM(D30,G30,J30,M30,P30,S30,V30,Y30,AB30,AE30,AH30,AK30) -> 31402963 | AP30: 29890157 | AQ30: 107758.28
A31: tax | D31: 1527660.3 | AN31: =SUM(D31,G31,J31,M31,P31,S31,V31,Y31,AB31,AE31,AH31,AK31) -> 1527660.3 | AP31: =AN27-AP30 -> 0.079999998 | AQ31: =AL27-AQ30 -> -1.28
A32: TCS | D32: 0 | AN32: =SUM(D32,G32,J32,M32,P32,S32,V32,Y32,AB32,AE32,AH32,AK32) -> 0
D33: =D31+D32 -> 1527660.3 | G33: =G31+G32 -> 0 | J33: =J31+J32 -> 0 | M33: =M31+M32 -> 0 | P33: =P31+P32 -> 0 | S33: =S31+S32 -> 0 | V33: =V31+V32 -> 0 | Y33: =Y31+Y32 -> 0 | AB33: =AB31+AB32 -> 0 | AE33: =AE31+AE32 -> 0 | AH33: =AH31+AH32 -> 0 | AK33: =AK31+AK32 -> 0 | AN33: =SUM(AN31:AN32) -> 1527660.3 | AQ33: P/L sales
D34: =D30-D33 -> 29875303 | G34: =G30-G33 -> 0 | J34: =J30-J33 -> 0 | M34: =M30-M33 -> 0 | P34: =P30-P33 -> 0 | S34: =S30-S33 -> 0 | V34: =V30-V33 -> 0 | Y34: =Y30-Y33 -> 0 | AB34: =AB30-AB33 -> 0 | AE34: =AE30-AE33 -> 0 | AH34: =AH30-AH33 -> 0 | AK34: =AK30-AK33 -> 0 | AN34: =AN30-AN33 -> 29875303 | AQ34: 29875303 | AR34: =AQ34-AN34 -> 0
A35: Discount | D35: 14854 | AN35: =SUM(D35,G35,J35,M35,P35,S35,V35,Y35,AB35,AE35,AH35,AK35) -> 14854
D36: =D34+D35-D37 -> 29890157 | G36: =G34+G35-G37 -> 0 | J36: =J34+J35 -> 0 | M36: =M34+M35-M37 -> 0 | P36: =P34+P35 -> 0 | S36: =S34+S35 -> 0 | V36: =V34+V35 -> 0 | Y36: =Y34+Y35 -> 0 | AB36: =AB34+AB35 -> 0 | AE36: =AE34+AE35 -> 0 | AH36: =AH34+AH35 -> 0 | AK36: =AK34+AK35 -> 0 | AN36: =AN34+AN35 -> 29890157 | AO36: =AN27-AN36 -> 0.080000002
A37: Credit Note | Y37: =Y36-Y27 -> 0 | AB37: =AB36-AB27 -> 0 | AE37: =AE36-AE27 -> 0 | AH37: 42540 | AK37: 51048 | AN37: =SUM(D37,G37,J37,M37,P37,S37,V37,Y37,AB37,AE37,AH37,AK37) -> 93588
D38: =D27-D36 -> 0.080000002 | G38: =G27-G36 -> 0 | J38: =J27-J36 -> 0 | M38: =M27-M36 -> 0 | P38: =P27-P36 -> 0 | S38: =S27-S36 -> 0 | V38: =V27-V36 -> 0 | Y38: =Y27-Y36 -> 0 | AB38: =AB27-AB36 -> 0 | AE38: =AE27-AE36 -> 0 | AH38: =AH27-AH36 -> 0 | AK38: =AK27-AK36 -> 0 | AN38: =AN36-AN27 -> -0.080000002
A39: PAL I- FINAL SALES +Less Waste & Discount | D39: =ROUND((D27-(D21+D22+D35)),0) -> 29853563 | G39: =ROUND((G27-(G21+G35)),0) -> 0 | J39: =ROUND((J27-(J21+J22+J35)),0) -> 0 | M39: =ROUND((M27-(M21+M22+M35)),0) -> 0 | P39: =ROUND((P27-(P21+P22+P35)),0) -> 0 | S39: =ROUND((S27-(S21+S22+S35)),0) -> 0 | V39: =ROUND((V27-(V21+V22+V35)),0) -> 0 | Y39: =ROUND((Y27-(Y21+Y22+Y35)),0) -> 0 | AB39: =ROUND((AB27-(AB21+AB22+AB35)),0) -> 0 | AE39: =ROUND((AE27-(AE21+AE22+AE35)),0) -> 0 | AH39: =ROUND((AH27-(AH21+AH22+AH35)),0) -> 0 | AK39: =ROUND((AK27-(AK21+AK22+AK35)),0) -> 0 | AN39: =ROUND((AN27-(AN21+AN22+AN35)),0) -> 29853563
AN40: =ROUND((AN39-(AN5+AN6)),0) -> 3575218 | AR40: =AR38-AR39 -> 0
AN41: =AN36-AN27 -> -0.080000002
A42: RM Purchase for sales | B42: =B25 -> 0 | D42: =ROUND((B25*C42),0) -> 0 | E42: =E25 -> 0 | F42: 90.36 | G42: =ROUND((E25*F42),0) -> 0 | H42: =H25 -> 0 | I42: 85.79 | J42: =ROUND((H25*I42),0) -> 0 | K42: =K25 -> 0 | L42: 102.13 | M42: =ROUND((K25*L42),0) -> 0 | N42: =N25 -> 0 | O42: 92.93 | P42: =ROUND((N25*O42),0) -> 0 | Q42: =Q25 -> 0 | R42: 99.79 | S42: =ROUND((Q25*R42),0) -> 0 | T42: =T25 -> 0 | U42: 96.12 | V42: =ROUND((T25*U42),0) -> 0 | W42: =W25 -> 0 | X42: 100.88 | Y42: =ROUND((W25*X42),0) -> 0 | Z42: =Z25 -> 0 | AA42: 97.44 | AB42: =ROUND((Z25*AA42),0) -> 0 | AC42: =AC25 -> 0 | AD42: 96.36 | AE42: =ROUND((AC25*AD42),0) -> 0 | AF42: =AF25 -> 0 | AG42: 98.91 | AH42: =ROUND((AF25*AG42),0) -> 0 | AI42: =AI25 -> 0 | AJ42: 96 | AK42: =ROUND((AI25*AJ42),0) -> 0 | AL42: =SUM(B42,E42,H42,K42,N42,Q42,T42,W42,Z42,AC42,AF42,AI42) -> 0 | AN42: =SUM(D42,G42,J42,M42,P42,S42,V42,Y42,AB42,AE42,AH42,AK42) -> 0 | AP42: `
...

Sheet Stock Valuation (FIFO)
B2: Opening Stock 01 Apr 26 | E2: 46113 | H2: 45778 | K2: 45809 | N2: 45839 | Q2: 45870 | T2: 45901 | W2: 45931 | Z2: 45962 | AC2: 45992 | AF2: 46023 | AI2: 46054 | AL2: 46082 | AO2: Bank Stock Statement
A3: RAW MATERIALS: | B3: QTY IN KGS. | C3: BASIC RATE | D3: BASIC VALUE | E3: QTY IN KGS. | F3: BASIC RATE | G3: BASIC VALUE | H3: QTY IN KGS. | I3: BASIC RATE | J3: BASIC VALUE | K3: QTY IN KGS. | L3: BASIC RATE | M3: BASIC VALUE | N3: QTY IN KGS. | O3: BASIC RATE | P3: BASIC VALUE | Q3: QTY IN KGS. | R3: BASIC RATE | S3: BASIC VALUE | T3: QTY IN KGS. | U3: BASIC RATE | V3: BASIC VALUE | W3: QTY IN KGS. | X3: BASIC RATE | Y3: BASIC VALUE | Z3: QTY IN KGS. | AA3: BASIC RATE | AB3: BASIC VALUE | AC3: QTY IN KGS. | AD3: BASIC RATE | AE3: BASIC VALUE | AF3: QTY IN KGS. | AG3: BASIC RATE | AH3: BASIC VALUE | AI3: QTY IN KGS. | AJ3: BASIC RATE | AL3: QTY IN KGS. | AM3: BASIC RATE | AN3: BASIC VALUE | AO3: QTY IN KGS. | AP3: BASIC RATE | AQ3: BASIC VALUE | AR3: QTY IN KGS. | AS3: BASIC RATE | AT3: BASIC VALUE | AU3: QTY IN KGS. | AV3: BASIC RATE | AW3: BASIC VALUE
AX4: Incr/(Decr)Stk | BA4: Stk frm Tarka as om 01 Apr(Srp) | BE4: Physical
A5: HDPE Granules | B5: 141140 | C5: =D5/B5+0.02 -> 121.99507 | D5: 17215561 | E5: 75695 | F5: =ROUND(IF(G5=0,0,(G5/E5)),0) -> 136 | G5: 10273379 | I5: =IF(J5=0,0,(J5/H5)) -> 0 | L5: =IF(M5=0,0,(M5/K5)) -> 0 | O5: =IF(P5=0,0,(P5/N5)) -> 0 | R5: =IF(S5=0,0,(S5/Q5)) -> 0 | U5: =IF(V5=0,0,(V5/T5)) -> 0 | X5: =IF(Y5=0,0,(Y5/W5)) -> 0 | AA5: =IF(AB5=0,0,(AB5/Z5)) -> 0 | AD5: =IF(AE5=0,0,(AE5/AC5))-0.07 -> -0.07 | AG5: =IF(AH5=0,0,(AH5/AF5))+0.04 -> 0.04 | AJ5: =IF(AK5=0,0,(AK5/AI5)) -> 0 | AM5: 122 | AP5: =IF(AQ5=0,0,(AQ5/AO5)) -> 0 | AR5: ='[1] Qty Analysis'!BE15 -> 0 | AT5: =ROUND((AS5*AR5),0) -> 0 | AU5: ='[1] Qty Analysis'!BH15 -> 0 | AW5: =ROUND((AV5*AU5),0) -> 0 | AX5: =Z5-B5 -> -141140 | AY5: =AX5/B5 -> -1 | BA5: =125000+40000 -> 165000 | BB5: 101 | BC5: =ROUND((BA5*BB5),0) -> 16665000 | BE5: 163575
A6: Master Batches | B6: 2330 | C6: =D6/B6+0.04 -> 226.96532 | D6: 528736 | E6: 2392 | F6: =ROUND(IF(G6=0,0,(G6/E6)),0) -> 245 | G6: 586833 | I6: =IF(J6=0,0,(J6/H6)) -> 0 | L6: =IF(M6=0,0,(M6/K6)) -> 0 | O6: =IF(P6=0,0,(P6/N6)) -> 0 | R6: =IF(S6=0,0,(S6/Q6)) -> 0 | U6: =IF(V6=0,0,(V6/T6)) -> 0 | X6: =IF(Y6=0,0,(Y6/W6)) -> 0 | AA6: =IF(AB6=0,0,(AB6/Z6)) -> 0 | AD6: =IF(AE6=0,0,(AE6/AC6))-0.17 -> -0.17 | AG6: =IF(AH6=0,0,(AH6/AF6))-0.38 -> -0.38 | AJ6: =IF(AK6=0,0,(AK6/AI6)) -> 0 | AM6: 227 | AP6: =IF(AQ6=0,0,(AQ6/AO6)) -> 0 | AR6: ='[1] Qty Analysis'!BE27 -> 0 | AT6: =ROUND((AS6*AR6),0) -> 0 | AU6: ='[1] Qty Analysis'!BH27 -> 0 | AW6: =ROUND((AV6*AU6),0) -> 0 | AX6: =Z6-B6 -> -2330 | AY6: =AX6/B6 -> -1 | BA6: 2730 | BB6: 215 | BC6: =ROUND((BA6*BB6),0) -> 586950 | BE6: 2645
A7: Colour Pigments | B7: 19 | C7: =D7/B7-0.37 -> 1596.9984 | D7: 30350 | E7: 21 | F7: =ROUND(IF(G7=0,0,(G7/E7)),0) -> 1515 | G7: 31807 | I7: =IF(J7=0,0,(J7/H7)) -> 0 | L7: =IF(M7=0,0,(M7/K7)) -> 0 | O7: =IF(P7=0,0,(P7/N7)) -> 0 | R7: =IF(S7=0,0,(S7/Q7)) -> 0 | U7: =IF(V7=0,0,(V7/T7)) -> 0 | X7: =IF(Y7=0,0,(Y7/W7)) -> 0 | AA7: =IF(AB7=0,0,(AB7/Z7)) -> 0 | AD7: =IF(AE7=0,0,(AE7/AC7))-0.45 -> -0.45 | AG7: =IF(AH7=0,0,(AH7/AF7))-0.38 -> -0.38 | AJ7: =IF(AK7=0,0,(AK7/AI7)) -> 0 | AM7: 1597 | AP7: =IF(AQ7=0,0,(AQ7/AO7)) -> 0 | AR7: ='[1] Qty Analysis'!BE39 -> 0 | AT7: =ROUND((AS7*AR7),0) -> 0 | AU7: ='[1] Qty Analysis'!BH39 -> 0 | AW7: =ROUND((AV7*AU7),0) -> 0 | AX7: =Z7-B7 -> -19 | AY7: =AX7/B7 -> -1 | BA7: 30 | BB7: 2280 | BC7: =ROUND((BA7*BB7),0) -> 68400 | BE7: 45.3
A8: Total | B8: =SUM(B5:B7) -> 143489 | C8: =D8/B8 -> 123.87463 | D8: =SUM(D5:D7) -> 17774647 | E8: =SUM(E5:E7) -> 78108 | F8: =IF(G8=0,0,(G8/E8)) -> 139.44819 | G8: =SUM(G5:G7) -> 10892019 | H8: =SUM(H5:H7) -> 0 | I8: =IF(J8=0,0,(J8/H8)) -> 0 | J8: =SUM(J5:J7) -> 0 | K8: =SUM(K5:K7) -> 0 | L8: =IF(M8=0,0,(M8/K8)) -> 0 | M8: =SUM(M5:M7) -> 0 | N8: =SUM(N5:N7) -> 0 | O8: =IF(P8=0,0,(P8/N8)) -> 0 | P8: =SUM(P5:P7) -> 0 | Q8: =SUM(Q5:Q7) -> 0 | R8: =IF(S8=0,0,(S8/Q8)) -> 0 | S8: =ROUND(SUM(S5:S7),0) -> 0 | T8: =SUM(T5:T7) -> 0 | U8: =IF(V8=0,0,(V8/T8)) -> 0 | V8: =SUM(V5:V7) -> 0 | W8: =SUM(W5:W7) -> 0 | X8: =IF(Y8=0,0,(Y8/W8)) -> 0 | Y8: =SUM(Y5:Y7) -> 0 | Z8: =SUM(Z5:Z7) -> 0 | AA8: =IF(AB8=0,0,(AB8/Z8)) -> 0 | AB8: =SUM(AB5:AB7) -> 0 | AC8: =SUM(AC5:AC7) -> 0 | AD8: =IF(AE8=0,0,(AE8/AC8)) -> 0 | AE8: =SUM(AE5:AE7) -> 0 | AF8: =SUM(AF5:AF7) -> 0 | AG8: =IF(AH8=0,0,(AH8/AF8)) -> 0 | AH8: =SUM(AH5:AH7) -> 0 | AI8: =SUM(AI5:AI7) -> 0 | AJ8: =IF(AK8=0,0,(AK8/AI8)) -> 0 | AK8: =SUM(AK5:AK7) -> 0 | AL8: =SUM(AL5:AL7) -> 0 | AM8: =IF(AN8=0,0,(AN8/AL8)) -> 0 | AN8: =SUM(AN5:AN7) -> 0 | AO8: =SUM(AO5:AO7) -> 0 | AP8: =IF(AQ8=0,0,(AQ8/AO8)) -> 0 | AQ8: =SUM(AQ5:AQ7) -> 0 | AR8: =SUM(AR5:AR7) -> 0 | AT8: =SUM(AT5:AT7) -> 0 | AU8: =SUM(AU5:AU7) -> 0 | AW8: =SUM(AW5:AW7) -> 0 | AX8: =Z8-B8 -> -143489 | AY8: =AX8/B8 -> -1 | BA8: =SUM(BA5:BA7) -> 167760 | BB8: =BC8/BA8 -> 103.24481 | BC8: =SUM(BC5:BC7) -> 17320350 | BE8: =SUM(BE5:BE7) -> 166265.3
A9: Work in Progress
A10: HDPE Tape - Factory | B10: 37996 | C10: 167 | D10: =B10*C10 -> 6345332 | E10: =26659.9+0.1 -> 26660 | F10: =66+116 -> 182 | G10: =ROUND(E10*F10,0) -> 4852120 | J10: =ROUND(H10*I10,0) -> 0 | M10: =ROUND(K10*L10,0) -> 0 | P10: =ROUND(N10*O10,0) -> 0 | AB10: =ROUND((Z10*AA10),0) -> 0 | AE10: =ROUND((AC10*AD10),0) -> 0 | AH10: =ROUND((AF10*AG10),0) -> 0 | AK10: =ROUND((AI10*AJ10),0) -> 0 | AN10: =ROUND((AL10*AM10),0) -> 0 | AP10: =IF(AQ10=0,0,(AQ10/AO10)) -> 0 | AR10: ='[1] Qty Analysis'!BE66 -> 0 | AT10: =ROUND((AS10*AR10),0) -> 0 | AU10: ='[1] Qty Analysis'!BH66 -> 0 | AW10: =ROUND((AV10*AU10),0) -> 0 | AX10: =Z10-B10 -> -37996 | AY10: =AX10/B10 -> -1 | BA10: 24480 | BB10: 163 | BC10: =ROUND((BA10*BB10),0) -> 3990240 | BE10: 24112
A11: HDPE Tape - Job Work | B11: =64171.5-0.5 -> 64171 | C11: =C10 -> 167 | D11: =B11*C11 -> 10716557 | E11: 50337 | F11: =F10 -> 182 | G11: =ROUND(E11*F11,0) -> 9161334 | I11: =I10 -> 0 | J11: =ROUND(H11*I11,0) -> 0 | L11: =L10 -> 0 | M11: =ROUND(K11*L11,0) -> 0 | P11: =ROUND(N11*O11,0) -> 0 | R11: =R10 -> 0 | U11: =U10 -> 0 | X11: 149 | AA11: =AA10 -> 0 | AB11: =ROUND((Z11*AA11),0) -> 0 | AD11: 146 | AE11: =ROUND((AC11*AD11),0) -> 0 | AG11: 147 | AH11: =ROUND((AF11*AG11),0) -> 0 | AJ11: =AJ10 -> 0 | AK11: =ROUND((AI11*AJ11),0) -> 0 | AM11: =AM10 -> 0 | AN11: =ROUND((AL11*AM11),0) -> 0 | AP11: =IF(AQ11=0,0,(AQ11/AO11)) -> 0 | AR11: ='[1] Qty Analysis'!BE81 -> 0 | AT11: =ROUND((AS11*AR11),0) -> 0 | AU11: ='[1] Qty Analysis'!BH81 -> 0 | AW11: =ROUND((AV11*AU11),0) -> 0 | AX11: =Z11-B11 -> -64171 | AY11: =AX11/B11 -> -1 | BA11: 66292 | BB11: 163 | BC11: =ROUND((BA11*BB11),0) -> 10805596 | BE11: 66292
A12: Total | B12: =SUM(B10:B11) -> 102167 | C12: =D12/B12 -> 167 | D12: =SUM(D10:D11) -> 17061889 | E12: =SUM(E10:E11) -> 76997 | F12: =G12/E12 -> 182 | G12: =SUM(G10:G11) -> 14013454 | H12: =SUM(H10:H11) -> 0 | J12: =SUM(J10:J11) -> 0 | K12: =SUM(K10:K11) -> 0 | M12: =SUM(M10:M11) -> 0 | N12: =SUM(N10:N11) -> 0 | P12: =SUM(P10:P11) -> 0 | Q12: =SUM(Q10:Q11) -> 0 | S12: =SUM(S10:S11) -> 0 | T12: =SUM(T10:T11) -> 0 | V12: =SUM(V10:V11) -> 0 | W12: =SUM(W10:W11) -> 0 | X12: =IF(Y12=0,0,(Y12/W12)) -> 0 | Y12: =SUM(Y10:Y11) -> 0 | Z12: =SUM(Z10:Z11) -> 0 | AB12: =SUM(AB10:AB11) -> 0 | AC12: =SUM(AC10:AC11) -> 0 | AE12: =SUM(AE10:AE11) -> 0 | AF12: =SUM(AF10:AF11) -> 0 | AH12: =SUM(AH10:AH11) -> 0 | AI12: =SUM(AI10:AI11) -> 0 | AK12: =SUM(AK10:AK11) -> 0 | AL12: =SUM(AL10:AL11) -> 0 | AN12: =SUM(AN10:AN11) -> 0 | AO12: =SUM(AO10:AO11) -> 0 | AP12: =IF(AQ12=0,0,(AQ12/AO12)) -> 0 | AQ12: =SUM(AQ10:AQ11) -> 0 | AR12: =SUM(AR10:AR11) -> 0 | AT12: =SUM(AT10:AT11) -> 0 | AU12: =SUM(AU10:AU11) -> 0 | AW12: =SUM(AW10:AW11) -> 0 | AX12: =Z12-B12 -> -102167 | AY12: =AX12/B12 -> -1 | BA12: =SUM(BA10:BA11) -> 90772 | BB12: =BC12/BA12 -> 163 | BC12: =SUM(BC10:BC11) -> 14795836 | BE12: =SUM(BE10:BE11) -> 90404
A13: FINISHED GOODS:
A14: HDPE Fishnet Fabrics | B14: 200810 | C14: 238 | D14: =B14*C14 -> 47792780 | E14: 216887 | F14: =116+66+68 -> 250 | G14: =ROUND(E14*F14,0) -> 54221750 | I14: 219 | L14: 219 | O14: 218 | R14: 220 | U14: 221 | X14: =IF(Y14=0,0,(Y14/W14)) -> 0 | AA14: =IF(AB14=0,0,(AB14/Z14)) -> 0 | AD14: =IF(AE14=0,0,(AE14/AC14)) -> 0 | AG14: =IF(AH14=0,0,(AH14/AF14)) -> 0 | AJ14: 222 | AM14: 238 | AP14: =IF(AQ14=0,0,(AQ14/AO14)) -> 0 | AR14: ='[1] Qty Analysis'!BE101 -> 0 | AT14: =ROUND((AS14*AR14),0) -> 0 | AU14: ='[1] Qty Analysis'!BH101 -> 0 | AW14: =ROUND((AV14*AU14),0) -> 0 | AX14: =Z14-B14 -> -200810 | AY14: =AX14/B14 -> -1 | BA14: 289350 | BB14: 228 | BC14: =ROUND((BA14*BB14),0) -> 65971800
A15: Monofilament Shade Net -MSN | B15: 387 | C15: =IF(B15=0,0,(D15/B15))+0.35 -> 215.00116 | D15: 83070 | E15: 387 | F15: =IF(E15=0,0,(G15/E15))-0.3 -> 240.00233 | G15: 92997 | I15: =IF(H15=0,0,(J15/H15)) -> 0 | L15: =IF(K15=0,0,(M15/K15)) -> 0 | O15: =IF(N15=0,0,(P15/N15)) -> 0 | R15: =S15/Q15 -> #DIV/0! | U15: =V15/T15 -> #DIV/0! | X15: =IF(Y15=0,0,(Y15/W15)) -> 0 | AA15: =IF(AB15=0,0,(AB15/Z15)) -> 0 | AD15: =IF(AE15=0,0,(AE15/AC15)) -> 0 | AG15: =IF(AH15=0,0,(AH15/AF15)) -> 0 | AJ15: 210 | AM15: 215 | AP15: =IF(AQ15=0,0,(AQ15/AO15)) -> 0 | AR15: ='[1] Qty Analysis'!BE122 -> 0 | AU15: ='[1] Qty Analysis'!BH122 -> 0 | AX15: =Z15-B15 -> -387 | AY15: =AX15/B15 -> -1 | BA15: 810 | BB15: =BC15/BA15 -> 214.81481 | BC15: 174000
A16: Tape Shade Net-TSN | B16: 172 | C16: =IF(B16=0,0,(D16/B16))+0.12 -> 240.86419 | D16: 41408 | E16: 172 | F16: =IF(E16=0,0,(G16/E16))+0.41 -> 266.84605 | G16: 45827 | I16: =IF(H16=0,0,(J16/H16)) -> 0 | L16: =IF(K16=0,0,(M16/K16)) -> 0 | O16: =IF(N16=0,0,(P16/N16)) -> 0 | R16: =S16/Q16 -> #DIV/0! | U16: =V16/T16 -> #DIV/0! | X16: =IF(Y16=0,0,(Y16/W16)) -> 0 | AA16: =IF(AB16=0,0,(AB16/Z16)) -> 0 | AD16: =IF(AE16=0,0,(AE16/AC16))-0.11 -> -0.11 | AG16: =IF(AH16=0,0,(AH16/AF16))-0.38 -> -0.38 | AJ16: 178 | AM16: 241 | AX16: =Z16-B16 -> -172 | AY16: =AX16/B16 -> -1
A17: Weed Mat | B17: 446 | C17: =IF(B17=0,0,(D17/B17))+0.5 -> 229.10314 | D17: 101957 | E17: 346 | F17: =IF(E17=0,0,(G17/E17))+0.5 -> 229.13295 | G17: 79107 | I17: =IF(H17=0,0,(J17/H17)) -> 0 | L17: =IF(K17=0,0,(M17/K17)) -> 0 | O17: =IF(N17=0,0,(P17/N17)) -> 0 | R17: =S17/Q17 -> #DIV/0! | U17: =V17/T17 -> #DIV/0! | X17: =IF(Y17=0,0,(Y17/W17)) -> 0 | AA17: =IF(AB17=0,0,(AB17/Z17)) -> 0 | AD17: =IF(AE17=0,0,(AE17/AC17))+0.14 -> 0.14 | AG17: =IF(AH17=0,0,(AH17/AF17))-0.17 -> -0.17 | AJ17: 171 | AM17: 229 | AX17: =Z17-B17 -> -446 | AY17: =AX17/B17 -> -1
A18: PP Fabric & Sacks | F18: =IF(E18=0,0,(G18/E18)) -> 0 | I18: =IF(H18=0,0,(J18/H18)) -> 0 | L18: =IF(K18=0,0,(M18/K18)) -> 0 | O18: =IF(N18=0,0,(P18/N18)) -> 0 | AA18: =IF(AB18=0,0,(AB18/Z18)) -> 0
A19: Miscellaneous | B19: 36 | C19: =IF(B19=0,0,(D19/B19))-0.01 -> 128.76778 | D19: 4636 | E19: 36 | F19: =IF(E19=0,0,(G19/E19))-0.14 -> 186.55444 | G19: 6721 | I19: =IF(H19=0,0,(J19/H19)) -> 0 | L19: =IF(K19=0,0,(M19/K19)) -> 0 | O19: =IF(N19=0,0,(P19/N19)) -> 0 | R19: =IF(S19=0,0,(S19/Q19)) -> 0 | U19: =IF(V19=0,0,(V19/T19)) -> 0 | X19: =IF(Y19=0,0,(Y19/W19)) -> 0 | AA19: =IF(AB19=0,0,(AB19/Z19)) -> 0 | AD19: =IF(AE19=0,0,(AE19/AC19))-0.3 -> -0.3 | AG19: =IF(AH19=0,0,(AH19/AF19))-0.3 -> -0.3 | AJ19: 127 | AM19: =IF(AN19=0,0,(AN19/AL19)) -> 0 | AP19: =IF(AQ19=0,0,(AQ19/AO19)) -> 0
