Workbook

Sheet Table of Contents
B2: Table of Contents
Q3: Remarks
Q4: 1 Reconcile sheet is comapring Tally Inventory with Tarka
Q5: 2.Review Purchase sheet is redundnt Started to compare Purchases & reconcile
Q6: 3.Qty Analysis is Made by Accounts dept
Q7: 4. Input -Purchase comes from Tally
Q8: 5.Input-Dirct Expns from Tally
Q9: 6.Input-Indirect Expns from Tally
Q10: 7.Input-Stock Vauation from Tally
Q11: 8.Input-Inventory Sales Recobciles Gross Sales to Net Sales
Q12: 9.Output- Cost OF Good Sold (COGS)
Q13: 10.Output-PAL1 Gross P& L compares with Tally P& L fro data Validation with Quantities
Q14: 11.Output_Trading PL is checking on Trading monthly performance
... Q17: 14,15,16,17 OUTPUT from abve sheets for MIS understanding

Sheet Reconcile(HMT)
B2: Op Stock | E2: Apr | H2: May | K2: Jun | N2: Jul | Q2: Aug | T2: Sep | W2: Oct | Z2: Nov | AC2: Dec | AF2: Jan | AI2: Feb | AL2: Mar
B3: HMT | C3: CRK | D3: Diff | E3: HMT | F3: CRK | G3: Diff | H3: HMT | I3: CRK | J3: Diff | K3: HMT | L3: CRK | M3: Diff | N3: HMT | O3: CRK | P3: Diff | Q3: HMT | R3: CRK | S3: Diff | T3: HMT | U3: CRK | V3: Diff | W3: HMT | X3: CRK | Y3: Diff | Z3: HMT | AA3: CRK | AB3: Diff | AC3: HMT | AD3: CRK | AE3: Diff | AF3: HMT | AG3: CRK | AH3: Diff | AI3: HMT | AJ3: CRK | AK3: Diff | AL3: HMT | AM3: CRK | AN3: Diff
A4: HDPE | B4: 195845 | C4: ='Stock Valuation (FIFO)'!B5 -> 195845 | D4: =B4-C4 -> 0 | E4: 180315 | F4: ='Stock Valuation (FIFO)'!E5 -> 180315 | G4: =IF(F4=0,0,(E4-F4)) -> 0 | H4: 147410 | I4: ='Stock Valuation (FIFO)'!H5 -> 147410 | J4: =IF(I4=0,0,(H4-I4)) -> 0 | K4: 164125 | L4: ='Stock Valuation (FIFO)'!K5 -> 164125 | M4: =IF(L4=0,0,(K4-L4)) -> 0 | N4: 146140 | O4: ='Stock Valuation (FIFO)'!N5 -> 146140 | P4: =IF(O4=0,0,(N4-O4)) -> 0 | Q4: 187620 | R4: =' Qty Analysis'!N8 -> 187620 | S4: =IF(R4=0,0,(Q4-R4)) -> 0 | T4: 114680 | U4: ='Stock Valuation (FIFO)'!T5 -> 114680 | V4: =IF(U4=0,0,(T4-U4)) -> 0 | W4: 139725 | X4: ='Stock Valuation (FIFO)'!W5 -> 139725 | Y4: =IF(X4=0,0,(W4-X4)) -> 0 | Z4: 164310 | AA4: ='Stock Valuation (FIFO)'!Z5 -> 164310 | AB4: =IF(AA4=0,0,(Z4-AA4)) -> 0 | AC4: 135475 | AD4: ='Stock Valuation (FIFO)'!AC5 -> 135475 | AE4: =IF(AD4=0,0,(AC4-AD4)) -> 0 | AF4: 174670 | AG4: 174670 | AH4: =IF(AG4=0,0,(AF4-AG4)) -> 0 | AI4: 154290 | AJ4: ='Stock Valuation (FIFO)'!AI5 -> 154290 | AK4: =IF(AJ4=0,0,(AI4-AJ4)) -> 0 | AL4: 141140 | AM4: ='Stock Valuation (FIFO)'!AL5 -> 141140 | AN4: =IF(AM4=0,0,(AL4-AM4)) -> 0
A5: MB | B5: 1664 | C5: ='Stock Valuation (FIFO)'!B6 -> 1664 | D5: =B5-C5 -> 0 | E5: 2120.4 | F5: ='Stock Valuation (FIFO)'!E6 -> 2120 | G5: =IF(F5=0,0,(E5-F5)) -> 0.4 | H5: 2293.7 | I5: ='Stock Valuation (FIFO)'!H6 -> 2294 | J5: =IF(I5=0,0,(H5-I5)) -> -0.3 | K5: 2613.1 | L5: ='Stock Valuation (FIFO)'!K6 -> 2613 | M5: =IF(L5=0,0,(K5-L5)) -> 0.1 | N5: 2768.7 | O5: ='Stock Valuation (FIFO)'!N6 -> 2769 | P5: =IF(O5=0,0,(N5-O5)) -> -0.3 | Q5: 3082.1 | R5: =' Qty Analysis'!N21 -> 3082 | S5: =IF(R5=0,0,(Q5-R5)) -> 0.1 | T5: 2819.3 | U5: ='Stock Valuation (FIFO)'!T6 -> 2819 | V5: =IF(U5=0,0,(T5-U5)) -> 0.3 | W5: 2895.3 | X5: ='Stock Valuation (FIFO)'!W6 -> 2895 | Y5: =IF(X5=0,0,(W5-X5)) -> 0.3 | Z5: 2396.4 | AA5: ='Stock Valuation (FIFO)'!Z6 -> 2396 | AB5: =IF(AA5=0,0,(Z5-AA5)) -> 0.4 | AC5: 2395.2 | AD5: ='Stock Valuation (FIFO)'!AC6 -> 2395 | AE5: =IF(AD5=0,0,(AC5-AD5)) -> 0.2 | AF5: 2511.2 | AG5: 2511 | AH5: =IF(AG5=0,0,(AF5-AG5)) -> 0.2 | AI5: 3260.1 | AJ5: ='Stock Valuation (FIFO)'!AI6 -> 3260 | AK5: =IF(AJ5=0,0,(AI5-AJ5)) -> 0.1 | AL5: 2329.6 | AM5: ='Stock Valuation (FIFO)'!AL6 -> 2330 | AN5: =IF(AM5=0,0,(AL5-AM5)) -> -0.4
A6: CP | B6: 32 | C6: ='Stock Valuation (FIFO)'!B7 -> 32 | D6: =B6-C6 -> 0 | E6: 28.2 | F6: ='Stock Valuation (FIFO)'!E7 -> 28 | G6: =IF(F6=0,0,(E6-F6)) -> 0.2 | H6: 40.1 | I6: ='Stock Valuation (FIFO)'!H7 -> 37 | J6: =IF(I6=0,0,(H6-I6)) -> 3.1 | K6: 40.1 | L6: ='Stock Valuation (FIFO)'!K7 -> 40 | M6: =IF(L6=0,0,(K6-L6)) -> 0.1 | N6: 38.4 | O6: ='Stock Valuation (FIFO)'!N7 -> 38 | P6: =IF(O6=0,0,(N6-O6)) -> 0.4 | Q6: 25.6 | R6: =' Qty Analysis'!N33 -> 26 | S6: =IF(R6=0,0,(Q6-R6)) -> -0.4 | T6: 16.2 | U6: ='Stock Valuation (FIFO)'!T7 -> 16 | V6: =IF(U6=0,0,(T6-U6)) -> 0.2 | W6: 40.9 | X6: ='Stock Valuation (FIFO)'!W7 -> 41 | Y6: =IF(X6=0,0,(W6-X6)) -> -0.1 | Z6: 46 | AA6: ='Stock Valuation (FIFO)'!Z7 -> 46 | AB6: =IF(AA6=0,0,(Z6-AA6)) -> 0 | AC6: 40.3 | AD6: ='Stock Valuation (FIFO)'!AC7 -> 40 | AE6: =IF(AD6=0,0,(AC6-AD6)) -> 0.3 | AF6: 40.1 | AG6: 40 | AH6: =IF(AG6=0,0,(AF6-AG6)) -> 0.1 | AI6: 38.8 | AJ6: ='Stock Valuation (FIFO)'!AI7 -> 38 | AK6: =IF(AJ6=0,0,(AI6-AJ6)) -> 0.8 | AL6: 19 | AM6: ='Stock Valuation (FIFO)'!AL7 -> 19 | AN6: =IF(AM6=0,0,(AL6-AM6)) -> 0
A7: RM Total | B7: =SUM(B4:B6) -> 197541 | C7: =SUM(C4:C6) -> 197541 | D7: =B7-C7 -> 0 | E7: =SUM(E4:E6) -> 182463.6 | F7: =SUM(F4:F6) -> 182463 | G7: =IF(F7=0,0,(E7-F7)) -> 0.6 | H7: =SUM(H4:H6) -> 149743.8 | I7: =SUM(I4:I6) -> 149741 | J7: =IF(I7=0,0,(H7-I7)) -> 2.8 | K7: =SUM(K4:K6) -> 166778.2 | L7: =SUM(L4:L6) -> 166778 | M7: =IF(L7=0,0,(K7-L7)) -> 0.2 | N7: =SUM(N4:N6) -> 148947.1 | O7: =SUM(O4:O6) -> 148947 | P7: =IF(O7=0,0,(N7-O7)) -> 0.1 | Q7: =SUM(Q4:Q6) -> 190727.7 | R7: =SUM(R4:R6) -> 190728 | S7: =IF(R7=0,0,(Q7-R7)) -> -0.3 | T7: =SUM(T4:T6) -> 117515.5 | U7: =SUM(U4:U6) -> 117515 | V7: =IF(U7=0,0,(T7-U7)) -> 0.5 | W7: =SUM(W4:W6) -> 142661.2 | X7: =SUM(X4:X6) -> 142661 | Y7: =IF(X7=0,0,(W7-X7)) -> 0.2 | Z7: =SUM(Z4:Z6) -> 166752.4 | AA7: =SUM(AA4:AA6) -> 166752 | AB7: =IF(AA7=0,0,(Z7-AA7)) -> 0.4 | AC7: =SUM(AC4:AC6) -> 137910.5 | AD7: =SUM(AD4:AD6) -> 137910 | AE7: =IF(AD7=0,0,(AC7-AD7)) -> 0.5 | AF7: =SUM(AF4:AF6) -> 177221.3 | AG7: =SUM(AG4:AG6) -> 177221 | AH7: =IF(AG7=0,0,(AF7-AG7)) -> 0.3 | AI7: =SUM(AI4:AI6) -> 157588.9 | AJ7: =SUM(AJ4:AJ6) -> 157588 | AK7: =IF(AJ7=0,0,(AI7-AJ7)) -> 0.9 | AL7: =SUM(AL4:AL6) -> 143488.6 | AM7: =SUM(AM4:AM6) -> 143489 | AN7: =IF(AM7=0,0,(AL7-AM7)) -> -0.4
A8: Yarn Factory | B8: 49725 | C8: ='Stock Valuation (FIFO)'!B10 -> 49725 | D8: =B8-C8 -> 0 | E8: 56270 | F8: ='Stock Valuation (FIFO)'!E10 -> 56270 | G8: =IF(F8=0,0,(E8-F8)) -> 0 | H8: 46564 | I8: ='Stock Valuation (FIFO)'!H10 -> 46564 | J8: =IF(I8=0,0,(H8-I8)) -> 0 | K8: 52761.2 | L8: ='Stock Valuation (FIFO)'!K10 -> 52761 | M8: =IF(L8=0,0,(K8-L8)) -> 0.2 | N8: 48737.1 | O8: ='Stock Valuation (FIFO)'!N10 -> 48737 | P8: =IF(O8=0,0,(N8-O8)) -> 0.1 | Q8: 49389.9 | R8: =' Qty Analysis'!N61 -> 49389.9 | S8: =IF(R8=0,0,(Q8-R8)) -> 0 | T8: 56273.8 | U8: ='Stock Valuation (FIFO)'!T10 -> 56274 | V8: =IF(U8=0,0,(T8-U8)) -> -0.2 | W8: 60795.6 | X8: ='Stock Valuation (FIFO)'!W10 -> 60796 | Y8: =IF(X8=0,0,(W8-X8)) -> -0.4 | Z8: 57317.4 | AA8: ='Stock Valuation (FIFO)'!Z10 -> 57318 | AB8: =IF(AA8=0,0,(Z8-AA8)) -> -0.6 | AC8: 54865.8 | AD8: ='Stock Valuation (FIFO)'!AC10 -> 54866 | AE8: =IF(AD8=0,0,(AC8-AD8)) -> -0.2 | AF8: 47773.2 | AG8: 47774 | AH8: =IF(AG8=0,0,(AF8-AG8)) -> -0.8 | AI8: 51821.9 | AJ8: ='Stock Valuation (FIFO)'!AI10 -> 51822 | AK8: =IF(AJ8=0,0,(AI8-AJ8)) -> -0.1 | AL8: 37996 | AM8: 37996 | AN8: =IF(AM8=0,0,(AL8-AM8)) -> 0
A9: Yarn Fabrctr | B9: 76468 | C9: ='Stock Valuation (FIFO)'!B11 -> 76468 | D9: =B9-C9 -> 0 | E9: 63905.6 | F9: ='Stock Valuation (FIFO)'!E11 -> 63906 | G9: =IF(F9=0,0,(E9-F9)) -> -0.4 | H9: 61851.2 | I9: ='Stock Valuation (FIFO)'!H11 -> 61851 | J9: =IF(I9=0,0,(H9-I9)) -> 0.2 | K9: 66528 | L9: ='Stock Valuation (FIFO)'!K11 -> 66528 | M9: =IF(L9=0,0,(K9-L9)) -> 0 | N9: 73740.4 | O9: ='Stock Valuation (FIFO)'!N11 -> 73740 | P9: =IF(O9=0,0,(N9-O9)) -> 0.4 | Q9: 77586 | R9: =' Qty Analysis'!N71 -> 77584.9 | S9: =IF(R9=0,0,(Q9-R9)) -> 1.1 | T9: =79105.0999999999-25 -> 79080.1 | U9: ='Stock Valuation (FIFO)'!T11 -> 79080 | V9: =IF(U9=0,0,(T9-U9)) -> 0.1 | W9: 80193.4 | X9: ='Stock Valuation (FIFO)'!W11 -> 80193 | Y9: =IF(X9=0,0,(W9-X9)) -> 0.4 | Z9: 85004.2 | AA9: ='Stock Valuation (FIFO)'!Z11 -> 85004 | AB9: =IF(AA9=0,0,(Z9-AA9)) -> 0.2 | AC9: 91727.2 | AD9: ='Stock Valuation (FIFO)'!AC11 -> 91727 | AE9: =IF(AD9=0,0,(AC9-AD9)) -> 0.2 | AF9: 91742.2 | AG9: 91742 | AH9: =IF(AG9=0,0,(AF9-AG9)) -> 0.2 | AI9: 86543.9 | AJ9: ='Stock Valuation (FIFO)'!AI11 -> 86544 | AK9: =IF(AJ9=0,0,(AI9-AJ9)) -> -0.1 | AL9: 84657.29 | AM9: 64171 | AN9: =IF(AM9=0,0,(AL9-AM9)) -> 20486.29
A10: Yarn Total | B10: =SUM(B8:B9) -> 126193 | C10: =SUM(C8:C9) -> 126193 | D10: =B10-C10 -> 0 | E10: =SUM(E8:E9) -> 120175.6 | F10: =SUM(F8:F9) -> 120176 | G10: =IF(F10=0,0,(E10-F10)) -> -0.4 | H10: =SUM(H8:H9) -> 108415.2 | I10: =SUM(I8:I9) -> 108415 | J10: =IF(I10=0,0,(H10-I10)) -> 0.2 | K10: =SUM(K8:K9) -> 119289.2 | L10: =SUM(L8:L9) -> 119289 | M10: =IF(L10=0,0,(K10-L10)) -> 0.2 | N10: =SUM(N8:N9) -> 122477.5 | O10: =SUM(O8:O9) -> 122477 | P10: =IF(O10=0,0,(N10-O10)) -> 0.5 | Q10: =SUM(Q8:Q9) -> 126975.9 | R10: =SUM(R8:R9) -> 126974.8 | S10: =IF(R10=0,0,(Q10-R10)) -> 1.1 | T10: =SUM(T8:T9) -> 135353.9 | U10: =SUM(U8:U9) -> 135354 | V10: =IF(U10=0,0,(T10-U10)) -> -0.1 | W10: =SUM(W8:W9) -> 140989 | X10: =SUM(X8:X9) -> 140989 | Y10: =IF(X10=0,0,(W10-X10)) -> 0 | Z10: =SUM(Z8:Z9) -> 142321.6 | AA10: =SUM(AA8:AA9) -> 142322 | AB10: =IF(AA10=0,0,(Z10-AA10)) -> -0.4 | AC10: =SUM(AC8:AC9) -> 146593 | AD10: =SUM(AD8:AD9) -> 146593 | AE10: =IF(AD10=0,0,(AC10-AD10)) -> 0 | AF10: =SUM(AF8:AF9) -> 139515.4 | AG10: =SUM(AG8:AG9) -> 139516 | AH10: =IF(AG10=0,0,(AF10-AG10)) -> -0.6 | AI10: =SUM(AI8:AI9) -> 138365.8 | AJ10: =SUM(AJ8:AJ9) -> 138366 | AK10: =IF(AJ10=0,0,(AI10-AJ10)) -> -0.2 | AL10: =SUM(AL8:AL9) -> 122653.29 | AM10: =SUM(AM8:AM9) -> 102167 | AN10: =IF(AM10=0,0,(AL10-AM10)) -> 20486.29 | AO10: Water Content Fabricator
A11: Fabric | B11: 206027 | C11: ='Stock Valuation (FIFO)'!B14 -> 206027 | D11: =B11-C11 -> 0 | E11: 224044.9 | F11: ='Stock Valuation (FIFO)'!E14 -> 224045 | G11: =IF(F11=0,0,(E11-F11)) -> -0.1 | H11: 201846.3 | I11: ='Stock Valuation (FIFO)'!H14 -> 168371 | J11: =IF(I11=0,0,(H11-I11)) -> 33475.3 | K11: 191275.2 | L11: ='Stock Valuation (FIFO)'!K14 -> 140447 | M11: =IF(L11=0,0,(K11-L11)) -> 50828.2 | N11: 197795.1 | O11: ='Stock Valuation (FIFO)'!N14 -> 130199 | P11: =IF(O11=0,0,(N11-O11)) -> 67596.1 | Q11: 202309.3 | R11: ='Stock Valuation (FIFO)'!Q14 -> 202593 | S11: =IF(R11=0,0,(Q11-R11)) -> -283.7 | T11: 228721.4 | U11: ='Stock Valuation (FIFO)'!T14 -> 228722 | V11: =IF(U11=0,0,(T11-U11)) -> -0.6 | W11: 237947.3 | X11: ='Stock Valuation (FIFO)'!W14 -> 237947 | Y11: =IF(X11=0,0,(W11-X11)) -> 0.3 | Z11: 218950.4 | AA11: ='Stock Valuation (FIFO)'!Z14 -> 218951 | AB11: =IF(AA11=0,0,(Z11-AA11)) -> -0.6 | AC11: 255945.6 | AD11: ='Stock Valuation (FIFO)'!AC14 -> 255947 | AE11: =IF(AD11=0,0,(AC11-AD11)) -> -1.4 | AF11: 261815 | AG11: 261816 | AH11: =IF(AG11=0,0,(AF11-AG11)) -> -1 | AI11: 239651.2 | AJ11: ='Stock Valuation (FIFO)'!AI14 -> 239651 | AK11: =IF(AJ11=0,0,(AI11-AJ11)) -> 0.2 | AL11: 200810.4 | AM11: ='Stock Valuation (FIFO)'!AL14 -> 200810 | AN11: =IF(AM11=0,0,(AL11-AM11)) -> 0.4
A12: TSN | B12: 244 | C12: ='Trading PL'!B42 -> 244 | D12: =B12-C12 -> 0 | E12: 256.6 | F12: ='Trading PL'!B35 -> 257 | G12: =IF(F12=0,0,(E12-F12)) -> -0.4 | H12: 257 | I12: ='Trading PL'!E35 -> 257 | J12: =IF(I12=0,0,(H12-I12)) -> 0 | K12: 197.1 | L12: ='Trading PL'!H35 -> 257 | M12: =IF(L12=0,0,(K12-L12)) -> -59.9 | N12: 197.1 | O12: ='Trading PL'!K35 -> 197 | P12: =IF(O12=0,0,(N12-O12)) -> 0.1 | Q12: 197.1 | R12: ='Trading PL'!N35 -> 197 | S12: =IF(R12=0,0,(Q12-R12)) -> 0.1 | T12: 183.1 | U12: ='Stock Valuation (FIFO)'!T16 -> 183 | V12: =IF(U12=0,0,(T12-U12)) -> 0.1 | W12: 183.1 | X12: ='Stock Valuation (FIFO)'!W16 -> 183 | Y12: =IF(X12=0,0,(W12-X12)) -> 0.1 | Z12: =423.5-36.5 -> 387 | AA12: ='Stock Valuation (FIFO)'!Z15 -> 387 | AB12: =IF(AA12=0,0,(Z12-AA12)) -> 0 | AC12: =423.5-AC16 -> 387 | AD12: ='Stock Valuation (FIFO)'!AC15 -> 387 | AE12: =IF(AD12=0,0,(AC12-AD12)) -> 0 | AF12: =423.5-37 -> 386.5 | AG12: 387 | AH12: =IF(AG12=0,0,(AF12-AG12)) -> -0.5 | AI12: =423.5-AI16 -> 386.5 | AJ12: ='Stock Valuation (FIFO)'!AI15 -> 387 | AK12: =IF(AJ12=0,0,(AI12-AJ12)) -> -0.5 | AL12: =423.5-AL16 -> 386.5 | AM12: ='Stock Valuation (FIFO)'!AL15 -> 387 | AN12: =IF(AM12=0,0,(AL12-AM12)) -> -0.5
A13: MSN | B13: 387 | C13: ='Trading PL'!B41 -> 387 | D13: =B13-C13 -> 0 | E13: 387 | F13: ='Trading PL'!B34 -> 387 | G13: =IF(F13=0,0,(E13-F13)) -> 0 | H13: 387 | I13: ='Trading PL'!E34 -> 387 | J13: =IF(I13=0,0,(H13-I13)) -> 0 | K13: 387 | L13: ='Trading PL'!H34 -> 387 | M13: =IF(L13=0,0,(K13-L13)) -> 0 | N13: 387 | O13: ='Trading PL'!K34 -> 387 | P13: =IF(O13=0,0,(N13-O13)) -> 0 | Q13: 404 | R13: ='Trading PL'!N34 -> 387 | S13: =IF(R13=0,0,(Q13-R13)) -> 17 | T13: 410 | U13: ='Stock Valuation (FIFO)'!T15 -> 387 | V13: =IF(U13=0,0,(T13-U13)) -> 23 | W13: 410 | X13: ='Stock Valuation (FIFO)'!W15 -> 387 | Y13: =IF(X13=0,0,(W13-X13)) -> 23 | Z13: 183.1 | AA13: ='Stock Valuation (FIFO)'!Z16 -> 183 | AB13: =IF(AA13=0,0,(Z13-AA13)) -> 0.1 | AC13: 179.1 | AD13: ='Stock Valuation (FIFO)'!AC16 -> 179 | AE13: =IF(AD13=0,0,(AC13-AD13)) -> 0.1 | AF13: 179.1 | AG13: 179 | AH13: =IF(AG13=0,0,(AF13-AG13)) -> 0.1 | AI13: 177.9 | AJ13: ='Stock Valuation (FIFO)'!AI16 -> 178 | AK13: =IF(AJ13=0,0,(AI13-AJ13)) -> -0.1 | AL13: 171.9 | AM13: ='Stock Valuation (FIFO)'!AL16 -> 172 | AN13: =IF(AM13=0,0,(AL13-AM13)) -> -0.1
A14: PP Sacks | C14: ='Trading PL'!B44 -> 0 | D14: =B14-C14 -> 0 | E14: 0 | F14: ='Trading PL'!B38 -> 0 | G14: =IF(F14=0,0,(E14-F14)) -> 0 | H14: 0 | I14: ='Trading PL'!E38 -> 0 | J14: =IF(I14=0,0,(H14-I14)) -> 0 | K14: 0 | L14: ='Trading PL'!H38 -> 0 | M14: =IF(L14=0,0,(K14-L14)) -> 0 | N14: 0 | O14: ='Trading PL'!K38 -> 0 | P14: =IF(O14=0,0,(N14-O14)) -> 0 | S14: =IF(R14=0,0,(Q14-R14)) -> 0 | T14: 0 | V14: =IF(U14=0,0,(T14-U14)) -> 0 | W14: 0 | Y14: =IF(X14=0,0,(W14-X14)) -> 0 | Z14: 804.1 | AA14: ='Stock Valuation (FIFO)'!Z17 -> 804 | AB14: =IF(AA14=0,0,(Z14-AA14)) -> 0.1 | AC14: 391.2 | AD14: ='Stock Valuation (FIFO)'!AC17 -> 391 | AE14: =IF(AD14=0,0,(AC14-AD14)) -> 0.2 | AF14: 196.2 | AG14: 196 | AH14: =IF(AG14=0,0,(AF14-AG14)) -> 0.2 | AK14: =IF(AJ14=0,0,(AI14-AJ14)) -> 0 | AL14: 0 | AN14: =IF(AM14=0,0,(AL14-AM14)) -> 0
A15: Weed Mat | B15: 75 | C15: ='Trading PL'!B43 -> 75 | D15: =B15-C15 -> 0 | E15: 46.8 | F15: ='Trading PL'!B37 -> 0 | G15: =IF(F15=0,0,(E15-F15)) -> 0 | H15: 36.1 | I15: ='Trading PL'!E37 -> 0 | J15: =IF(I15=0,0,(H15-I15)) -> 0 | K15: 26.1 | L15: ='Trading PL'!H37 -> 0 | M15: =IF(L15=0,0,(K15-L15)) -> 0 | N15: 129.1 | O15: ='Trading PL'!K37 -> 0 | P15: =IF(O15=0,0,(N15-O15)) -> 0 | Q15: 153.1 | R15: ='Trading PL'!N36 -> 153 | S15: =IF(R15=0,0,(R15-Q15)) -> -0.1 | T15: 450.1 | U15: ='Stock Valuation (FIFO)'!T17 -> 450 | V15: =IF(U15=0,0,(T15-U15)) -> 0.1 | W15: 172.1 | X15: ='Stock Valuation (FIFO)'!W17 -> 172 | Y15: =IF(X15=0,0,(W15-X15)) -> 0.1 | AB15: =IF(AA15=0,0,(Z15-AA15)) -> 0 | AD15: ='Stock Valuation (FIFO)'!AC18 -> 0 | AE15: =IF(AD15=0,0,(AC15-AD15)) -> 0 | AH15: =IF(AG15=0,0,(AF15-AG15)) -> 0 | AI15: 446.2 | AJ15: ='Stock Valuation (FIFO)'!AI17 -> 446 | AK15: =IF(AJ15=0,0,(AI15-AJ15)) -> 0.2 | AL15: 446.2 | AM15: ='Stock Valuation (FIFO)'!AL17 -> 446 | AN15: =IF(AM15=0,0,(AL15-AM15)) -> 0.2
A16: PP Fabric | D16: =B16-C16 -> 0 | G16: =IF(F16=0,0,(E16-F16)) -> 0 | J16: =IF(I16=0,0,(H16-I16)) -> 0 | M16: =IF(L16=0,0,(K16-L16)) -> 0 | P16: =IF(O16=0,0,(N16-O16)) -> 0 | R16: ='Trading PL'!N38 -> 17 | S16: =IF(R16=0,0,(R16-Q16)) -> 17 | U16: ='Stock Valuation (FIFO)'!T19 -> 17 | X16: ='Stock Valuation (FIFO)'!W19 -> 23 | Y16: =IF(X16=0,0,(W16-X16)) -> -23 | Z16: 36.5 | AA16: ='Stock Valuation (FIFO)'!Z19 -> 37 | AB16: =IF(AA16=0,0,(Z16-AA16)) -> -0.5 | AC16: 36.5 | AD16: ='Stock Valuation (FIFO)'!AC19 -> 37 | AE16: =IF(AD16=0,0,(AC16-AD16)) -> -0.5 | AF16: 37 | AG16: 37 | AH16: =IF(AG16=0,0,(AF16-AG16)) -> 0 | AI16: 37 | AJ16: ='Stock Valuation (FIFO)'!AI19 -> 37 | AK16: =IF(AJ16=0,0,(AI16-AJ16)) -> 0 | AL16: 37 | AM16: ='Stock Valuation (FIFO)'!AL19 -> 37 | AN16: =IF(AM16=0,0,(AL16-AM16)) -> 0
A17: Fabric Total | B17: =SUM(B11:B16) -> 206733 | C17: =SUM(C11:C16) -> 206733 | D17: =B17-C17 -> 0 | E17: =SUM(E11:E16) -> 224735.3 | F17: =SUM(F11:F16) -> 224689 | G17: =IF(F17=0,0,(E17-F17)) -> 46.3 | H17: =SUM(H11:H16) -> 202526.4 | I17: =SUM(I11:I16) -> 169015 | J17: =IF(I17=0,0,(H17-I17)) -> 33511.4 | K17: =SUM(K11:K16) -> 191885.4 | L17: =SUM(L11:L16) -> 141091 | M17: =IF(L17=0,0,(K17-L17)) -> 50794.4 | N17: =SUM(N11:N16) -> 198508.3 | O17: =SUM(O11:O16) -> 130783 | P17: =IF(O17=0,0,(N17-O17)) -> 67725.3 | Q17: =SUM(Q11:Q16) -> 203063.5 | R17: =SUM(R11:R15) -> 203330 | S17: =IF(R17=0,0,(Q17-R17)) -> -266.5 | T17: =SUM(T11:T16) -> 229764.6 | U17: =SUM(U11:U16) -> 229759 | V17: =IF(U17=0,0,(T17-U17)) -> 5.6 | W17: =SUM(W11:W16) -> 238712.5 | X17: =SUM(X11:X16) -> 238712 | Y17: =IF(X17=0,0,(W17-X17)) -> 0.5 | Z17: =SUM(Z11:Z16) -> 220361.1 | AA17: =SUM(AA11:AA16) -> 220362 | AB17: =IF(AA17=0,0,(Z17-AA17)) -> -0.9 | AC17: =SUM(AC11:AC16) -> 256939.4 | AD17: =SUM(AD11:AD16) -> 256941 | AE17: =IF(AD17=0,0,(AC17-AD17)) -> -1.6 | AF17: =SUM(AF11:AF16) -> 262613.8 | AG17: =SUM(AG11:AG16) -> 262615 | AH17: =IF(AG17=0,0,(AF17-AG17)) -> -1.2 | AI17: =SUM(AI11:AI16) -> 240698.8 | AJ17: =SUM(AJ11:AJ16) -> 240699 | AK17: =IF(AJ17=0,0,(AI17-AJ17)) -> -0.2 | AL17: =SUM(AL11:AL16) -> 201852 | AM17: =SUM(AM11:AM16) -> 201852 | AN17: =IF(AM17=0,0,(AL17-AM17)) -> 0
A18: TOTAL | B18: =B7+B10+B17 -> 530467 | C18: =C7+C10+C17 -> 530467 | D18: =B18-C18 -> 0 | E18: =E7+E10+E17 -> 527374.5 | F18: =F7+F10+F17 -> 527328 | G18: =IF(F18=0,0,(E18-F18)) -> 46.5 | H18: =H7+H10+H17 -> 460685.4 | I18: =I7+I10+I17 -> 427171 | J18: =IF(I18=0,0,(H18-I18)) -> 33514.4 | K18: =K7+K10+K17 -> 477952.8 | L18: =L7+L10+L17 -> 427158 | M18: =IF(L18=0,0,(K18-L18)) -> 50794.8 | N18: =N7+N10+N17 -> 469932.9 | O18: =O7+O10+O17 -> 402207 | P18: =IF(O18=0,0,(N18-O18)) -> 67725.9 | Q18: =Q7+Q10+Q17 -> 520767.1 | R18: =R7+R10+R17 -> 521032.8 | S18: =IF(R18=0,0,(Q18-R18)) -> -265.7 | T18: =T7+T10+T17 -> 482634 | U18: =U7+U10+U17 -> 482628 | V18: =IF(U18=0,0,(T18-U18)) -> 6 | W18: =W7+W10+W17 -> 522362.7 | X18: =X7+X10+X17 -> 522362 | Y18: =IF(X18=0,0,(W18-X18)) -> 0.7 | Z18: =Z7+Z10+Z17 -> 529435.1 | AA18: =AA7+AA10+AA17 -> 529436 | AB18: =IF(AA18=0,0,(Z18-AA18)) -> -0.9 | AC18: =AC7+AC10+AC17 -> 541442.9 | AD18: =AD7+AD10+AD17 -> 541444 | AE18: =IF(AD18=0,0,(AC18-AD18)) -> -1.1 | AF18: =AF7+AF10+AF17 -> 579350.5 | AG18: =AG7+AG10+AG17 -> 579352 | AH18: =IF(AG18=0,0,(AF18-AG18)) -> -1.5 | AI18: =AI7+AI10+AI17 -> 536653.5 | AJ18: =AJ7+AJ10+AJ17 -> 536653 | AK18: =IF(AJ18=0,0,(AI18-AJ18)) -> 0.5 | AL18: =AL7+AL10+AL17 -> 467993.89 | AM18: =AM7+AM10+AM17 -> 447508 | AN18: =IF(AM18=0,0,(AL18-AM18)) -> 20485.89
A20: SFG/FG | B20: =B18-B7 -> 332926 | C20: =C18-C7 -> 332926 | D20: =B20-C20 -> 0 | E20: =E18-E7 -> 344910.9 | F20: =F18-F7 -> 344865 | G20: =IF(F20=0,0,(E20-F20)) -> 45.9 | H20: =H18-H7 -> 310941.6 | I20: =I18-I7 -> 277430 | J20: =IF(I20=0,0,(H20-I20)) -> 33511.6 | K20: =K18-K7 -> 311174.6 | L20: =L18-L7 -> 260380 | M20: =IF(L20=0,0,(K20-L20)) -> 50794.6 | N20: =N18-N7 -> 320985.8 | O20: =O18-O7 -> 253260 | P20: =IF(O20=0,0,(N20-O20)) -> 67725.8 | Q20: =Q18-Q7 -> 330039.4 | R20: =R18-R7 -> 330304.8 | S20: =IF(R20=0,0,(Q20-R20)) -> -265.4 | T20: =T18-T7 -> 365118.5 | U20: =U18-U7 -> 365113 | V20: =IF(U20=0,0,(T20-U20)) -> 5.5 | W20: =W18-W7 -> 379701.5 | X20: =X18-X7 -> 379701 | Y20: =IF(X20=0,0,(W20-X20)) -> 0.5 | Z20: =Z18-Z7 -> 362682.7 | AA20: =AA18-AA7 -> 362684 | AB20: =IF(AA20=0,0,(Z20-AA20)) -> -1.3 | AC20: =AC18-AC7 -> 403532.4 | AD20: =AD18-AD7 -> 403534 | AE20: =IF(AD20=0,0,(AC20-AD20)) -> -1.6 | AF20: =AF18-AF7 -> 402129.2 | AG20: =AG18-AG7 -> 402131 | AH20: =IF(AG20=0,0,(AF20-AG20)) -> -1.8 | AI20: =AI18-AI7 -> 379064.6 | AJ20: =AJ18-AJ7 -> 379065 | AK20: =IF(AJ20=0,0,(AI20-AJ20)) -> -0.4 | AL20: =AL18-AL7 -> 324505.29 | AM20: =AM18-AM7 -> 304019 | AN20: =IF(AM20=0,0,(AL20-AM20)) -> 20486.29
E21: =E20-B20 -> 11984.9 | H21: =H20-E20 -> -33969.3 | K21: =K20-H20 -> 233 | N21: =N20-K20 -> 9811.2 | Q21: =Q20-N20 -> 9053.6 | T21: =T20-Q20 -> 35079.1 | W21: =W20-T20 -> 14583
E22: =E20-$B$20 -> 11984.9 | H22: =H20-$B$20 -> -21984.4 | K22: =K20-$B$20 -> -21751.4 | N22: =N20-$B$20 -> -11940.2 | Q22: =Q20-$B$20 -> -2886.6 | T22: =T20-$B$20 -> 32192.5 | W22: =W20-$B$20 -> 46775.5
A23: Tarka->
A24: HDPE | H24: =63410+93000 -> 156410 | I24: =H4-H24 -> -9000
A25: MB | H25: 2240 | I25: =H5-H25 -> 53.7
A26: CP | H26: 80 | I26: =H6-H26 -> -39.9
A27: RM Total | H27: =SUM(H24:H26) -> 158730 | I27: =SUM(I24:I26) -> -8986.2
A28: Yarn Factory | H28: 30450 | I28: =H8-H28 -> 16114
A29: Yarn Fabrctr | H29: 64627 | I29: =H9-H29 -> -2775.8
A30: Yarn Total | H30: =SUM(H28:H29) -> 95077 | I30: =SUM(I28:I29) -> 13338.2
A31: Fabric | H31: 332260 | I31: =H11-H31 -> -130413.7
A32: TSN | H32: 108 | I32: =H12-H32 -> 149
A33: MSN | H33: 1015 | I33: =H13-H33 -> -628
A34: Weed Mat
A35: PP Fab
A36: PP Sacks | Q36: 942.6
A37: Fabric Total | H37: =SUM(H31:H36) -> 333383 | I37: =SUM(I31:I36) -> -130892.7
A38: TOTAL | H38: =H27+H30+H37 -> 587190 | I38: =I27+I30+I37 -> -126540.7
A40: SFG/FG | H40: =H38-H27 -> 428460 | I40: =I38-I27 -> -117554.5

Sheet Inventory Sales
A2: Particulars | B2: Apr | E2: May | H2: Jun | K2: Jul | N2: Aug | Q2: Sep | T2: Oct | W2: Nov | Z2: Dec | AC2: Jan | AF2: Feb | AI2: Mar | AL2: Total
A3: Finished Goods | B3: Outwards Qty | C3: Rate | D3: Amount | E3: Outwards Qty | F3: Rate | G3: Amount | H3: Outwards Qty | I3: Rate | J3: Amount | K3: Outwards Qty | L3: Rate | M3: Amount | N3: Outwards Qty | O3: Rate | P3: Amount | Q3: Outwards Qty | R3: Rate | S3: Amount | T3: Outwards Qty | U3: Rate | V3: Amount | W3: Outwards Qty | X3: Rate | Y3: Amount | Z3: Outwards Qty | AA3: Rate | AB3: Amount | AC3: Outwards Qty | AD3: Rate | AE3: Amount | AF3: Outwards Qty | AG3: Rate | AH3: Amount | AI3: Outwards Qty | AJ3: Rate | AK3: Amount | AL3: Outwards Qty | AM3: Rate | AN3: Amount
A5: MCF | B5: 41120.23 | C5: =IF(B5=0,0,D5/B5) -> 265.6654 | D5: 10924222 | E5: 72520.71 | F5: =IF(E5=0,0,G5/E5) -> 270.28471 | G5: 19601239 | H5: 66711.07 | I5: =IF(H5=0,0,J5/H5) -> 275.40072 | J5: 18372276 | K5: 54632.46 | L5: =IF(K5=0,0,M5/K5) -> 280.06473 | M5: 15300625 | N5: 43167.19 | O5: =IF(N5=0,0,P5/N5) -> 278.77556 | P5: 12033958 | Q5: 38963.1 | R5: =IF(Q5=0,0,S5/Q5) -> 275.56432 | S5: 10736840 | T5: 50565.14 | U5: =IF(T5=0,0,V5/T5) -> 263.90285 | V5: 13344284 | W5: 42420.62 | X5: =IF(W5=0,0,Y5/W5) -> 262.15435 | Y5: 11120750 | Z5: 29769.32 | AA5: =IF(Z5=0,0,AB5/Z5) -> 265.79562 | AB5: 7912555 | AC5: 39918.5 | AD5: =IF(AC5=0,0,AE5/AC5) -> 265.37483 | AE5: 10593365 | AF5: 60348.07 | AG5: =IF(AF5=0,0,AH5/AF5) -> 268.19502 | AH5: 16185052 | AI5: 77562.79 | AJ5: =IF(AI5=0,0,AK5/AI5) -> 285.65156 | AK5: 22155932 | AL5: =SUM(B5,E5,H5,K5,N5,Q5,T5,W5,Z5,AC5,AF5,AI5) -> 617699.2 | AM5: =IF(AL5=0,0,AN5/AL5) -> 272.43211 | AN5: =SUM(D5,G5,J5,M5,P5,S5,V5,Y5,AB5,AE5,AH5,AK5) -> 168281099 | AQ5: =AM5 -> 272.43211 | AR5: =AM6 -> 260.884
A6: WMF | B6: 52570.56 | C6: =IF(B6=0,0,D6/B6) -> 252.51645 | D6: 13274931 | E6: 53892.04 | F6: =IF(E6=0,0,G6/E6) -> 258.49398 | G6: 13930768 | H6: 46431.97 | I6: =IF(H6=0,0,J6/H6) -> 277.11921 | J6: 12867191 | K6: 50356.34 | L6: =IF(K6=0,0,M6/K6) -> 262.57795 | M6: 13222464 | N6: 59476.5 | O6: =IF(N6=0,0,P6/N6) -> 255.71268 | P6: 15208895 | Q6: 49063.76 | R6: =IF(Q6=0,0,S6/Q6) -> 259.38175 | S6: 12726244 | T6: 36661.11 | U6: =IF(T6=0,0,V6/T6) -> 257.84578 | V6: 9452912.5 | W6: 76513.39 | X6: =IF(W6=0,0,Y6/W6) -> 249.27027 | Y6: 19072514 | Z6: 46944.17 | AA6: =IF(Z6=0,0,AB6/Z6) -> 252.25225 | AB6: 11841772 | AC6: 70387 | AD6: =IF(AC6=0,0,AE6/AC6) -> 260.00611 | AE6: 18301050 | AF6: 58203.1 | AG6: =IF(AF6=0,0,AH6/AF6) -> 263.23728 | AH6: 15321226 | AI6: 70675.97 | AJ6: =IF(AI6=0,0,AK6/AI6) -> 281.27086 | AK6: 19879091 | AL6: =SUM(B6,E6,H6,K6,N6,Q6,T6,W6,Z6,AC6,AF6,AI6) -> 671175.91 | AM6: =IF(AL6=0,0,AN6/AL6) -> 260.884 | AN6: =SUM(D6,G6,J6,M6,P6,S6,V6,Y6,AB6,AE6,AH6,AK6) -> 175099059 | AP6: ='PAL I'!AN5+'PAL I'!AN8 -> 209386214 | AQ6: =(AP6/(AL11)) -> 148.77815 | AR6: =AQ6 -> 148.77815
A7: MONOFILAMENT FABRIC INSECT BAGS | C7: =IF(B7=0,0,D7/B7) -> 0 | I7: =IF(H7=0,0,J7/H7) -> 0 | L7: =IF(K7=0,0,M7/K7) -> 0 | R7: =IF(Q7=0,0,S7/Q7) -> 0 | U7: =IF(T7=0,0,V7/T7) -> 0 | X7: =IF(W7=0,0,Y7/W7) -> 0 | AA7: =IF(Z7=0,0,AB7/Z7) -> 0 | AD7: =IF(AC7=0,0,AE7/AC7) -> 0 | AG7: =IF(AF7=0,0,AH7/AF7) -> 0 | AJ7: =IF(AI7=0,0,AK7/AI7) -> 0 | AL7: =SUM(B7,E7,H7,K7,N7,Q7,T7,W7,Z7,AC7,AF7,AI7) -> 0 | AM7: =IF(AL7=0,0,AN7/AL7) -> 0 | AN7: =SUM(D7,G7,J7,M7,P7,S7,V7,Y7,AB7,AE7,AH7,AK7) -> 0 | AQ7: =AQ5-AQ6 -> 123.65397 | AR7: =AR5-AR6 -> 112.10586
A8: MONOFILAMENT FABRIC INSECT NET | B8: 30.08 | C8: =IF(B8=0,0,D8/B8) -> 376.16356 | D8: 11315 | H8: 1039.9 | I8: =IF(H8=0,0,J8/H8) -> 359.63073 | J8: 373980 | K8: 6 | L8: =IF(K8=0,0,M8/K8) -> 390 | M8: 2340 | R8: =IF(Q8=0,0,S8/Q8) -> 0 | T8: 26 | U8: =IF(T8=0,0,V8/T8) -> 360 | V8: 9360 | W8: 389.2 | X8: =IF(W8=0,0,Y8/W8) -> 412.84687 | Y8: 160680 | AA8: =IF(Z8=0,0,AB8/Z8) -> 0 | AD8: =IF(AC8=0,0,AE8/AC8) -> 0 | AF8: 271.7 | AG8: =IF(AF8=0,0,AH8/AF8) -> 336.5035 | AH8: 91428 | AJ8: =IF(AI8=0,0,AK8/AI8) -> 0 | AL8: =SUM(B8,E8,H8,K8,N8,Q8,T8,W8,Z8,AC8,AF8,AI8) -> 1762.88 | AM8: =IF(AL8=0,0,AN8/AL8) -> 368.206 | AN8: =SUM(D8,G8,J8,M8,P8,S8,V8,Y8,AB8,AE8,AH8,AK8) -> 649103
A9: MONOFILAMENT FABRIC HAPPA | C9: =IF(B9=0,0,D9/B9) -> 0 | E9: 23 | F9: =IF(E9=0,0,G9/E9) -> 660.86957 | G9: 15200 | I9: =IF(H9=0,0,J9/H9) -> 0 | L9: =IF(K9=0,0,M9/K9) -> 0 | N9: 217.8 | O9: =IF(N9=0,0,P9/N9) -> 977.95684 | P9: 212999 | Q9: 236.9 | R9: =IF(Q9=0,0,S9/Q9) -> 886.44998 | S9: 210000 | T9: 93.4 | U9: =IF(T9=0,0,V9/T9) -> 1027.8373 | V9: 96000 | X9: =IF(W9=0,0,Y9/W9) -> 0 | Z9: 196.3 | AA9: =IF(Z9=0,0,AB9/Z9) -> 937.3408 | AB9: 184000 | AD9: =IF(AC9=0,0,AE9/AC9) -> 0 | AG9: =IF(AF9=0,0,AH9/AF9) -> 0 | AI9: 6 | AJ9: =IF(AI9=0,0,AK9/AI9) -> 1257.125 | AK9: 7542.75 | AL9: =SUM(B9,E9,H9,K9,N9,Q9,T9,W9,Z9,AC9,AF9,AI9) -> 773.4 | AM9: =IF(AL9=0,0,AN9/AL9) -> 938.37826 | AN9: =SUM(D9,G9,J9,M9,P9,S9,V9,Y9,AB9,AE9,AH9,AK9) -> 725741.75 | AP9: MCF/WMF | AQ9: =ROUND((AQ7*AL5),0) -> 76380956 | AR9: =ROUND((AR7*AL6),0) -> 75242750
A10: NWF/Yarn / Twisted Yarn | B10: 9900 | C10: =IF(B10=0,0,D10/B10) -> 130.79545 | D10: 1294875 | E10: 12025 | F10: =IF(E10=0,0,G10/E10) -> 129.7817 | G10: 1560625 | H10: 8080.9 | I10: =IF(H10=0,0,J10/H10) -> 129.43138 | J10: 1045922 | K10: 8625 | L10: =IF(K10=0,0,M10/K10) -> 128.66667 | M10: 1109750 | N10: 7500 | O10: =IF(N10=0,0,P10/N10) -> 126.33333 | P10: 947500 | Q10: 7750 | R10: =IF(Q10=0,0,S10/Q10) -> 126.93548 | S10: 983750 | T10: 6375 | U10: =IF(T10=0,0,V10/T10) -> 128.13725 | V10: 816875 | W10: 10250 | X10: =IF(W10=0,0,Y10/W10) -> 129.07317 | Y10: 1323000 | Z10: 10291.4 | AA10: =IF(Z10=0,0,AB10/Z10) -> 127.77348 | AB10: 1314968 | AC10: 9500 | AD10: =IF(AC10=0,0,AE10/AC10) -> 127.63158 | AE10: 1212500 | AF10: 9394 | AG10: =IF(AF10=0,0,AH10/AF10) -> 128.41761 | AH10: 1206355 | AI10: 16269.4 | AJ10: =IF(AI10=0,0,AK10/AI10) -> 120.63932 | AK10: 1962729.4 | AL10: =SUM(B10,E10,H10,K10,N10,Q10,T10,W10,Z10,AC10,AF10,AI10) -> 115960.7 | AM10: =IF(AL10=0,0,AN10/AL10) -> 127.44705 | AN10: =SUM(D10,G10,J10,M10,P10,S10,V10,Y10,AB10,AE10,AH10,AK10) -> 14778849 | AQ10: =AQ9+AR9 -> 151623706
B11: =SUM(B5:B10) -> 103620.87 | C11: =IF(B11=0,0,D11/B11) -> 246.14099 | D11: =SUM(D5:D10) -> 25505344 | E11: =SUM(E5:E10) -> 138460.75 | F11: =IF(E11=0,0,G11/E11) -> 253.55801 | G11: =SUM(G5:G10) -> 35107832 | H11: =SUM(H5:H10) -> 122263.84 | I11: =IF(H11=0,0,J11/H11) -> 267.12207 | J11: =SUM(J5:J10) -> 32659370 | K11: =SUM(K5:K10) -> 113619.8 | L11: =IF(K11=0,0,M11/K11) -> 260.8276 | M11: =SUM(M5:M10) -> 29635180 | N11: =SUM(N5:N10) -> 110361.49 | O11: =IF(N11=0,0,P11/N11) -> 257.36651 | P11: =SUM(P5:P10) -> 28403352 | Q11: =SUM(Q5:Q10) -> 96013.76 | R11: =IF(Q11=0,0,S11/Q11) -> 256.80521 | S11: =SUM(S5:S10) -> 24656834 | T11: =SUM(T5:T10) -> 93720.65 | U11: =IF(T11=0,0,V11/T11) -> 253.08651 | V11: =SUM(V5:V10) -> 23719432 | W11: =SUM(W5:W10) -> 129573.21 | X11: =IF(W11=0,0,Y11/W11) -> 244.4714 | Y11: =SUM(Y5:Y10) -> 31676944 | Z11: =SUM(Z5:Z10) -> 87201.19 | AA11: =IF(Z11=0,0,AB11/Z11) -> 243.72713 | AB11: =SUM(AB5:AB10) -> 21253296 | AC11: =SUM(AC5:AC10) -> 119805.5 | AD11: =IF(AC11=0,0,AE11/AC11) -> 251.29827 | AE11: =SUM(AE5:AE10) -> 30106915 | AF11: =SUM(AF5:AF10) -> 128216.87 | AG11: =IF(AF11=0,0,AH11/AF11) -> 255.84824 | AH11: =SUM(AH5:AH10) -> 32804061 | AI11: =SUM(AI5:AI10) -> 164514.16 | AJ11: =IF(AI11=0,0,AK11/AI11) -> 267.48637 | AK11: =SUM(AK5:AK10) -> 44005295 | AL11: =SUM(AL5:AL10) -> 1407372.1 | AM11: =IF(AL11=0,0,AN11/AL11) -> 255.46467 | AN11: =SUM(AN5:AN10) -> 3.5953385e+08 | AP11: Othr MF | AQ11: =SUM(AN7:AN10) -> 16153694 | AR11: ='PAL I'!AN26 -> 160821412
A12: MSN | E12: 1908 | F12: =IF(E12=0,0,G12/E12) -> 263.19706 | G12: 502180 | H12: 580 | I12: =IF(H12=0,0,J12/H12) -> 282.41379 | J12: 163800 | N12: =405+15 -> 420 | O12: =IF(N12=0,0,P12/N12) -> 326.71429 | P12: =126000+11220 -> 137220 | R12: =IF(Q12=0,0,S12/Q12) -> 0 | T12: 653 | U12: =IF(T12=0,0,V12/T12) -> 250.84227 | V12: 163800 | X12: =IF(W12=0,0,Y12/W12) -> 0 | Z12: 205 | AA12: =IF(Z12=0,0,AB12/Z12) -> 266.34146 | AB12: 54600 | AC12: 415 | AD12: =IF(AC12=0,0,AE12/AC12) -> 303.61446 | AE12: 126000 | AF12: 1263 | AG12: =IF(AF12=0,0,AH12/AF12) -> 266.47664 | AH12: 336560 | AI12: 90 | AJ12: =IF(AI12=0,0,AK12/AI12) -> 320 | AK12: 28800 | AL12: =SUM(B12,E12,H12,K12,N12,Q12,T12,W12,Z12,AC12,AF12,AI12) -> 5534 | AM12: =IF(AL12=0,0,AN12/AL12) -> 273.39357 | AN12: =SUM(D12,G12,J12,M12,P12,S12,V12,Y12,AB12,AE12,AH12,AK12) -> 1512960 | AP12: Inc from MF | AQ12: =SUM(AQ10:AQ11) -> 1.677774e+08
A13: TSN | B13: 887.91 | C13: =IF(B13=0,0,D13/B13) -> 227.27754 | D13: 201802 | E13: 195 | F13: =IF(E13=0,0,G13/E13) -> 267.40513 | G13: 52144 | H13: 348 | I13: =IF(H13=0,0,J13/H13) -> 239.56897 | J13: 83370 | K13: 168 | L13: =IF(K13=0,0,M13/K13) -> 261.78571 | M13: 43980 | Q13: 14 | R13: =IF(Q13=0,0,S13/Q13) -> 342.85714 | S13: 4800 | T13: 128 | U13: =IF(T13=0,0,V13/T13) -> 236.25 | V13: 30240 | W13: 117 | X13: =IF(W13=0,0,Y13/W13) -> 226.92308 | Y13: 26550 | Z13: 381 | AA13: =IF(Z13=0,0,AB13/Z13) -> 220.95801 | AB13: 84185 | AC13: 828 | AD13: =IF(AC13=0,0,AE13/AC13) -> 216.30435 | AE13: 179100 | AF13: 55.2 | AG13: =IF(AF13=0,0,AH13/AF13) -> 228.07971 | AH13: 12590 | AI13: 917.5 | AJ13: =IF(AI13=0,0,AK13/AI13) -> 265.65907 | AK13: 243742.2 | AL13: =SUM(B13,E13,H13,K13,N13,Q13,T13,W13,Z13,AC13,AF13,AI13) -> 4039.61 | AM13: =IF(AL13=0,0,AN13/AL13) -> 238.26637 | AN13: =SUM(D13,G13,J13,M13,P13,S13,V13,Y13,AB13,AE13,AH13,AK13) -> 962503.2 | AP13: Trading Inc | AQ13: =ROUND((AN18-'PAL I'!AN6),0) -> 2077971
A14: PP Woven Sacks | B14: 4797.6 | C14: =IF(B14=0,0,D14/B14) -> 166.02885 | D14: 796540 | E14: 5704.65 | F14: =IF(E14=0,0,G14/E14) -> 165.74917 | G14: 945541 | H14: 4826 | I14: =IF(H14=0,0,J14/H14) -> 169.20659 | J14: 816591 | K14: 6780.8 | L14: =IF(K14=0,0,M14/K14) -> 169.49254 | M14: 1149295 | N14: 4998.6 | O14: =IF(N14=0,0,P14/N14) -> 168.75185 | P14: 843523 | Q14: 5020.2 | R14: =IF(Q14=0,0,S14/Q14) -> 163.75264 | S14: =847407-S37 -> 822071 | T14: 5785.2 | U14: =IF(T14=0,0,V14/T14) -> 168.65519 | V14: 975704 | W14: 5688.5 | X14: =IF(W14=0,0,Y14/W14) -> 169.15338 | Y14: 962229 | Z14: 4737.4 | AA14: =IF(Z14=0,0,AB14/Z14) -> 169.27998 | AB14: 801947 | AC14: 2164.2 | AD14: =IF(AC14=0,0,AE14/AC14) -> 165.76287 | AE14: 358744 | AF14: 5103.1 | AG14: =IF(AF14=0,0,AH14/AF14) -> 167.88011 | AH14: =899249-AH37 -> 856709 | AI14: 2928.6 | AJ14: =IF(AI14=0,0,AK14/AI14) -> 168.10216 | AK14: =543352-AK37 -> 492304 | AL14: =SUM(B14,E14,H14,K14,N14,Q14,T14,W14,Z14,AC14,AF14,AI14) -> 58534.85 | AM14: =IF(AL14=0,0,AN14/AL14) -> 167.78377 | AN14: =SUM(D14,G14,J14,M14,P14,S14,V14,Y14,AB14,AE14,AH14,AK14) -> 9821198 | AP14: RM Inco | AQ14: =ROUND((AN25),0) -> 41330800
A15: ANTI BIRD NET / Rope/MULCH/FIBC | B15: 1 | C15: =IF(B15=0,0,D15/B15) -> 720 | D15: 720 | N15: 282 | O15: =IF(N15=0,0,P15/N15) -> 131.17021 | P15: 36990 | Q15: 292 | R15: =IF(Q15=0,0,S15/Q15) -> 144.0137 | S15: 42052 | U15: =IF(T15=0,0,V15/T15) -> 0 | W15: 8994.5 | X15: =IF(W15=0,0,Y15/W15) -> 117.73273 | Y15: 1058947 | Z15: 110 | AA15: =IF(Z15=0,0,AB15/Z15) -> 153.15455 | AB15: 16847 | AD15: =IF(AC15=0,0,AE15/AC15) -> 0 | AG15: =IF(AF15=0,0,AH15/AF15) -> 0 | AJ15: =IF(AI15=0,0,AK15/AI15) -> 0 | AL15: =SUM(B15,E15,H15,K15,N15,Q15,T15,W15,Z15,AC15,AF15,AI15) -> 9679.5 | AM15: =IF(AL15=0,0,AN15/AL15) -> 119.38179 | AN15: =SUM(D15,G15,J15,M15,P15,S15,V15,Y15,AB15,AE15,AH15,AK15) -> 1155556 | AP15: Asset Inc | AQ15: =AN22 -> 270339
A16: Knitted Fabric 8" Red/60" D Green | H16: 51 | I16: =IF(H16=0,0,J16/H16) -> 890.7451 | J16: 45428 | N16: 646.92 | O16: =IF(N16=0,0,P16/N16) -> 215.63717 | P16: 139500 | Q16: 49 | R16: =IF(Q16=0,0,S16/Q16) -> 875.5102 | S16: 42900 | T16: 27 | U16: =IF(T16=0,0,V16/T16) -> 995.2963 | V16: 26873 | X16: =IF(W16=0,0,Y16/W16) -> 0 | Z16: 15 | AA16: =IF(Z16=0,0,AB16/Z16) -> 480.53333 | AB16: 7208 | AC16: 38 | AD16: =IF(AC16=0,0,AE16/AC16) -> 903.15789 | AE16: 34320 | AF16: 157.34 | AG16: =IF(AF16=0,0,AH16/AF16) -> 264.61167 | AH16: 41634 | AJ16: =IF(AI16=0,0,AK16/AI16) -> 0 | AL16: =SUM(B16,E16,H16,K16,N16,Q16,T16,W16,Z16,AC16,AF16,AI16) -> 984.26 | AM16: =IF(AL16=0,0,AN16/AL16) -> 343.26601 | AN16: =SUM(D16,G16,J16,M16,P16,S16,V16,Y16,AB16,AE16,AH16,AK16) -> 337863 | AP16: Waste Inc | AQ16: =AN21+AN20 -> 676652
A17: Weed Mat | B17: 2058.25 | C17: =IF(B17=0,0,D17/B17) -> 183.90866 | D17: 378530 | E17: 870.65 | F17: =IF(E17=0,0,G17/E17) -> 193.84942 | G17: 168775 | H17: 1226 | I17: =IF(H17=0,0,J17/H17) -> 190.6199 | J17: 233700 | K17: 1580 | L17: =IF(K17=0,0,M17/K17) -> 190.63291 | M17: 301200 | N17: 715 | P17: 137160 | Q17: 508 | R17: =IF(Q17=0,0,S17/Q17) -> 189.4685 | S17: 96250 | T17: 856 | U17: =IF(T17=0,0,V17/T17) -> 193.63318 | V17: 165750 | W17: 378 | X17: =IF(W17=0,0,Y17/W17) -> 200.89947 | Y17: 75940 | Z17: 1223 | AA17: =IF(Z17=0,0,AB17/Z17) -> 192.59035 | AB17: 235538 | AC17: 1005 | AD17: =IF(AC17=0,0,AE17/AC17) -> 189.02985 | AE17: 189975 | AF17: 250 | AG17: =IF(AF17=0,0,AH17/AF17) -> 190 | AH17: 47500 | AI17: 2040 | AJ17: =IF(AI17=0,0,AK17/AI17) -> 236.47059 | AK17: 482400 | AL17: =SUM(B17,E17,H17,K17,N17,Q17,T17,W17,Z17,AC17,AF17,AI17) -> 12709.9 | AM17: =IF(AL17=0,0,AN17/AL17) -> 197.6977 | AN17: =SUM(D17,G17,J17,M17,P17,S17,V17,Y17,AB17,AE17,AH17,AK17) -> 2512718 | AP17: Other Inc | AQ17: ='PAL I'!AN17 -> 148503
B18: =SUM(B12:B17) -> 7744.76 | C18: =IF(B18=0,0,D18/B18) -> 177.87407 | D18: =SUM(D12:D17) -> 1377592 | E18: =SUM(E12:E17) -> 8678.3 | F18: =IF(E18=0,0,G18/E18) -> 192.27729 | G18: =SUM(G12:G17) -> 1668640 | H18: =SUM(H12:H17) -> 7031 | I18: =IF(H18=0,0,J18/H18) -> 190.99545 | J18: =SUM(J12:J17) -> 1342889 | K18: =SUM(K12:K17) -> 8528.8 | L18: =IF(K18=0,0,M18/K18) -> 175.22688 | M18: =SUM(M12:M17) -> 1494475 | N18: =SUM(N12:N17) -> 7062.52 | O18: =IF(N18=0,0,P18/N18) -> 183.27637 | P18: =SUM(P12:P17) -> 1294393 | Q18: =SUM(Q12:Q17) -> 5883.2 | R18: =IF(Q18=0,0,S18/Q18) -> 171.34774 | S18: =SUM(S12:S17) -> 1008073 | T18: =SUM(T12:T17) -> 7449.2 | U18: =IF(T18=0,0,V18/T18) -> 182.88769 | V18: =SUM(V12:V17) -> 1362367 | W18: =SUM(W12:W17) -> 15178 | X18: =IF(W18=0,0,Y18/W18) -> 139.91738 | Y18: =SUM(Y12:Y17) -> 2123666 | Z18: =SUM(Z12:Z17) -> 6671.4 | AA18: =IF(Z18=0,0,AB18/Z18) -> 179.92101 | AB18: =SUM(AB12:AB17) -> 1200325 | AC18: =SUM(AC12:AC17) -> 4450.2 | AD18: =IF(AC18=0,0,AE18/AC18) -> 199.57283 | AE18: =SUM(AE12:AE17) -> 888139 | AF18: =SUM(AF12:AF17) -> 6828.64 | AG18: =IF(AF18=0,0,AH18/AF18) -> 189.64142 | AH18: =SUM(AH12:AH17) -> 1294993 | AI18: =SUM(AI12:AI17) -> 5976.1 | AJ18: =IF(AI18=0,0,AK18/AI18) -> 208.70571 | AK18: =SUM(AK12:AK17) -> 1247246.2 | AL18: =SUM(AL12:AL17) -> 91482.12 | AM18: =IF(AL18=0,0,AN18/AL18) -> 178.20748 | AN18: =SUM(AN12:AN17) -> 16302798 | AO18: =AL11+AL18 -> 1498854.2 | AQ18: =SUM(AQ10:AQ17) -> 3.8005907e+08 | AR18: =SUM(AR11:AR17) -> 160821412
A19: Flexible Intermediate Bulk Container | F19: =IF(E19=0,0,G19/E19) -> 0 | R19: =IF(Q19=0,0,S19/Q19) -> 0 | AA19: =IF(Z19=0,0,AB19/Z19) -> 0 | AD19: =IF(AC19=0,0,AE19/AC19) -> 0 | AG19: =IF(AF19=0,0,AH19/AF19) -> 0 | AJ19: =IF(AI19=0,0,AK19/AI19) -> 0 | AL19: =SUM(B19,E19,H19,K19,N19,Q19,T19,W19,Z19,AC19,AF19,AI19) -> 0 | AM19: =IF(AL19=0,0,AN19/AL19) -> 0 | AN19: =SUM(D19,G19,J19,M19,P19,S19,V19,Y19,AB19,AE19,AH19,AK19) -> 0 | AR19: =AQ18-AR18 -> 2.1923765e+08
A20: Packing Materials / Old use Batteries | F20: =IF(E20=0,0,G20/E20) -> 0 | R20: =IF(Q20=0,0,S20/Q20) -> 0 | U20: =IF(T20=0,0,V20/T20) -> 0 | AA20: =IF(Z20=0,0,AB20/Z20) -> 0 | AL20: =SUM(B20,E20,H20,K20,N20,Q20,T20,W20,Z20,AC20,AF20,AI20) -> 0 | AM20: =IF(AL20=0,0,AN20/AL20) -> 0 | AN20: =SUM(D20,G20,J20,M20,P20,S20,V20,Y20,AB20,AE20,AH20,AK20) -> 0
A21: HDPE Monofilament Waste | B21: 2110 | C21: =IF(B21=0,0,D21/B21) -> 10 | D21: 21100 | E21: 7739 | F21: =IF(E21=0,0,G21/E21) -> 10 | G21: 77390 | H21: 5654 | I21: =IF(H21=0,0,J21/H21) -> 10 | J21: 56540 | K21: 5340.5 | L21: =IF(K21=0,0,M21/K21) -> 10 | M21: 53405 | N21: 5389 | O21: =IF(N21=0,0,P21/N21) -> 10 | P21: 53890 | Q21: 7178 | R21: =IF(Q21=0,0,S21/Q21) -> 10 | S21: 71780 | T21: 3584 | U21: =IF(T21=0,0,V21/T21) -> 10 | V21: 35840 | W21: 5507 | X21: =IF(W21=0,0,Y21/W21) -> 10 | Y21: 55070 | Z21: 6958 | AA21: =IF(Z21=0,0,AB21/Z21) -> 10 | AB21: 69580 | AC21: 4497 | AD21: =IF(AC21=0,0,AE21/AC21) -> 10 | AE21: 44970 | AF21: 7534.5 | AG21: =IF(AF21=0,0,AH21/AF21) -> 10 | AH21: 75345 | AI21: 5864.6 | AJ21: =IF(AI21=0,0,AK21/AI21) -> 10.527913 | AK21: 61742 | AL21: =SUM(B21,E21,H21,K21,N21,Q21,T21,W21,Z21,AC21,AF21,AI21) -> 67355.6 | AM21: =IF(AL21=0,0,AN21/AL21) -> 10.045965 | AN21: =SUM(D21,G21,J21,M21,P21,S21,V21,Y21,AB21,AE21,AH21,AK21) -> 676652
A22: Sale of Asset Etc | P22: 270339 | R22: =IF(Q22=0,0,S22/Q22) -> 0 | U22: =IF(T22=0,0,V22/T22) -> 0 | X22: =IF(W22=0,0,Y22/W22) -> 0 | AA22: =IF(Z22=0,0,AB22/Z22) -> 0 | AL22: =SUM(B22,E22,H22,K22,N22,Q22,T22,W22,Z22,AC22,AF22,AI22) -> 0 | AM22: =IF(AL22=0,0,AN22/AL22) -> 0 | AN22: =SUM(D22,G22,J22,M22,P22,S22,V22,Y22,AB22,AE22,AH22,AK22) -> 270339
A23: Colour Pigment | B23: 10 | C23: =IF(B23=0,0,D23/B23) -> 1000 | D23: 10000 | K23: 2 | L23: =IF(K23=0,0,M23/K23) -> 2200 | M23: 4400 | N23: 4 | O23: =IF(N23=0,0,P23/N23) -> 1000 | P23: 4000 | R23: =IF(Q23=0,0,S23/Q23) -> 0 | U23: =IF(T23=0,0,V23/T23) -> 0 | X23: =IF(W23=0,0,Y23/W23) -> 0 | AA23: =IF(Z23=0,0,AB23/Z23) -> 0 | AL23: =SUM(B23,E23,H23,K23,N23,Q23,T23,W23,Z23,AC23,AF23,AI23) -> 16 | AM23: =IF(AL23=0,0,AN23/AL23) -> 1150 | AN23: =SUM(D23,G23,J23,M23,P23,S23,V23,Y23,AB23,AE23,AH23,AK23) -> 18400
A24: Master Batch | B24: 211 | C24: =IF(B24=0,0,D24/B24) -> 310.45024 | D24: 65505 | E24: 25 | F24: =IF(E24=0,0,G24/E24) -> 200 | G24: 5000 | H24: 228 | I24: =IF(H24=0,0,J24/H24) -> 298.20175 | J24: 67990 | K24: 227 | L24: =IF(K24=0,0,M24/K24) -> 304.6696 | M24: 69160 | N24: 367 | O24: =IF(N24=0,0,P24/N24) -> 305.20436 | P24: 112010 | Q24: 229 | R24: =IF(Q24=0,0,S24/Q24) -> 302.48908 | S24: 69270 | T24: 221 | U24: =IF(T24=0,0,V24/T24) -> 309.86425 | V24: 68480 | W24: 285 | X24: =IF(W24=0,0,Y24/W24) -> 286.14035 | Y24: 81550 | Z24: 175 | AA24: =IF(Z24=0,0,AB24/Z24) -> 274.28571 | AB24: 48000 | AC24: 215 | AD24: =IF(AC24=0,0,AE24/AC24) -> 310.69767 | AE24: 66800 | AF24: 237 | AG24: =IF(AF24=0,0,AH24/AF24) -> 329.36709 | AH24: 78060 | AI24: 90 | AJ24: =IF(AI24=0,0,AK24/AI24) -> 324.88889 | AK24: 29240 | AL24: =SUM(B24,E24,H24,K24,N24,Q24,T24,W24,Z24,AC24,AF24,AI24) -> 2510 | AM24: =IF(AL24=0,0,AN24/AL24) -> 303.21315 | AN24: =SUM(D24,G24,J24,M24,P24,S24,V24,Y24,AB24,AE24,AH24,AK24) -> 761065
A25: HDPE | B25: 40000 | C25: =IF(B25=0,0,D25/B25) -> 99.7 | D25: 3988000 | E25: 14000 | F25: =IF(E25=0,0,G25/E25) -> 95 | G25: 1330000 | H25: 51000 | I25: =IF(H25=0,0,J25/H25) -> 94.784314 | J25: 4834000 | K25: 55000 | L25: =IF(K25=0,0,M25/K25) -> 98.614545 | M25: 5423800 | N25: 58000 | O25: =IF(N25=0,0,P25/N25) -> 99.12069 | P25: 5749000 | Q25: 31000 | R25: =IF(Q25=0,0,S25/Q25) -> 97.580645 | S25: 3025000 | T25: 24000 | U25: =IF(T25=0,0,V25/T25) -> 95.791667 | V25: 2299000 | W25: 15000 | X25: =IF(W25=0,0,Y25/W25) -> 96.666667 | Y25: 1450000 | Z25: 31000 | AA25: =IF(Z25=0,0,AB25/Z25) -> 92 | AB25: 2852000 | AC25: 38000 | AD25: =IF(AC25=0,0,AE25/AC25) -> 96.605263 | AE25: 3671000 | AF25: 37000 | AG25: =IF(AF25=0,0,AH25/AF25) -> 100.83784 | AH25: 3731000 | AI25: 25000 | AJ25: =IF(AI25=0,0,AK25/AI25) -> 119.12 | AK25: 2978000 | AL25: =SUM(B25,E25,H25,K25,N25,Q25,T25,W25,Z25,AC25,AF25,AI25) -> 419000 | AM25: =IF(AL25=0,0,AN25/AL25) -> 98.641527 | AN25: =SUM(D25,G25,J25,M25,P25,S25,V25,Y25,AB25,AE25,AH25,AK25) -> 41330800 | AO25: =AO18+AL25 -> 1917854.2
B26: =SUM(B19:B25) -> 42331 | C26: =IF(B26=0,0,D26/B26) -> 96.492051 | D26: =SUM(D19:D25) -> 4084605 | E26: =SUM(E19:E25) -> 21764 | F26: =IF(E26=0,0,G26/E26) -> 64.895699 | G26: =SUM(G19:G25) -> 1412390 | H26: =SUM(H19:H25) -> 56882 | I26: =IF(H26=0,0,J26/H26) -> 87.172216 | J26: =SUM(J19:J25) -> 4958530 | K26: =SUM(K19:K25) -> 60569.5 | L26: =IF(K26=0,0,M26/K26) -> 91.642906 | M26: =SUM(M19:M25) -> 5550765 | N26: =SUM(N19:N25) -> 63760 | O26: =IF(N26=0,0,P26/N26) -> 97.070875 | P26: =SUM(P19:P25) -> 6189239 | Q26: =SUM(Q19:Q25) -> 38407 | R26: =IF(Q26=0,0,S26/Q26) -> 82.434192 | S26: =SUM(S19:S25) -> 3166050 | T26: =SUM(T19:T25) -> 27805 | U26: =IF(T26=0,0,V26/T26) -> 86.434814 | V26: =SUM(V19:V25) -> 2403320 | W26: =SUM(W19:W25) -> 20792 | X26: =IF(W26=0,0,Y26/W26) -> 76.309157 | Y26: =SUM(Y19:Y25) -> 1586620 | Z26: =SUM(Z19:Z25) -> 38133 | AA26: =IF(Z26=0,0,AB26/Z26) -> 77.874282 | AB26: =SUM(AB19:AB25) -> 2969580 | AC26: =SUM(AC19:AC25) -> 42712 | AD26: =IF(AC26=0,0,AE26/AC26) -> 88.564572 | AE26: =SUM(AE19:AE25) -> 3782770 | AF26: =SUM(AF19:AF25) -> 44771.5 | AG26: =IF(AF26=0,0,AH26/AF26) -> 86.760662 | AH26: =SUM(AH19:AH25) -> 3884405 | AI26: =SUM(AI19:AI25) -> 30954.6 | AJ26: =IF(AI26=0,0,AK26/AI26) -> 99.144618 | AK26: =SUM(AK19:AK25) -> 3068982 | AL26: =SUM(AL19:AL25) -> 488881.6 | AM26: =IF(AL26=0,0,AN26/AL26) -> 88.072973 | AN26: =SUM(AN19:AN25) -> 43057256
A27: Grand total: | B27: =SUM(B11,B18,B26) -> 153696.63 | C27: =IF(B27=0,0,D27/B27) -> 201.48484 | D27: =SUM(D11,D18,D26) -> 30967540 | E27: =SUM(E11,E18,E26) -> 168903.05 | F27: =IF(E27=0,0,G27/E27) -> 226.0993 | G27: =SUM(G11,G18,G26) -> 38188862 | H27: =SUM(H11,H18,H26) -> 186176.84 | I27: =IF(H27=0,0,J27/H27) -> 209.26764 | J27: =SUM(J11,J18,J26) -> 38960788 | K27: =SUM(K11,K18,K26) -> 182718.1 | L27: =IF(K27=0,0,M27/K27) -> 200.74869 | M27: =SUM(M11,M18,M26) -> 36680420 | N27: =SUM(N11,N18,N26) -> 181184.01 | O27: =IF(N27=0,0,P27/N27) -> 198.06926 | P27: =SUM(P11,P18,P26) -> 35886984 | Q27: =SUM(Q11,Q18,Q26) -> 140303.96 | R27: =IF(Q27=0,0,S27/Q27) -> 205.48926 | S27: =SUM(S11,S18,S26) -> 28830957 | T27: =SUM(T11,T18,T26) -> 128974.85 | U27: =IF(T27=0,0,V27/T27) -> 213.10449 | V27: =SUM(V11,V18,V26) -> 27485119 | W27: =SUM(W11,W18,W26) -> 165543.21 | X27: =IF(W27=0,0,Y27/W27) -> 213.76431 | Y27: =SUM(Y11,Y18,Y26) -> 35387230 | Z27: =SUM(Z11,Z18,Z26) -> 132005.59 | AA27: =IF(Z27=0,0,AB27/Z27) -> 192.59185 | AB27: =SUM(AB11,AB18,AB26) -> 25423200 | AC27: =SUM(AC11,AC18,AC26) -> 166967.7 | AD27: =IF(AC27=0,0,AE27/AC27) -> 208.29073 | AE27: =SUM(AE11,AE18,AE26) -> 34777824 | AF27: =SUM(AF11,AF18,AF26) -> 179817.01 | AG27: =IF(AF27=0,0,AH27/AF27) -> 211.23396 | AH27: =SUM(AH11,AH18,AH26) -> 37983459 | AI27: =SUM(AI11,AI18,AI26) -> 201444.86 | AJ27: =IF(AI27=0,0,AK27/AI27) -> 239.87469 | AK27: =SUM(AK11,AK18,AK26) -> 48321523 | AL27: =SUM(AL11,AL18,AL26) -> 1987735.8 | AM27: =IF(AL27=0,0,AN27/AL27) -> 210.73923 | AN27: =SUM(AN11,AN18,AN26) -> 4.1889391e+08 | AO27: =AN27-AN21 -> 4.1821725e+08
A28: Other Income | D28: 17.85 | G28: 798.67 | J28: 41 | M28: 4.49 | P28: 51.29 | S28: 0.26 | V28: 90.25 | Y28: 4.57 | AB28: 37847.24 | AE28: 0.5 | AH28: 50448.9 | AK28: 59197.67 | AN28: =SUM(D28,G28,J28,M28,P28,S28,V28,Y28,AB28,AE28,AH28,AK28) -> 148502.69
D29: =ROUND((D27-D21),0) -> 30946441 | G29: =ROUND((G27-G21),0) -> 38111472 | J29: =ROUND((J27-J21),0) -> 38904249 | M29: =ROUND((M27-M21),0) -> 36627015 | P29: =ROUND((P27-P21),0) -> 35833094 | S29: =ROUND((S27-S21),0) -> 28759177 | V29: =ROUND((V27-V21),0) -> 27449279 | Y29: =ROUND((Y27-Y21),0) -> 35332160 | AB29: =ROUND((AB27-AB21),0) -> 25353621 | AE29: =ROUND((AE27-AE21),0) -> 34732854 | AH29: =ROUND((AH27-AH21),0) -> 37908114 | AK29: =ROUND((AK27-AK21),0) -> 48259781 | AL29: =AL11+AL18 -> 1498854.2 | AM29: =AN29/AL29 -> 250.7493 | AN29: =AN11+AN18 -> 3.7583665e+08 | AP29: Sales extract value | AQ29: Sales extract kgs
A30: Gross sales | D30: 33048761 | G30: 40365923 | J30: 41624497 | M30: 39437879 | P30: 38487670 | S30: 30634990 | V30: 29269753 | Y30: 37272442 | AB30: 26988536 | AE30: 36691119 | AH30: 40235065 | AK30: 49127787 | AN30: =SUM(D30,G30,J30,M30,P30,S30,V30,Y30,AB30,AE30,AH30,AK30) -> 4.4318442e+08 | AP30: 2.0954089e+08 | AQ30: 1012982.9
A31: tax | D31: 2263250.1 | G31: 2243080.5 | J31: 2763631.2 | M31: 2770897.1 | P31: 2617607 | S31: 1897146.9 | V31: 1807715.8 | Y31: 1897513.5 | AB31: 1745590.6 | AE31: 2045320.7 | AH31: 2406110.5 | AK31: 2779015.6 | AN31: =SUM(D31,G31,J31,M31,P31,S31,V31,Y31,AB31,AE31,AH31,AK31) -> 27236879 | AP31: =AN27-AP30 -> 2.0935302e+08 | AQ31: =AL27-AQ30 -> 974752.92
A32: TCS | D32: 0 | AN32: =SUM(D32,G32,J32,M32,P32,S32,V32,Y32,AB32,AE32,AH32,AK32) -> 0
D33: =D31+D32 -> 2263250.1 | G33: =G31+G32 -> 2243080.5 | J33: =J31+J32 -> 2763631.2 | M33: =M31+M32 -> 2770897.1 | P33: =P31+P32 -> 2617607 | S33: =S31+S32 -> 1897146.9 | V33: =V31+V32 -> 1807715.8 | Y33: =Y31+Y32 -> 1897513.5 | AB33: =AB31+AB32 -> 1745590.6 | AE33: =AE31+AE32 -> 2045320.7 | AH33: =AH31+AH32 -> 2406110.5 | AK33: =AK31+AK32 -> 2779015.6 | AN33: =SUM(AN31:AN32) -> 27236879 | AQ33: P/L sales
D34: =D30-D33 -> 30785511 | G34: =G30-G33 -> 38122842 | J34: =J30-J33 -> 38860866 | M34: =M30-M33 -> 36666982 | P34: =P30-P33 -> 35870064 | S34: =S30-S33 -> 28737843 | V34: =V30-V33 -> 27462037 | Y34: =Y30-Y33 -> 35374929 | AB34: =AB30-AB33 -> 25242946 | AE34: =AE30-AE33 -> 34645798 | AH34: =AH30-AH33 -> 37828954 | AK34: =AK30-AK33 -> 46348771 | AN34: =AN30-AN33 -> 4.1594754e+08 | AQ34: 2.0874843e+08 | AR34: =AQ34-AN34 -> -2.0719911e+08
A35: Discount | D35: 182030 | G35: 66020 | J35: 99922 | M35: 13438 | P35: 16920 | S35: 118450 | V35: 23083.2 | Y35: 12300 | AB35: 180255 | AE35: 132026 | AH35: 197045 | AK35: =2023800+2 -> 2023802 | AN35: =SUM(D35,G35,J35,M35,P35,S35,V35,Y35,AB35,AE35,AH35,AK35) -> 3065291.2 | AR35: =AP30-AQ34 -> 792455 | AS35: OLD USED EICHER 10.90H. MGV VEHICLE NO.KA02AA6749
D36: =D34+D35-D37 -> 30967541 | G36: =G34+G35-G37 -> 38188862 | J36: =J34+J35 -> 38960788 | M36: =M34+M35-M37 -> 36680420 | P36: =P34+P35 -> 35886984 | S36: =S34+S35 -> 28856293 | V36: =V34+V35 -> 27485120 | Y36: =Y34+Y35 -> 35387229 | AB36: =AB34+AB35 -> 25423200 | AE36: =AE34+AE35 -> 34777824 | AH36: =AH34+AH35 -> 38026000 | AK36: =AK34+AK35-AK37 -> 48321525 | AN36: =AN34+AN35 -> 4.1901283e+08 | AO36: =AN27-AN36 -> -118927.03 | AR36: =AN35 -> 3065291.2 | AS36: Discount
A37: Credit Note | P37: 270339 | S37: 25336 | Y37: =Y36-Y27 -> -0.5 | AB37: =AB36-AB27 -> 0 | AH37: 42540 | AK37: 51048 | AN37: =SUM(D37,G37,J37,M37,P37,S37,V37,Y37,AB37,AE37,AH37,AK37) -> 389262.5
D38: =D27-D36 -> -0.18 | G38: =G27-G36 -> -0.2 | J38: =J27-J36 -> 1 | M38: =M27-M36 -> 0 | P38: =P27-P36 -> 0 | Y38: =Y27-Y36 -> 0.5 | AB38: =AB27-AB36 -> 0 | AR38: =AR35-AR36 -> -2272836.2
A39: PAL I- FINAL SALES +Less Waste & Discount | D39: =ROUND((D27-(D21+D22+D35)),0) -> 30764411 | G39: =ROUND((G27-(G21+G35)),0) -> 38045452 | J39: =ROUND((J27-(J21+J22+J35)),0) -> 38804327 | M39: =ROUND((M27-(M21+M22+M35)),0) -> 36613577 | P39: =ROUND((P27-(P21+P22+P35)),0) -> 35545835 | S39: =ROUND((S27-(S21+S22+S35)),0) -> 28640727 | V39: =ROUND((V27-(V21+V22+V35)),0) -> 27426196 | Y39: =ROUND((Y27-(Y21+Y22+Y35)),0) -> 35319860 | AB39: =ROUND((AB27-(AB21+AB22+AB35)),0) -> 25173366 | AE39: =ROUND((AE27-(AE21+AE22+AE35)),0) -> 34600828 | AH39: =ROUND((AH27-(AH21+AH22+AH35)),0) -> 37711069 | AK39: =ROUND((AK27-(AK21+AK22+AK35)),0) -> 46235979 | AN39: =ROUND((AN27-(AN21+AN22+AN35)),0) -> 414881624 | AR39: =AP31+AR38 -> 2.0708018e+08
AN40: =ROUND((AN39-(AN5+AN6)),0) -> 71501466
AN41: =AN36-AN27 -> 118927.03
A42: RM Purchase for sales | B42: =B25+B23+B24 -> 40221 | C42: 95.23 | D42: =ROUND((B25*C42),0) -> 3809200 | E42: =E25+E23+E24 -> 14025 | F42: 99.13 | G42: =ROUND((E25*F42),0) -> 1387820 | H42: =H25+H23+H24 -> 51228 | I42: 93.5 | J42: =ROUND((H25*I42),0) -> 4768500 | K42: =K25+K23+K24 -> 55229 | L42: 94.68 | M42: =ROUND((K25*L42),0) -> 5207400 | N42: =N25+N23+N24 -> 58371 | O42: 95.54 | P42: =ROUND((N25*O42),0) -> 5541320 | Q42: =Q25+Q23+Q24 -> 31229 | R42: 96.7 | S42: =ROUND((Q25*R42),0) -> 2997700 | T42: =T25+T23+T24 -> 24221 | U42: 98.89 | V42: =ROUND((T25*U42),0) -> 2373360 | W42: =W25+W23+W24 -> 15285 | X42: 93.12 | Y42: =ROUND((W25*X42),0) -> 1396800 | Z42: =Z25+Z24+Z23 -> 31175 | AA42: 94.15 | AB42: =ROUND((Z25*AA42),0) -> 2918650 | AC42: =AC25+AC23+AC24 -> 38215 | AD42: 95.39 | AE42: =ROUND((AC25*AD42),0) -> 3624820 | AF42: =AF25+AF23+AF24 -> 37237 | AG42: 96.32 | AH42: =ROUND((AF25*AG42),0) -> 3563840 | AI42: =AI25+AI23+AI24 -> 25090 | AJ42: 104 | AK42: =ROUND((AI25*AJ42),0) -> 2600000 | AL42: =SUM(B42,E42,H42,K42,N42,Q42,T42,W42,Z42,AC42,AF42,AI42) -> 421526 | AM42: =AN42/AL42 -> 95.34266 | AN42: =SUM(D42,G42,J42,M42,P42,S42,V42,Y42,AB42,AE42,AH42,AK42) -> 40189410
...

Sheet Stock Valuation (FIFO)
B2: Opening Stock 01 Apr 25 | E2: 45748 | H2: 45778 | K2: 45809 | N2: 45839 | Q2: 45870 | T2: 45901 | W2: 45931 | Z2: 45962 | AC2: 45992 | AF2: 46023 | AI2: 46054 | AL2: 46082 | AO2: Bank Stock Statement Dec'25
A3: RAW MATERIALS: | B3: QTY IN KGS. | C3: BASIC RATE | D3: BASIC VALUE | E3: QTY IN KGS. | F3: BASIC RATE | G3: BASIC VALUE | H3: QTY IN KGS. | I3: BASIC RATE | J3: BASIC VALUE | K3: QTY IN KGS. | L3: BASIC RATE | M3: BASIC VALUE | N3: QTY IN KGS. | O3: BASIC RATE | P3: BASIC VALUE | Q3: QTY IN KGS. | R3: BASIC RATE | S3: BASIC VALUE | T3: QTY IN KGS. | U3: BASIC RATE | V3: BASIC VALUE | W3: QTY IN KGS. | X3: BASIC RATE | Y3: BASIC VALUE | Z3: QTY IN KGS. | AA3: BASIC RATE | AB3: BASIC VALUE | AC3: QTY IN KGS. | AD3: BASIC RATE | AE3: BASIC VALUE | AF3: QTY IN KGS. | AG3: BASIC RATE | AH3: BASIC VALUE | AI3: QTY IN KGS. | AJ3: BASIC RATE | AK3: BASIC VALUE | AL3: QTY IN KGS. | AM3: BASIC RATE | AN3: BASIC VALUE | AO3: QTY IN KGS. | AP3: BASIC RATE | AQ3: BASIC VALUE | AR3: QTY IN KGS. | AS3: BASIC RATE | AT3: BASIC VALUE | AU3: QTY IN KGS. | AV3: BASIC RATE | AW3: BASIC VALUE
AX4: Incr/(Decr)Stk | BA4: Stk frm Tarka as om 01 Apr(Srp) | BE4: Physical
A5: HDPE Granules | B5: 195845 | C5: =D5/B5 -> 100.68931 | D5: 19719497 | E5: 180315 | F5: =ROUND(IF(G5=0,0,(G5/E5)),0) -> 100 | G5: 17959508 | H5: 147410 | I5: =IF(J5=0,0,(J5/H5)) -> 97.488915 | J5: 14370841 | K5: 164125 | L5: =IF(M5=0,0,(M5/K5)) -> 97.338395 | M5: 15975664 | N5: 146140 | O5: =IF(P5=0,0,(P5/N5)) -> 99.437929 | P5: 14531859 | Q5: 187620 | R5: =IF(S5=0,0,(S5/Q5)) -> 101.20382 | S5: 18987861 | T5: 114680 | U5: =IF(V5=0,0,(V5/T5)) -> 100.40339 | V5: 11514261 | W5: 139725 | X5: =IF(Y5=0,0,(Y5/W5)) -> 98.732253 | Y5: 13795364 | Z5: 164310 | AA5: =IF(AB5=0,0,(AB5/Z5)) -> 97.311454 | AB5: 15989245 | AC5: 135475 | AD5: =IF(AE5=0,0,(AE5/AC5)) -> 96.066846 | AE5: 13014656 | AF5: 174670 | AG5: =IF(AH5=0,0,(AH5/AF5)) -> 98.956106 | AH5: 17284663 | AI5: 154290 | AJ5: =IF(AK5=0,0,(AK5/AI5)) -> 103.4773 | AK5: 15965513 | AL5: 141140 | AM5: =IF(AN5=0,0,(AN5/AL5)) -> 121.97507 | AN5: 17215561 | AO5: 141140 | AP5: =IF(AQ5=0,0,(AQ5/AO5)) -> 121.97507 | AQ5: 17215561 | AR5: =' Qty Analysis'!BE15 -> 0 | AT5: =ROUND((AS5*AR5),0) -> 0 | AU5: =' Qty Analysis'!BH15 -> 0 | AW5: =ROUND((AV5*AU5),0) -> 0 | AX5: =Z5-B5 -> -31535 | AY5: =AX5/B5 -> -0.16102019 | BA5: =125000+40000 -> 165000 | BB5: 101 | BC5: =ROUND((BA5*BB5),0) -> 16665000 | BE5: 163575
A6: Master Batches | B6: 1664 | C6: =D6/B6 -> 223.625 | D6: 372112 | E6: 2120 | F6: =ROUND(IF(G6=0,0,(G6/E6)),0) -> 227 | G6: 481968 | H6: 2294 | I6: =IF(J6=0,0,(J6/H6)) -> 249.52964 | J6: 572421 | K6: 2613 | L6: =IF(M6=0,0,(M6/K6)) -> 236.99732 | M6: 619274 | N6: 2769 | O6: =IF(P6=0,0,(P6/N6)) -> 264.36114 | P6: 732016 | Q6: 3082 | R6: =IF(S6=0,0,(S6/Q6)) -> 263.87897 | S6: 813275 | T6: 2819 | U6: =IF(V6=0,0,(V6/T6)) -> 256.02838 | V6: 721744 | W6: 2895 | X6: =IF(Y6=0,0,(Y6/W6)) -> 236.59896 | Y6: 684954 | Z6: 2396 | AA6: =IF(AB6=0,0,(AB6/Z6)) -> 227.95659 | AB6: 546184 | AC6: 2395 | AD6: =IF(AE6=0,0,(AE6/AC6)) -> 237.1666 | AE6: 568014 | AF6: 2511 | AG6: =IF(AH6=0,0,(AH6/AF6)) -> 241.37634 | AH6: 606096 | AI6: 3260 | AJ6: =IF(AK6=0,0,(AK6/AI6)) -> 233.5911 | AK6: 761507 | AL6: 2330 | AM6: =IF(AN6=0,0,(AN6/AL6)) -> 226.92532 | AN6: 528736 | AO6: 2330 | AP6: =IF(AQ6=0,0,(AQ6/AO6)) -> 226.92532 | AQ6: 528736 | AR6: =' Qty Analysis'!BE27 -> 0 | AT6: =ROUND((AS6*AR6),0) -> 0 | AU6: =' Qty Analysis'!BH27 -> 0 | AW6: =ROUND((AV6*AU6),0) -> 0 | AX6: =Z6-B6 -> 732 | AY6: =AX6/B6 -> 0.43990385 | BA6: 2730 | BB6: 215 | BC6: =ROUND((BA6*BB6),0) -> 586950 | BE6: 2645
A7: Colour Pigments | B7: 32 | C7: =D7/B7 -> 996.90625 | D7: 31901 | E7: 28 | F7: =ROUND(IF(G7=0,0,(G7/E7)),0) -> 1529 | G7: 42808 | H7: 37 | I7: =IF(J7=0,0,(J7/H7)) -> 1769.8919 | J7: 65486 | K7: 40 | L7: =IF(M7=0,0,(M7/K7)) -> 1466.775 | M7: 58671 | N7: 38 | O7: =IF(P7=0,0,(P7/N7)) -> 1621.3158 | P7: 61610 | Q7: 26 | R7: =IF(S7=0,0,(S7/Q7)) -> 1642.8846 | S7: 42715 | T7: 16 | U7: =IF(V7=0,0,(V7/T7)) -> 1711.25 | V7: 27380 | W7: 41 | X7: =IF(Y7=0,0,(Y7/W7)) -> 1775.9024 | Y7: 72812 | Z7: 46 | AA7: =IF(AB7=0,0,(AB7/Z7)) -> 1659.0435 | AB7: 76316 | AC7: 40 | AD7: =IF(AE7=0,0,(AE7/AC7)) -> 1629.45 | AE7: 65178 | AF7: 40 | AG7: =IF(AH7=0,0,(AH7/AF7)) -> 1629.45 | AH7: 65178 | AI7: 38 | AJ7: =IF(AK7=0,0,(AK7/AI7)) -> 1606.7368 | AK7: 61056 | AL7: 19 | AM7: =IF(AN7=0,0,(AN7/AL7)) -> 1597.3684 | AN7: 30350 | AO7: 19 | AP7: =IF(AQ7=0,0,(AQ7/AO7)) -> 1597.3684 | AQ7: 30350 | AR7: =' Qty Analysis'!BE39 -> 0 | AT7: =ROUND((AS7*AR7),0) -> 0 | AU7: =' Qty Analysis'!BH39 -> 0 | AW7: =ROUND((AV7*AU7),0) -> 0 | AX7: =Z7-B7 -> 14 | AY7: =AX7/B7 -> 0.4375 | BA7: 30 | BB7: 2280 | BC7: =ROUND((BA7*BB7),0) -> 68400 | BE7: 45.3
A8: Total | B8: =SUM(B5:B7) -> 197541 | C8: =D8/B8 -> 101.87004 | D8: =SUM(D5:D7) -> 20123510 | E8: =SUM(E5:E7) -> 182463 | F8: =IF(G8=0,0,(G8/E8)) -> 101.30429 | G8: =SUM(G5:G7) -> 18484284 | H8: =SUM(H5:H7) -> 149741 | I8: =IF(J8=0,0,(J8/H8)) -> 100.23139 | J8: =SUM(J5:J7) -> 15008748 | K8: =SUM(K5:K7) -> 166778 | L8: =IF(M8=0,0,(M8/K8)) -> 99.854951 | M8: =SUM(M5:M7) -> 16653609 | N8: =SUM(N5:N7) -> 148947 | O8: =IF(P8=0,0,(P8/N8)) -> 102.8922 | P8: =SUM(P5:P7) -> 15325485 | Q8: =SUM(Q5:Q7) -> 190728 | R8: =IF(S8=0,0,(S8/Q8)) -> 104.04267 | S8: =ROUND(SUM(S5:S7),0) -> 19843851 | T8: =SUM(T5:T7) -> 117515 | U8: =IF(V8=0,0,(V8/T8)) -> 104.35591 | V8: =SUM(V5:V7) -> 12263385 | W8: =SUM(W5:W7) -> 142661 | X8: =IF(Y8=0,0,(Y8/W8)) -> 102.01197 | Y8: =SUM(Y5:Y7) -> 14553130 | Z8: =SUM(Z5:Z7) -> 166752 | AA8: =IF(AB8=0,0,(AB8/Z8)) -> 99.619465 | AB8: =SUM(AB5:AB7) -> 16611745 | AC8: =SUM(AC5:AC7) -> 137910 | AD8: =IF(AE8=0,0,(AE8/AC8)) -> 98.96199 | AE8: =SUM(AE5:AE7) -> 13647848 | AF8: =SUM(AF5:AF7) -> 177221 | AG8: =IF(AH8=0,0,(AH8/AF8)) -> 101.31947 | AH8: =SUM(AH5:AH7) -> 17955937 | AI8: =SUM(AI5:AI7) -> 157588 | AJ8: =IF(AK8=0,0,(AK8/AI8)) -> 106.53144 | AK8: =SUM(AK5:AK7) -> 16788076 | AL8: =SUM(AL5:AL7) -> 143489 | AM8: =IF(AN8=0,0,(AN8/AL8)) -> 123.87463 | AN8: =SUM(AN5:AN7) -> 17774647 | AO8: =SUM(AO5:AO7) -> 143489 | AP8: =IF(AQ8=0,0,(AQ8/AO8)) -> 123.87463 | AQ8: =SUM(AQ5:AQ7) -> 17774647 | AR8: =SUM(AR5:AR7) -> 0 | AT8: =SUM(AT5:AT7) -> 0 | AU8: =SUM(AU5:AU7) -> 0 | AW8: =SUM(AW5:AW7) -> 0 | AX8: =Z8-B8 -> -30789 | AY8: =AX8/B8 -> -0.15586131 | BA8: =SUM(BA5:BA7) -> 167760 | BB8: =BC8/BA8 -> 103.24481 | BC8: =SUM(BC5:BC7) -> 17320350 | BE8: =SUM(BE5:BE7) -> 166265.3
A9: Work in Progress
A10: HDPE Tape - Factory | B10: 49725 | C10: 154 | D10: =B10*C10 -> 7657650 | E10: 56270 | F10: 153 | G10: =ROUND(E10*F10,0) -> 8609310 | H10: 46564 | I10: 153 | J10: =ROUND(H10*I10,0) -> 7124292 | K10: 52761 | L10: 153 | M10: =ROUND(K10*L10,0) -> 8072433 | N10: 48737 | O10: 147 | P10: =ROUND(N10*O10,0) -> 7164339 | Q10: 49390 | R10: 149 | S10: =ROUND(Q10*R10,0) -> 7359110 | T10: =56274 -> 56274 | U10: 150 | V10: =ROUND(T10*U10,0) -> 8441100 | W10: 60796 | X10: 149 | Y10: =ROUND((W10*X10),0) -> 9058604 | Z10: 57318 | AA10: 147 | AB10: =ROUND((Z10*AA10),0) -> 8425746 | AC10: 54866 | AD10: =IF(AE10=0,0,(AE10/AC10)) -> 146 | AE10: 8010436 | AF10: 47774 | AG10: =IF(AH10=0,0,(AH10/AF10)) -> 147 | AH10: 7022778 | AI10: 51822 | AJ10: 151 | AK10: 7825122 | AL10: 37996 | AM10: 167 | AN10: 6345333 | AO10: 37996 | AP10: =IF(AQ10=0,0,(AQ10/AO10)) -> 167 | AQ10: 6345332 | AR10: =' Qty Analysis'!BE66 -> 0 | AT10: =ROUND((AS10*AR10),0) -> 0 | AU10: =' Qty Analysis'!BH66 -> 0 | AW10: =ROUND((AV10*AU10),0) -> 0 | AX10: =Z10-B10 -> 7593 | AY10: =AX10/B10 -> 0.15269985 | BA10: 24480 | BB10: 163 | BC10: =ROUND((BA10*BB10),0) -> 3990240 | BE10: 24112
A11: HDPE Tape - Job Work | B11: 76468 | C11: 154 | D11: =B11*C11 -> 11776072 | E11: 63906 | F11: =F10 -> 153 | G11: =ROUND(E11*F11,0) -> 9777618 | H11: 61851 | I11: =I10 -> 153 | J11: =ROUND(H11*I11,0) -> 9463203 | K11: 66528 | L11: =L10 -> 153 | M11: =ROUND(K11*L11,0) -> 10178784 | N11: 73740 | O11: 147 | P11: =ROUND(N11*O11,0) -> 10839780 | Q11: 77585 | R11: =R10 -> 149 | S11: =ROUND(Q11*R11,0) -> 11560165 | T11: 79080 | U11: =U10 -> 150 | V11: =ROUND(T11*U11,0) -> 11862000 | W11: 80193 | X11: 149 | Y11: =ROUND((W11*X11),0)-1 -> 11948756 | Z11: 85004 | AA11: =AA10 -> 147 | AB11: =ROUND((Z11*AA11),0) -> 12495588 | AC11: 91727 | AD11: =IF(AE11=0,0,(AE11/AC11)) -> 146 | AE11: 13392142 | AF11: 91742 | AG11: =IF(AH11=0,0,(AH11/AF11)) -> 147 | AH11: 13486074 | AI11: 86544 | AJ11: =AJ10 -> 151 | AK11: 13068144 | AL11: 64171 | AM11: 167 | AN11: 10716557 | AO11: 64171 | AP11: =IF(AQ11=0,0,(AQ11/AO11)) -> 167 | AQ11: 10716557 | AR11: =' Qty Analysis'!BE81 -> 0 | AT11: =ROUND((AS11*AR11),0) -> 0 | AU11: =' Qty Analysis'!BH81 -> 0 | AW11: =ROUND((AV11*AU11),0) -> 0 | AX11: =Z11-B11 -> 8536 | AY11: =AX11/B11 -> 0.11162839 | BA11: 66292 | BB11: 163 | BC11: =ROUND((BA11*BB11),0) -> 10805596 | BE11: 66292
A12: Total | B12: =SUM(B10:B11) -> 126193 | C12: =D12/B12 -> 154 | D12: =SUM(D10:D11) -> 19433722 | E12: =SUM(E10:E11) -> 120176 | F12: =G12/E12 -> 153 | G12: =SUM(G10:G11) -> 18386928 | H12: =SUM(H10:H11) -> 108415 | J12: =SUM(J10:J11) -> 16587495 | K12: =SUM(K10:K11) -> 119289 | M12: =SUM(M10:M11) -> 18251217 | N12: =SUM(N10:N11) -> 122477 | P12: =SUM(P10:P11) -> 18004119 | Q12: =SUM(Q10:Q11) -> 126975 | S12: =SUM(S10:S11) -> 18919275 | T12: =SUM(T10:T11) -> 135354 | V12: =SUM(V10:V11) -> 20303100 | W12: =SUM(W10:W11) -> 140989 | X12: =IF(Y12=0,0,(Y12/W12)) -> 148.99999 | Y12: =SUM(Y10:Y11) -> 21007360 | Z12: =SUM(Z10:Z11) -> 142322 | AB12: =SUM(AB10:AB11) -> 20921334 | AC12: =SUM(AC10:AC11) -> 146593 | AD12: =IF(AE12=0,0,(AE12/AC12)) -> 146 | AE12: =SUM(AE10:AE11) -> 21402578 | AF12: =SUM(AF10:AF11) -> 139516 | AH12: =SUM(AH10:AH11) -> 20508852 | AI12: =SUM(AI10:AI11) -> 138366 | AK12: =SUM(AK10:AK11) -> 20893266 | AL12: =SUM(AL10:AL11) -> 102167 | AN12: =SUM(AN10:AN11) -> 17061890 | AO12: =SUM(AO10:AO11) -> 102167 | AP12: =IF(AQ12=0,0,(AQ12/AO12)) -> 167 | AQ12: =SUM(AQ10:AQ11) -> 17061889 | AR12: =SUM(AR10:AR11) -> 0 | AT12: =SUM(AT10:AT11) -> 0 | AU12: =SUM(AU10:AU11) -> 0 | AW12: =SUM(AW10:AW11) -> 0 | AX12: =Z12-B12 -> 16129 | AY12: =AX12/B12 -> 0.12781216 | BA12: =SUM(BA10:BA11) -> 90772 | BB12: =BC12/BA12 -> 163 | BC12: =SUM(BC10:BC11) -> 14795836 | BE12: =SUM(BE10:BE11) -> 90404
A13: FINISHED GOODS:
